Workbook

Sheet Resumen
A1: Universidad Distrital vs. Maestría en Ciencias de la Información y las Comunicaciones (MCIC)
A2: Cifras generales de la U (presentación institucional, visita CNA 23-25 sep 2026) y la porción que corresponde a la MCIC (SNIES 17528 y 116070)
A3: Azul = dato de la fuente · Negro = fórmula · Verde = vínculo a otra hoja · Amarillo = indicador clave
A5: Dimensión | B5: Indicador | C5: Universidad Distrital | D5: Referencia intermedia | E5: Valor ref. | F5: MCIC | G5: % MCIC / UD | H5: % MCIC / ref. | I5: Hoja de detalle
A6: Estudiantes | B6: Estudiantes matriculados 2026-1 | C6: ='Estudiantes'!$B$6 | D6: Maestría UD | E6: ='Estudiantes'!$B$10 | F6: ='Estudiantes'!$F$20 | G6: =IF(C6>0,F6/C6,"") | H6: =IF(E6>0,F6/E6,"") | I6: Estudiantes
A7: Estudiantes | B7: · Modalidad Investigación / Profundización | F7: ='Estudiantes'!$B$23&" / "&'Estudiantes'!$B$24 | I7: Estudiantes
A8: Docentes | B8: Docentes (núcleo del programa) | C8: ='Docentes'!$D$11 | D8: Planta UD | E8: ='Docentes'!$B$10 | F8: ='Docentes'!$B$33 | G8: =IF(C8>0,F8/C8,"") | H8: =IF(E8>0,F8/E8,"") | I8: Docentes
A9: Docentes | B9: Docentes que dirigen o codirigen trabajos de grado | C9: ='Docentes'!$D$11 | F9: ='Docentes'!$B$49 | G9: =IF(C9>0,F9/C9,"") | I9: Docentes
A10: Docentes | B10: Docentes con doctorado | C10: ='Docentes'!$D$6 | F10: ='Docentes'!$B$34 | G10: =IF(C10>0,F10/C10,"") | I10: Docentes
A11: Docentes | B11: % docentes con doctorado | C11: ='Docentes'!$D$12 | F11: ='Docentes'!$B$35 | I11: Docentes
A12: Docentes | B12: % reconocidos como investigador (MinCiencias) | C12: ='Docentes'!$C$42 | F12: ='Docentes'!$B$42 | I12: Docentes
A13: Docentes | B13: Estudiantes por docente | C13: ='Estudiantes'!$B$6/'Docentes'!$D$11 | D13: Por docente que dirige/codirige | E13: ='Estudiantes'!$F$20/'Docentes'!$B$49 | F13: ='Estudiantes'!$F$20/'Docentes'!$B$33 | I13: Docentes
A14: Investigación | B14: Grupos de investigación | C14: ='Investigación'!$B$12 | D14: Facultad de Ingeniería | E14: ='Investigación'!$C$12 | F14: ='Investigación'!$D$12 | G14: =IF(C14>0,F14/C14,"") | I14: Investigación
A15: Investigación | B15: Grupos en categoría A1 o A | C15: ='Investigación'!$B$13 | D15: Facultad de Ingeniería | E15: ='Investigación'!$C$13 | F15: ='Investigación'!$D$13 | G15: =IF(C15>0,F15/C15,"") | I15: Investigación
A16: Investigación | B16: % grupos A1 + A | C16: ='Investigación'!$B$14 | D16: Facultad de Ingeniería | E16: ='Investigación'!$C$14 | F16: ='Investigación'!$D$14 | I16: Investigación
A17: Graduados | B17: Graduados últimos 5 años | C17: ='Graduados'!$B$6 | D17: Posgrado UD | E17: ='Graduados'!$B$8 | F17: ='Graduados'!$B$18 | G17: =IF(C17>0,F17/C17,"") | H17: =IF(E17>0,F17/E17,"") | I17: Graduados
A18: Graduados | B18: Graduados históricos | C18: ='Graduados'!$B$9 | F18: ='Graduados'!$C$31 | G18: =IF(C18>0,F18/C18,"") | I18: Graduados
A19: Internacionalización | B19: Convenios vigentes | C19: ='Internacionalización'!$B$7 | D19: Relacionados con Ingeniería | E19: ='Internacionalización'!$B$10 | F19: ='Internacionalización'!$B$11 | G19: =IF(C19>0,F19/C19,"") | H19: =IF(E19>0,F19/E19,"") | I19: Internacionalización
A20: Internacionalización | B20: Estudiantes en movilidad saliente | C20: ='Internacionalización'!$B$34 | F20: ='Internacionalización'!$C$34 | G20: =IF(C20>0,F20/C20,"") | I20: Internacionalización
A21: Internacionalización | B21: Docentes en movilidad saliente | C21: ='Internacionalización'!$B$35 | F21: ='Internacionalización'!$C$35 | G21: =IF(C21>0,F21/C21,"") | I21: Internacionalización
A22: Internacionalización | B22: Docentes visitantes | C22: ='Internacionalización'!$B$36 | F22: ='Internacionalización'!$C$36 | G22: =IF(C22>0,F22/C22,"") | I22: Internacionalización
A23: Infraestructura | B23: Laboratorios (UAL) / espacios relacionados | C23: ='Infraestructura'!$B$13 | D23: UAL Facultad de Ingeniería | E23: ='Infraestructura'!$B$8 | F23: ='Infraestructura'!$B$23 | I23: Infraestructura
A25: Lectura rápida
A26: • La MCIC tiene cerca del 0,5 % de los estudiantes de la U, pero alrededor del 14 % de los estudiantes de maestría.
A27: • De los 1.989 docentes de la U, 11 conforman el núcleo que la MCIC reporta al CNA (0,6 %); 10 tienen doctorado (91 % vs. 26 % en la U).
A28: • La base de docentes que realmente sostiene el programa es más amplia: los que hoy dirigen o codirigen trabajos de grado y los integrantes de los 19 grupos del directorio.
A29: • El 47 % de los grupos que soportan la MCIC está en A1 o A, frente al 20 % en la U y el 22 % en Ingeniería.
A30: • Internacionalización y bienestar son los puntos más débiles en comparación: solo 3 convenios aplican expresamente al posgrado y el uso de bienestar registrado es muy bajo.
A31: • No hay en Data/ cifras de presupuesto propio de la MCIC; el presupuesto de la presentación es institucional ($668.317 millones en 2026).
A33: Indicadores relativos (para el gráfico)
A34: Indicador | B34: UD | C34: MCIC
A35: % docentes con doctorado | B35: ='Docentes'!$D$12 | C35: ='Docentes'!$B$35
A36: % docentes reconocidos como investigador | B36: ='Docentes'!$C$42 | C36: ='Docentes'!$B$42
A37: % grupos A1 + A | B37: ='Investigación'!$B$14 | C37: ='Investigación'!$D$14
A39: Participación de la MCIC en la U | B39: %
A40: Estudiantes (sobre total UD) | B40: ='Estudiantes'!$B$28
A41: Estudiantes (sobre maestría UD) | B41: ='Estudiantes'!$B$30
A42: Graduados 5 años (sobre posgrado UD) | B42: ='Graduados'!$B$19
A43: Convenios aplicables | B43: ='Internacionalización'!$B$12
A44: Docentes núcleo (sobre total UD) | B44: ='Docentes'!$B$52
...

Sheet Estudiantes
A1: Estudiantes
A2: UD 2026-1 (presentación institucional) vs. MCIC 2026-1 (estudiantes activos por énfasis)
A4: A. Universidad Distrital — Población estudiantil 2026-1
A5: Concepto | B5: Estudiantes | C5: Fuente
A6: Total estudiantes UD | B6: 28549 | C6: Presentación institucional 23-sep-2026 (PRES_INST_23_SEPTIEMBRE_2026 VF.pdf), diap. 4
A7: Pregrado | B7: 26523 | C7: Presentación institucional 23-sep-2026 (PRES_INST_23_SEPTIEMBRE_2026 VF.pdf), diap. 4
A8: Posgrado | B8: 2026 | C8: Presentación institucional 23-sep-2026 (PRES_INST_23_SEPTIEMBRE_2026 VF.pdf), diap. 4
A9: Doctorado | B9: 290 | C9: Presentación institucional 23-sep-2026 (PRES_INST_23_SEPTIEMBRE_2026 VF.pdf), diap. 4
A10: Maestría | B10: 1147 | C10: Presentación institucional 23-sep-2026 (PRES_INST_23_SEPTIEMBRE_2026 VF.pdf), diap. 4
A11: Especialización | B11: 589 | C11: Presentación institucional 23-sep-2026 (PRES_INST_23_SEPTIEMBRE_2026 VF.pdf), diap. 4
A12: Facultad de Ingeniería (pre + posgrado) | B12: 6093 | C12: Presentación institucional 23-sep-2026 (PRES_INST_23_SEPTIEMBRE_2026 VF.pdf), diap. 4
A14: B. MCIC — Estudiantes activos 2026-1 por modalidad y énfasis
A15: Plan / modalidad | B15: Geomática | C15: Ingeniería De Software | D15: Teleinformática | E15: Inteligencia Artificial | F15: Total
A16: MCIC. Énfasis en Investigación | B16: 7 | C16: 8 | D16: 10 | E16: 0 | F16: =SUM(B16:E16)
A17: MCIC. Énfasis en Profundización | B17: 3 | C17: 12 | D17: 6 | E17: 0 | F17: =SUM(B17:E17)
A18: MCIC. Investigación | B18: 9 | C18: 18 | D18: 12 | E18: 15 | F18: =SUM(B18:E18)
A19: MCIC. Profundización | B19: 27 | C19: 12 | D19: 6 | E19: 11 | F19: =SUM(B19:E19)
A20: Total MCIC | B20: =SUM(B16:B19) | C20: =SUM(C16:C19) | D20: =SUM(D16:D19) | E20: =SUM(E16:E19) | F20: =SUM(F16:F19)
A21: Fuente: Data/Bronze/Maestria CIC/Énfasis estudiantes - Consolidado.xlsx (actualizado 2026-1). Coincide con los 'Matriculados' de Cóndor (Data/Bronze/Estados).
A23: Modalidad Investigación (SNIES 17528) | B23: =F16+F18
A24: Modalidad Profundización (SNIES 116070) | B24: =F17+F19
A26: C. Participación de la MCIC en la población de la U
A27: Indicador | B27: Valor | C27: Cómo se calcula
A28: MCIC / total estudiantes UD | B28: =F20/$B$6 | C28: MCIC (F20) ÷ total estudiantes UD
A29: MCIC / estudiantes de posgrado UD | B29: =F20/$B$8 | C29: MCIC (F20) ÷ estudiantes de posgrado UD
A30: MCIC / estudiantes de maestría UD | B30: =F20/$B$10 | C30: MCIC (F20) ÷ estudiantes de maestría UD
A31: MCIC / estudiantes Facultad de Ingeniería | B31: =F20/$B$12 | C31: MCIC (F20) ÷ estudiantes Facultad de Ingeniería
A33: D. MCIC — Histórico Cuadro Maestro CNA No. 02 (programa completo)
A34: Periodo | B34: Inscritos | C34: Admitidos | D34: Tasa selectividad | E34: Matriculados (total) | F34: Matriculados 1er curso | G34: Graduados
A35: 2019-I | B35: 44 | C35: 42 | D35: =IF(AND(ISNUMBER(B35),B35>0),C35/B35,"") | E35: 266 | F35: 42 | G35: 7
A36: 2019-II | B36: 31 | C36: 31 | D36: =IF(AND(ISNUMBER(B36),B36>0),C36/B36,"") | E36: 275 | F36: 31 | G36: 5
A37: 2020-I | B37: 29 | C37: 28 | D37: =IF(AND(ISNUMBER(B37),B37>0),C37/B37,"") | E37: 285 | F37: 28 | G37: 5
A38: 2020-II | B38: 64 | C38: 42 | D38: =IF(AND(ISNUMBER(B38),B38>0),C38/B38,"") | E38: 334 | F38: 41 | G38: 16
A39: 2021-I | B39: 31 | C39: 31 | D39: =IF(AND(ISNUMBER(B39),B39>0),C39/B39,"") | E39: 328 | F39: 31 | G39: 14
A40: 2021-II | B40: 19 | C40: 19 | D40: =IF(AND(ISNUMBER(B40),B40>0),C40/B40,"") | E40: 308 | F40: 18 | G40: 23
A41: 2022-I | B41: 25 | C41: 25 | D41: =IF(AND(ISNUMBER(B41),B41>0),C41/B41,"") | E41: 283 | F41: 25 | G41: 19
A42: 2022-II | D42: =IF(AND(ISNUMBER(B42),B42>0),C42/B42,"") | E42: 250 | G42: 16
A43: 2023-I | D43: =IF(AND(ISNUMBER(B43),B43>0),C43/B43,"") | E43: 216 | G43: 24
A44: 2023-II | D44: =IF(AND(ISNUMBER(B44),B44>0),C44/B44,"") | E44: 164 | G44: 15
A45: 2024-I | B45: 10 | C45: 10 | D45: =IF(AND(ISNUMBER(B45),B45>0),C45/B45,"") | E45: 155 | F45: 10 | G45: 13
...

Sheet Docentes
A1: Docentes
A2: UD 2026-1: 1.989 docentes. ¿Cuántos corresponden a la MCIC? (Cuadros Maestros CNA No. 05 y 06, bases de trabajos de grado)
A4: A. Universidad Distrital — Planta docente 2026-1 por nivel de formación
A5: Nivel de formación | B5: Planta | C5: Vinculación especial | D5: Total
A6: Doctorado | B6: 343 | C6: 175 | D6: =B6+C6
A7: Maestría | B7: 255 | C7: 925 | D7: =B7+C7
A8: Especialización | B8: 21 | C8: 135 | D8: =B8+C8
A9: Pregrado | B9: 7 | C9: 129 | D9: =B9+C9
A10: Total (suma) | B10: =SUM(B6:B9) | C10: =SUM(C6:C9) | D10: =SUM(D6:D9)
A11: Total reportado en la presentación | D11: 1989
A12: % docentes con doctorado (UD) | D12: =$D$6/$D$10
A13: % docentes de vinculación especial (UD) | D13: =C10/D10
A14: Fuente: Presentación institucional 23-sep-2026 (PRES_INST_23_SEPTIEMBRE_2026 VF.pdf), diap. 5.
A16: B. MCIC — Profesores del núcleo (Cuadro Maestro CNA No. 05, igual en ambas modalidades)
A17: Profesor | B17: Nivel máx. formación | C17: Título | D17: Escalafón | E17: Grupo de investigación | F17: Categoría MinCiencias | G17: Tipo de contrato | H17: Dedicación | I17: Asignatura(s) | J17: Horas/periodo | K17: Art. nal. | L17: Art. int. | M17: Libros/cap. | N17: Patentes
A18: Perdomo Charry Cesar Andrey | B18: Doctorado | C18: Doctorado en Ingeniería | D18: PROFESOR TITULAR COMPLETO | E18: LASER | F18: Senior | G18: fijo menos 11 meses al año | H18: Hora Cátedra | I18: SEMINARIO DE INVESTIGACIÓN | J18: 64 | K18: 0 | L18: 0 | M18: 1 | N18: 29
A19: Gomez Vargas Ernesto | B19: Doctorado | C19: Doctorado en Ingeniería | D19: PROFESOR TITULAR COMPLETO | E19: LASER | F19: Asociado | G19: fijo menos 11 meses al año | H19: Hora Cátedra | I19: SEMINARIO DE INVESTIGACIÓN | J19: 64 | K19: 0 | L19: 0 | M19: 4 | N19: 9
A20: Ortiz Davila Alvaro Enrique | B20: Doctorado | C20: Doctorado en Ingeniería | D20: PROFESOR ASOCIADO COMPLETO | E20: NIDE | F20: Asociado | G20: indefinido | H20: Tiempo completo | I20: BASES DE DATOS / BASES DE DATOS ESPECIALES / INGENIERIA DE SOTFWARE II | J20: 192 | K20: 4 | L20: 0 | M20: 3 | N20: 13
A21: Valero Medina Jose Antonio | B21: Doctorado | C21: Doctorado en Ingeniería | D21: PROFESOR TITULAR COMPLETO | E21: NIDE | F21: Junior | G21: indefinido | H21: Tiempo completo | I21: SEMINARIO DE INVESTIGACIÓN | J21: 64 | K21: 10 | L21: 0 | M21: 1 | N21: 1
A22: Diosa Henry Alberto | B22: Doctorado | C22: Doctorado en Ingeniería | D22: PROFESOR ASOCIADO COMPLETO | E22: ARQUISOFT | F22: Junior | G22: indefinido | H22: Tiempo completo | I22: PATRONES Y ARQUITECTURA DE SOFTWARE | J22: 64 | K22: 6 | L22: 0 | M22: 0 | N22: 0
A23: Rodriguez Rodriguez Jorge Enrique | B23: Doctorado | C23: Doctorado en Ingeniería | D23: PROFESOR TITULAR COMPLETO | E23: SIN GRUPO DE LA FACULTAD DE INGENIERÍA | F23: Junior | G23: fijo menos 11 meses al año | H23: Hora Cátedra | I23: ANÁLISIS DE DATOS | J23: 64 | K23: 0 | L23: 0 | M23: 0 | N23: 2
A24: Lopez Chavez Hans Igor | B24: Maestría | C24: Maestria en Ciencias de la Informacion y Comunicaciones | D24: PROFESOR TITULAR COMPLETO | E24: IDEAS | F24: Junior | G24: fijo menos 11 meses al año | H24: Hora Cátedra | I24: HERRAMIENTAS MATEMÁTICAS PARA EL MANEJO DE LA INFORMACIÓN | J24: 64 | K24: 0 | L24: 0 | M24: 0 | N24: 4
A25: Castillo Mendez Luis Eduardo | B25: Doctorado | C25: Doctorado en Ciencias -Estadistica | D25: PROFESOR TITULAR COMPLETO | E25: GEFEM | F25: Sin categoría | G25: fijo menos 11 meses al año | H25: Hora Cátedra | I25: INFORMATICA / ESTADISTICA ESPACIAL | J25: 128 | K25: 0 | L25: 0 | M25: 0 | N25: 1
A26: Salcedo Parra Octavio Jose | B26: Doctorado | C26: Doctorado en Ingeniería Informática | D26: PROFESOR TITULAR COMPLETO | E26: INTERNET INTELIGENTE | F26: Senior | G26: indefinido | H26: Tiempo completo | I26: REDES | J26: 64 | K26: 6 | L26: 6 | M26: 3 | N26: 54
A27: Jutinico Alarcon Andres Leonardo | B27: Doctorado | C27: Doutorado em Engenharia Mecânica | D27: PROFESOR ASOCIADO COMPLETO | E27: LASER | F27: Junior | G27: Sin dato | H27: Sin dato | I27: ROBÓTICA | J27: 64 | K27: 0 | L27: 0 | M27: 0 | N27: 0
A28: Alzate Monroy Marco Aurelio | B28: Doctorado | C28: Doctorado en Ingeniería | D28: TITULAR XXII | E28: IDEAS | F28: Sin categoría | G28: indefinido | H28: Tiempo completo | I28: PROCESOS ESTOCÁSTICOS | J28: 64 | K28: 12 | L28: 0 | M28: 0 | N28: 2
A29: Fuente: SNIES17528 y SNIES116070-Cuadros maestros.xlsx, hoja 'Profesores Listado_Detallad'. Jutinico: el cuadro no trae tipo de contrato ni dedicación.
A31: C. MCIC — Resumen del núcleo docente (fórmulas sobre la tabla B)
A32: Indicador | B32: MCIC | C32: UD | D32: Comentario
A33: Profesores del núcleo (Cuadro 05) | B33: =COUNTA(A18:A28) | C33: =$D$11 | D33: Profesores que el programa reporta al CNA como su planta docente.
A34: Con doctorado | B34: =COUNTIF(B18:B28,"Doctorado") | C34: =$D$6
A35: % con doctorado | B35: =B34/B33 | C35: =C34/C33 | D35: Indicador clave de calidad docente.
A36: Tiempo completo (término indefinido) | B36: =COUNTIF(H18:H28,"Tiempo completo")
A37: Hora cátedra | B37: =COUNTIF(H18:H28,"Hora Cátedra") | D37: Son profesores titulares de planta que dictan en la maestría como carga de hora cátedra.
A38: Investigador Sénior | B38: =COUNTIF(F18:F28,"Senior") | C38: 52 | D38: UD: docentes de planta (Conv. 957).
A39: Investigador Asociado | B39: =COUNTIF(F18:F28,"Asociado") | C39: 69
A40: Investigador Júnior | B40: =COUNTIF(F18:F28,"Junior") | C40: 122
A41: Sin categoría / no reconocido | B41: =COUNTIF(F18:F28,"Sin categoría") | C41: 373
A42: % reconocidos como investigador | B42: =SUM(B38:B40)/B33 | C42: =SUM(C38:C40)/SUM(C38:C41) | D42: UD: 243 de 616 docentes de planta.
A43: Artículos (nal. + int.) últimos años | B43: =SUM(K18:K28)+SUM(L18:L28) | D43: Producción declarada en el Cuadro 05.
...

Sheet Investigación
A1: Investigación
A2: Grupos UD (Convocatoria 957) vs. grupos que soportan la MCIC (Directorio de grupos MCIC)
A4: A. Grupos de investigación por categoría
A5: Categoría | B5: UD | C5: Facultad de Ingeniería | D5: MCIC
A6: A1 | B6: 9 | C6: 1 | D6: =COUNTIF($C$20:$C$38,"A1")
A7: A | B7: 29 | C7: 7 | D7: =COUNTIF($C$20:$C$38,"A")
A8: B | B8: 22 | C8: 7 | D8: =COUNTIF($C$20:$C$38,"B")
A9: C | B9: 48 | C9: 8 | D9: =COUNTIF($C$20:$C$38,"C")
A10: Reconocido | B10: 10 | C10: 0 | D10: =COUNTIF($C$20:$C$38,"Reconocido")
A11: No reconocido | B11: 70 | C11: 13 | D11: =COUNTIF($C$20:$C$38,"No reconocido")
A12: Total | B12: =SUM(B6:B11) | C12: =SUM(C6:C11) | D12: =SUM(D6:D11)
A13: A1 + A (alta categoría) | B13: =B6+B7 | C13: =C6+C7 | D13: =D6+D7
A14: % A1 + A sobre total | B14: =B13/B12 | C14: =C13/C12 | D14: =D13/D12
A15: UD y Ingeniería: Presentación institucional 23-sep-2026 (PRES_INST_23_SEPTIEMBRE_2026 VF.pdf), diap. 35 (se usan las barras por facultad: 70 no reconocidos; la cifra resumen de la diapositiva dice 68).
A16: MCIC: Directorio Grupos de Inv MCIC.xlsx (19 grupos, clasificación registrada en cada hoja).
A18: B. MCIC — Grupos que soportan la maestría
A19: Sigla | B19: Nombre | C19: Categoría | D19: Líder | E19: Docentes integrantes
A20: GCEM | B20: Grupo de Compatibilidad e Interferencia Electromagnética | C20: A1 | D20: Edwin Rivas Trujillo | E20: 4
A21: GICOECOL | B21: Comercio Electronico en Colombia | C21: A1 | D21: José Ignacio Rodríguez Molano | E21: 2
A22: GICOGE | B22: Grupo Informática Comunicaciones y Gestión del conocimiento | C22: A1 | D22: José Nelson Pérez Castillo | E22: 8
A23: GIIRA | B23: Grupo de Investigación en Interconexión de Redes Académicas | C23: A1 | D23: Carlos Enrique Montenegro Marín | E23: 6
A24: LIFAE | B24: Laboratorio de Investigación en Fuentes Alternativas de Energía | C24: A1 | D24: Nelson Díaz Aldana | E24: 3
A25: ITI | B25: ITI: Innovación en Tecnologías de Información | C25: A | D25: Hector Florez | E25: 1
A26: LAMIC | B26: Laboratorio de Automática e Inteligencia Computacional | C26: A | D26: Andrés Eduardo Gaona Barrera | E26: 4
A27: LIDER | B27: Laboratorio de Investigación y Desarrollo en Electrónica y Redes | C27: A | D27: Roberto Ferro Escobar | E27: 3
A28: NIDE | B28: Núcleo de Investigación en Datos Espaciales | C28: A | D28: Luz Ángela Rocha Salamanca | E28: 13
A29: GITUD | B29: Grupo de investigación en Telecomunicaciones de la Universidad Distrital | C29: B | D29: Elvis Eduardo Gaona García | E29: 6
A30: GRECO | B30: Grupo de Radiación Electromagnética y Comunicaciones Ópticas | C30: B | D30: Carlos Arturo Suárez Fajardo | E30: 3
A31: INTECSE | B31: Interoperabilidad Tecnología y Semántica | C31: B | D31: Julio Barón Velandia | E31: 2
... A38: GITEM++ | B38: Grupo de Investigación de Telemedicina | C38: C | D38: Lilia Edith Aparicio Pico | E38: 5
A39: Docentes integrantes = filas del directorio (incluye docentes marcados 'pendiente'); un docente puede estar en más de un grupo.
A41: C. MCIC — Procesos de trabajo de grado por etapa y modalidad
A42: Etapa | B42: Investigación | C42: Profundización | D42: Total
A43: Anteproyecto radicado | B43: 2 | C43: 2 | D43: =B43+C43
A44: Anteproyecto radicado, pendiente asignación de jurados | B44: 158 | C44: 109 | D44: =B44+C44
A45: Sustentado | B45: 92 | C45: 41 | D45: =B45+C45
A46: Jurados solicitados | B46: 5 | C46: 6 | D46: =B46+C46
A47: Jurados solicitados, pendiente sustentación | B47: 40 | C47: 12 | D47: =B47+C47
A48: Sustentado (Meritorio) | B48: 20 | C48: 6 | D48: =B48+C48
A49: Sustentado (Aprobado) | B49: 55 | C49: 42 | D49: =B49+C49
...

Sheet Graduados
A1: Graduados
A2: UD: graduados últimos 5 años e histórico vs. MCIC
A4: A. Universidad Distrital
A5: Concepto | B5: Graduados | C5: Fuente
A6: Graduados últimos 5 años (total) | B6: 21994 | C6: Presentación institucional 23-sep-2026 (PRES_INST_23_SEPTIEMBRE_2026 VF.pdf), diap. 4
A7: Pregrado | B7: 17297 | C7: Presentación institucional 23-sep-2026 (PRES_INST_23_SEPTIEMBRE_2026 VF.pdf), diap. 4
A8: Posgrado | B8: 4697 | C8: Presentación institucional 23-sep-2026 (PRES_INST_23_SEPTIEMBRE_2026 VF.pdf), diap. 4
A9: Total graduados históricos | B9: 115975 | C9: Presentación institucional 23-sep-2026 (PRES_INST_23_SEPTIEMBRE_2026 VF.pdf), diap. 4
A11: B. MCIC — Graduados por año (2022-2026, año estimado)
A12: Año | B12: Graduados MCIC
A13: 2022 | B13: 35
A14: 2023 | B14: 39
A15: 2024 | B15: 28
A16: 2025 | B16: 36
A17: 2026 | B17: 15
A18: Total 2022-2026 | B18: =SUM(B13:B17)
A19: % de los graduados de posgrado UD (5 años) | B19: =$B$18/$B$8
A20: Año estimado con la última matrícula (Cóndor no guarda fecha de grado); validado 100 % contra actas 2022-2023. 2026 es parcial.
A22: C. MCIC — Graduados históricos por código de proyecto curricular
A23: Código | B23: Proyecto curricular | C23: Graduados | D23: Matriculados hoy | E23: Incluir en MCIC
A24: 195 | B24: MAE. EN CIENCIAS DE LA INF. Y LAS COMUNICACIONES ENFASIS EN TELEINF. | C24: 167 | D24: 14 | E24: Sí
A25: 295 | B25: MAE. EN CIENCIAS DE LA INF. Y LAS COMUNICACIONES ENFASIS EN SIS. INFOR | C25: 109 | D25: 0 | E25: Sí
A26: 395 | B26: MAE. EN CIENCIAS DE LA INF. Y LAS COMUNICACIONES ENFASIS EN GEOMATICA | C26: 88 | D26: 9 | E26: Sí
A27: 495 | B27: MAE. EN CIENCIAS DE LA INF. Y LAS COMUNICACIONES ENFASIS EN ING. SOFT | C27: 78 | D27: 26 | E27: Sí
A28: 595 | B28: MAESTRÍA EN CIENCIAS DE LA INFORMACIÓN Y LAS COMUNICACIONES | C28: 4 | D28: 49 | E28: Sí
A29: 695 | B29: MAESTRÍA EN CIENCIAS DE LA INFORMACIÓN Y LAS COMUNICACIONES | C29: 10 | D29: 58 | E29: Sí
A30: 95 | B30: MAESTRIA EN TELEINFORMATICA | C30: 121 | D30: 0 | E30: No (antecesor)
A31: Total MCIC (sin Maestría en Teleinformática) | C31: =SUMIF(E24:E30,"Sí",C24:C30) | D31: =SUMIF(E24:E30,"Sí",D24:D30)
A32: Incluyendo Maestría en Teleinformática (cód. 95) | C32: =SUM(C24:C30)
A33: % de los graduados históricos UD | C33: =$C$31/$B$9
A34: Fuente: Data/Bronze/Estados/Listado_de_estudiantes_por_estado_*.csv (Cóndor). 'Matriculados hoy' no incluye estudiantes en vacaciones.
A36: D. MCIC — Cuadro Maestro CNA No. 04 (graduación por periodo)
A37: Periodo | B37: Matrícula total | C37: Graduados
A38: 2019-I | B38: 266 | C38: 7
A39: 2019-II | B39: 275 | C39: 5
A40: 2020-I | B40: 285 | C40: 5
A41: 2020-II | B41: 334 | C41: 16
A42: 2021-I | B42: 328 | C42: 14
A43: 2021-II | B43: 308 | C43: 23
A44: 2022-I | B44: 283 | C44: 19
...

Sheet Internacionalización
A1: Internacionalización y convenios
A2: UD (URELINTER) vs. MCIC (Cuadros Maestros CNA No. 07 y 09, cruce de convenios)
A4: A. Convenios
A5: Concepto | B5: Cantidad | C5: Fuente
A6: Convenios suscritos UD 2026 (presentación) | B6: 386 | C6: Presentación institucional 23-sep-2026 (PRES_INST_23_SEPTIEMBRE_2026 VF.pdf), diap. 51
A7: Convenios vigentes en el listado URELINTER | B7: 388 | C7: Convenios vigentes URELINTER.xlsx
A8: Nacionales | B8: 167 | C8: Ídem
A9: Internacionales | B9: 221 | C9: Ídem
A10: Relacionados con Ingeniería / áreas de la MCIC (búsqueda por palabras clave) | B10: 7 | C10: Data/Silver/convenios.json
A11: Aplicables a la MCIC (posgrado, objeto no restringido) | B11: 3 | C11: Ídem
A12: % de convenios UD aplicables a la MCIC | B12: =$B$11/$B$7
A13: Ningún convenio de URELINTER menciona por nombre a la MCIC; la aplicabilidad se infiere del objeto del convenio.
A15: Código | B15: Institución | C15: País / categoría | D15: Tipo | E15: Estado | F15: ¿Aplica a MCIC?
A16: C-2012-12 | B16: Comisión Interamericana de Telecomunicaciones de la OEA- CITEL | C16: Estados Unidos | D16: Convenio Marco | E16: Vigencia indefinida | F16: Sí
A17: C-2012-36 | B17: Universidad de Caldas | C17: Colombia IES | D17: Convenio Específico | E17: Renovación Automática | F17: No
A18: C-2016-10 | B18: New Net S.A. | C18: Colombia Otros Organismos | D18: Convenio Específico | E18: Renovación Automática | F18: No
A19: C-2019-28 | B19: Universidad de Valparaiso | C19: Chile | D19: Convenio Específico | E19: Renovación Automática | F19: Sí
A20: C-2022-29 | B20: Universidad Popular Autónoma del Estado de Puebla UPAEP | C20: México | D20: Convenio Específico | E20: Vigente | F20: Sí
A21: C-2023-19 | B21: Fundación UNIR | C21: Colombia IES | D21: Convenio Específico | E21: Vigente | F21: No
A22: C-2025-46 | B22: IMT Ataltique | C22: Francia | D22: Convenio Específico | E22: Vigente | F22: No
A24: B. Movilidad académica
A25: Tipo de movilidad | B25: UD 2021-2026 | C25: MCIC 2019-2025 | D25: % MCIC / UD
A26: Estudiantes salientes – nacional | B26: 45 | C26: 17 | D26: =IF(B26>0,C26/B26,"")
A27: Estudiantes salientes – internacional | B27: 274 | C27: 18 | D27: =IF(B27>0,C27/B27,"")
A28: Estudiantes entrantes – nacional | B28: 30 | C28: 0 | D28: =IF(B28>0,C28/B28,"")
A29: Estudiantes entrantes – internacional | B29: 132 | C29: 0 | D29: =IF(B29>0,C29/B29,"")
A30: Docentes salientes – nacional | B30: 9 | C30: 11 | D30: =IF(B30>0,C30/B30,"")
A31: Docentes salientes – internacional | B31: 50 | C31: 19 | D31: =IF(B31>0,C31/B31,"")
A32: Docentes visitantes – nacional | B32: 48 | C32: 6 | D32: =IF(B32>0,C32/B32,"")
A33: Docentes visitantes – internacional | B33: 326 | C33: 9 | D33: =IF(B33>0,C33/B33,"")
A34: Total estudiantes salientes | B34: =B26+B27 | C34: =C26+C27 | D34: =IF(B34>0,C34/B34,"")
A35: Total docentes salientes | B35: =B30+B31 | C35: =C30+C31 | D35: =IF(B35>0,C35/B35,"")
A36: Total docentes visitantes | B36: =B32+B33 | C36: =C32+C33 | D36: =IF(B36>0,C36/B36,"")
A37: UD: Presentación institucional 23-sep-2026 (PRES_INST_23_SEPTIEMBRE_2026 VF.pdf), diap. 53 (datos a 30-jun-2026). MCIC: Cuadros maestros, hojas 'Estudiante Movilidad' (ambas modalidades, sin registros de docentes) y 'Profesores Movilidad'.
A38: Los periodos no coinciden (UD 2021-2026; MCIC 2019-2025): el % es orientativo.

Sheet Bienestar
A1: Bienestar universitario
A2: UD (atenciones por semestre) vs. MCIC (Cuadro Maestro CNA, Estadísticas de Bienestar)
A4: A. Universidad Distrital — Desarrollo Humano (servicios por semestre)
A5: Servicio | B5: 2025-1 | C5: 2025-3 | D5: 2026-1
A6: Enfermería | B6: 5733 | C6: 4260 | D6: 6545
A7: Medicina | B7: 6214 | C7: 3449 | D7: 5029
A8: Psicología | B8: 1975 | C8: 1663 | D8: 1728
A9: Odontología | B9: 3264 | C9: 1914 | D9: 2463
A10: Fisioterapia | B10: 2412 | C10: 1839 | D10: 3277
A11: Total servicios | B11: =SUM(B6:B10) | C11: =SUM(C6:C10) | D11: =SUM(D6:D10)
A12: Presupuesto Bienestar 2026 (COP) | D12: 12999871529
A13: Presupuesto de bienestar por estudiante UD 2026 (COP) | D13: =$D$12/'Estudiantes'!$B$6
A14: Fuente: Presentación institucional 23-sep-2026 (PRES_INST_23_SEPTIEMBRE_2026 VF.pdf), diap. 56-57.
A16: B. MCIC — Actividades de bienestar registradas para estudiantes del programa
A17: Servicio | B17: 2022-3 | C17: 2023-1 | D17: 2023-3 | E17: 2024-1 | F17: 2024-3
A18: Servicios Medicina | B18: 0 | C18: 1 | D18: 1 | E18: 0 | F18: 1
A19: Servicios Enfermeria | B19: 2 | C19: 3 | D19: 2 | E19: 0 | F19: 2
A20: Servicios Fisioterapia | B20: 0 | C20: 0 | D20: 1 | E20: 0 | F20: 1
A21: Servicios Psicologia | B21: 0 | C21: 2 | D21: 0 | E21: 0 | F21: 0
A22: Acompañamientos Icetex | B22: 0 | C22: 0 | D22: 2 | E22: 0 | F22: 2
A23: Total actividades | B23: =SUM(B18:B22) | C23: =SUM(C18:C22) | D23: =SUM(D18:D22) | E23: =SUM(E18:E22) | F23: =SUM(F18:F22)
A24: Total 2022-3 a 2024-3 | B24: =SUM(B23:F23)
A25: Fuente: SNIES17528-Cuadros maestros.xlsx, hoja 'Estadisticas Bienestar'. Se omiten servicios con 0 en todos los semestres (apoyo alimentario, deportes, talleres, etc.).
A26: Lectura: el uso registrado de bienestar por estudiantes de la MCIC es muy bajo frente al de la U; conviene explicar por qué (estudiantes de posgrado que trabajan, horarios nocturnos/sábados).

Sheet Infraestructura
A1: Infraestructura, laboratorios y recursos compartidos
A2: UAL de la UD por facultad vs. espacios que usa la MCIC
A4: A. Unidades Académicas de Laboratorio (UAL) por facultad — UD
A5: Facultad | B5: UAL | C5: % del total
A6: Artes (ASAB) | B6: 108 | C6: =B6/$B$13
A7: Tecnológica | B7: 98 | C7: =B7/$B$13
A8: Ingeniería | B8: 56 | C8: =B8/$B$13
A9: Matemáticas | B9: 56 | C9: =B9/$B$13
A10: Medio Ambiente | B10: 51 | C10: =B10/$B$13
A11: Ciencias y Educación | B11: 44 | C11: =B11/$B$13
A12: Salud | B12: 13 | C12: =B12/$B$13
A13: Total UAL | B13: =SUM(B6:B12)
A14: Fuente: Presentación institucional 23-sep-2026 (PRES_INST_23_SEPTIEMBRE_2026 VF.pdf), diap. 25 (Resolución 633 de 2022).
A16: B. Espacios de la Facultad de Ingeniería en el nuevo edificio de laboratorios (usados por la MCIC)
A17: Espacio | B17: Cantidad | C17: Relación con la MCIC
A18: Salas de informática | B18: 12 | C18: Asignaturas de software, IA, redes y geomática
A19: Laboratorio de Realidad Aumentada (GIIRA + Multimedia Interactiva) | B19: 1 | C19: Grupo GIIRA (A1) del directorio MCIC
A20: Centro de Análisis NIDE | B20: 2 | C20: Grupo NIDE (A), énfasis Geomática
A21: Laboratorios de Eléctrica y Electrónica | B21: 12 | C21: Énfasis Teleinformática (grupos LASER, GITUD, GRECO)
A22: Laboratorios del Doctorado en Ingeniería | B22: 2 | C22: Compartidos con el doctorado
A23: Espacios relacionados con la MCIC | B23: =SUM(B18:B22)
A24: Fuente: Data/Bronze/PresLabIng-20261-esuarez-01-p36-48.pdf (Dotación Edificio Nuevo de Laboratorios, 2026-1).
A26: C. Recursos institucionales que la MCIC usa en común (no se asignan por programa)
A27: Recurso | B27: UD | C27: Comentario
A28: Área construida total (m²) | B28: 138189.4 | C28: No hay distribución de m² por programa.
A29: Bases de datos bibliográficas suscritas | B29: 56 | C29: Acceso para todos los programas (IEEE, Scopus, etc.).
A30: Libros | B30: 250000 | C30: Colección institucional.
A31: Documentos en el repositorio RIUD | B31: 93000 | C31: Incluye los trabajos de grado de la MCIC.
A32: Puestos de lectura | B32: 1426

Sheet Fuentes y notas
A1: Fuentes, supuestos y alertas
A2: Qué se usó para cada cifra y qué inconsistencias hay que tener presentes
A4: Tema | B4: Nota
A5: Fuente UD | B5: Presentación institucional 23-sep-2026 (PRES_INST_23_SEPTIEMBRE_2026 VF.pdf). Todas las cifras institucionales se transcribieron de las diapositivas (en azul en cada hoja).
A6: Fuente MCIC | B6: Carpeta Data/: Cuadros Maestros CNA (SNIES 17528 y 116070), Énfasis estudiantes - Consolidado.xlsx, Estados de Cóndor, Directorio Grupos de Inv MCIC.xlsx, bases de trabajos de grado, Convenios URELINTER y Data/Gold.
A7: Docentes MCIC | B7: Se usa el Cuadro Maestro No. 05 (11 profesores) como núcleo. Es el dato que el CNA ya tiene; el Cuadro 06 reporta 14 para 2025-I (6 TC + 8 HC). La base de trabajos de grado registra 214 profesores históricos (director/revisor/jurado).
A8: Docentes UD | B8: La presentación dice 1.989 docentes, pero el desglose planta (626) + vinculación especial (1.364) suma 1.990. Las diapositivas de investigación hablan de 616 de planta y 1.317 de vinculación especial.
A9: Estudiantes MCIC | B9: 156 activos 2026-1 (énfasis) = matriculados en Cóndor. El resumen PII_Interno reporta 146 activos (corte distinto).
A10: Grupos MCIC | B10: Se usa la clasificación del Directorio Grupos de Inv MCIC.xlsx (19 grupos). El Cuadro Maestro No. 08 (16 grupos) y Data/Gold traen algunas categorías distintas (p. ej. Internet Inteligente A1 vs. B; GICOECOL A1 vs. B); conviene verificar en GrupLAC antes de la visita.
A11: Grupos UD | B11: La diapositiva 35 dice 68 grupos no reconocidos, pero las barras por facultad suman 70 (que es lo que cuadra con 188).
A12: Graduados MCIC | B12: El año de grado 2022-2026 es estimado (última matrícula). 2026 es parcial. El total histórico excluye la Maestría en Teleinformática (código 95), antecesora del programa.
A13: Movilidad | B13: UD 2021-2026 vs. MCIC 2019-2025 (Cuadros 07 y 09). Los periodos no coinciden. Se excluyeron 2 registros de docentes que estaban en la hoja de movilidad estudiantil.
A14: Bienestar | B14: El Cuadro Maestro de bienestar llega hasta 2024-3; la U reporta 2025-1 a 2026-1. Comparar tendencias, no valores absolutos.
A15: Presupuesto | B15: No se encontró presupuesto propio de la MCIC en Data/. La presentación solo trae el presupuesto institucional (2026: $668.317 millones; inversión ejecutada 25,6 % a agosto).
... A17: Acreditación | B17: UD: acreditación institucional renovada en 2021 por 8 años. MCIC: acreditación de alta calidad Res. 024858 del 30-dic-2022, por 4 años (vence dic-2026); registros calificados Res. 16163/2023 (Investigación) y 9925/2023 (Profundización).
