Workbook

Sheet Datos Personales
A1: CODIGO | B1: NOMBRE ESTUDIANTE | C1: COD. PROYECTO | D1: PROYECTO CURRICULAR | E1: ESTADO | F1: ESTADOS | G1: ESTRATO | H1: CORREO INSTITUCIONAL | I1: CORREO PERSONAL | J1: ID | K1: DOCUMENTO | L1: CELULAR | M1: FECHA NAC | N1: GRUPO DE INVESTIGACION
A2: 9929531 | B2: =VLOOKUP(A2,'ESTADOS ESTUDIANTES'!B:L,2,0) -> PAEZ PISCO SAMUEL | C2: =VLOOKUP(A2,'ESTADOS ESTUDIANTES'!B:L,3,0) -> 195 | D2: =VLOOKUP(A2,'ESTADOS ESTUDIANTES'!B:L,4,0) -> MAE. EN CIENCIAS DE LA INF. Y LAS COMUNICACIONES ENFASIS EN TELEINF. | E2: =VLOOKUP(A2,'ESTADOS ESTUDIANTES'!B:L,5,0) -> X | F2: =VLOOKUP(E2,Listas!B1:C1004,2,0) -> EXCLUIDO | G2: =VLOOKUP(A2,'ESTADOS ESTUDIANTES'!B:L,7,0) -> 3 | H2: =VLOOKUP(A2,'ESTADOS ESTUDIANTES'!B:L,8,0) -> spaezp@correo.udistrital.edu.co | I2: =VLOOKUP(A2,'ESTADOS ESTUDIANTES'!B:L,9,0) -> samuel.paez@fiscalia.gov.co | J2: =VLOOKUP(A2,'ESTADOS ESTUDIANTES'!B:L,10,0) -> CC | K2: =VLOOKUP(A2,'ESTADOS ESTUDIANTES'!B:L,11,0) -> 79472385 | L2: 3174861160
A3: 9929539 | B3: =VLOOKUP(A3,'ESTADOS ESTUDIANTES'!B:L,2,0) -> RODRIGUEZ RENGIFO JORGE | C3: =VLOOKUP(A3,'ESTADOS ESTUDIANTES'!B:L,3,0) -> 195 | D3: =VLOOKUP(A3,'ESTADOS ESTUDIANTES'!B:L,4,0) -> MAE. EN CIENCIAS DE LA INF. Y LAS COMUNICACIONES ENFASIS EN TELEINF. | E3: =VLOOKUP(A3,'ESTADOS ESTUDIANTES'!B:L,5,0) -> X | F3: =VLOOKUP(E3,Listas!B1:C1004,2,0) -> EXCLUIDO | G3: =VLOOKUP(A3,'ESTADOS ESTUDIANTES'!B:L,7,0) -> 3 | H3: =VLOOKUP(A3,'ESTADOS ESTUDIANTES'!B:L,8,0) -> jrodriguezr@udistrital.edu.co | I3: =VLOOKUP(A3,'ESTADOS ESTUDIANTES'!B:L,9,0) -> jorge.rodriguez@engineer.com | J3: =VLOOKUP(A3,'ESTADOS ESTUDIANTES'!B:L,10,0) -> CC | K3: =VLOOKUP(A3,'ESTADOS ESTUDIANTES'!B:L,11,0) -> 7545588 | L3: 3012399398
A4: 20012095004 | B4: =VLOOKUP(A4,'ESTADOS ESTUDIANTES'!B:L,2,0) -> BECERRA FINO JOSE YASIS | C4: =VLOOKUP(A4,'ESTADOS ESTUDIANTES'!B:L,3,0) -> 195 | D4: =VLOOKUP(A4,'ESTADOS ESTUDIANTES'!B:L,4,0) -> MAE. EN CIENCIAS DE LA INF. Y LAS COMUNICACIONES ENFASIS EN TELEINF. | E4: =VLOOKUP(A4,'ESTADOS ESTUDIANTES'!B:L,5,0) -> X | F4: =VLOOKUP(E4,Listas!B1:C1004,2,0) -> EXCLUIDO | G4: =VLOOKUP(A4,'ESTADOS ESTUDIANTES'!B:L,7,0) -> 3 | H4: =VLOOKUP(A4,'ESTADOS ESTUDIANTES'!B:L,8,0) -> jybecerraf@correo.udistrital.edu.co | I4: =VLOOKUP(A4,'ESTADOS ESTUDIANTES'!B:L,9,0) -> jybecerra@gmail.com | J4: =VLOOKUP(A4,'ESTADOS ESTUDIANTES'!B:L,10,0) -> CC | K4: =VLOOKUP(A4,'ESTADOS ESTUDIANTES'!B:L,11,0) -> 79483121 | L4: 3106981701
A5: 20022095016 | B5: =VLOOKUP(A5,'ESTADOS ESTUDIANTES'!B:L,2,0) -> SEGURA ASCENCIO OMAR ENRIQUE | C5: =VLOOKUP(A5,'ESTADOS ESTUDIANTES'!B:L,3,0) -> 295 | D5: =VLOOKUP(A5,'ESTADOS ESTUDIANTES'!B:L,4,0) -> MAE. EN CIENCIAS DE LA INF. Y LAS COMUNICACIONES ENFASIS EN SIS. INFOR | E5: =VLOOKUP(A5,'ESTADOS ESTUDIANTES'!B:L,5,0) -> X | F5: =VLOOKUP(E5,Listas!B1:C1004,2,0) -> EXCLUIDO | G5: =VLOOKUP(A5,'ESTADOS ESTUDIANTES'!B:L,7,0) -> NO REGISTRA | H5: =VLOOKUP(A5,'ESTADOS ESTUDIANTES'!B:L,8,0) -> oeseguraa@correo.udistrital.edu.co | I5: =VLOOKUP(A5,'ESTADOS ESTUDIANTES'!B:L,9,0) -> omarsegura12@hotmail.com | J5: =VLOOKUP(A5,'ESTADOS ESTUDIANTES'!B:L,10,0) -> CC | K5: =VLOOKUP(A5,'ESTADOS ESTUDIANTES'!B:L,11,0) -> 4979940
A6: 20032095001 | B6: =VLOOKUP(A6,'ESTADOS ESTUDIANTES'!B:L,2,0) -> AMAYA CORREDOR YESID | C6: =VLOOKUP(A6,'ESTADOS ESTUDIANTES'!B:L,3,0) -> 195 | D6: =VLOOKUP(A6,'ESTADOS ESTUDIANTES'!B:L,4,0) -> MAE. EN CIENCIAS DE LA INF. Y LAS COMUNICACIONES ENFASIS EN TELEINF. | E6: =VLOOKUP(A6,'ESTADOS ESTUDIANTES'!B:L,5,0) -> Z | F6: =VLOOKUP(E6,Listas!B1:C1004,2,0) -> NO SUP. PRUEBA ACAD. | G6: =VLOOKUP(A6,'ESTADOS ESTUDIANTES'!B:L,7,0) -> NO REGISTRA | H6: =VLOOKUP(A6,'ESTADOS ESTUDIANTES'!B:L,8,0) -> 0 | I6: =VLOOKUP(A6,'ESTADOS ESTUDIANTES'!B:L,9,0) -> 0 | J6: =VLOOKUP(A6,'ESTADOS ESTUDIANTES'!B:L,10,0) -> CC | K6: =VLOOKUP(A6,'ESTADOS ESTUDIANTES'!B:L,11,0) -> 13928471
A7: 20032095004 | B7: =VLOOKUP(A7,'ESTADOS ESTUDIANTES'!B:L,2,0) -> CEDANO GARCIA ROCIO | C7: =VLOOKUP(A7,'ESTADOS ESTUDIANTES'!B:L,3,0) -> 195 | D7: =VLOOKUP(A7,'ESTADOS ESTUDIANTES'!B:L,4,0) -> MAE. EN CIENCIAS DE LA INF. Y LAS COMUNICACIONES ENFASIS EN TELEINF. | E7: =VLOOKUP(A7,'ESTADOS ESTUDIANTES'!B:L,5,0) -> E | F7: =VLOOKUP(E7,Listas!B1:C1004,2,0) -> EGRESADO | G7: =VLOOKUP(A7,'ESTADOS ESTUDIANTES'!B:L,7,0) -> 1 | H7: =VLOOKUP(A7,'ESTADOS ESTUDIANTES'!B:L,8,0) -> rcedanog@correo.udistrital.edu.co | I7: =VLOOKUP(A7,'ESTADOS ESTUDIANTES'!B:L,9,0) -> rociocedano@yahoo.com | J7: =VLOOKUP(A7,'ESTADOS ESTUDIANTES'!B:L,10,0) -> CC | K7: =VLOOKUP(A7,'ESTADOS ESTUDIANTES'!B:L,11,0) -> 51960945
A8: 20032095006 | B8: =VLOOKUP(A8,'ESTADOS ESTUDIANTES'!B:L,2,0) -> FAJARDO ORTEGA OSCAR ALFREDO | C8: =VLOOKUP(A8,'ESTADOS ESTUDIANTES'!B:L,3,0) -> 295 | D8: =VLOOKUP(A8,'ESTADOS ESTUDIANTES'!B:L,4,0) -> MAE. EN CIENCIAS DE LA INF. Y LAS COMUNICACIONES ENFASIS EN SIS. INFOR | E8: =VLOOKUP(A8,'ESTADOS ESTUDIANTES'!B:L,5,0) -> E | F8: =VLOOKUP(E8,Listas!B1:C1004,2,0) -> EGRESADO | G8: =VLOOKUP(A8,'ESTADOS ESTUDIANTES'!B:L,7,0) -> 1 | H8: =VLOOKUP(A8,'ESTADOS ESTUDIANTES'!B:L,8,0) -> oafajardoo@correo.udistrital.edu.co | I8: =VLOOKUP(A8,'ESTADOS ESTUDIANTES'!B:L,9,0) -> fajardo_oscar@hotmail.com | J8: =VLOOKUP(A8,'ESTADOS ESTUDIANTES'!B:L,10,0) -> CC | K8: =VLOOKUP(A8,'ESTADOS ESTUDIANTES'!B:L,11,0) -> 97470859
A9: 20032095007 | B9: =VLOOKUP(A9,'ESTADOS ESTUDIANTES'!B:L,2,0) -> GAMBA AGUIRRE DEISY JUDITH | C9: =VLOOKUP(A9,'ESTADOS ESTUDIANTES'!B:L,3,0) -> 195 | D9: =VLOOKUP(A9,'ESTADOS ESTUDIANTES'!B:L,4,0) -> MAE. EN CIENCIAS DE LA INF. Y LAS COMUNICACIONES ENFASIS EN TELEINF. | E9: =VLOOKUP(A9,'ESTADOS ESTUDIANTES'!B:L,5,0) -> Z | F9: =VLOOKUP(E9,Listas!B1:C1004,2,0) -> NO SUP. PRUEBA ACAD. | G9: =VLOOKUP(A9,'ESTADOS ESTUDIANTES'!B:L,7,0) -> NO REGISTRA | H9: =VLOOKUP(A9,'ESTADOS ESTUDIANTES'!B:L,8,0) -> 0 | I9: =VLOOKUP(A9,'ESTADOS ESTUDIANTES'!B:L,9,0) -> 0 | J9: =VLOOKUP(A9,'ESTADOS ESTUDIANTES'!B:L,10,0) -> CC | K9: =VLOOKUP(A9,'ESTADOS ESTUDIANTES'!B:L,11,0) -> 52396642
A10: 20032095008 | B10: =VLOOKUP(A10,'ESTADOS ESTUDIANTES'!B:L,2,0) -> RENE GEOVANI GONZALEZ CABALLERO | C10: =VLOOKUP(A10,'ESTADOS ESTUDIANTES'!B:L,3,0) -> 195 | D10: =VLOOKUP(A10,'ESTADOS ESTUDIANTES'!B:L,4,0) -> MAE. EN CIENCIAS DE LA INF. Y LAS COMUNICACIONES ENFASIS EN TELEINF. | E10: =VLOOKUP(A10,'ESTADOS ESTUDIANTES'!B:L,5,0) -> E | F10: =VLOOKUP(E10,Listas!B1:C1004,2,0) -> EGRESADO | G10: =VLOOKUP(A10,'ESTADOS ESTUDIANTES'!B:L,7,0) -> 1 | H10: =VLOOKUP(A10,'ESTADOS ESTUDIANTES'!B:L,8,0) -> rggonzalezc@correo.udistrital.edu.co | I10: =VLOOKUP(A10,'ESTADOS ESTUDIANTES'!B:L,9,0) -> rengoca@hotmail.com | J10: =VLOOKUP(A10,'ESTADOS ESTUDIANTES'!B:L,10,0) -> CC | K10: =VLOOKUP(A10,'ESTADOS ESTUDIANTES'!B:L,11,0) -> 13957351
A11: 20032095009 | B11: =VLOOKUP(A11,'ESTADOS ESTUDIANTES'!B:L,2,0) -> LOPEZ HERNANDEZ HERLEDY | C11: =VLOOKUP(A11,'ESTADOS ESTUDIANTES'!B:L,3,0) -> 195 | D11: =VLOOKUP(A11,'ESTADOS ESTUDIANTES'!B:L,4,0) -> MAE. EN CIENCIAS DE LA INF. Y LAS COMUNICACIONES ENFASIS EN TELEINF. | E11: =VLOOKUP(A11,'ESTADOS ESTUDIANTES'!B:L,5,0) -> X | F11: =VLOOKUP(E11,Listas!B1:C1004,2,0) -> EXCLUIDO | G11: =VLOOKUP(A11,'ESTADOS ESTUDIANTES'!B:L,7,0) -> NO REGISTRA | H11: =VLOOKUP(A11,'ESTADOS ESTUDIANTES'!B:L,8,0) -> 0 | I11: =VLOOKUP(A11,'ESTADOS ESTUDIANTES'!B:L,9,0) -> 0 | J11: =VLOOKUP(A11,'ESTADOS ESTUDIANTES'!B:L,10,0) -> CC | K11: =VLOOKUP(A11,'ESTADOS ESTUDIANTES'!B:L,11,0) -> 79414063
A12: 20032095010 | B12: =VLOOKUP(A12,'ESTADOS ESTUDIANTES'!B:L,2,0) -> MEJIA ARIAS GASTON ANTONIO | C12: =VLOOKUP(A12,'ESTADOS ESTUDIANTES'!B:L,3,0) -> 295 | D12: =VLOOKUP(A12,'ESTADOS ESTUDIANTES'!B:L,4,0) -> MAE. EN CIENCIAS DE LA INF. Y LAS COMUNICACIONES ENFASIS EN SIS. INFOR | E12: =VLOOKUP(A12,'ESTADOS ESTUDIANTES'!B:L,5,0) -> E | F12: =VLOOKUP(E12,Listas!B1:C1004,2,0) -> EGRESADO | G12: =VLOOKUP(A12,'ESTADOS ESTUDIANTES'!B:L,7,0) -> NO REGISTRA | H12: =VLOOKUP(A12,'ESTADOS ESTUDIANTES'!B:L,8,0) -> gamejiaa@correo.udistrital.edu.co | I12: =VLOOKUP(A12,'ESTADOS ESTUDIANTES'!B:L,9,0) -> gaston.mejia@gmail.com | J12: =VLOOKUP(A12,'ESTADOS ESTUDIANTES'!B:L,10,0) -> CC | K12: =VLOOKUP(A12,'ESTADOS ESTUDIANTES'!B:L,11,0) -> 79697729
A13: 20032095012 | B13: =VLOOKUP(A13,'ESTADOS ESTUDIANTES'!B:L,2,0) -> PADILLA BAÑOS DOLLY MARCELA | C13: =VLOOKUP(A13,'ESTADOS ESTUDIANTES'!B:L,3,0) -> 195 | D13: =VLOOKUP(A13,'ESTADOS ESTUDIANTES'!B:L,4,0) -> MAE. EN CIENCIAS DE LA INF. Y LAS COMUNICACIONES ENFASIS EN TELEINF. | E13: =VLOOKUP(A13,'ESTADOS ESTUDIANTES'!B:L,5,0) -> E | F13: =VLOOKUP(E13,Listas!B1:C1004,2,0) -> EGRESADO | G13: =VLOOKUP(A13,'ESTADOS ESTUDIANTES'!B:L,7,0) -> 3 | H13: =VLOOKUP(A13,'ESTADOS ESTUDIANTES'!B:L,8,0) -> dmpadillab@correo.udistrital.edu.co | I13: =VLOOKUP(A13,'ESTADOS ESTUDIANTES'!B:L,9,0) -> dollypadilla@hotmail.com | J13: =VLOOKUP(A13,'ESTADOS ESTUDIANTES'!B:L,10,0) -> CC | K13: =VLOOKUP(A13,'ESTADOS ESTUDIANTES'!B:L,11,0) -> 22546893
A14: 20032095013 | B14: =VLOOKUP(A14,'ESTADOS ESTUDIANTES'!B:L,2,0) -> RINCON LEGUIZAMON LIZT MARICELLA | C14: =VLOOKUP(A14,'ESTADOS ESTUDIANTES'!B:L,3,0) -> 195 | D14: =VLOOKUP(A14,'ESTADOS ESTUDIANTES'!B:L,4,0) -> MAE. EN CIENCIAS DE LA INF. Y LAS COMUNICACIONES ENFASIS EN TELEINF. | E14: =VLOOKUP(A14,'ESTADOS ESTUDIANTES'!B:L,5,0) -> Z | F14: =VLOOKUP(E14,Listas!B1:C1004,2,0) -> NO SUP. PRUEBA ACAD. | G14: =VLOOKUP(A14,'ESTADOS ESTUDIANTES'!B:L,7,0) -> NO REGISTRA | H14: =VLOOKUP(A14,'ESTADOS ESTUDIANTES'!B:L,8,0) -> lmrinconl@correo.udistrital.edu.co | I14: =VLOOKUP(A14,'ESTADOS ESTUDIANTES'!B:L,9,0) -> lmrinconl@estudiante.udistrital.edu.co | J14: =VLOOKUP(A14,'ESTADOS ESTUDIANTES'!B:L,10,0) -> CC | K14: =VLOOKUP(A14,'ESTADOS ESTUDIANTES'!B:L,11,0) -> 40031895
A15: 20032095014 | B15: =VLOOKUP(A15,'ESTADOS ESTUDIANTES'!B:L,2,0) -> RINCON BARRERA RAFAEL ANDRES | C15: =VLOOKUP(A15,'ESTADOS ESTUDIANTES'!B:L,3,0) -> 195 | D15: =VLOOKUP(A15,'ESTADOS ESTUDIANTES'!B:L,4,0) -> MAE. EN CIENCIAS DE LA INF. Y LAS COMUNICACIONES ENFASIS EN TELEINF. | E15: =VLOOKUP(A15,'ESTADOS ESTUDIANTES'!B:L,5,0) -> Z | F15: =VLOOKUP(E15,Listas!B1:C1004,2,0) -> NO SUP. PRUEBA ACAD. | G15: =VLOOKUP(A15,'ESTADOS ESTUDIANTES'!B:L,7,0) -> NO REGISTRA | H15: =VLOOKUP(A15,'ESTADOS ESTUDIANTES'!B:L,8,0) -> 0 | I15: =VLOOKUP(A15,'ESTADOS ESTUDIANTES'!B:L,9,0) -> 0 | J15: =VLOOKUP(A15,'ESTADOS ESTUDIANTES'!B:L,10,0) -> CC | K15: =VLOOKUP(A15,'ESTADOS ESTUDIANTES'!B:L,11,0) -> 79185945
A16: 20032095016 | B16: =VLOOKUP(A16,'ESTADOS ESTUDIANTES'!B:L,2,0) -> BARACALDO JULIO CESAR | C16: =VLOOKUP(A16,'ESTADOS ESTUDIANTES'!B:L,3,0) -> 295 | D16: =VLOOKUP(A16,'ESTADOS ESTUDIANTES'!B:L,4,0) -> MAE. EN CIENCIAS DE LA INF. Y LAS COMUNICACIONES ENFASIS EN SIS. INFOR | E16: =VLOOKUP(A16,'ESTADOS ESTUDIANTES'!B:L,5,0) -> X | F16: =VLOOKUP(E16,Listas!B1:C1004,2,0) -> EXCLUIDO | G16: =VLOOKUP(A16,'ESTADOS ESTUDIANTES'!B:L,7,0) -> NO REGISTRA | H16: =VLOOKUP(A16,'ESTADOS ESTUDIANTES'!B:L,8,0) -> jbaracaldo@correo.udistrital.edu.co | I16: =VLOOKUP(A16,'ESTADOS ESTUDIANTES'!B:L,9,0) -> jcbaracaldo@gmail.com | J16: =VLOOKUP(A16,'ESTADOS ESTUDIANTES'!B:L,10,0) -> CC | K16: =VLOOKUP(A16,'ESTADOS ESTUDIANTES'!B:L,11,0) -> 19359635
A17: 20032095017 | B17: =VLOOKUP(A17,'ESTADOS ESTUDIANTES'!B:L,2,0) -> RIVERO PEREZ JUAN CARLOS | C17: =VLOOKUP(A17,'ESTADOS ESTUDIANTES'!B:L,3,0) -> 195 | D17: =VLOOKUP(A17,'ESTADOS ESTUDIANTES'!B:L,4,0) -> MAE. EN CIENCIAS DE LA INF. Y LAS COMUNICACIONES ENFASIS EN TELEINF. | E17: =VLOOKUP(A17,'ESTADOS ESTUDIANTES'!B:L,5,0) -> X | F17: =VLOOKUP(E17,Listas!B1:C1004,2,0) -> EXCLUIDO | G17: =VLOOKUP(A17,'ESTADOS ESTUDIANTES'!B:L,7,0) -> NO REGISTRA | H17: =VLOOKUP(A17,'ESTADOS ESTUDIANTES'!B:L,8,0) -> jucriverop@correo.udistrital.edu.co | I17: =VLOOKUP(A17,'ESTADOS ESTUDIANTES'!B:L,9,0) -> jucriverop@estudiante.udistrital.edu.co | J17: =VLOOKUP(A17,'ESTADOS ESTUDIANTES'!B:L,10,0) -> CC | K17: =VLOOKUP(A17,'ESTADOS ESTUDIANTES'!B:L,11,0) -> 79425695
A18: 20041195001 | B18: =VLOOKUP(A18,'ESTADOS ESTUDIANTES'!B:L,2,0) -> ACERO SOTO DIEGO MAURICIO | C18: =VLOOKUP(A18,'ESTADOS ESTUDIANTES'!B:L,3,0) -> 195 | D18: =VLOOKUP(A18,'ESTADOS ESTUDIANTES'!B:L,4,0) -> MAE. EN CIENCIAS DE LA INF. Y LAS COMUNICACIONES ENFASIS EN TELEINF. | E18: =VLOOKUP(A18,'ESTADOS ESTUDIANTES'!B:L,5,0) -> X | F18: =VLOOKUP(E18,Listas!B1:C1004,2,0) -> EXCLUIDO | G18: =VLOOKUP(A18,'ESTADOS ESTUDIANTES'!B:L,7,0) -> NO REGISTRA | H18: =VLOOKUP(A18,'ESTADOS ESTUDIANTES'!B:L,8,0) -> dmaceros@correo.udistrital.edu.co | I18: =VLOOKUP(A18,'ESTADOS ESTUDIANTES'!B:L,9,0) -> dmaceros@estudiante.udistrital.edu.co | J18: =VLOOKUP(A18,'ESTADOS ESTUDIANTES'!B:L,10,0) -> CC | K18: =VLOOKUP(A18,'ESTADOS ESTUDIANTES'!B:L,11,0) -> 79576183
A19: 20041195002 | B19: =VLOOKUP(A19,'ESTADOS ESTUDIANTES'!B:L,2,0) -> AMAYA CAICEDO HERNAN G. | C19: =VLOOKUP(A19,'ESTADOS ESTUDIANTES'!B:L,3,0) -> 195 | D19: =VLOOKUP(A19,'ESTADOS ESTUDIANTES'!B:L,4,0) -> MAE. EN CIENCIAS DE LA INF. Y LAS COMUNICACIONES ENFASIS EN TELEINF. | E19: =VLOOKUP(A19,'ESTADOS ESTUDIANTES'!B:L,5,0) -> Z | F19: =VLOOKUP(E19,Listas!B1:C1004,2,0) -> NO SUP. PRUEBA ACAD. | G19: =VLOOKUP(A19,'ESTADOS ESTUDIANTES'!B:L,7,0) -> NO REGISTRA | H19: =VLOOKUP(A19,'ESTADOS ESTUDIANTES'!B:L,8,0) -> hgamayac@correo.udistrital.edu.co | I19: =VLOOKUP(A19,'ESTADOS ESTUDIANTES'!B:L,9,0) -> hgamayac@estudiante.udistrital.edu.co | J19: =VLOOKUP(A19,'ESTADOS ESTUDIANTES'!B:L,10,0) -> CC | K19: =VLOOKUP(A19,'ESTADOS ESTUDIANTES'!B:L,11,0) -> 7170256
A20: 20041195003 | B20: =VLOOKUP(A20,'ESTADOS ESTUDIANTES'!B:L,2,0) -> BONILLA OLAYA JOSE EBERT | C20: =VLOOKUP(A20,'ESTADOS ESTUDIANTES'!B:L,3,0) -> 195 | D20: =VLOOKUP(A20,'ESTADOS ESTUDIANTES'!B:L,4,0) -> MAE. EN CIENCIAS DE LA INF. Y LAS COMUNICACIONES ENFASIS EN TELEINF. | E20: =VLOOKUP(A20,'ESTADOS ESTUDIANTES'!B:L,5,0) -> E | F20: =VLOOKUP(E20,Listas!B1:C1004,2,0) -> EGRESADO | G20: =VLOOKUP(A20,'ESTADOS ESTUDIANTES'!B:L,7,0) -> NO REGISTRA | H20: =VLOOKUP(A20,'ESTADOS ESTUDIANTES'!B:L,8,0) -> jebonillao@correo.udistrital.edu.co | I20: =VLOOKUP(A20,'ESTADOS ESTUDIANTES'!B:L,9,0) -> jose.ebert@gmail.com | J20: =VLOOKUP(A20,'ESTADOS ESTUDIANTES'!B:L,10,0) -> CC | K20: =VLOOKUP(A20,'ESTADOS ESTUDIANTES'!B:L,11,0) -> 80269115
A21: 20041195004 | B21: =VLOOKUP(A21,'ESTADOS ESTUDIANTES'!B:L,2,0) -> BUITRAGO BRAVO RONALD YESID | C21: =VLOOKUP(A21,'ESTADOS ESTUDIANTES'!B:L,3,0) -> 195 | D21: =VLOOKUP(A21,'ESTADOS ESTUDIANTES'!B:L,4,0) -> MAE. EN CIENCIAS DE LA INF. Y LAS COMUNICACIONES ENFASIS EN TELEINF. | E21: =VLOOKUP(A21,'ESTADOS ESTUDIANTES'!B:L,5,0) -> E | F21: =VLOOKUP(E21,Listas!B1:C1004,2,0) -> EGRESADO | G21: =VLOOKUP(A21,'ESTADOS ESTUDIANTES'!B:L,7,0) -> NO REGISTRA | H21: =VLOOKUP(A21,'ESTADOS ESTUDIANTES'!B:L,8,0) -> rybuitragob@correo.udistrital.edu.co | I21: =VLOOKUP(A21,'ESTADOS ESTUDIANTES'!B:L,9,0) -> rybuitrago@bancodeoccidente.com.co | J21: =VLOOKUP(A21,'ESTADOS ESTUDIANTES'!B:L,10,0) -> CC | K21: =VLOOKUP(A21,'ESTADOS ESTUDIANTES'!B:L,11,0) -> 79796071
A22: 20041195005 | B22: =VLOOKUP(A22,'ESTADOS ESTUDIANTES'!B:L,2,0) -> CORTES LOPEZ HERNAN ANDRES | C22: =VLOOKUP(A22,'ESTADOS ESTUDIANTES'!B:L,3,0) -> 195 | D22: =VLOOKUP(A22,'ESTADOS ESTUDIANTES'!B:L,4,0) -> MAE. EN CIENCIAS DE LA INF. Y LAS COMUNICACIONES ENFASIS EN TELEINF. | E22: =VLOOKUP(A22,'ESTADOS ESTUDIANTES'!B:L,5,0) -> X | F22: =VLOOKUP(E22,Listas!B1:C1004,2,0) -> EXCLUIDO | G22: =VLOOKUP(A22,'ESTADOS ESTUDIANTES'!B:L,7,0) -> NO REGISTRA | H22: =VLOOKUP(A22,'ESTADOS ESTUDIANTES'!B:L,8,0) -> 0 | I22: =VLOOKUP(A22,'ESTADOS ESTUDIANTES'!B:L,9,0) -> 0 | J22: =VLOOKUP(A22,'ESTADOS ESTUDIANTES'!B:L,10,0) -> CC | K22: =VLOOKUP(A22,'ESTADOS ESTUDIANTES'!B:L,11,0) -> 74187327
A23: 20041195006 | B23: =VLOOKUP(A23,'ESTADOS ESTUDIANTES'!B:L,2,0) -> CUBILLOS SANCHEZ RAFAEL ORLANDO | C23: =VLOOKUP(A23,'ESTADOS ESTUDIANTES'!B:L,3,0) -> 195 | D23: =VLOOKUP(A23,'ESTADOS ESTUDIANTES'!B:L,4,0) -> MAE. EN CIENCIAS DE LA INF. Y LAS COMUNICACIONES ENFASIS EN TELEINF. | E23: =VLOOKUP(A23,'ESTADOS ESTUDIANTES'!B:L,5,0) -> X | F23: =VLOOKUP(E23,Listas!B1:C1004,2,0) -> EXCLUIDO | G23: =VLOOKUP(A23,'ESTADOS ESTUDIANTES'!B:L,7,0) -> NO REGISTRA | H23: =VLOOKUP(A23,'ESTADOS ESTUDIANTES'!B:L,8,0) -> rocubilloss@udistrital.edu.co | I23: =VLOOKUP(A23,'ESTADOS ESTUDIANTES'!B:L,9,0) -> rocubilloss@estudiante.udistrital.edu.co | J23: =VLOOKUP(A23,'ESTADOS ESTUDIANTES'!B:L,10,0) -> CC | K23: =VLOOKUP(A23,'ESTADOS ESTUDIANTES'!B:L,11,0) -> 79578336
A24: 20041195007 | B24: =VLOOKUP(A24,'ESTADOS ESTUDIANTES'!B:L,2,0) -> DIAZ MARTINEZ NEIL ORLANDO | C24: =VLOOKUP(A24,'ESTADOS ESTUDIANTES'!B:L,3,0) -> 195 | D24: =VLOOKUP(A24,'ESTADOS ESTUDIANTES'!B:L,4,0) -> MAE. EN CIENCIAS DE LA INF. Y LAS COMUNICACIONES ENFASIS EN TELEINF. | E24: =VLOOKUP(A24,'ESTADOS ESTUDIANTES'!B:L,5,0) -> E | F24: =VLOOKUP(E24,Listas!B1:C1004,2,0) -> EGRESADO | G24: =VLOOKUP(A24,'ESTADOS ESTUDIANTES'!B:L,7,0) -> NO REGISTRA | H24: =VLOOKUP(A24,'ESTADOS ESTUDIANTES'!B:L,8,0) -> nodiazm@correo.udistrital.edu.co | I24: =VLOOKUP(A24,'ESTADOS ESTUDIANTES'!B:L,9,0) -> neil_or@yahoo.com | J24: =VLOOKUP(A24,'ESTADOS ESTUDIANTES'!B:L,10,0) -> CC | K24: =VLOOKUP(A24,'ESTADOS ESTUDIANTES'!B:L,11,0) -> 72270879
A25: 20041195008 | B25: =VLOOKUP(A25,'ESTADOS ESTUDIANTES'!B:L,2,0) -> GAONA GARCIA ELVIS EDUARDO | C25: =VLOOKUP(A25,'ESTADOS ESTUDIANTES'!B:L,3,0) -> 195 | D25: =VLOOKUP(A25,'ESTADOS ESTUDIANTES'!B:L,4,0) -> MAE. EN CIENCIAS DE LA INF. Y LAS COMUNICACIONES ENFASIS EN TELEINF. | E25: =VLOOKUP(A25,'ESTADOS ESTUDIANTES'!B:L,5,0) -> E | F25: =VLOOKUP(E25,Listas!B1:C1004,2,0) -> EGRESADO | G25: =VLOOKUP(A25,'ESTADOS ESTUDIANTES'!B:L,7,0) -> NO REGISTRA | H25: =VLOOKUP(A25,'ESTADOS ESTUDIANTES'!B:L,8,0) -> eegaonag@correo.udistrital.edu.co | I25: =VLOOKUP(A25,'ESTADOS ESTUDIANTES'!B:L,9,0) -> egaona@udistrital.edu.co | J25: =VLOOKUP(A25,'ESTADOS ESTUDIANTES'!B:L,10,0) -> CC | K25: =VLOOKUP(A25,'ESTADOS ESTUDIANTES'!B:L,11,0) -> 79950025
A26: 20041195009 | B26: =VLOOKUP(A26,'ESTADOS ESTUDIANTES'!B:L,2,0) -> GAONA GARCIA PAULO ALONSO | C26: =VLOOKUP(A26,'ESTADOS ESTUDIANTES'!B:L,3,0) -> 195 | D26: =VLOOKUP(A26,'ESTADOS ESTUDIANTES'!B:L,4,0) -> MAE. EN CIENCIAS DE LA INF. Y LAS COMUNICACIONES ENFASIS EN TELEINF. | E26: =VLOOKUP(A26,'ESTADOS ESTUDIANTES'!B:L,5,0) -> E | F26: =VLOOKUP(E26,Listas!B1:C1004,2,0) -> EGRESADO | G26: =VLOOKUP(A26,'ESTADOS ESTUDIANTES'!B:L,7,0) -> NO REGISTRA | H26: =VLOOKUP(A26,'ESTADOS ESTUDIANTES'!B:L,8,0) -> pagaonag@correo.udistrital.edu.co | I26: =VLOOKUP(A26,'ESTADOS ESTUDIANTES'!B:L,9,0) -> gaoanaalonso@yahoo.es | J26: =VLOOKUP(A26,'ESTADOS ESTUDIANTES'!B:L,10,0) -> CC | K26: =VLOOKUP(A26,'ESTADOS ESTUDIANTES'!B:L,11,0) -> 80092512
A27: 20041195010 | B27: =VLOOKUP(A27,'ESTADOS ESTUDIANTES'!B:L,2,0) -> LOPEZ QUINTERO JOSE FERNANDO | C27: =VLOOKUP(A27,'ESTADOS ESTUDIANTES'!B:L,3,0) -> 195 | D27: =VLOOKUP(A27,'ESTADOS ESTUDIANTES'!B:L,4,0) -> MAE. EN CIENCIAS DE LA INF. Y LAS COMUNICACIONES ENFASIS EN TELEINF. | E27: =VLOOKUP(A27,'ESTADOS ESTUDIANTES'!B:L,5,0) -> X | F27: =VLOOKUP(E27,Listas!B1:C1004,2,0) -> EXCLUIDO | G27: =VLOOKUP(A27,'ESTADOS ESTUDIANTES'!B:L,7,0) -> NO REGISTRA | H27: =VLOOKUP(A27,'ESTADOS ESTUDIANTES'!B:L,8,0) -> jflopezq@correo.udistrital.edu.co | I27: =VLOOKUP(A27,'ESTADOS ESTUDIANTES'!B:L,9,0) -> jflopezq@estudiante.udistrital.edu.co | J27: =VLOOKUP(A27,'ESTADOS ESTUDIANTES'!B:L,10,0) -> CC | K27: =VLOOKUP(A27,'ESTADOS ESTUDIANTES'!B:L,11,0) -> 79788244
A28: 20041195011 | B28: =VLOOKUP(A28,'ESTADOS ESTUDIANTES'!B:L,2,0) -> MACIAS MUNOZ GERMAN | C28: =VLOOKUP(A28,'ESTADOS ESTUDIANTES'!B:L,3,0) -> 195 | D28: =VLOOKUP(A28,'ESTADOS ESTUDIANTES'!B:L,4,0) -> MAE. EN CIENCIAS DE LA INF. Y LAS COMUNICACIONES ENFASIS EN TELEINF. | E28: =VLOOKUP(A28,'ESTADOS ESTUDIANTES'!B:L,5,0) -> E | F28: =VLOOKUP(E28,Listas!B1:C1004,2,0) -> EGRESADO | G28: =VLOOKUP(A28,'ESTADOS ESTUDIANTES'!B:L,7,0) -> NO REGISTRA | H28: =VLOOKUP(A28,'ESTADOS ESTUDIANTES'!B:L,8,0) -> gmaciasm@udistrital.edu.co | I28: =VLOOKUP(A28,'ESTADOS ESTUDIANTES'!B:L,9,0) -> germaci@gmail.com | J28: =VLOOKUP(A28,'ESTADOS ESTUDIANTES'!B:L,10,0) -> CC | K28: =VLOOKUP(A28,'ESTADOS ESTUDIANTES'!B:L,11,0) -> 79453519
A29: 20041195012 | B29: =VLOOKUP(A29,'ESTADOS ESTUDIANTES'!B:L,2,0) -> MARTINEZ WITTINGHAN OSCAR H. | C29: =VLOOKUP(A29,'ESTADOS ESTUDIANTES'!B:L,3,0) -> 195 | D29: =VLOOKUP(A29,'ESTADOS ESTUDIANTES'!B:L,4,0) -> MAE. EN CIENCIAS DE LA INF. Y LAS COMUNICACIONES ENFASIS EN TELEINF. | E29: =VLOOKUP(A29,'ESTADOS ESTUDIANTES'!B:L,5,0) -> X | F29: =VLOOKUP(E29,Listas!B1:C1004,2,0) -> EXCLUIDO | G29: =VLOOKUP(A29,'ESTADOS ESTUDIANTES'!B:L,7,0) -> NO REGISTRA | H29: =VLOOKUP(A29,'ESTADOS ESTUDIANTES'!B:L,8,0) -> ohmartinezw@correo.udistrital.edu.co | I29: =VLOOKUP(A29,'ESTADOS ESTUDIANTES'!B:L,9,0) -> ohmartinezw@estudiante.udistrital.edu.co | J29: =VLOOKUP(A29,'ESTADOS ESTUDIANTES'!B:L,10,0) -> CC | K29: =VLOOKUP(A29,'ESTADOS ESTUDIANTES'!B:L,11,0) -> 74184170
A30: 20041195013 | B30: =VLOOKUP(A30,'ESTADOS ESTUDIANTES'!B:L,2,0) -> MONTENEGRO MARIN CARLOS E. | C30: =VLOOKUP(A30,'ESTADOS ESTUDIANTES'!B:L,3,0) -> 195 | D30: =VLOOKUP(A30,'ESTADOS ESTUDIANTES'!B:L,4,0) -> MAE. EN CIENCIAS DE LA INF. Y LAS COMUNICACIONES ENFASIS EN TELEINF. | E30: =VLOOKUP(A30,'ESTADOS ESTUDIANTES'!B:L,5,0) -> E | F30: =VLOOKUP(E30,Listas!B1:C1004,2,0) -> EGRESADO | G30: =VLOOKUP(A30,'ESTADOS ESTUDIANTES'!B:L,7,0) -> NO REGISTRA | H30: =VLOOKUP(A30,'ESTADOS ESTUDIANTES'!B:L,8,0) -> cemontenegrom@correo.udistrital.edu.co | I30: =VLOOKUP(A30,'ESTADOS ESTUDIANTES'!B:L,9,0) -> cemontenegrom@estudiante.udistrital.edu.co | J30: =VLOOKUP(A30,'ESTADOS ESTUDIANTES'!B:L,10,0) -> CC | K30: =VLOOKUP(A30,'ESTADOS ESTUDIANTES'!B:L,11,0) -> 80093200
A31: 20041195014 | B31: =VLOOKUP(A31,'ESTADOS ESTUDIANTES'!B:L,2,0) -> MUSKUS RINCON ELKIN GABRIEL | C31: =VLOOKUP(A31,'ESTADOS ESTUDIANTES'!B:L,3,0) -> 195 | D31: =VLOOKUP(A31,'ESTADOS ESTUDIANTES'!B:L,4,0) -> MAE. EN CIENCIAS DE LA INF. Y LAS COMUNICACIONES ENFASIS EN TELEINF. | E31: =VLOOKUP(A31,'ESTADOS ESTUDIANTES'!B:L,5,0) -> X | F31: =VLOOKUP(E31,Listas!B1:C1004,2,0) -> EXCLUIDO | G31: =VLOOKUP(A31,'ESTADOS ESTUDIANTES'!B:L,7,0) -> NO REGISTRA | H31: =VLOOKUP(A31,'ESTADOS ESTUDIANTES'!B:L,8,0) -> 0 | I31: =VLOOKUP(A31,'ESTADOS ESTUDIANTES'!B:L,9,0) -> 0 | J31: =VLOOKUP(A31,'ESTADOS ESTUDIANTES'!B:L,10,0) -> CC | K31: =VLOOKUP(A31,'ESTADOS ESTUDIANTES'!B:L,11,0) -> 80021637
A32: 20041195015 | B32: =VLOOKUP(A32,'ESTADOS ESTUDIANTES'!B:L,2,0) -> PAVA DIAZ ROBERTO ALBEIRO | C32: =VLOOKUP(A32,'ESTADOS ESTUDIANTES'!B:L,3,0) -> 195 | D32: =VLOOKUP(A32,'ESTADOS ESTUDIANTES'!B:L,4,0) -> MAE. EN CIENCIAS DE LA INF. Y LAS COMUNICACIONES ENFASIS EN TELEINF. | E32: =VLOOKUP(A32,'ESTADOS ESTUDIANTES'!B:L,5,0) -> X | F32: =VLOOKUP(E32,Listas!B1:C1004,2,0) -> EXCLUIDO | G32: =VLOOKUP(A32,'ESTADOS ESTUDIANTES'!B:L,7,0) -> NO REGISTRA | H32: =VLOOKUP(A32,'ESTADOS ESTUDIANTES'!B:L,8,0) -> 0 | I32: =VLOOKUP(A32,'ESTADOS ESTUDIANTES'!B:L,9,0) -> 0 | J32: =VLOOKUP(A32,'ESTADOS ESTUDIANTES'!B:L,10,0) -> CC | K32: =VLOOKUP(A32,'ESTADOS ESTUDIANTES'!B:L,11,0) -> 79943556
A33: 20041195016 | B33: =VLOOKUP(A33,'ESTADOS ESTUDIANTES'!B:L,2,0) -> PENA SALGADO PIERRE AUGUSTO | C33: =VLOOKUP(A33,'ESTADOS ESTUDIANTES'!B:L,3,0) -> 195 | D33: =VLOOKUP(A33,'ESTADOS ESTUDIANTES'!B:L,4,0) -> MAE. EN CIENCIAS DE LA INF. Y LAS COMUNICACIONES ENFASIS EN TELEINF. | E33: =VLOOKUP(A33,'ESTADOS ESTUDIANTES'!B:L,5,0) -> I | F33: =VLOOKUP(E33,Listas!B1:C1004,2,0) -> INACTIVO | G33: =VLOOKUP(A33,'ESTADOS ESTUDIANTES'!B:L,7,0) -> NO REGISTRA | H33: =VLOOKUP(A33,'ESTADOS ESTUDIANTES'!B:L,8,0) -> 0 | I33: =VLOOKUP(A33,'ESTADOS ESTUDIANTES'!B:L,9,0) -> 0 | J33: =VLOOKUP(A33,'ESTADOS ESTUDIANTES'!B:L,10,0) -> CC | K33: =VLOOKUP(A33,'ESTADOS ESTUDIANTES'!B:L,11,0) -> 78674082
A34: 20041195017 | B34: =VLOOKUP(A34,'ESTADOS ESTUDIANTES'!B:L,2,0) -> PUENTES PARAMO RAFAEL MAURICIO | C34: =VLOOKUP(A34,'ESTADOS ESTUDIANTES'!B:L,3,0) -> 195 | D34: =VLOOKUP(A34,'ESTADOS ESTUDIANTES'!B:L,4,0) -> MAE. EN CIENCIAS DE LA INF. Y LAS COMUNICACIONES ENFASIS EN TELEINF. | E34: =VLOOKUP(A34,'ESTADOS ESTUDIANTES'!B:L,5,0) -> X | F34: =VLOOKUP(E34,Listas!B1:C1004,2,0) -> EXCLUIDO | G34: =VLOOKUP(A34,'ESTADOS ESTUDIANTES'!B:L,7,0) -> NO REGISTRA | H34: =VLOOKUP(A34,'ESTADOS ESTUDIANTES'!B:L,8,0) -> rmpuentesp@correo.udistrital.edu.co | I34: =VLOOKUP(A34,'ESTADOS ESTUDIANTES'!B:L,9,0) -> rpuentes2000@gmail.com | J34: =VLOOKUP(A34,'ESTADOS ESTUDIANTES'!B:L,10,0) -> CC | K34: =VLOOKUP(A34,'ESTADOS ESTUDIANTES'!B:L,11,0) -> 79137742
A35: 20041195018 | B35: =VLOOKUP(A35,'ESTADOS ESTUDIANTES'!B:L,2,0) -> TRIANA PERDOMO FABIO ALEXIS | C35: =VLOOKUP(A35,'ESTADOS ESTUDIANTES'!B:L,3,0) -> 195 | D35: =VLOOKUP(A35,'ESTADOS ESTUDIANTES'!B:L,4,0) -> MAE. EN CIENCIAS DE LA INF. Y LAS COMUNICACIONES ENFASIS EN TELEINF. | E35: =VLOOKUP(A35,'ESTADOS ESTUDIANTES'!B:L,5,0) -> E | F35: =VLOOKUP(E35,Listas!B1:C1004,2,0) -> EGRESADO | G35: =VLOOKUP(A35,'ESTADOS ESTUDIANTES'!B:L,7,0) -> NO REGISTRA | H35: =VLOOKUP(A35,'ESTADOS ESTUDIANTES'!B:L,8,0) -> fatrianap@correo.udistrital.edu.co | I35: =VLOOKUP(A35,'ESTADOS ESTUDIANTES'!B:L,9,0) -> trianafp@gmail.com | J35: =VLOOKUP(A35,'ESTADOS ESTUDIANTES'!B:L,10,0) -> CC | K35: =VLOOKUP(A35,'ESTADOS ESTUDIANTES'!B:L,11,0) -> 80084469
A36: 20041195019 | B36: =VLOOKUP(A36,'ESTADOS ESTUDIANTES'!B:L,2,0) -> URBANO CHAVES DIEGO FERNANDO | C36: =VLOOKUP(A36,'ESTADOS ESTUDIANTES'!B:L,3,0) -> 195 | D36: =VLOOKUP(A36,'ESTADOS ESTUDIANTES'!B:L,4,0) -> MAE. EN CIENCIAS DE LA INF. Y LAS COMUNICACIONES ENFASIS EN TELEINF. | E36: =VLOOKUP(A36,'ESTADOS ESTUDIANTES'!B:L,5,0) -> E | F36: =VLOOKUP(E36,Listas!B1:C1004,2,0) -> EGRESADO | G36: =VLOOKUP(A36,'ESTADOS ESTUDIANTES'!B:L,7,0) -> NO REGISTRA | H36: =VLOOKUP(A36,'ESTADOS ESTUDIANTES'!B:L,8,0) -> dfurbanoc@udistrital.edu.co | I36: =VLOOKUP(A36,'ESTADOS ESTUDIANTES'!B:L,9,0) -> diego.urbano@gmail.com | J36: =VLOOKUP(A36,'ESTADOS ESTUDIANTES'!B:L,10,0) -> CC | K36: =VLOOKUP(A36,'ESTADOS ESTUDIANTES'!B:L,11,0) -> 79965521
A37: 20041195020 | B37: =VLOOKUP(A37,'ESTADOS ESTUDIANTES'!B:L,2,0) -> VARGAS ROJAS HUBER ALVARO | C37: =VLOOKUP(A37,'ESTADOS ESTUDIANTES'!B:L,3,0) -> 195 | D37: =VLOOKUP(A37,'ESTADOS ESTUDIANTES'!B:L,4,0) -> MAE. EN CIENCIAS DE LA INF. Y LAS COMUNICACIONES ENFASIS EN TELEINF. | E37: =VLOOKUP(A37,'ESTADOS ESTUDIANTES'!B:L,5,0) -> I | F37: =VLOOKUP(E37,Listas!B1:C1004,2,0) -> INACTIVO | G37: =VLOOKUP(A37,'ESTADOS ESTUDIANTES'!B:L,7,0) -> NO REGISTRA | H37: =VLOOKUP(A37,'ESTADOS ESTUDIANTES'!B:L,8,0) -> havargasr@correo.udistrital.edu.co | I37: =VLOOKUP(A37,'ESTADOS ESTUDIANTES'!B:L,9,0) -> havargasr@estudiante.udistrital.edu.co | J37: =VLOOKUP(A37,'ESTADOS ESTUDIANTES'!B:L,10,0) -> CC | K37: =VLOOKUP(A37,'ESTADOS ESTUDIANTES'!B:L,11,0) -> 79460726
A38: 20041195021 | B38: =VLOOKUP(A38,'ESTADOS ESTUDIANTES'!B:L,2,0) -> ARDILA NIÑO YAZMIN ALEXANDRA | C38: =VLOOKUP(A38,'ESTADOS ESTUDIANTES'!B:L,3,0) -> 195 | D38: =VLOOKUP(A38,'ESTADOS ESTUDIANTES'!B:L,4,0) -> MAE. EN CIENCIAS DE LA INF. Y LAS COMUNICACIONES ENFASIS EN TELEINF. | E38: =VLOOKUP(A38,'ESTADOS ESTUDIANTES'!B:L,5,0) -> X | F38: =VLOOKUP(E38,Listas!B1:C1004,2,0) -> EXCLUIDO | G38: =VLOOKUP(A38,'ESTADOS ESTUDIANTES'!B:L,7,0) -> NO REGISTRA | H38: =VLOOKUP(A38,'ESTADOS ESTUDIANTES'!B:L,8,0) -> yaardilan@udistrital.edu.co | I38: =VLOOKUP(A38,'ESTADOS ESTUDIANTES'!B:L,9,0) -> yaardilan@estudiante.udistrital.edu.co | J38: =VLOOKUP(A38,'ESTADOS ESTUDIANTES'!B:L,10,0) -> CC | K38: =VLOOKUP(A38,'ESTADOS ESTUDIANTES'!B:L,11,0) -> 52530310
A39: 20041195022 | B39: =VLOOKUP(A39,'ESTADOS ESTUDIANTES'!B:L,2,0) -> DIEZ JIMENEZ GABRIEL HORACIO | C39: =VLOOKUP(A39,'ESTADOS ESTUDIANTES'!B:L,3,0) -> 195 | D39: =VLOOKUP(A39,'ESTADOS ESTUDIANTES'!B:L,4,0) -> MAE. EN CIENCIAS DE LA INF. Y LAS COMUNICACIONES ENFASIS EN TELEINF. | E39: =VLOOKUP(A39,'ESTADOS ESTUDIANTES'!B:L,5,0) -> X | F39: =VLOOKUP(E39,Listas!B1:C1004,2,0) -> EXCLUIDO | G39: =VLOOKUP(A39,'ESTADOS ESTUDIANTES'!B:L,7,0) -> NO REGISTRA | H39: =VLOOKUP(A39,'ESTADOS ESTUDIANTES'!B:L,8,0) -> 0 | I39: =VLOOKUP(A39,'ESTADOS ESTUDIANTES'!B:L,9,0) -> 0 | J39: =VLOOKUP(A39,'ESTADOS ESTUDIANTES'!B:L,10,0) -> CC | K39: =VLOOKUP(A39,'ESTADOS ESTUDIANTES'!B:L,11,0) -> 19457291
A40: 20041195023 | B40: =VLOOKUP(A40,'ESTADOS ESTUDIANTES'!B:L,2,0) -> HERRERA BOLIVAR CLAUDIA YANETH | C40: =VLOOKUP(A40,'ESTADOS ESTUDIANTES'!B:L,3,0) -> 195 | D40: =VLOOKUP(A40,'ESTADOS ESTUDIANTES'!B:L,4,0) -> MAE. EN CIENCIAS DE LA INF. Y LAS COMUNICACIONES ENFASIS EN TELEINF. | E40: =VLOOKUP(A40,'ESTADOS ESTUDIANTES'!B:L,5,0) -> X | F40: =VLOOKUP(E40,Listas!B1:C1004,2,0) -> EXCLUIDO | G40: =VLOOKUP(A40,'ESTADOS ESTUDIANTES'!B:L,7,0) -> NO REGISTRA | H40: =VLOOKUP(A40,'ESTADOS ESTUDIANTES'!B:L,8,0) -> cyherrerab@correo.udistrital.edu.co | I40: =VLOOKUP(A40,'ESTADOS ESTUDIANTES'!B:L,9,0) -> cyherrerab@estudiante.udistrital.edu.co | J40: =VLOOKUP(A40,'ESTADOS ESTUDIANTES'!B:L,10,0) -> CC | K40: =VLOOKUP(A40,'ESTADOS ESTUDIANTES'!B:L,11,0) -> 52228374
...

Sheet Listas
A1: Grupo Investigacion | B1: Codigo Estado | C1: Descripcion Estado | D1: Codigo Enfasis | E1: Descripcion Enfasis | F1: Puntuacion Ingles | G1: Clasificacion Ingles | H1: Caracter tesis (nuevo) | I1: Caracter tesis (antiguo) | J1: Revisores | K1: Categoría revista | L1: Porcentaje | M1: NOTA | N1: Estado Pasantía | O1: Modalidad | P1: ESTADO ARTICULO | Q1: AMPLIACION | R1: COD. | S1: PROYECTO
A2: ARMOS* | B2: A | C2: ACTIVO | D2: 95 | E2: Sin Enfasis | F2: 300 | G2: C2 | H2: Aprobado | I2: LISTO PARA SUSTENTAR | J2: VIABLE | K2: Revista A1 | L2: 0.8 | M2: =50*L2 -> 40 | N2: Finalizada | O2: Profundización | P2: Enviado | Q2: SI | R2: 95 | S2: MAESTRIA EN TELEINFORMATICA
A3: ARQUISOT | B3: B | C3: PRUEBA ACADEMICA Y MATRICULADO | D3: 195 | E3: Teleinformatica | F3: 250 | G3: C1 | H3: Meritorio | I3: MODIFICABLE | J3: NO VIABLE | K3: Revista A2 | L3: 0.8 | M3: =50*L3 -> 40 | N3: En proceso | O3: Investigación | P3: Publicado | Q3: NO | R3: 195 | S3: EN TELEINF.
A4: CEPMS | B4: C | C4: CANCELADO | D4: 295 | E4: Sis. Informaticos | F4: 200 | G4: B2 | H4: Laureado | I4: RECHAZADO | J4: MODIFICABLE | K4: Libro de investigación | L4: 0.8 | M4: =50*L4 -> 40 | N4: Pendiente | P4: Por publicar | R4: 295 | S4: ENFASIS EN SIS. INFOR
A5: GCEM | B5: D | C5: NO REPORTO NOTAS | D5: 395 | E5: Geomatica | F5: 150 | G5: B1 | K5: Revista B | L5: 0.6 | M5: =50*L5 -> 30 | N5: Perdida | R5: 395 | S5: ENFASIS EN GEOMATICA
A6: GEFEM | B6: E | C6: EGRESADO | D6: 495 | E6: Ing. Software | F6: 70 | G6: A2 | K6: capítulo de un libro | L6: 0.6 | M6: =50*L6 -> 30 | R6: 495 | S6: ENFASIS EN ING. SOFT
A7: GESETIC | B7: F | C7: PRUEBA ACADEM Y NO SE MATRICULO | F7: 45 | G7: A1 | K7: Revista C | L7: 0.4 | M7: =50*L7 -> 20 | R7: 595 | S7: INVESTIGACIÓN
A8: GESDATOS | B8: G | C8: POR DEFINIR DEL 2001/1 | K8: Ponencia | L8: 0.2 | M8: =50*L8 -> 10 | R8: 695 | S8: PROFUNDIZACIÓN
A9: GICOECOL | B9: H | C9: TERMINO MATERIA Y MATRICULADO ACTUAL PERIODO | K9: N/A | L9: N/A | M9: 0
A10: GICOGE | B10: I | C10: INACTIVO
A11: GIDENUTAS¨* | B11: J | C11: PRUEBA ACAD
A12: GIIRA | B12: K | C12: PRUEBA AC.NO REPORTO NOTAS DE SEM ACTIVO
A13: GITEM ++ | B13: L | C13: PASANTIA O TRABAJO DE GRADO
A14: GITUD | B14: M | C14: NO SE MATRICULO
A15: GRECO | B15: N | C15: ERROR DE CODIGO
A16: GINFRA
A17: INTECSE | B17: O | C17: ESTUDIANTE MOVILIDAD ACADEMICA
A18: ITI* | B18: P | C18: APLAZO SEMESTRE
A19: INTERNET INTELIGENTE | B19: Q | C19: ESTUDIANTE MOVILIDAD ACADEMICA EN VACACIONES
A20: LAMIC | B20: R | C20: RETIRADO
A21: LASER | B21: S | C21: PERDIO CUPO DURANTE UN A?O
A22: LIDER | B22: T | C22: TERMINO MATERIAS Y NO SE MATRICULO
A23: LIFAE | B23: U | C23: PERDIDA CALIDAD ESTUDIANTE ACUERDO 004
A24: NIDE | B24: V | C24: VACACIONES
A25: GIICUD | B25: W | C25: ABANDONO
A26: PROPROBOS
A27: FISINFOR | B27: X | C27: EXCLUIDO
A28: Bionanotecnología | C28: Z - NO SUPERO PRUEBA ACADEMICA
A29: LIFAE
A30: NIDE | B30: Z | C30: NO SUP. PRUEBA ACAD.
A31: SIE
A32: IAFT
A33: COMPLEX UD
A34: DIMSI
A35: XUE
A36: INFRAESTRUCTURA SOSTENIBLE

Sheet N-A Investigación
A1: CODIGO | B1: NOMBRE | C1: CEDULA | D1: ENFASIS | E1: PROYECTO | F1: CORREO INSTITUCIONAL | G1: CORREO PERSONAL | H1: ESTADO | I1: RECIBO | J1: MODALIDAD | K1: TITULO DE PROYECTO | L1: DIRECTOR | M1: CO-DIRECTOR | N1: FECHA DE RADICACION ANTEPROYECTO | O1: AÑO | P1: GRUPO DE INVESTIGACION | Q1: DIRECTOR G. INVESTIGACION | R1: FECHA DE ACEPTACION DEL GRUP. INV. | S1: FECHA DE VENCIMIENTO ANTE PROYECTO | T1: ¿PROYECTO VENCIDO? | U1: AMPLIACION | V1: FECHA MAXIMA RADICACIÓN2 | W1: ACTA ACEPTACION PROPUESTA | X1: LINEA DE INVESTIGACIÓN | Y1: Ex. Ingles Historico | Z1: Pts. Ingles Historico | AA1: Ex. Ingles Actual | AB1: Pts. Ingles Actual | AC1: Clasifiacion Ingles | AD1: ACTA COMPONENTE 1 | AE1: FECHA ACTA | AF1: TITULO COMPONENTE 1 | AG1: REVISTA O EVENTO | AH1: AÑO DE PUBLICACIÓN O EVENTO | AI1: Componente 1 | AJ1: % COMPONENTE 1 | AK1: NOTA COMPONENTE 1 | AL1: FECHA DE RADICACION | AM1: ACTA ASIGNACIÓN JURADOS | AN1: FECHA ASIGNACION JURADOS | AO1: JURADO 1 | AP1: FECHA DE RECIBIDO | AQ1: FECHA ENTREGADO | AR1: NOTA 1 INFORME | AS1: NOTA 2 SUSTENTACIÓN | AT1: CONCEPTO JURADO 1 | AU1: JURADO 2 | AV1: FECHA DE RECIBIDO2 | AW1: FECHA ENTREGADO2 | AX1: NOTA 1 INFORME5 | AY1: NOTA 2 SUSTENTACIÓN2 | AZ1: CONCEPTO JURADO 2 | BA1: FECHA SUSTENTACION | BB1: NOTA SUSTENTACION | BC1: PORCENTAJE DE COMPONENTE 2 | BD1: Columna1 | BE1: ESTUDIANTE VERIFICADO | BF1: PAZ Y SALVO FINANCIERO | BG1: DIRECTOR2
A2: 9929531 | B2: =VLOOKUP(A2,'Datos Personales'!A:M,2,FALSE) -> PAEZ PISCO SAMUEL | C2: =VLOOKUP(A2,'ESTADOS ESTUDIANTES'!B:L,11,0) -> 79472385 | D2: =VLOOKUP(A2,'Datos Personales'!$A:$M,3,FALSE) -> 195 | E2: =VLOOKUP(Tabla4[[#This Row],[ENFASIS]],Listas!$R$2:$S$8,2,0) -> EN TELEINF. | F2: =VLOOKUP(A2,'Datos Personales'!A:M,8,0) -> spaezp@correo.udistrital.edu.co | G2: =VLOOKUP(A2,'Datos Personales'!A:M,9,0) -> samuel.paez@fiscalia.gov.co | H2: =VLOOKUP(A2,'Datos Personales'!A:M,5,FALSE) -> X | I2: =VLOOKUP(Tabla4[[#This Row],[CODIGO]],'ESTADOS ESTUDIANTES'!B:M,12,0) -> 2022-1 | S2: =IF(Tabla4[[#This Row],[FECHA DE ACEPTACION DEL GRUP. INV.]]="","",DATE(YEAR(Tabla4[[#This Row],[FECHA DE ACEPTACION DEL GRUP. INV.]])+2,MONTH(Tabla4[[#This Row],[FECHA DE ACEPTACION DEL GRUP. INV.]]),DAY(Tabla4[[#This Row],[FECHA DE ACEPTACION DEL GRUP. INV.]]))) | T2: =IF(Tabla4[[#This Row],[FECHA DE ACEPTACION DEL GRUP. INV.]]="","",IF(Tabla4[[#This Row],[FECHA DE VENCIMIENTO ANTE PROYECTO]]<TODAY(),"SÍ","NO")) | AA2: 44510 | AB2: 101 | AC2: B1 | AJ2: =IFERROR(VLOOKUP(AI2,Listas!K:L,2,0),"") | AK2: =IFERROR(VLOOKUP(AJ2,Listas!L:M,2,0),"") | BB2: =IFERROR(ROUND(AVERAGE(AY2,AX2,AS2,AR2),0),"") | BC2: =BB2*(100%-AJ2) -> #VALUE! | BD2: =SUM(BC2,AK2) -> #VALUE! | BG2: =IF(OR(H2="A",$H2="D",$H2="P",$H2="V"),L2,"")
A3: 9929539 | B3: =VLOOKUP(A3,'Datos Personales'!A:M,2,FALSE) -> RODRIGUEZ RENGIFO JORGE | C3: =VLOOKUP(A3,'ESTADOS ESTUDIANTES'!B:L,11,0) -> 7545588 | D3: =VLOOKUP(A3,'Datos Personales'!$A:$M,3,FALSE) -> 195 | E3: =VLOOKUP(Tabla4[[#This Row],[ENFASIS]],Listas!$R$2:$S$8,2,0) -> EN TELEINF. | F3: =VLOOKUP(A3,'Datos Personales'!A:M,8,0) -> jrodriguezr@udistrital.edu.co | G3: =VLOOKUP(A3,'Datos Personales'!A:M,9,0) -> jorge.rodriguez@engineer.com | H3: =VLOOKUP(A3,'Datos Personales'!A:M,5,FALSE) -> X | I3: =VLOOKUP(Tabla4[[#This Row],[CODIGO]],'ESTADOS ESTUDIANTES'!B:M,12,0) -> 2022-1 | S3: =IF(Tabla4[[#This Row],[FECHA DE ACEPTACION DEL GRUP. INV.]]="","",DATE(YEAR(Tabla4[[#This Row],[FECHA DE ACEPTACION DEL GRUP. INV.]])+2,MONTH(Tabla4[[#This Row],[FECHA DE ACEPTACION DEL GRUP. INV.]]),DAY(Tabla4[[#This Row],[FECHA DE ACEPTACION DEL GRUP. INV.]]))) | T3: =IF(Tabla4[[#This Row],[FECHA DE ACEPTACION DEL GRUP. INV.]]="","",IF(Tabla4[[#This Row],[FECHA DE VENCIMIENTO ANTE PROYECTO]]<TODAY(),"SÍ","NO")) | AJ3: =IFERROR(VLOOKUP(AI3,Listas!K:L,2,0),"") | AK3: =IFERROR(VLOOKUP(AJ3,Listas!L:M,2,0),"") | BB3: =IFERROR(ROUND(AVERAGE(AY3,AX3,AS3,AR3),0),"") | BC3: =BB3*(100%-AJ3) -> #VALUE! | BD3: =SUM(BC3,AK3) -> #VALUE! | BG3: =IF(OR(H3="A",$H3="D",$H3="P",$H3="V"),L3,"")
A4: 20012095004 | B4: =VLOOKUP(A4,'Datos Personales'!A:M,2,FALSE) -> BECERRA FINO JOSE YASIS | C4: =VLOOKUP(A4,'ESTADOS ESTUDIANTES'!B:L,11,0) -> 79483121 | D4: =VLOOKUP(A4,'Datos Personales'!$A:$M,3,FALSE) -> 195 | E4: =VLOOKUP(Tabla4[[#This Row],[ENFASIS]],Listas!$R$2:$S$8,2,0) -> EN TELEINF. | F4: =VLOOKUP(A4,'Datos Personales'!A:M,8,0) -> jybecerraf@correo.udistrital.edu.co | G4: =VLOOKUP(A4,'Datos Personales'!A:M,9,0) -> jybecerra@gmail.com | H4: =VLOOKUP(A4,'Datos Personales'!A:M,5,FALSE) -> X | I4: =VLOOKUP(Tabla4[[#This Row],[CODIGO]],'ESTADOS ESTUDIANTES'!B:M,12,0) -> 2022-3 | J4: Investigación | K4: CODISEÑO HARDWARE-SOFTWARE PARA LA IMPLEMENTACION DE UN ALGORITMO CRIPTOGRAFICO | L4: Elvis Eduardo Gaona Garcia | M4: Edwar Jacinto Gomez | N4: 44367 | O4: 2021 | P4: GIIRA | Q4: Carlos Enrique Montenegro Marin | R4: 44374 | S4: =IF(Tabla4[[#This Row],[FECHA DE ACEPTACION DEL GRUP. INV.]]="","",DATE(YEAR(Tabla4[[#This Row],[FECHA DE ACEPTACION DEL GRUP. INV.]])+2,MONTH(Tabla4[[#This Row],[FECHA DE ACEPTACION DEL GRUP. INV.]]),DAY(Tabla4[[#This Row],[FECHA DE ACEPTACION DEL GRUP. INV.]]))) -> 45104 | T4: =IF(Tabla4[[#This Row],[FECHA DE ACEPTACION DEL GRUP. INV.]]="","",IF(Tabla4[[#This Row],[FECHA DE VENCIMIENTO ANTE PROYECTO]]<TODAY(),"SÍ","NO")) -> SÍ | W4: 08-2021 | AA4: 43964 | AB4: 92.17 | AC4: B1 | AJ4: =IFERROR(VLOOKUP(AI4,Listas!K:L,2,0),"") | AK4: =IFERROR(VLOOKUP(AJ4,Listas!L:M,2,0),"") | BB4: =IFERROR(ROUND(AVERAGE(AY4,AX4,AS4,AR4),0),"") | BC4: =BB4*(100%-AJ4) -> #VALUE! | BD4: =SUM(BC4,AK4) -> #VALUE! | BG4: =IF(OR(H4="A",$H4="D",$H4="P",$H4="V"),L4,"")
A5: 20101295014 | B5: =VLOOKUP(A5,'Datos Personales'!A:M,2,FALSE) -> SANCHEZ JOSE ALEJANDRO | C5: =VLOOKUP(A5,'ESTADOS ESTUDIANTES'!B:L,11,0) -> 79763774 | D5: =VLOOKUP(A5,'Datos Personales'!$A:$M,3,FALSE) -> 295 | E5: =VLOOKUP(Tabla4[[#This Row],[ENFASIS]],Listas!$R$2:$S$8,2,0) -> ENFASIS EN SIS. INFOR | F5: =VLOOKUP(A5,'Datos Personales'!A:M,8,0) -> jrestivang@udistrital.edu.co | G5: =VLOOKUP(A5,'Datos Personales'!A:M,9,0) -> ijasanchez@gmail.com | H5: =VLOOKUP(A5,'Datos Personales'!A:M,5,FALSE) -> E | I5: =VLOOKUP(Tabla4[[#This Row],[CODIGO]],'ESTADOS ESTUDIANTES'!B:M,12,0) -> 2022-1 | J5: Investigación | K5: PROPUESTA DE UN MARCO DE ENSEÑANZAAPRENDIZAJE BASADO EN CASOS DE ESTUDIO PARA LA IMPLEMENTACION AGIL DE PROYECTOS DE ANALITICA GEOESPACIAL | L5: Jose Nelson Perez | Q5: Sandro Javier Bolaños | R5: 43891 | S5: =IF(Tabla4[[#This Row],[FECHA DE ACEPTACION DEL GRUP. INV.]]="","",DATE(YEAR(Tabla4[[#This Row],[FECHA DE ACEPTACION DEL GRUP. INV.]])+2,MONTH(Tabla4[[#This Row],[FECHA DE ACEPTACION DEL GRUP. INV.]]),DAY(Tabla4[[#This Row],[FECHA DE ACEPTACION DEL GRUP. INV.]]))) -> 44621 | T5: =IF(Tabla4[[#This Row],[FECHA DE ACEPTACION DEL GRUP. INV.]]="","",IF(Tabla4[[#This Row],[FECHA DE VENCIMIENTO ANTE PROYECTO]]<TODAY(),"SÍ","NO")) -> SÍ | AA5: 43888 | AB5: 73.04 | AC5: B1 | AD5: 11-2022 | AE5: 44692 | AJ5: =IFERROR(VLOOKUP(AI5,Listas!K:L,2,0),"") | AK5: =IFERROR(VLOOKUP(AJ5,Listas!L:M,2,0),"") | AL5: 44011 | AN5: 44011 | AO5: Sandro Bolaños | AP5: 44011 | AQ5: 44014 | AR5: 47 | AS5: 47 | AT5: Aprobado | AU5: Luz Angela Rocha Salamanca | AV5: 44011 | AW5: 44025 | AX5: 47 | AY5: 47 | AZ5: Aprobado | BA5: 44120 | BB5: =IFERROR(ROUND(AVERAGE(AY5,AX5,AS5,AR5),0),"") -> 47 | BC5: =BB5*(100%-AJ5) -> #VALUE! | BD5: =SUM(BC5,AK5) -> #VALUE! | BG5: =IF(OR(H5="A",$H5="D",$H5="P",$H5="V"),L5,"")
A6: 20102195004 | B6: =VLOOKUP(A6,'Datos Personales'!A:M,2,FALSE) -> MOLINA MONGUI ANDRES MAURICIO | C6: =VLOOKUP(A6,'ESTADOS ESTUDIANTES'!B:L,11,0) -> 80926416 | D6: =VLOOKUP(A6,'Datos Personales'!$A:$M,3,FALSE) -> 195 | E6: =VLOOKUP(Tabla4[[#This Row],[ENFASIS]],Listas!$R$2:$S$8,2,0) -> EN TELEINF. | F6: =VLOOKUP(A6,'Datos Personales'!A:M,8,0) -> ammolinam@udistrital.edu.co | G6: =VLOOKUP(A6,'Datos Personales'!A:M,9,0) -> maomolina@hotmail.com | H6: =VLOOKUP(A6,'Datos Personales'!A:M,5,FALSE) -> X | I6: =VLOOKUP(Tabla4[[#This Row],[CODIGO]],'ESTADOS ESTUDIANTES'!B:M,12,0) -> 2022-3 | S6: =IF(Tabla4[[#This Row],[FECHA DE ACEPTACION DEL GRUP. INV.]]="","",DATE(YEAR(Tabla4[[#This Row],[FECHA DE ACEPTACION DEL GRUP. INV.]])+2,MONTH(Tabla4[[#This Row],[FECHA DE ACEPTACION DEL GRUP. INV.]]),DAY(Tabla4[[#This Row],[FECHA DE ACEPTACION DEL GRUP. INV.]]))) | T6: =IF(Tabla4[[#This Row],[FECHA DE ACEPTACION DEL GRUP. INV.]]="","",IF(Tabla4[[#This Row],[FECHA DE VENCIMIENTO ANTE PROYECTO]]<TODAY(),"SÍ","NO")) | AA6: 44153 | AB6: 84.11 | AC6: B1 | AJ6: =IFERROR(VLOOKUP(AI6,Listas!K:L,2,0),"") | AK6: =IFERROR(VLOOKUP(AJ6,Listas!L:M,2,0),"") | BB6: =IFERROR(ROUND(AVERAGE(AY6,AX6,AS6,AR6),0),"") | BC6: =BB6*(100%-AJ6) -> #VALUE! | BD6: =SUM(BC6,AK6) -> #VALUE! | BG6: =IF(OR(H6="A",$H6="D",$H6="P",$H6="V"),L6,"")
A7: 20121195003 | B7: =VLOOKUP(A7,'Datos Personales'!A:M,2,FALSE) -> AVILA SANCHEZ JAIME ANTONIO | C7: =VLOOKUP(A7,'ESTADOS ESTUDIANTES'!B:L,11,0) -> 7174732 | D7: =VLOOKUP(A7,'Datos Personales'!$A:$M,3,FALSE) -> 195 | E7: =VLOOKUP(Tabla4[[#This Row],[ENFASIS]],Listas!$R$2:$S$8,2,0) -> EN TELEINF. | F7: =VLOOKUP(A7,'Datos Personales'!A:M,8,0) -> jaaavilas@udistrital.edu.co | G7: =VLOOKUP(A7,'Datos Personales'!A:M,9,0) -> jaimejaas@gmail.com | H7: =VLOOKUP(A7,'Datos Personales'!A:M,5,FALSE) -> E | I7: =VLOOKUP(Tabla4[[#This Row],[CODIGO]],'ESTADOS ESTUDIANTES'!B:M,12,0) -> 2023-1 | K7: OPTIMIZACION DE LA OPERACION DE UNA MICRO RED RURAL AISLADA ENFOCADA EN COSTOS/ MODELO DE OPTIMIZACION ENFOCADO EN LA MINIMIZACION DE COSTOS DEGENERACION DE UNA MICRORRED RURAL AISLADA - CASO DE ESTUDIO CORREGIMIENTO NAZARETH URIBIA (LA GUAJIRA). | L7: Elvis Eduardo Gaona Garcia | M7: Jose Guillermo Guarnizo | O7: 2020 | P7: LIFAE | Q7: Nelson Diaz Aldana | R7: 44021 | S7: =IF(Tabla4[[#This Row],[FECHA DE ACEPTACION DEL GRUP. INV.]]="","",DATE(YEAR(Tabla4[[#This Row],[FECHA DE ACEPTACION DEL GRUP. INV.]])+2,MONTH(Tabla4[[#This Row],[FECHA DE ACEPTACION DEL GRUP. INV.]]),DAY(Tabla4[[#This Row],[FECHA DE ACEPTACION DEL GRUP. INV.]]))) -> 44751 | T7: =IF(Tabla4[[#This Row],[FECHA DE ACEPTACION DEL GRUP. INV.]]="","",IF(Tabla4[[#This Row],[FECHA DE VENCIMIENTO ANTE PROYECTO]]<TODAY(),"SÍ","NO")) -> SÍ | W7: 08-2020 | AA7: 44873 | AB7: 88 | AC7: B1 | AD7: 003/2023 | AE7: 44993 | AF7: Optimización de la operación rural aislada enfocada en costos | AG7: Segundo congreso internacional de ingenieria "Ingenieria para todos" | AH7: 2022 | AI7: Ponencia | AJ7: =IFERROR(VLOOKUP(AI7,Listas!K:L,2,0),"") -> 0.2 | AK7: =IFERROR(VLOOKUP(AJ7,Listas!L:M,2,0),"") -> 10 | AL7: 44867 | AM7: 023/2022 | AN7: 44867 | AO7: Javier Guacaneme | AP7: 44869 | AQ7: 44909 | AR7: 41 | AS7: 44 | AT7: Aprobado | AU7: Francisco Santamaria Piedrahita | AV7: 44869 | AW7: 44909 | AX7: 40 | AY7: 40 | AZ7: Aprobado | BA7: 44907 | BB7: =IFERROR(AVERAGE(AR7,AS7,AX7,AY7),"") -> 41.25 | BC7: =BB7*(100%-AJ7) -> 33 | BD7: =SUM(BC7,AK7) -> 43 | BE7: OK | BF7: OK | BG7: =IF(OR(H7="A",$H7="D",$H7="P",$H7="V"),L7,"")
A8: 20121195016 | B8: =VLOOKUP(A8,'Datos Personales'!A:M,2,FALSE) -> BECERRA FINO JOSE YASIS | C8: =VLOOKUP(A8,'ESTADOS ESTUDIANTES'!B:L,11,0) -> 79483121 | D8: =VLOOKUP(A8,'Datos Personales'!$A:$M,3,FALSE) -> 195 | E8: =VLOOKUP(Tabla4[[#This Row],[ENFASIS]],Listas!$R$2:$S$8,2,0) -> EN TELEINF. | F8: =VLOOKUP(A8,'Datos Personales'!A:M,8,0) -> jybecerraf@correo.udistrital.edu.co | G8: =VLOOKUP(A8,'Datos Personales'!A:M,9,0) -> jybecerra@gmail.com | H8: =VLOOKUP(A8,'Datos Personales'!A:M,5,FALSE) -> X | I8: =VLOOKUP(Tabla4[[#This Row],[CODIGO]],'ESTADOS ESTUDIANTES'!B:M,12,0) -> 2013-3 | S8: =IF(Tabla4[[#This Row],[FECHA DE ACEPTACION DEL GRUP. INV.]]="","",DATE(YEAR(Tabla4[[#This Row],[FECHA DE ACEPTACION DEL GRUP. INV.]])+2,MONTH(Tabla4[[#This Row],[FECHA DE ACEPTACION DEL GRUP. INV.]]),DAY(Tabla4[[#This Row],[FECHA DE ACEPTACION DEL GRUP. INV.]]))) | T8: =IF(Tabla4[[#This Row],[FECHA DE ACEPTACION DEL GRUP. INV.]]="","",IF(Tabla4[[#This Row],[FECHA DE VENCIMIENTO ANTE PROYECTO]]<TODAY(),"SÍ","NO")) | AA8: 43964 | AB8: 92.17 | AC8: B1 | AJ8: =IFERROR(VLOOKUP(AI8,Listas!K:L,2,0),"") | AK8: =IFERROR(VLOOKUP(AJ8,Listas!L:M,2,0),"") | BB8: =IFERROR(ROUND(AVERAGE(AY8,AX8,AS8,AR8),0),"") | BC8: =BB8*(100%-AJ8) -> #VALUE! | BD8: =SUM(BC8,AK8) -> #VALUE! | BG8: =IF(OR(H8="A",$H8="D",$H8="P",$H8="V"),L8,"")
A9: 20121395015 | B9: =VLOOKUP(A9,'Datos Personales'!A:M,2,FALSE) -> RODRIGUEZ SABOGAL EDWIN MAURICIO | C9: =VLOOKUP(A9,'ESTADOS ESTUDIANTES'!B:L,11,0) -> 79764993 | D9: =VLOOKUP(A9,'Datos Personales'!$A:$M,3,FALSE) -> 395 | E9: =VLOOKUP(Tabla4[[#This Row],[ENFASIS]],Listas!$R$2:$S$8,2,0) -> ENFASIS EN GEOMATICA | F9: =VLOOKUP(A9,'Datos Personales'!A:M,8,0) -> 0 | G9: =VLOOKUP(A9,'Datos Personales'!A:M,9,0) -> emauriciors@gmail.com | H9: =VLOOKUP(A9,'Datos Personales'!A:M,5,FALSE) -> X | I9: =VLOOKUP(Tabla4[[#This Row],[CODIGO]],'ESTADOS ESTUDIANTES'!B:M,12,0) -> 2021-1 | S9: =IF(Tabla4[[#This Row],[FECHA DE ACEPTACION DEL GRUP. INV.]]="","",DATE(YEAR(Tabla4[[#This Row],[FECHA DE ACEPTACION DEL GRUP. INV.]])+2,MONTH(Tabla4[[#This Row],[FECHA DE ACEPTACION DEL GRUP. INV.]]),DAY(Tabla4[[#This Row],[FECHA DE ACEPTACION DEL GRUP. INV.]]))) | T9: =IF(Tabla4[[#This Row],[FECHA DE ACEPTACION DEL GRUP. INV.]]="","",IF(Tabla4[[#This Row],[FECHA DE VENCIMIENTO ANTE PROYECTO]]<TODAY(),"SÍ","NO")) | AA9: 44097 | AB9: 92.52 | AC9: B1 | AJ9: =IFERROR(VLOOKUP(AI9,Listas!K:L,2,0),"") | AK9: =IFERROR(VLOOKUP(AJ9,Listas!L:M,2,0),"") | BB9: =IFERROR(ROUND(AVERAGE(AY9,AX9,AS9,AR9),0),"") | BC9: =BB9*(100%-AJ9) -> #VALUE! | BD9: =SUM(BC9,AK9) -> #VALUE! | BG9: =IF(OR(H9="A",$H9="D",$H9="P",$H9="V"),L9,"")
A10: 20141295003 | B10: =VLOOKUP(A10,'Datos Personales'!A:M,2,FALSE) -> DIAZ ESCUDERO HUMBERTO ANDRES | C10: =VLOOKUP(A10,'ESTADOS ESTUDIANTES'!B:L,11,0) -> 10323622759 | D10: =VLOOKUP(A10,'Datos Personales'!$A:$M,3,FALSE) -> 295 | E10: =VLOOKUP(Tabla4[[#This Row],[ENFASIS]],Listas!$R$2:$S$8,2,0) -> ENFASIS EN SIS. INFOR | F10: =VLOOKUP(A10,'Datos Personales'!A:M,8,0) -> huadiaze@correo.udistrital.edu.co | G10: =VLOOKUP(A10,'Datos Personales'!A:M,9,0) -> humbertodiaz2@gmail.com | H10: =VLOOKUP(A10,'Datos Personales'!A:M,5,FALSE) -> X | I10: =VLOOKUP(Tabla4[[#This Row],[CODIGO]],'ESTADOS ESTUDIANTES'!B:M,12,0) -> 2021-1 | S10: =IF(Tabla4[[#This Row],[FECHA DE ACEPTACION DEL GRUP. INV.]]="","",DATE(YEAR(Tabla4[[#This Row],[FECHA DE ACEPTACION DEL GRUP. INV.]])+2,MONTH(Tabla4[[#This Row],[FECHA DE ACEPTACION DEL GRUP. INV.]]),DAY(Tabla4[[#This Row],[FECHA DE ACEPTACION DEL GRUP. INV.]]))) | T10: =IF(Tabla4[[#This Row],[FECHA DE ACEPTACION DEL GRUP. INV.]]="","",IF(Tabla4[[#This Row],[FECHA DE VENCIMIENTO ANTE PROYECTO]]<TODAY(),"SÍ","NO")) | AJ10: =IFERROR(VLOOKUP(AI10,Listas!K:L,2,0),"") | AK10: =IFERROR(VLOOKUP(AJ10,Listas!L:M,2,0),"") | BB10: =IFERROR(ROUND(AVERAGE(AY10,AX10,AS10,AR10),0),"") | BC10: =BB10*(100%-AJ10) -> #VALUE! | BD10: =SUM(BC10,AK10) -> #VALUE! | BG10: =IF(OR(H10="A",$H10="D",$H10="P",$H10="V"),L10,"")
A11: 20141395002 | B11: =VLOOKUP(A11,'Datos Personales'!A:M,2,FALSE) -> GONZALEZ RODRIGUEZ ADRIAN ALEJANDRO | C11: =VLOOKUP(A11,'ESTADOS ESTUDIANTES'!B:L,11,0) -> 1013607129 | D11: =VLOOKUP(A11,'Datos Personales'!$A:$M,3,FALSE) -> 395 | E11: =VLOOKUP(Tabla4[[#This Row],[ENFASIS]],Listas!$R$2:$S$8,2,0) -> ENFASIS EN GEOMATICA | F11: =VLOOKUP(A11,'Datos Personales'!A:M,8,0) -> adagonzalezr@correo.udistrital.edu.co | G11: =VLOOKUP(A11,'Datos Personales'!A:M,9,0) -> gerencia@geomap.com.co | H11: =VLOOKUP(A11,'Datos Personales'!A:M,5,FALSE) -> X | I11: =VLOOKUP(Tabla4[[#This Row],[CODIGO]],'ESTADOS ESTUDIANTES'!B:M,12,0) -> 2021-3 | S11: =IF(Tabla4[[#This Row],[FECHA DE ACEPTACION DEL GRUP. INV.]]="","",DATE(YEAR(Tabla4[[#This Row],[FECHA DE ACEPTACION DEL GRUP. INV.]])+2,MONTH(Tabla4[[#This Row],[FECHA DE ACEPTACION DEL GRUP. INV.]]),DAY(Tabla4[[#This Row],[FECHA DE ACEPTACION DEL GRUP. INV.]]))) | T11: =IF(Tabla4[[#This Row],[FECHA DE ACEPTACION DEL GRUP. INV.]]="","",IF(Tabla4[[#This Row],[FECHA DE VENCIMIENTO ANTE PROYECTO]]<TODAY(),"SÍ","NO")) | AJ11: =IFERROR(VLOOKUP(AI11,Listas!K:L,2,0),"") | AK11: =IFERROR(VLOOKUP(AJ11,Listas!L:M,2,0),"") | BB11: =IFERROR(ROUND(AVERAGE(AY11,AX11,AS11,AR11),0),"") | BC11: =BB11*(100%-AJ11) -> #VALUE! | BD11: =SUM(BC11,AK11) -> #VALUE! | BG11: =IF(OR(H11="A",$H11="D",$H11="P",$H11="V"),L11,"")
A12: 20142295002 | B12: =VLOOKUP(A12,'Datos Personales'!A:M,2,FALSE) -> CRISTIAN JHONATAN IZQUIERDO ORTIZ | C12: =VLOOKUP(A12,'ESTADOS ESTUDIANTES'!B:L,11,0) -> 1032379203 | D12: =VLOOKUP(A12,'Datos Personales'!$A:$M,3,FALSE) -> 295 | E12: =VLOOKUP(Tabla4[[#This Row],[ENFASIS]],Listas!$R$2:$S$8,2,0) -> ENFASIS EN SIS. INFOR | F12: =VLOOKUP(A12,'Datos Personales'!A:M,8,0) -> cjizquierdoo@udistrital.edu.co | G12: =VLOOKUP(A12,'Datos Personales'!A:M,9,0) -> izquierdo.cristhian@gmail.com | H12: =VLOOKUP(A12,'Datos Personales'!A:M,5,FALSE) -> E | I12: =VLOOKUP(Tabla4[[#This Row],[CODIGO]],'ESTADOS ESTUDIANTES'!B:M,12,0) -> 2024-1 | J12: Investigación | K12: PREDICCIÓN DE INDICADORES ECONÓMICOS A TRAVES DE NOTICIAS USÁNDO RSS, MINERÍA DE TEXTO E INTELIGENCIA COMPUTACIONAL. | L12: Deicy Alvarado | N12: 44824 | O12: 2022 | P12: COMPLEX UD | Q12: Deicy Alvarado | R12: 5--10-2022 | S12: =IF(Tabla4[[#This Row],[FECHA DE ACEPTACION DEL GRUP. INV.]]="","",DATE(YEAR(Tabla4[[#This Row],[FECHA DE ACEPTACION DEL GRUP. INV.]])+2,MONTH(Tabla4[[#This Row],[FECHA DE ACEPTACION DEL GRUP. INV.]]),DAY(Tabla4[[#This Row],[FECHA DE ACEPTACION DEL GRUP. INV.]]))) -> #VALUE! | T12: =IF(Tabla4[[#This Row],[FECHA DE ACEPTACION DEL GRUP. INV.]]="","",IF(Tabla4[[#This Row],[FECHA DE VENCIMIENTO ANTE PROYECTO]]<TODAY(),"SÍ","NO")) -> #VALUE! | AA12: 44887 | AB12: 167 | AC12: B2 | AD12: 012 de 2023 | AE12: 45191 | AF12: Analysis of economic indicators through news and Twitter using text mining, machine learning and multiagent systems. | AG12: IEEE ColCACI 2023 | AH12: 2023 | AI12: Ponencia | AJ12: =IFERROR(VLOOKUP(AI12,Listas!K:L,2,0),"") -> 0.2 | AK12: =IFERROR(VLOOKUP(AJ12,Listas!L:M,2,0),"") -> 10 | AO12: Cesar Augusto Hernandez Suarez | AQ12: 45252 | AR12: 42 | AS12: 41 | AT12: Aprobado | AU12: Andres Eduardo Gaona Barrera | AW12: 45253 | AX12: 41 | AY12: 42 | AZ12: Aprobado | BA12: 45233 | BB12: =IFERROR(AVERAGE(AR12,AS12,AX12,AY12),"") -> 41.5 | BC12: =BB12*(100%-AJ12) -> 33.2 | BD12: =SUM(BC12,AK12) -> 43.2 | BG12: =IF(OR(H12="A",$H12="D",$H12="P",$H12="V"),L12,"")
A13: 20142395005 | B13: =VLOOKUP(A13,'Datos Personales'!A:M,2,FALSE) -> JESSICA ANDREA ZAPATA GRAJALES | C13: =VLOOKUP(A13,'ESTADOS ESTUDIANTES'!B:L,11,0) -> 1026269883 | D13: =VLOOKUP(A13,'Datos Personales'!$A:$M,3,FALSE) -> 395 | E13: =VLOOKUP(Tabla4[[#This Row],[ENFASIS]],Listas!$R$2:$S$8,2,0) -> ENFASIS EN GEOMATICA | F13: =VLOOKUP(A13,'Datos Personales'!A:M,8,0) -> azapatag@correo.udistrital.edu.co | G13: =VLOOKUP(A13,'Datos Personales'!A:M,9,0) -> jessiandre71@gmail.com | H13: =VLOOKUP(A13,'Datos Personales'!A:M,5,FALSE) -> E | I13: =VLOOKUP(Tabla4[[#This Row],[CODIGO]],'ESTADOS ESTUDIANTES'!B:M,12,0) -> 2022-3 | J13: Investigación | K13: MODELO DE DIAGNOSTICO DE LAS ESTRUCTURAS DE LAS EDIFICACIONES DE CHAPINERO Y BOSA EN EL CASO DE UN EVENTO SISMICO QUE AFECTE A LA CIUDAD DE BOGOTA. / MODELO PROBABILISTICO APLICADO AL COLAPSO DE LAS ESTRUCTURAS DE LAS EDIFICACIONES DE LA UPZ DE EL RETIRO, CHAPINERO Y DE LA UPZ EL PORVENIR EN BOSA, EN CASO DE PRESENTARSE UN EVENTO SISMICO. | L13: Andres Cardenas Contreras | N13: 43054 | Q13: Mauricio Rocha | R13: 43182 | S13: =IF(Tabla4[[#This Row],[FECHA DE ACEPTACION DEL GRUP. INV.]]="","",DATE(YEAR(Tabla4[[#This Row],[FECHA DE ACEPTACION DEL GRUP. INV.]])+2,MONTH(Tabla4[[#This Row],[FECHA DE ACEPTACION DEL GRUP. INV.]]),DAY(Tabla4[[#This Row],[FECHA DE ACEPTACION DEL GRUP. INV.]]))) -> 43913 | T13: =IF(Tabla4[[#This Row],[FECHA DE ACEPTACION DEL GRUP. INV.]]="","",IF(Tabla4[[#This Row],[FECHA DE VENCIMIENTO ANTE PROYECTO]]<TODAY(),"SÍ","NO")) -> SÍ | Y13: 43964 | Z13: 51.3 | AA13: 44097 | AB13: 89.72 | AC13: B1 | AD13: 11-2022 | AE13: 44692 | AJ13: =IFERROR(VLOOKUP(AI13,Listas!K:L,2,0),"") | AK13: =IFERROR(VLOOKUP(AJ13,Listas!L:M,2,0),"") | AL13: 43983 | AO13: ROBINSON QUINTANA | AP13: 44140 | AQ13: 44166 | AR13: 50 | AS13: 50 | AT13: Meritorio | AU13: MAURICIO ROCHA | AV13: 43991 | AW13: 44033 | AX13: 50 | AY13: 50 | AZ13: Meritorio | BA13: 44180 | BB13: =IFERROR(ROUND(AVERAGE(AY13,AX13,AS13,AR13),0),"") -> 50 | BC13: =BB13*(100%-AJ13) -> #VALUE! | BD13: =SUM(BC13,AK13) -> #VALUE! | BE13: SI | BG13: =IF(OR(H13="A",$H13="D",$H13="P",$H13="V"),L13,"")
A14: 20152495005 | B14: =VLOOKUP(A14,'Datos Personales'!A:M,2,FALSE) -> DAZA ESPITIA CARLOS ANDRES | C14: =VLOOKUP(A14,'ESTADOS ESTUDIANTES'!B:L,11,0) -> 1033698113 | D14: =VLOOKUP(A14,'Datos Personales'!$A:$M,3,FALSE) -> 495 | E14: =VLOOKUP(Tabla4[[#This Row],[ENFASIS]],Listas!$R$2:$S$8,2,0) -> ENFASIS EN ING. SOFT | F14: =VLOOKUP(A14,'Datos Personales'!A:M,8,0) -> cadazae@udistrital.edu.co | G14: =VLOOKUP(A14,'Datos Personales'!A:M,9,0) -> cdaza1@outlook.com | H14: =VLOOKUP(A14,'Datos Personales'!A:M,5,FALSE) -> X | I14: =VLOOKUP(Tabla4[[#This Row],[CODIGO]],'ESTADOS ESTUDIANTES'!B:M,12,0) -> 2023-1 | J14: Investigación | K14: SIMULACION BASADA EN AGENTES DEL PROCESO DE APROXIMACION FINAL Y ATERRIZAJE DE UNA AERONAVE, EN UN AERODROMO APLICANDO METAHEURISTICAS // MODELACION METAHEURISTICA DEL PROCESO DE APROXIMACION FINAL Y ATERRIZAJE DE UNA AERONAVE, EN UN AERODROMO | L14: Luz Deyci Alvarado Nieto | N14: 43809 | O14: 2019 | P14: COMPLEXUD | Q14: Deicy Alvarado | R14: 44312 | S14: =IF(Tabla4[[#This Row],[FECHA DE ACEPTACION DEL GRUP. INV.]]="","",DATE(YEAR(Tabla4[[#This Row],[FECHA DE ACEPTACION DEL GRUP. INV.]])+2,MONTH(Tabla4[[#This Row],[FECHA DE ACEPTACION DEL GRUP. INV.]]),DAY(Tabla4[[#This Row],[FECHA DE ACEPTACION DEL GRUP. INV.]]))) -> 45042 | T14: =IF(Tabla4[[#This Row],[FECHA DE ACEPTACION DEL GRUP. INV.]]="","",IF(Tabla4[[#This Row],[FECHA DE VENCIMIENTO ANTE PROYECTO]]<TODAY(),"SÍ","NO")) -> SÍ | W14: 05-2021 | AA14: 44802 | AB14: 137 | AC14: B1 | AJ14: =IFERROR(VLOOKUP(AI14,Listas!K:L,2,0),"") | AK14: =IFERROR(VLOOKUP(AJ14,Listas!L:M,2,0),"") | BB14: =IFERROR(AVERAGE(AR14,AS14,AX14,AY14),"") | BC14: =BB14*(100%-AJ14) -> #VALUE! | BD14: =SUM(BC14,AK14) -> #VALUE! | BG14: =IF(OR(H14="A",$H14="D",$H14="P",$H14="V"),L14,"")
A15: 20161195004 | B15: =VLOOKUP(A15,'Datos Personales'!A:M,2,FALSE) -> CORTES FONSECA DAVID RICAUTE | C15: =VLOOKUP(A15,'ESTADOS ESTUDIANTES'!B:L,11,0) -> 1022953913 | D15: =VLOOKUP(A15,'Datos Personales'!$A:$M,3,FALSE) -> 195 | E15: =VLOOKUP(Tabla4[[#This Row],[ENFASIS]],Listas!$R$2:$S$8,2,0) -> EN TELEINF. | F15: =VLOOKUP(A15,'Datos Personales'!A:M,8,0) -> drcortesf@udistrital.edu.co | G15: =VLOOKUP(A15,'Datos Personales'!A:M,9,0) -> davidcortesfonseca@gmail.com | H15: =VLOOKUP(A15,'Datos Personales'!A:M,5,FALSE) -> X | I15: =VLOOKUP(Tabla4[[#This Row],[CODIGO]],'ESTADOS ESTUDIANTES'!B:M,12,0) -> 2022-1 | J15: Investigación | K15: PRONOSTICO DE OPORTUNIDADES ESPECTRALES CON BASE EN EL MODELO DE PROPAGACION SAKAGAMI-KUBOI | L15: Luis Fernando Pedraza | M15: Abel Antonio Navarrete | N15: 43717 | O15: 2019 | P15: GIDENUTAS | Q15: Luis Fernando Pedraza | R15: 43717 | S15: =IF(Tabla4[[#This Row],[FECHA DE ACEPTACION DEL GRUP. INV.]]="","",DATE(YEAR(Tabla4[[#This Row],[FECHA DE ACEPTACION DEL GRUP. INV.]])+2,MONTH(Tabla4[[#This Row],[FECHA DE ACEPTACION DEL GRUP. INV.]]),DAY(Tabla4[[#This Row],[FECHA DE ACEPTACION DEL GRUP. INV.]]))) -> 44448 | T15: =IF(Tabla4[[#This Row],[FECHA DE ACEPTACION DEL GRUP. INV.]]="","",IF(Tabla4[[#This Row],[FECHA DE VENCIMIENTO ANTE PROYECTO]]<TODAY(),"SÍ","NO")) -> SÍ | W15: 14-2019 | AA15: 44097 | AB15: 92.52 | AC15: B1 | AJ15: =IFERROR(VLOOKUP(AI15,Listas!K:L,2,0),"") | AK15: =IFERROR(VLOOKUP(AJ15,Listas!L:M,2,0),"") | BB15: =IFERROR(ROUND(AVERAGE(AY15,AX15,AS15,AR15),0),"") | BC15: =BB15*(100%-AJ15) -> #VALUE! | BD15: =SUM(BC15,AK15) -> #VALUE! | BG15: =IF(OR(H15="A",$H15="D",$H15="P",$H15="V"),L15,"")
A16: 20161395002 | B16: =VLOOKUP(A16,'Datos Personales'!A:M,2,FALSE) -> CABIATIVA SANCHEZ OSCAR ABRAHAM | C16: =VLOOKUP(A16,'ESTADOS ESTUDIANTES'!B:L,11,0) -> 1019040864 | D16: =VLOOKUP(A16,'Datos Personales'!$A:$M,3,FALSE) -> 395 | E16: =VLOOKUP(Tabla4[[#This Row],[ENFASIS]],Listas!$R$2:$S$8,2,0) -> ENFASIS EN GEOMATICA | F16: =VLOOKUP(A16,'Datos Personales'!A:M,8,0) -> oacabiativas@udistrital.edu.co | G16: =VLOOKUP(A16,'Datos Personales'!A:M,9,0) -> cabiato90@gmail.com | H16: =VLOOKUP(A16,'Datos Personales'!A:M,5,FALSE) -> E | I16: =VLOOKUP(Tabla4[[#This Row],[CODIGO]],'ESTADOS ESTUDIANTES'!B:M,12,0) -> 2023-1 | J16: Investigación | K16: MODELO DE IDENTIDAD DIGITAL PARA DOCUMENTOS ADMINISTRATIVOS MEDIANTE FIRMA ELECTRONICA Y BLOCKCHAIN | L16: Edward Jacinto Gomez | S16: =IF(Tabla4[[#This Row],[FECHA DE ACEPTACION DEL GRUP. INV.]]="","",DATE(YEAR(Tabla4[[#This Row],[FECHA DE ACEPTACION DEL GRUP. INV.]])+2,MONTH(Tabla4[[#This Row],[FECHA DE ACEPTACION DEL GRUP. INV.]]),DAY(Tabla4[[#This Row],[FECHA DE ACEPTACION DEL GRUP. INV.]]))) | T16: =IF(Tabla4[[#This Row],[FECHA DE ACEPTACION DEL GRUP. INV.]]="","",IF(Tabla4[[#This Row],[FECHA DE VENCIMIENTO ANTE PROYECTO]]<TODAY(),"SÍ","NO")) | AD16: 02-2023 | AE16: 44979 | AF16: Modelo de identidad digital con firma digital y Blockchain | AJ16: =IFERROR(VLOOKUP(AI16,Listas!K:L,2,0),"") | AK16: =IFERROR(VLOOKUP(AJ16,Listas!L:M,2,0),"") | BB16: =IFERROR(AVERAGE(AR16,AS16,AX16,AY16),"") | BC16: =BB16*(100%-AJ16) -> #VALUE! | BD16: =SUM(BC16,AK16) -> #VALUE! | BG16: Edward Jacinto Gómez
A17: 20161395005 | B17: =VLOOKUP(A17,'Datos Personales'!A:M,2,FALSE) -> CUELLAR GUTIERREZ JULIO ARMANDO | C17: =VLOOKUP(A17,'ESTADOS ESTUDIANTES'!B:L,11,0) -> 1032423220 | D17: =VLOOKUP(A17,'Datos Personales'!$A:$M,3,FALSE) -> 395 | E17: =VLOOKUP(Tabla4[[#This Row],[ENFASIS]],Listas!$R$2:$S$8,2,0) -> ENFASIS EN GEOMATICA | F17: =VLOOKUP(A17,'Datos Personales'!A:M,8,0) -> jacuellarg@correo.udistrital.edu.co | G17: =VLOOKUP(A17,'Datos Personales'!A:M,9,0) -> ingjuliocuellar@gmail.com | H17: =VLOOKUP(A17,'Datos Personales'!A:M,5,FALSE) -> E | I17: =VLOOKUP(Tabla4[[#This Row],[CODIGO]],'ESTADOS ESTUDIANTES'!B:M,12,0) -> 2021-1 | J17: Investigación | K17: IMPLEMENTACION DE IMAGENES HIPERESPECTRALES Y DE RADAR COMO HERRAMIENTA PARA LA IDENTIFICACION MINERALOGICA PARA GRANDES EXTENSIONES EN ESTUDIOS DE EXPLORACION - ZONA DE ESTUDIO: REGION DEL MAGDALENA MEDIO | L17: Ruben Javier Medina Daza | N17: 44012 | O17: 2020 | P17: GEFEM | Q17: Ruben Javier Medina Daza | R17: 44012 | S17: =IF(Tabla4[[#This Row],[FECHA DE ACEPTACION DEL GRUP. INV.]]="","",DATE(YEAR(Tabla4[[#This Row],[FECHA DE ACEPTACION DEL GRUP. INV.]])+2,MONTH(Tabla4[[#This Row],[FECHA DE ACEPTACION DEL GRUP. INV.]]),DAY(Tabla4[[#This Row],[FECHA DE ACEPTACION DEL GRUP. INV.]]))) -> 44742 | T17: =IF(Tabla4[[#This Row],[FECHA DE ACEPTACION DEL GRUP. INV.]]="","",IF(Tabla4[[#This Row],[FECHA DE VENCIMIENTO ANTE PROYECTO]]<TODAY(),"SÍ","NO")) -> SÍ | W17: 08-2020 | AA17: 43888 | AB17: 73.04 | AC17: B1 | AJ17: =IFERROR(VLOOKUP(AI17,Listas!K:L,2,0),"") | AK17: =IFERROR(VLOOKUP(AJ17,Listas!L:M,2,0),"") | AL17: 44347 | AM17: 44348 | AN17: 44348 | AO17: Nelson Enrique Vera Parra | AP17: 44348 | AQ17: 44371 | AR17: 50 | AS17: 50 | AT17: Aprobado | AU17: Erika Sofia Upegui Cardona | AV17: 44348 | AW17: 44371 | AX17: 50 | AY17: 50 | AZ17: Aprobado | BA17: 44371 | BB17: 50 | BC17: =BB17*(100%-AJ17) -> #VALUE! | BD17: =SUM(BC17,AK17) -> #VALUE! | BF17: OK | BG17: =IF(OR(H17="A",$H17="D",$H17="P",$H17="V"),L17,"")
