Workbook

Sheet LIQUIDACION
A1: LLAVE | B1: Ultima_Fecha | C1: Valor | D1: VIGENCIA | E1: CUENTA | F1: DESCRIPCION | G1: VALOR PROYECTO | H1: BENEFICIO | I1: % | K1: INGRESOS-EJECUCION A LA FECHA | L1: BENEF REAL | M1: BENEFI TOMADO | N1: A TOMAR | O1: IDEXUD | Q1: OP IDEXUD | R1: UNIVERSIDAD | S1: OP UD | T1: CDP | U1: RP | V1: USUARIO | W1: FECHA DE DILIGENCIAMIENTO | X1: OBSERVACIONES
A2: =_xlfn.CONCAT(E2,W2,L2) -> 291090640144222611712530,330077 | B2: =_xlfn.MAXIFS(W:W,E:E,E2) -> 45957 | C2: =_xlfn.MAXIFS(L:L,E:E,E2) -> 6.7887808e+08 | D2: 2021 | E2: 2910906401 | F2: ILUD | G2: 5623455339 | H2: 674814641 | I2: =+H2/G2 -> 0.12 | K2: 5097604417 | L2: =+K2*I2 -> 6.1171253e+08 | M2: 611712530 | N2: 63102111 | O2: =+N2 -> 63102111 | Q2: 52 | R2: 0 | S2: 0 | V2: LORELY | W2: 44222
A3: =_xlfn.CONCAT(E3,W3,L3) -> 24530104064423812318000 | B3: =_xlfn.MAXIFS(W:W,E:E,E3) -> 44238 | C3: =_xlfn.MAXIFS(L:L,E:E,E3) -> 12318000 | D3: 2020 | E3: 2453010406 | F3: CONV ESPECIFICO 001 DE 2019 UNIVERSIDAD FHNW | G3: 102650000 | H3: 12318000 | I3: =+H3/G3 -> 0.12 | K3: 102650000 | L3: =+K3*I3 -> 12318000 | M3: 8490000 | N3: =+L3-M3 -> 3828000 | O3: =ROUND((N3*40%),0) -> 1531200 | Q3: 455 | R3: =+N3-O3 -> 2296800 | S3: 456 | T3: 1891 | U3: 3180 | V3: MONICA MOYA | W3: 44238
A4: =_xlfn.CONCAT(E4,W4,L4) -> 245301999644238188205671,909939 | B4: =_xlfn.MAXIFS(W:W,E:E,E4) -> 44831 | C4: =_xlfn.MAXIFS(L:L,E:E,E4) -> 190206861 | D4: 2020 | E4: 2453019996 | F4: CONV 430 2016 IDIGER - FONDIGER | G4: 1829508300 | H4: 196018746 | I4: =+H4/G4 -> 0.10714286 | K4: 1756586275 | L4: =+K4*I4 -> 1.8820567e+08 | M4: 184341692 | N4: =+L4-M4 -> 3863979.9 | O4: =ROUND((N4*40%),0) -> 1545592 | Q4: 457 | R4: =+N4-O4 -> 2318387.9 | S4: 458 | T4: 1889 | U4: 3178 | V4: MONICA MOYA | W4: 44238
A5: =_xlfn.CONCAT(E5,W5,L5) -> 29109066024423839831418,9258679 | B5: =_xlfn.MAXIFS(W:W,E:E,E5) -> 44406 | C5: =_xlfn.MAXIFS(L:L,E:E,E5) -> 57170161 | D5: 2020 | E5: 2910906602 | F5: CTTO INTERV TECN 121 DE 2019 GOB NORTE SANTANDER | G5: 899333962 | H5: 74256933 | I5: =+H5/G5 -> 0.082568808 | K5: 482402738 | L5: =+K5*I5 -> 39831419 | M5: 22504801 | N5: =+L5-M5 -> 17326618 | O5: =ROUND((N5*40%),0) -> 6930647 | Q5: 459 | R5: =+N5-O5 -> 10395971 | S5: 460 | T5: 1885 | U5: 3174 | V5: MONICA MOYA | W5: 44238
A6: =_xlfn.CONCAT(E6,W6,L6) -> 291090629944251155982593 | B6: =_xlfn.MAXIFS(W:W,E:E,E6) -> 44251 | C6: =_xlfn.MAXIFS(L:L,E:E,E6) -> 155982593 | D6: 2021 | E6: 2910906299 | F6: CONT 148 DE 2016 FDL RAFAEL URIBE URIBE | G6: 1299854942 | H6: 155982593 | I6: =+H6/G6 -> 0.12 | K6: 1299854942 | L6: =+K6*I6 -> 155982593 | M6: 131629790 | N6: =+L6-M6 -> 24352803 | O6: =ROUND((N6*40%),0) -> 9741121 | Q6: 996 | R6: =+N6-O6 -> 14611682 | S6: 997 | T6: 283 | U6: 242 | V6: MONICA MOYA | W6: 44251
A7: =_xlfn.CONCAT(E7,W7,L7) -> 2910906646442522200000 | B7: =_xlfn.MAXIFS(W:W,E:E,E7) -> 44252 | C7: =_xlfn.MAXIFS(L:L,E:E,E7) -> 2200000 | D7: 2020 | E7: 2910906646 | F7: CTTO INTERADM 31-2019 CONCEJO MUNICIPAL DE CHIA | G7: 20000000 | H7: 2200000 | I7: =+H7/G7 -> 0.11 | K7: 20000000 | L7: =+K7*I7 -> 2200000 | M7: 1980000 | N7: =+L7-M7 -> 220000 | O7: =ROUND((N7*40%),0) -> 88000 | Q7: 461 | R7: =+N7-O7 -> 132000 | S7: 462 | T7: 1886 | U7: 3175 | V7: MONICA MOYA | W7: 44252
A8: =_xlfn.CONCAT(E8,W8,L8) -> 2910906651442528717773,44 | B8: =_xlfn.MAXIFS(W:W,E:E,E8) -> 44405 | C8: =_xlfn.MAXIFS(L:L,E:E,E8) -> 15872640 | D8: 2020 | E8: 2910906651 | F8: CTTO INTERVENTORIA 201-5-19 FONDO ROTATORIO POLICI | G8: 132272000 | H8: 15872640 | I8: =+H8/G8 -> 0.12 | K8: 72648112 | L8: =+K8*I8 -> 8717773.4 | M8: 5295370 | N8: =+L8-M8 -> 3422403.4 | O8: =ROUND((N8*40%),0) -> 1368961 | Q8: 463 | R8: =+N8-O8 -> 2053442.4 | S8: 464 | T8: 1890 | U8: 3179 | V8: MONICA MOYA | W8: 44252
A9: =_xlfn.CONCAT(E9,W9,L9) -> 2910906657442521359369,09 | B9: =_xlfn.MAXIFS(W:W,E:E,E9) -> 44252 | C9: =_xlfn.MAXIFS(L:L,E:E,E9) -> 1359369.1 | D9: 2020 | E9: 2910906657 | F9: CTTO INTERADM 001-2019 CONCEJO DE TUNJA | G9: 12000000 | H9: 1527381 | I9: =+H9/G9 -> 0.12728175 | K9: 10680000 | L9: =+K9*I9 -> 1359369.1 | M9: 0 | N9: =+L9-M9 -> 1359369.1 | O9: =ROUND((N9*40%),0) -> 543748 | Q9: 465 | R9: =+N9-O9 -> 815621.09 | S9: 466 | T9: 1887 | U9: 3176 | V9: MONICA MOYA | W9: 44252
A10: =_xlfn.CONCAT(E10,W10,L10) -> 2910906661442522083630 | B10: =_xlfn.MAXIFS(W:W,E:E,E10) -> 44252 | C10: =_xlfn.MAXIFS(L:L,E:E,E10) -> 2083630 | D10: 2020 | E10: 2910906661 | F10: CPS 03 de 2019 ASAMBLEA DEPARTAMENTAL DEL CESAR | G10: 12000000 | H10: 2083630 | I10: =+H10/G10 -> 0.17363583 | K10: 12000000 | L10: =+K10*I10 -> 2083630 | M10: 0 | N10: =+L10-M10 -> 2083630 | O10: =ROUND((N10*40%),0) -> 833452 | Q10: 467 | R10: =+N10-O10 -> 1250178 | S10: 468 | T10: 1888 | U10: 3177 | V10: MONICA MOYA | W10: 44252
A11: =_xlfn.CONCAT(E11,W11,L11) -> 29109011644425716310893 | B11: =_xlfn.MAXIFS(W:W,E:E,E11) -> 44434 | C11: =_xlfn.MAXIFS(L:L,E:E,E11) -> 16310893 | D11: 2021 | E11: 2910901164 | F11: CTTO INTERADM 061-5-19 FONDO ROTATORIO POLICIA | G11: 153000000 | H11: 16392857 | I11: =+H11/G11 -> 0.10714286 | K11: 152234999 | L11: =ROUND((+K11*I11),0) -> 16310893 | M11: 14037154 | N11: 2273739 | O11: =ROUND((N11*40%),0) -> 909496 | Q11: 1037 | R11: =+N11-O11 -> 1364243 | S11: 1038 | T11: 321 | U11: 314 | V11: MONICA MOYA | W11: 44257
A12: =_xlfn.CONCAT(E12,W12,L12) -> 291090596144257982934233 | B12: =_xlfn.MAXIFS(W:W,E:E,E12) -> 44498 | C12: =_xlfn.MAXIFS(L:L,E:E,E12) -> 1224203654 | D12: 2021 | E12: 2910905961 | F12: MODIFICATORIO 2 ANEXO FINANCIERO 1029 2010 | G12: 8349652066 | H12: 934245965 | I12: =+H12/G12 -> 0.11189041 | K12: 8784794540 | L12: =ROUND((+K12*I12),0) -> 982934233 | M12: 896365068 | N12: =+L12-M12 -> 86569165 | O12: =ROUND((N12*40%),0) -> 34627666 | Q12: 1039 | R12: =+N12-O12 -> 51941499 | S12: 1040 | T12: 323 | U12: 315 | V12: MONICA MOYA | W12: 44257
A13: =_xlfn.CONCAT(E13,W13,L13) -> 24530183014425760556114 | B13: =_xlfn.MAXIFS(W:W,E:E,E13) -> 45099 | C13: =_xlfn.MAXIFS(L:L,E:E,E13) -> 133063733 | D13: 2021 | E13: 2453018301 | F13: CONV. INTERAD.389 2019 FDL CIUDAD BOLIVAR | G13: =941984000+470992000 -> 1412976000 | H13: 151390286 | I13: =+H13/G13 -> 0.10714286 | K13: 565190400 | L13: =ROUND((+K13*I13),0) -> 60556114 | M13: 0 | N13: =+L13-M13 -> 60556114 | O13: =ROUND((N13*40%),0) -> 24222446 | Q13: 1041 | R13: =+N13-O13 -> 36333668 | S13: 1042 | T13: 324 | U13: 316 | V13: MONICA MOYA | W13: 44257
A14: =_xlfn.CONCAT(E14,W14,L14) -> 24530183024425980828827 | B14: =_xlfn.MAXIFS(W:W,E:E,E14) -> 44434 | C14: =_xlfn.MAXIFS(L:L,E:E,E14) -> 89809808 | D14: 2021 | E14: 2453018302 | F14: CONV.COOP.003 2020 CAR VALLES DEL SINU Y SAN JORGE | G14: 838224872 | H14: 89809808 | I14: =+H14/G14 -> 0.10714286 | K14: 754402385 | L14: =ROUND((+K14*I14),0) -> 80828827 | M14: 62866866 | N14: =+L14-M14 -> 17961961 | Q14: 1043 | S14: 1044 | T14: 325 | U14: 317 | V14: MONICA MOYA | W14: 44259 | X14: NO HAY SALDO EN LA CUENTA CONTABLE. NO REALIZARON EL INGRESO. SE ANULA
A15: =_xlfn.CONCAT(E15,W15,L15) -> 2910906153442571574445174 | B15: =_xlfn.MAXIFS(W:W,E:E,E15) -> 44404 | C15: =_xlfn.MAXIFS(L:L,E:E,E15) -> 1.6000309e+09 | D15: 2021 | E15: 2910906153 | F15: CONTRAT 1069 DE 2015 SENA | I15: 0.1071 | K15: 14694821628 | L15: 1574445174 | M15: 370028904 | N15: 200000000 | O15: =ROUND((N15*40%),0) -> 80000000 | Q15: 1080 | R15: =+N15-O15 -> 120000000 | S15: 1081 | T15: 326 | U15: 382 | V15: MONICA MOYA | W15: 44257 | X15: SEGÚN LO ESTABLECIDO CON DIANA CARO EL VR DEL BENEFICIO A TOMAR ES DE $200,000,000, EXISTEN UNAS MULTAS POR VALOR DE $441,785,257
A16: =_xlfn.CONCAT(E16,W16,L16) -> 291090616444263346814269 | B16: =_xlfn.MAXIFS(W:W,E:E,E16) -> 44617 | C16: =_xlfn.MAXIFS(L:L,E:E,E16) -> 356207712 | D16: 2021 | E16: 2910906164 | F16: CONTR 226 FDL KENNEDY | G16: 3324605309 | H16: 356207712 | I16: =+H16/G16 -> 0.10714286 | K16: 3236933176 | L16: =ROUND((+K16*I16),0) -> 346814269 | M16: 291049114 | N16: 43224000 | O16: =ROUND((N16*40%),0) -> 17289600 | Q16: 1215 | R16: =+N16-O16 -> 25934400 | S16: 1216 | T16: 339 | U16: 414 | V16: KATIA FLOREZ | W16: 44263 | X16: SE APROPIA EL SALDO QUE HAY EN LA CUENTA CONTABLE.
A17: =_xlfn.CONCAT(E17,W17,L17) -> 29109067074427962142857 | B17: =_xlfn.MAXIFS(W:W,E:E,E17) -> 44279 | C17: =_xlfn.MAXIFS(L:L,E:E,E17) -> 62142857 | D17: 2021 | E17: 2910906707 | F17: CTTO INTERAD SFP-CDCTI-027-2020 GOBER.CUNDINAMARCA | G17: 580000000 | H17: 62142857 | I17: =+H17/G17 -> 0.10714286 | K17: 580000000 | L17: =ROUND((+K17*I17),0) -> 62142857 | M17: 55928571 | N17: 6214286 | O17: =ROUND((N17*40%),0) -> 2485714 | Q17: 1471 | R17: =+N17-O17 -> 3728572 | S17: 1472 | T17: 364 | U17: 508 | V17: MONICA MOYA | W17: 44279
A18: =_xlfn.CONCAT(E18,W18,L18) -> 2910906713442792257285 | B18: =_xlfn.MAXIFS(W:W,E:E,E18) -> 44279 | C18: =_xlfn.MAXIFS(L:L,E:E,E18) -> 2257285 | D18: 2021 | E18: 2910906713 | F18: CTTO INTER No SFP-CDCTI-044-2020 | G18: 21068000 | H18: 2257285 | I18: =+H18/G18 -> 0.10714282 | K18: 21068000 | L18: =ROUND((+K18*I18),0) -> 2257285 | M18: 0 | N18: 2257285 | O18: =ROUND((N18*40%),0) -> 902914 | Q18: 1473 | R18: =+N18-O18 -> 1354371 | S18: 1474 | T18: 343 | U18: 442 | V18: MONICA MOYA | W18: 44279
A19: =_xlfn.CONCAT(E19,W19,L19) -> 29109063204427925617621 | B19: =_xlfn.MAXIFS(W:W,E:E,E19) -> 44279 | C19: =_xlfn.MAXIFS(L:L,E:E,E19) -> 25617621 | D19: 2021 | E19: 2910906320 | F19: CONTRATO 083 DE 2017 ICCU | G19: 282092787 | H19: 30224228 | I19: =+H19/G19 -> 0.10714286 | K19: 239097794 | L19: =ROUND((+K19*I19),0) -> 25617621 | M19: 25617621 | N19: =+H19-L19 -> 4606607 | O19: =ROUND((N19*40%),0) -> 1842643 | Q19: 1475 | R19: =+N19-O19 -> 2763964 | S19: 1476 | T19: 344 | U19: 443 | V19: MONICA MOYA | W19: 44279
A20: =_xlfn.CONCAT(E20,W20,L20) -> 2453010405442799642857 | B20: =_xlfn.MAXIFS(W:W,E:E,E20) -> 44279 | C20: =_xlfn.MAXIFS(L:L,E:E,E20) -> 9642857 | D20: 2021 | E20: 2453010405 | F20: CONV INTERADM 80 DE 2019 REG ADMIN Y PLAN ESP RAPE | G20: 100000000 | H20: 10714285 | I20: =+H20/G20 -> 0.10714285 | J20: =+I20/H20 -> 1e-08 | K20: 90000000 | L20: =ROUND((+K20*I20),0) -> 9642857 | M20: 9639000 | N20: =+L20-M20 -> 3857 | O20: =ROUND((N20*40%),0) -> 1543 | Q20: 1477 | R20: =+N20-O20 -> 2314 | S20: 1478 | T20: 346 | U20: 444 | V20: MONICA MOYA | W20: 44279
A21: =_xlfn.CONCAT(E21,W21,L21) -> 2910906718442791875000 | B21: =_xlfn.MAXIFS(W:W,E:E,E21) -> 44279 | C21: =_xlfn.MAXIFS(L:L,E:E,E21) -> 1875000 | D21: 2021 | E21: 2910906718 | F21: CTTO INTER 230 IDECUT 2020 - ASAB | G21: 17500000 | H21: 1875000 | I21: =+H21/G21 -> 0.10714286 | K21: 17500000 | L21: =ROUND((+K21*I21),0) -> 1875000 | M21: 0 | N21: 1875000 | O21: =ROUND((N21*40%),0) -> 750000 | Q21: 1479 | R21: =+N21-O21 -> 1125000 | S21: 1480 | T21: 347 | U21: 445 | V21: MONICA MOYA | W21: 44279
A22: =_xlfn.CONCAT(E22,W22,L22) -> 2910901163442799521601 | B22: =_xlfn.MAXIFS(W:W,E:E,E22) -> 44279 | C22: =_xlfn.MAXIFS(L:L,E:E,E22) -> 9521601 | D22: 2021 | E22: 2910901163 | F22: CTTO INTERADM 025-5-19 FONDO ROTATORIO POLICIA | G22: 99238720 | H22: 10632720 | I22: =+H22/G22 -> 0.10714286 | K22: 88868274 | L22: =ROUND((+K22*I22),0) -> 9521601 | M22: 9517792 | N22: =+L22-M22 -> 3809 | O22: =ROUND((N22*40%),0) -> 1524 | Q22: 1481 | R22: =+N22-O22 -> 2285 | S22: 1482 | T22: 348 | U22: 446 | V22: MONICA MOYA | W22: 44279
A23: =_xlfn.CONCAT(E23,W23,L23) -> 29109066514427913872699 | B23: =_xlfn.MAXIFS(W:W,E:E,E23) -> 44405 | C23: =_xlfn.MAXIFS(L:L,E:E,E23) -> 15872640 | D23: 2021 | E23: 2910906651 | F23: CTTO INTERVENTORIA 201-5-19 FONDO ROTATORIO POLICIA | G23: 132272000 | H23: 15872640 | I23: =+H23/G23 -> 0.12 | K23: 115605827 | L23: =ROUND((+K23*I23),0) -> 13872699 | M23: 8717773 | N23: 4798715 | O23: =ROUND((N23*40%),0) -> 1919486 | Q23: 1483 | R23: =+N23-O23 -> 2879229 | S23: 1484 | T23: 349 | U23: 447 | V23: MONICA MOYA | W23: 44279 | X23: EL VR A APROPIAR DE BENEFICIO SEGÚN LOS INGRESOS A MARZO 24-2021 CORRESPONDE A $ 5,154,926, PERO SOLO DE TOMA $4,798,715 SEGÚN EL SALDO EXISTENTE A LA FECHA EN LA CTA CONTABLE 2910906651.
A24: =_xlfn.CONCAT(E24,W24,L24) -> 2910906699442792220540 | B24: =_xlfn.MAXIFS(W:W,E:E,E24) -> 44279 | C24: =_xlfn.MAXIFS(L:L,E:E,E24) -> 2220540 | D24: 2021 | E24: 2910906699 | F24: CTTO INTERADM 45 ASAMBLEA DEPARTAMENTAL | G24: 20000000 | H24: 2317891 | I24: =+H24/G24 -> 0.11589455 | K24: 19160000 | L24: =ROUND((+K24*I24),0) -> 2220540 | M24: 2220540 | N24: =+H24-L24 -> 97351 | O24: =ROUND((N24*40%),0) -> 38940 | Q24: 1485 | R24: =+N24-O24 -> 58411 | S24: 1486 | T24: 350 | U24: 448 | V24: MONICA MOYA | W24: 44279 | X24: SE APROPIA EL SALDO PTE DEL BENEFICIO ESTABLECIDO EN EL PRESUPUESTO, DEBIDO A QUE EL PROYECTO ESTA LIQUIDADO Y GENERA UN EXCEDENTE.
A25: =_xlfn.CONCAT(E25,W25,L25) -> 24530183064427918542880 | B25: =_xlfn.MAXIFS(W:W,E:E,E25) -> 44281 | C25: =_xlfn.MAXIFS(L:L,E:E,E25) -> 23107179 | D25: 2021 | E25: 2453018306 | F25: CONV INTER 092 RAP-E-UD-GICALYT-2020 | G25: 236667000 | H25: 25357179 | I25: =+H25/G25 -> 0.10714286 | K25: 173066880 | L25: =ROUND((+K25*I25),0) -> 18542880 | M25: 0 | N25: =+L25-M25 -> 18542880 | O25: =ROUND((N25*40%),0) -> 7417152 | Q25: 1487 | R25: =+N25-O25 -> 11125728 | S25: 1488 | T25: 351 | U25: 449 | V25: MONICA MOYA | W25: 44279
A26: =_xlfn.CONCAT(E26,W26,L26) -> 2453018307442791933071 | B26: =_xlfn.MAXIFS(W:W,E:E,E26) -> 44279 | C26: =_xlfn.MAXIFS(L:L,E:E,E26) -> 1933071 | D26: 2021 | E26: 2453018307 | F26: CENTRO PENSAMIENTO Y DIALOGO POLITICO | G26: 18042000 | H26: 1933071 | I26: =+H26/G26 -> 0.10714283 | K26: 18042000 | L26: =ROUND((+K26*I26),0) -> 1933071 | M26: 0 | N26: =+L26-M26 -> 1933071 | O26: =ROUND((N26*40%),0) -> 773228 | Q26: 1489 | R26: =+N26-O26 -> 1159843 | S26: 1490 | T26: 353 | U26: 450 | V26: MONICA MOYA | W26: 44279
A27: =_xlfn.CONCAT(E27,W27,L27) -> 2910901169442795308344 | B27: =_xlfn.MAXIFS(W:W,E:E,E27) -> 44434 | C27: =_xlfn.MAXIFS(L:L,E:E,E27) -> 5308344 | D27: 2021 | E27: 2910901169 | F27: CTTO INTERADM 152-5-19 INTERV FONDO ROTATORIO POLICIA | G27: 49793510 | H27: 5335019 | I27: =+H27/G27 -> 0.10714286 | K27: 49544542 | L27: =ROUND((+K27*I27),0) -> 5308344 | M27: 989610 | N27: =+L27-M27 -> 4318734 | O27: =ROUND((N27*40%),0) -> 1727494 | Q27: 1491 | R27: =+N27-O27 -> 2591240 | S27: 1492 | T27: 354 | U27: 451 | V27: MONICA MOYA | W27: 44279
A28: =_xlfn.CONCAT(E28,W28,L28) -> 29109058784427919860040 | B28: =_xlfn.MAXIFS(W:W,E:E,E28) -> 44279 | C28: =_xlfn.MAXIFS(L:L,E:E,E28) -> 19860040 | D28: 2021 | E28: 2910905878 | F28: G-27 2013 SERVIVIENDA | G28: 438947360 | H28: 47030074 | I28: =+H28/G28 -> 0.10714286 | K28: 185360377 | L28: =ROUND((+K28*I28),0) -> 19860040 | M28: 0 | N28: =+L28-M28 -> 19860040 | O28: =ROUND((N28*40%),0) -> 7944016 | Q28: 1493 | R28: =+N28-O28 -> 11916024 | S28: 1494 | T28: 355 | U28: 452 | V28: MONICA MOYA | W28: 44279
A29: =_xlfn.CONCAT(E29,W29,L29) -> 291090626044279306737224 | B29: =_xlfn.MAXIFS(W:W,E:E,E29) -> 44459 | C29: =_xlfn.MAXIFS(L:L,E:E,E29) -> 306737224 | D29: 2021 | E29: 2910906260 | F29: EMPRESA DE SERVICIOS PÚBICOS DE CHÍA EMSECHIA E.S.P. | G29: 4300708566 | H29: 516085028 | I29: =+H29/G29 -> 0.12 | K29: 2556143530 | L29: =ROUND((+K29*I29),0) -> 306737224 | M29: 203289922 | N29: 50000000 | O29: =ROUND((N29*40%),0) -> 20000000 | Q29: 1495 | R29: =+N29-O29 -> 30000000 | S29: 1496 | T29: 356 | U29: 453 | V29: MONICA MOYA | W29: 44279 | X29: SEGÚN LO ACORDADO CON DIANA CARO SE APROPIA $50,000,000
A30: =_xlfn.CONCAT(E30,W30,L30) -> 24530183064428123107179 | B30: =_xlfn.MAXIFS(W:W,E:E,E30) -> 44281 | C30: =_xlfn.MAXIFS(L:L,E:E,E30) -> 23107179 | D30: 2021 | E30: 2453018306 | F30: CONV INTER 092 RAP-E-UD-GICALYT-2020 | G30: 236667000 | H30: 25357179 | I30: =+H30/G30 -> 0.10714286 | K30: 215667000 | L30: =ROUND((+K30*I30),0) -> 23107179 | M30: 18542880 | N30: =+L30-M30 -> 4564299 | O30: =ROUND((N30*40%),0) -> 1825720 | Q30: 1546 | R30: =+N30-O30 -> 2738579 | S30: 1547 | T30: 449 | U30: 714 | V30: MONICA MOYA | W30: 44281 | X30: POR ERROR SE REGISTRO UN REINTEGRO DE UN AVANCE COMO UN INGRESO, SE CORRIJE EN ABRIL . OJO PARA TENER ENCUENTA AL APROPIAR BENEFICIO DE INGRESOS POSTERIORES A ABRIL 2021. EL INGRESO REAL DEL PROYECTO CON CORTE 23 DE ABRIL ES $194,067,000. SE TOMO MAS BENEFICIO DEL QUE CORRESPONDIA.
A31: =_xlfn.CONCAT(E31,W31,L31) -> 29109067214429110155046 | B31: =_xlfn.MAXIFS(W:W,E:E,E31) -> 44406 | C31: =_xlfn.MAXIFS(L:L,E:E,E31) -> 10897200 | D31: 2021 | E31: 2910906721 | F31: CTTO INTER 118-ICFE-2020 - INST DE CASAS FISCALES | G31: 90810000 | H31: 10897200 | I31: =+H31/G31 -> 0.12 | K31: 84625384 | L31: =ROUND((+K31*I31),0) -> 10155046 | M31: 0 | N31: =+L31-M31 -> 10155046 | O31: =ROUND((N31*40%),0) -> 4062018 | Q31: 1596 | R31: =+N31-O31 -> 6093028 | S31: 1597 | T31: 502 | U31: 760 | V31: MONICA MOYA | W31: 44291
A32: =_xlfn.CONCAT(E32,W32,L32) -> 2910906724442914467407 | B32: =_xlfn.MAXIFS(W:W,E:E,E32) -> 44291 | C32: =_xlfn.MAXIFS(L:L,E:E,E32) -> 4467407 | D32: 2021 | E32: 2910906724 | F32: CTTO INTER 2385 IDIPROM - 2020 | G32: 41695800 | H32: 4467407 | I32: =+H32/G32 -> 0.10714285 | K32: 41695800 | L32: =ROUND((+K32*I32),0) -> 4467407 | M32: 0 | N32: =+L32-M32 -> 4467407 | O32: =ROUND((N32*40%),0) -> 1786963 | Q32: 1598 | R32: =+N32-O32 -> 2680444 | S32: 1599 | T32: 503 | U32: 761 | V32: MONICA MOYA | W32: 44291
A33: =_xlfn.CONCAT(E33,W33,L33) -> 2910908024442933479129 | B33: =_xlfn.MAXIFS(W:W,E:E,E33) -> 44293 | C33: =_xlfn.MAXIFS(L:L,E:E,E33) -> 3479129 | D33: 2021 | E33: 2910908024 | F33: PROG ACADÉMICO TRANSIT FAC MEDIO AMBIENTE 2020-3 | G33: 28967499 | H33: 3479129 | I33: =+H33/G33 -> 0.12010457 | K33: 28967499 | L33: =ROUND((+K33*I33),0) -> 3479129 | M33: 0 | N33: =+L33-M33 -> 3479129 | O33: 3479129 | Q33: 1766 | R33: 0 | S33: 0 | T33: 504 | U33: 768 | V33: MONICA MOYA | W33: 44293
A34: =_xlfn.CONCAT(E34,W34,L34) -> 291090631544294110362094 | B34: =_xlfn.MAXIFS(W:W,E:E,E34) -> 44375 | C34: =_xlfn.MAXIFS(L:L,E:E,E34) -> 122624549 | D34: 2021 | E34: 2910906315 | F34: CONT 232 DE 2016 FDL USME | G34: 1144495782 | H34: 122624549 | I34: =+H34/G34 -> 0.10714286 | K34: =840262114+189784089 -> 1030046203 | L34: =ROUND((+K34*I34),0) -> 110362094 | M34: 69140917 | N34: =+L34-M34 -> 41221177 | O34: =ROUND((N34*40%),0) -> 16488471 | Q34: 1935 | R34: =+N34-O34 -> 24732706 | S34: 1936 | T34: 508 | U34: 790 | V34: MONICA MOYA | W34: 44294
A35: =_xlfn.CONCAT(E35,W35,L35) -> 29109080084429412414836 | B35: =_xlfn.MAXIFS(W:W,E:E,E35) -> 44294 | C35: =_xlfn.MAXIFS(L:L,E:E,E35) -> 12414836 | D35: 2021 | E35: 2910908008 | F35: PROGRAMA ACADÉMICO DE GRADO FACULTAD TECNOLÓGICA | G35: 115871800 | H35: 12414836 | I35: =+H35/G35 -> 0.10714286 | K35: 115871800 | L35: =ROUND((+K35*I35),0) -> 12414836 | M35: 12127836 | N35: =+L35-M35 -> 287000 | O35: =ROUND((N35*100%),0) -> 287000 | Q35: 1937 | R35: 0 | S35: 0 | T35: 509 | U35: 791 | V35: MONICA MOYA | W35: 44294
A36: =_xlfn.CONCAT(E36,W36,L36) -> 2910908021442953644222 | B36: =_xlfn.MAXIFS(W:W,E:E,E36) -> 44295 | C36: =_xlfn.MAXIFS(L:L,E:E,E36) -> 3644222 | D36: 2021 | E36: 2910908021 | F36: PROGRAMA ACADÉMICO DE GRADO 2020-III FAC ING | G36: 30368519 | H36: 3644222 | I36: =+H36/G36 -> 0.11999999 | K36: 30368519 | L36: =ROUND((+K36*I36),0) -> 3644222 | M36: 0 | N36: =+L36-M36 -> 3644222 | O36: =ROUND((N36*100%),0) -> 3644222 | Q36: 1938 | R36: 0 | S36: 0 | T36: 514 | U36: 804 | V36: MONICA MOYA | W36: 44295
A37: =_xlfn.CONCAT(E37,W37,L37) -> 2910908023442957268322 | B37: =_xlfn.MAXIFS(W:W,E:E,E37) -> 44295 | C37: =_xlfn.MAXIFS(L:L,E:E,E37) -> 7268322 | D37: 2021 | E37: 2910908023 | F37: PROGRAMA ACADÉMICO DE GRADO FACULTAD TECNOLÓGICA | G37: 60569350 | H37: 7268322 | I37: =+H37/G37 -> 0.12 | K37: 60569350 | L37: =ROUND((+K37*I37),0) -> 7268322 | M37: 0 | N37: =+L37-M37 -> 7268322 | O37: =ROUND((N37*100%),0) -> 7268322 | Q37: 1939 | R37: 0 | S37: 0 | T37: 515 | U37: 823 | V37: MONICA MOYA | W37: 44295
A38: =_xlfn.CONCAT(E38,W38,L38) -> 2910906629443015857500 | B38: =_xlfn.MAXIFS(W:W,E:E,E38) -> 44770 | C38: =_xlfn.MAXIFS(L:L,E:E,E38) -> 6214482 | D38: 2021 | E38: 2910906629 | F38: DIPLOMADO EN INNOVACIÓN FORM Y EVAL DE PROYECTOS | G38: 54670000 | H38: 5857500 | I38: =+H38/G38 -> 0.10714286 | K38: 54670000 | L38: =+K38*I38 -> 5857500 | M38: 0 | N38: 5591250 | O38: =ROUND((N38*100%),0) -> 5591250 | Q38: 1973 | R38: 0 | S38: 0 | T38: 544 | U38: 871 | V38: MONICA MOYA | W38: 44301 | X38: SE APROPIA $5,591,250 SEGÚN CORREO ENVIADO POR CARLOS ESTE ES EL SALDO PRESUPUESTAL.
A39: =_xlfn.CONCAT(E39,W39,L39) -> 2910908005443012413200 | B39: =_xlfn.MAXIFS(W:W,E:E,E39) -> 44301 | C39: =_xlfn.MAXIFS(L:L,E:E,E39) -> 2413200 | D39: 2021 | E39: 2910908005 | F39: DIPLOMADO EN ECONOMIA CIRCULAR Y SOSTENIBILIDAD | G39: 20110000 | H39: 2413200 | I39: =+H39/G39 -> 0.12 | K39: 20110000 | L39: =+K39*I39 -> 2413200 | M39: 1733400 | N39: =+L39-M39 -> 679800 | O39: =ROUND((N39*100%),0) -> 679800 | Q39: 1974 | R39: 0 | S39: 0 | T39: 545 | U39: 872 | V39: MONICA MOYA | W39: 44301
A40: =_xlfn.CONCAT(E40,W40,L40) -> 29109067194430816379464 | B40: =_xlfn.MAXIFS(W:W,E:E,E40) -> 44529 | C40: =_xlfn.MAXIFS(L:L,E:E,E40) -> 71236607 | D40: 2021 | E40: 2910906719 | F40: CTTO INTER 085-00-D-CACOM1-DEDHU-2020 | G40: 664875000 | H40: 71236607 | I40: =+H40/G40 -> 0.10714286 | K40: 152875000 | L40: =ROUND((+K40*I40),0) -> 16379464 | M40: 0 | N40: =+L40-M40 -> 16379464 | O40: =ROUND((N40*40%),0) -> 6551786 | Q40: 2467 | R40: =+N40-O40 -> 9827678 | S40: 2468 | T40: 594 | U40: 958 | V40: MONICA MOYA | W40: 44308
...

Sheet Proyectos Extensión
E1: FORMATO LIQUIDACIÓN BENEFICIO INSTITUCIONAL | J1: Código: GRF-FR-041
E2: Macroproceso: Gestión de Recursos | J2: Versión: 01
E3: Proceso: Gestión de Recursos Financieros | J3: Fecha de Aprobación: 2025/07/02
B5: BENEFICIO INSTITUCIONAL DEL 01 DE ABRIL AL 30 DE JUNIO DEL 2026 | V5: 1 TRIMESTRE | Z5: 2 TRIMESTRE | AD5: 3 TRIMESTRE | AH5: 4 TRIMESTRE
A6: ITEM | B6: VIGENCIA | C6: ENTIDAD CONTRATANTE | D6: NOMBRE PROYECTO | E6: Tipo | F6: FECHA DE SUSCRIPCIÓN | G6: FECHA DE FINALIZACIÓN | H6: DURACION EN TRIMESTRES | I6: ESTADO | J6: OBSERVACIONES AL ESTADO | K6: ENTIDAD BANCARIA DEPOSITARIA DE LOS RECURSOS | L6: TIPO DE CUENTA | M6: N° CUENTA | N6: N° CENTRO DE COSTOS ASIGNADO | O6: CÓDIGO CONTABLE | P6: VALOR PROYECTO SEGÚN MINUTA | Q6: VALOR ADICIONES | R6: VALOR TOTAL PRESUPUESTO | S6: % DE B.I. AUTORIZADO - SEGÚN PRESUPUESTO | T6: BENEFICIO TOTAL PRESUPUESTADO | U6: TOTAL INGRESOS A LA FECHA | V6: VALOR RECAUDO DEL TRIMESTRE 1 | W6: BENEFICIO TOTAL A DISTRIBUIR EN EL TRIMESTRE LIQUIDADO | X6: IDEXUD 40% | Y6: UNIVERSIDAD 60% | Z6: VALOR RECAUDO DEL TRIMESTRE 2 | AA6: BENEFICIO TOTAL A DISTRIBUIR EN EL TRIMESTRE LIQUIDADO | AB6: IDEXUD 40% | AC6: UNIVERSIDAD 60% | AD6: VALOR RECAUDO DEL TRIMESTRE 3 | AE6: BENEFICIO TOTAL A DISTRIBUIR EN EL TRIMESTRE LIQUIDADO | AF6: IDEXUD 40% | AG6: UNIVERSIDAD 60% | AH6: VALOR RECAUDO DEL TRIMESTRE 4 | AI6: BENEFICIO TOTAL A DISTRIBUIR EN EL TRIMESTRE LIQUIDADO | AJ6: IDEXUD 40% | AK6: UNIVERSIDAD 60% | AL6: BENEFICIO TOTAL APROPIADO (ACUMULADO) A LA FECHA | AM6: VALOR TOTAL DE B.I. EN LA VIGENCIA | AN6: NOTAS PRIMER TRIMESTRE | AO6: NOTAS SEGUNDO TRIMESTRE
A7: 1 | B7: 2021 | C7: UNIVERSIDAD DISTRITAL FRANCISCO JOSÉ DE CALDAS - UD | D7: FAC-ASAB-8016-UNIVERSIDAD DISTRITAL FRANCISCO JOSÉ DE CALDAS - UD | E7: Curso Propio | F7: 44167 | G7: 44287 | H7: =+(G7-F7)/90 -> 1.3333333 | I7: Liquidado | J7: Sin Observaciones | K7: OCCIDENTE | L7: Cuenta de ahorros | M7: 230-85718-7 | N7: 580 16 | O7: 2910908016 | P7: =+_xlfn.XLOOKUP(O7,'[3]Benef Primera fecha '!$C:$C,'[3]Benef Primera fecha '!$E:$E,0) -> 25096800 | Q7: 0 | R7: =+(P7+Q7) -> 25096800 | S7: 0.028018089 | T7: =(R7/(1+S7))*S7 -> 684000 | U7: 25096800 | V7: 0 | W7: =+V7/(1+$S7)*$S7 -> 0 | X7: =+W7*40% -> 0 | Y7: =+W7*60% -> 0 | Z7: =_xlfn.XLOOKUP(O7,'[4]2DO TRIMESTRE'!$C:$C,'[4]2DO TRIMESTRE'!$I:$I,0,0) -> 0 | AA7: =+Z7/(1+$S7)*$S7 -> 0 | AB7: =+AA7*40% -> 0 | AC7: =+AA7*60% -> 0 | AD7: 0 | AE7: =+AD7/(1+$S7)*$S7 -> 0 | AF7: =+AE7*40% -> 0 | AG7: =+AE7*60% -> 0 | AH7: 0 | AI7: =+AH7/(1+$S7)*$S7 -> 0 | AJ7: =+AI7*40% -> 0 | AK7: =+AI7*60% -> 0 | AL7: 684000 | AM7: =W7+AA7+AE7+AI7 -> 0
A8: 2 | B8: 2021 | C8: DIEZX CONSULTORES SAS | D8: ACUERDO Y CONDICIO-2-DIEZX CONSULTORES SAS | E8: Contrato | F8: 44215 | G8: 44531 | H8: =+(G8-F8)/90 -> 3.5111111 | I8: En Ejecución | J8: Sin Observaciones | K8: OCCIDENTE | L8: Cuenta de ahorros | M8: 230-87986-8 | N8: 567 71 | O8: 2910906771 | P8: =+_xlfn.XLOOKUP(O8,'[3]Benef Primera fecha '!$C:$C,'[3]Benef Primera fecha '!$E:$E,0) -> 22500000 | Q8: 0 | R8: =+(P8+Q8) -> 22500000 | S8: 0.12 | T8: =(R8/(1+S8))*S8 -> 2410714.3 | U8: 22500000 | V8: 0 | W8: =+V8/(1+$S8)*$S8 -> 0 | X8: =+W8*40% -> 0 | Y8: =+W8*60% -> 0 | Z8: =_xlfn.XLOOKUP(O8,'[4]2DO TRIMESTRE'!$C:$C,'[4]2DO TRIMESTRE'!$I:$I,0,0) -> 0 | AA8: =+Z8/(1+$S8)*$S8 -> 0 | AB8: =+AA8*40% -> 0 | AC8: =+AA8*60% -> 0 | AD8: 0 | AE8: =+AD8/(1+$S8)*$S8 -> 0 | AF8: =+AE8*40% -> 0 | AG8: =+AE8*60% -> 0 | AH8: 0 | AI8: =+AH8/(1+$S8)*$S8 -> 0 | AJ8: =+AI8*40% -> 0 | AK8: =+AI8*60% -> 0 | AL8: 2410710 | AM8: =W8+AA8+AE8+AI8 -> 0
A9: 3 | B9: 2021 | C9: DIEZX CONSULTORES SAS | D9: S/N ACUERDO-DIEZX CONSULTORES SAS | E9: Contrato | F9: 44215 | G9: 44394 | H9: =+(G9-F9)/90 -> 1.9888889 | I9: Terminado | J9: Sin Observaciones | K9: OCCIDENTE | L9: Cuenta de ahorros | M9: 230-87986-8 | N9: 567 36 | O9: 2910906736 | P9: =+_xlfn.XLOOKUP(O9,'[3]Benef Primera fecha '!$C:$C,'[3]Benef Primera fecha '!$E:$E,0) -> 15250000 | Q9: 0 | R9: =+(P9+Q9) -> 15250000 | S9: 0.12 | T9: =(R9/(1+S9))*S9 -> 1633928.6 | U9: 15250000 | V9: 0 | W9: =+V9/(1+$S9)*$S9 -> 0 | X9: =+W9*40% -> 0 | Y9: =+W9*60% -> 0 | Z9: =_xlfn.XLOOKUP(O9,'[4]2DO TRIMESTRE'!$C:$C,'[4]2DO TRIMESTRE'!$I:$I,0,0) -> 0 | AA9: =+Z9/(1+$S9)*$S9 -> 0 | AB9: =+AA9*40% -> 0 | AC9: =+AA9*60% -> 0 | AD9: 0 | AE9: =+AD9/(1+$S9)*$S9 -> 0 | AF9: =+AE9*40% -> 0 | AG9: =+AE9*60% -> 0 | AH9: 0 | AI9: =+AH9/(1+$S9)*$S9 -> 0 | AJ9: =+AI9*40% -> 0 | AK9: =+AI9*60% -> 0 | AL9: 1633929 | AM9: =W9+AA9+AE9+AI9 -> 0
A10: 4 | B10: 2021 | C10: AGENCIA NACIONAL DE SEGURIDAD VIAL | D10: ANSV-003-AGENCIA NACIONAL DE SEGURIDAD VIAL | E10: Contrato | F10: 44238 | G10: 44424 | H10: =+(G10-F10)/90 -> 2.0666667 | I10: Cierre Financiero | J10: Sin Observaciones | K10: OCCIDENTE | L10: Cuenta de ahorros | M10: 230-85893- 8 | N10: 567 32 | O10: 2910906732 | P10: =+_xlfn.XLOOKUP(O10,'[3]Benef Primera fecha '!$C:$C,'[3]Benef Primera fecha '!$E:$E,0) -> 1475936000 | Q10: 0 | R10: =+(P10+Q10) -> 1475936000 | S10: 0.12 | T10: =(R10/(1+S10))*S10 -> 1.58136e+08 | U10: 1475936000 | V10: 0 | W10: =+V10/(1+$S10)*$S10 -> 0 | X10: =+W10*40% -> 0 | Y10: =+W10*60% -> 0 | Z10: =_xlfn.XLOOKUP(O10,'[4]2DO TRIMESTRE'!$C:$C,'[4]2DO TRIMESTRE'!$I:$I,0,0) -> 0 | AA10: =+Z10/(1+$S10)*$S10 -> 0 | AB10: =+AA10*40% -> 0 | AC10: =+AA10*60% -> 0 | AD10: 0 | AE10: =+AD10/(1+$S10)*$S10 -> 0 | AF10: =+AE10*40% -> 0 | AG10: =+AE10*60% -> 0 | AH10: 0 | AI10: =+AH10/(1+$S10)*$S10 -> 0 | AJ10: =+AI10*40% -> 0 | AK10: =+AI10*60% -> 0 | AL10: 158136000 | AM10: =W10+AA10+AE10+AI10 -> 0
A11: 5 | B11: 2021 | C11: UNIVERSIDAD DISTRITAL FRANCISCO JOSÉ DE CALDAS - UD | D11: FAC-MED-8024-UNIVERSIDAD DISTRITAL FRANCISCO JOSÉ DE CALDAS - UD | E11: Curso Propio | F11: 44238 | G11: 44293 | H11: =+(G11-F11)/90 -> 0.61111111 | I11: Liquidado | J11: Sin Observaciones | K11: OCCIDENTE | L11: Cuenta de ahorros | M11: 230-85718-7 | N11: 580 24 | O11: 2910908024 | P11: =+_xlfn.XLOOKUP(O11,'[3]Benef Primera fecha '!$C:$C,'[3]Benef Primera fecha '!$E:$E,0) -> 28967499 | Q11: 0 | R11: =+(P11+Q11) -> 28967499 | S11: 0.1365 | T11: =(R11/(1+S11))*S11 -> 3479158.5 | U11: 28967499 | V11: 0 | W11: =+V11/(1+$S11)*$S11 -> 0 | X11: =+W11*40% -> 0 | Y11: =+W11*60% -> 0 | Z11: =_xlfn.XLOOKUP(O11,'[4]2DO TRIMESTRE'!$C:$C,'[4]2DO TRIMESTRE'!$I:$I,0,0) -> 0 | AA11: =+Z11/(1+$S11)*$S11 -> 0 | AB11: =+AA11*40% -> 0 | AC11: =+AA11*60% -> 0 | AD11: 0 | AE11: =+AD11/(1+$S11)*$S11 -> 0 | AF11: =+AE11*40% -> 0 | AG11: =+AE11*60% -> 0 | AH11: 0 | AI11: =+AH11/(1+$S11)*$S11 -> 0 | AJ11: =+AI11*40% -> 0 | AK11: =+AI11*60% -> 0 | AL11: 3479129 | AM11: =W11+AA11+AE11+AI11 -> 0
A12: 6 | B12: 2021 | C12: MINISTERIO DE DEFENSA NACIONAL | D12: 021-00-G-CACOM-4-MINISTERIO DE DEFENSA NACIONAL | E12: Contrato | F12: 44249 | G12: 44700 | H12: =+(G12-F12)/90 -> 5.0111111 | I12: En Ejecución | J12: Sin Observaciones | K12: OCCIDENTE | L12: Cuenta de ahorros | M12: 230-85893- 8 | N12: 567 31 | O12: 2910906731 | P12: =+_xlfn.XLOOKUP(O12,'[3]Benef Primera fecha '!$C:$C,'[3]Benef Primera fecha '!$E:$E,0) -> 739371600 | Q12: 367057023 | R12: =+(P12+Q12) -> 1106428623 | S12: 0.12 | T12: =(R12/(1+S12))*S12 -> 118545925 | U12: 1106428623 | V12: 0 | W12: =+V12/(1+$S12)*$S12 -> 0 | X12: =+W12*40% -> 0 | Y12: =+W12*60% -> 0 | Z12: =_xlfn.XLOOKUP(O12,'[4]2DO TRIMESTRE'!$C:$C,'[4]2DO TRIMESTRE'!$I:$I,0,0) -> 0 | AA12: =+Z12/(1+$S12)*$S12 -> 0 | AB12: =+AA12*40% -> 0 | AC12: =+AA12*60% -> 0 | AD12: 0 | AE12: =+AD12/(1+$S12)*$S12 -> 0 | AF12: =+AE12*40% -> 0 | AG12: =+AE12*60% -> 0 | AH12: 0 | AI12: =+AH12/(1+$S12)*$S12 -> 0 | AJ12: =+AI12*40% -> 0 | AK12: =+AI12*60% -> 0 | AL12: 118545925 | AM12: =W12+AA12+AE12+AI12 -> 0
A13: 7 | B13: 2021 | C13: MUNICIPIO DE EL COLEGIO | D13: 128-MUNICIPIO DE EL COLEGIO | E13: Convenio Interadministrativo | F13: 44257 | G13: 44867 | H13: =+(G13-F13)/90 -> 6.7777778 | I13: Terminado | J13: Sin Observaciones | K13: OCCIDENTE | L13: Cuenta de ahorros | M13: 230-85893- 8 | N13: 83 10 | O13: 2453018310 | P13: =+_xlfn.XLOOKUP(O13,'[3]Benef Primera fecha '!$C:$C,'[3]Benef Primera fecha '!$E:$E,0) -> 306603272 | Q13: 0 | R13: =+(P13+Q13) -> 306603272 | S13: 0.12 | T13: =(R13/(1+S13))*S13 -> 32850351 | U13: 283797434 | V13: 0 | W13: =+V13/(1+$S13)*$S13 -> 0 | X13: =+W13*40% -> 0 | Y13: =+W13*60% -> 0 | Z13: =_xlfn.XLOOKUP(O13,'[4]2DO TRIMESTRE'!$C:$C,'[4]2DO TRIMESTRE'!$I:$I,0,0) -> 0 | AA13: =+Z13/(1+$S13)*$S13 -> 0 | AB13: =+AA13*40% -> 0 | AC13: =+AA13*60% -> 0 | AD13: 0 | AE13: =+AD13/(1+$S13)*$S13 -> 0 | AF13: =+AE13*40% -> 0 | AG13: =+AE13*60% -> 0 | AH13: 0 | AI13: =+AH13/(1+$S13)*$S13 -> 0 | AJ13: =+AI13*40% -> 0 | AK13: =+AI13*60% -> 0 | AL13: 30406868 | AM13: =W13+AA13+AE13+AI13 -> 0
A14: 8 | B14: 2021 | C14: INSTITUTO DEPARTAMENTAL DE CULTURA Y TURISMO DE CUNDINAMARCA | D14: 117-INSTITUTO DEPARTAMENTAL DE CULTURA Y TURISMO DE CUNDINAMARCA | E14: Contrato | F14: 44258 | G14: 44412 | H14: =+(G14-F14)/90 -> 1.7111111 | I14: Liquidado | J14: Sin Observaciones | K14: OCCIDENTE | L14: Cuenta de ahorros | M14: 230-85893- 8 | N14: 567 33 | O14: 2910906733 | P14: =+_xlfn.XLOOKUP(O14,'[3]Benef Primera fecha '!$C:$C,'[3]Benef Primera fecha '!$E:$E,0) -> 35000000 | Q14: 0 | R14: =+(P14+Q14) -> 35000000 | S14: 0.12 | T14: =(R14/(1+S14))*S14 -> 3750000 | U14: 35000000 | V14: 0 | W14: =+V14/(1+$S14)*$S14 -> 0 | X14: =+W14*40% -> 0 | Y14: =+W14*60% -> 0 | Z14: =_xlfn.XLOOKUP(O14,'[4]2DO TRIMESTRE'!$C:$C,'[4]2DO TRIMESTRE'!$I:$I,0,0) -> 0 | AA14: =+Z14/(1+$S14)*$S14 -> 0 | AB14: =+AA14*40% -> 0 | AC14: =+AA14*60% -> 0 | AD14: 0 | AE14: =+AD14/(1+$S14)*$S14 -> 0 | AF14: =+AE14*40% -> 0 | AG14: =+AE14*60% -> 0 | AH14: 0 | AI14: =+AH14/(1+$S14)*$S14 -> 0 | AJ14: =+AI14*40% -> 0 | AK14: =+AI14*60% -> 0 | AL14: 3750000 | AM14: =W14+AA14+AE14+AI14 -> 0
A15: 9 | B15: 2021 | C15: CORPORACIÓN AUTÓNOMA REGIONAL DE LOS VALLES DEL SINÚ Y DEL SAN JORGE - CVS | D15: 001-CORPORACIÓN AUTÓNOMA REGIONAL DE LOS VALLES DEL SINÚ Y DEL SAN JORGE - CVS | E15: Convenio Interadministrativo | F15: 44281 | G15: 44538 | H15: =+(G15-F15)/90 -> 2.8555556 | I15: Cierre Financiero | J15: Sin Observaciones | K15: OCCIDENTE | L15: Cuenta de ahorros | M15: 230-89456-0 | N15: 83 11 | O15: 2453018311 | P15: =+_xlfn.XLOOKUP(O15,'[3]Benef Primera fecha '!$C:$C,'[3]Benef Primera fecha '!$E:$E,0) -> 839500000 | Q15: 0 | R15: =+(P15+Q15) -> 839500000 | S15: 0.12 | T15: =(R15/(1+S15))*S15 -> 89946429 | U15: 693521814 | V15: 0 | W15: =+V15/(1+$S15)*$S15 -> 0 | X15: =+W15*40% -> 0 | Y15: =+W15*60% -> 0 | Z15: =_xlfn.XLOOKUP(O15,'[4]2DO TRIMESTRE'!$C:$C,'[4]2DO TRIMESTRE'!$I:$I,0,0) -> 0 | AA15: =+Z15/(1+$S15)*$S15 -> 0 | AB15: =+AA15*40% -> 0 | AC15: =+AA15*60% -> 0 | AD15: 0 | AE15: =+AD15/(1+$S15)*$S15 -> 0 | AF15: =+AE15*40% -> 0 | AG15: =+AE15*60% -> 0 | AH15: 0 | AI15: =+AH15/(1+$S15)*$S15 -> 0 | AJ15: =+AI15*40% -> 0 | AK15: =+AI15*60% -> 0 | AL15: 74305909 | AM15: =W15+AA15+AE15+AI15 -> 0
A16: 10 | B16: 2021 | C16: GOBERNACIÓN DE CUNDINAMARCA | D16: SFP-CDCTI-043-GOBERNACIÓN DE CUNDINAMARCA | E16: Contrato | F16: 44306 | G16: 44505 | H16: =+(G16-F16)/90 -> 2.2111111 | I16: Liquidado | J16: Sin Observaciones | K16: OCCIDENTE | L16: Cuenta de ahorros | M16: 230-85718-7 | N16: 567 34 | O16: 2910906734 | P16: =+_xlfn.XLOOKUP(O16,'[3]Benef Primera fecha '!$C:$C,'[3]Benef Primera fecha '!$E:$E,0) -> 39028000 | Q16: 0 | R16: =+(P16+Q16) -> 39028000 | S16: 0.12 | T16: =(R16/(1+S16))*S16 -> 4181571.4 | U16: 20814936 | V16: 0 | W16: =+V16/(1+$S16)*$S16 -> 0 | X16: =+W16*40% -> 0 | Y16: =+W16*60% -> 0 | Z16: =_xlfn.XLOOKUP(O16,'[4]2DO TRIMESTRE'!$C:$C,'[4]2DO TRIMESTRE'!$I:$I,0,0) -> 0 | AA16: =+Z16/(1+$S16)*$S16 -> 0 | AB16: =+AA16*40% -> 0 | AC16: =+AA16*60% -> 0 | AD16: 0 | AE16: =+AD16/(1+$S16)*$S16 -> 0 | AF16: =+AE16*40% -> 0 | AG16: =+AE16*60% -> 0 | AH16: 0 | AI16: =+AH16/(1+$S16)*$S16 -> 0 | AJ16: =+AI16*40% -> 0 | AK16: =+AI16*60% -> 0 | AL16: 2230171 | AM16: =W16+AA16+AE16+AI16 -> 0
A17: 11 | B17: 2021 | C17: INSTITUTO NACIONAL DE VIAS - INVIAS | D17: 891-2021-INSTITUTO NACIONAL DE VIAS - INVIAS | E17: Contrato | F17: 44315 | H17: =+(G17-F17)/90 -> -492.38889 | I17: Liquidado | J17: Sin Observaciones | K17: OCCIDENTE | L17: Cuenta de ahorros | M17: 230-85893- 8 | N17: 567 35 | O17: 2910906735 | P17: =+_xlfn.XLOOKUP(O17,'[3]Benef Primera fecha '!$C:$C,'[3]Benef Primera fecha '!$E:$E,0) -> 925000000 | Q17: 0 | R17: =+(P17+Q17) -> 925000000 | S17: 0.12 | T17: =(R17/(1+S17))*S17 -> 99107143 | U17: 1121496023 | V17: 0 | W17: =+V17/(1+$S17)*$S17 -> 0 | X17: =+W17*40% -> 0 | Y17: =+W17*60% -> 0 | Z17: =_xlfn.XLOOKUP(O17,'[4]2DO TRIMESTRE'!$C:$C,'[4]2DO TRIMESTRE'!$I:$I,0,0) -> 0 | AA17: =+Z17/(1+$S17)*$S17 -> 0 | AB17: =+AA17*40% -> 0 | AC17: =+AA17*60% -> 0 | AD17: 0 | AE17: =+AD17/(1+$S17)*$S17 -> 0 | AF17: =+AE17*40% -> 0 | AG17: =+AE17*60% -> 0 | AH17: 0 | AI17: =+AH17/(1+$S17)*$S17 -> 0 | AJ17: =+AI17*40% -> 0 | AK17: =+AI17*60% -> 0 | AL17: 99107143 | AM17: =W17+AA17+AE17+AI17 -> 0
A18: 12 | B18: 2021 | C18: CIDC-UNIVERSIDAD NACIONAL DE COLOMBIA | D18: 80740-542 S/N CONVENIO DE ASOCIACION-UNIVERSIDAD NACIONAL DE COLOMBIA | E18: Convenio Interadministrativo | F18: 44320 | G18: 45236 | H18: =+(G18-F18)/90 -> 10.177778 | I18: En Ejecución | J18: Sin Observaciones | K18: OCCIDENTE | L18: Cuenta de ahorros | M18: 230-85893- 8 | N18: 83 12 | O18: 2453018312 | P18: =_xlfn.XLOOKUP(O18,[5]Base!$C:$C,[5]Base!$E:$E,0,0) -> 0 | Q18: 0 | R18: =+(P18+Q18) -> 0 | S18: 0 | T18: =(R18/(1+S18))*S18 -> 0 | U18: 0 | V18: 0 | W18: =+V18/(1+$S18)*$S18 -> 0 | X18: =+W18*40% -> 0 | Y18: =+W18*60% -> 0 | Z18: =_xlfn.XLOOKUP(O18,'[4]2DO TRIMESTRE'!$C:$C,'[4]2DO TRIMESTRE'!$I:$I,0,0) -> 0 | AA18: =+Z18/(1+$S18)*$S18 -> 0 | AB18: =+AA18*40% -> 0 | AC18: =+AA18*60% -> 0 | AD18: 0 | AE18: =+AD18/(1+$S18)*$S18 -> 0 | AF18: =+AE18*40% -> 0 | AG18: =+AE18*60% -> 0 | AH18: 0 | AI18: =+AH18/(1+$S18)*$S18 -> 0 | AJ18: =+AI18*40% -> 0 | AK18: =+AI18*60% -> 0 | AL18: 0 | AM18: =W18+AA18+AE18+AI18 -> 0 | AN18: Proyecto sin beneficio institucional estipulado en el presupuesto | AO18: Proyecto sin beneficio institucional estipulado en el presupuesto
A19: 13 | B19: 2021 | C19: UNIVERSIDAD DISTRITAL FRANCISCO JOSÉ DE CALDAS - UD | D19: FAC-TECNO-8033-UNIVERSIDAD DISTRITAL FRANCISCO JOSÉ DE CALDAS - UD | E19: Curso Propio | F19: 44323 | G19: 44419 | H19: =+(G19-F19)/90 -> 1.0666667 | I19: Liquidado | J19: Sin Observaciones | K19: OCCIDENTE | L19: Cuenta de ahorros | M19: 230-85718-7 | N19: 580 33 | O19: 2910908033 | P19: =+_xlfn.XLOOKUP(O19,'[3]Benef Primera fecha '!$C:$C,'[3]Benef Primera fecha '!$E:$E,0) -> 65415600 | Q19: 0 | R19: =+(P19+Q19) -> 65415600 | S19: 0.12 | T19: 7849872 | U19: 65415600 | V19: 0 | W19: =+V19/(1+$S19)*$S19 -> 0 | X19: =+W19*40% -> 0 | Y19: =+W19*60% -> 0 | Z19: =_xlfn.XLOOKUP(O19,'[4]2DO TRIMESTRE'!$C:$C,'[4]2DO TRIMESTRE'!$I:$I,0,0) -> 0 | AA19: =+Z19/(1+$S19)*$S19 -> 0 | AB19: =+AA19*40% -> 0 | AC19: =+AA19*60% -> 0 | AD19: 0 | AE19: =+AD19/(1+$S19)*$S19 -> 0 | AF19: =+AE19*40% -> 0 | AG19: =+AE19*60% -> 0 | AH19: 0 | AI19: =+AH19/(1+$S19)*$S19 -> 0 | AJ19: =+AI19*40% -> 0 | AK19: =+AI19*60% -> 0 | AL19: 7849872 | AM19: =W19+AA19+AE19+AI19 -> 0
A20: 14 | B20: 2021 | C20: ORGANISMO INTERNACIONAL DE ENERGÍA ATOMICA | D20: 24500-ORGANISMO INTERNACIONAL DE ENERGÍA ATOMICA | E20: Contrato | F20: 44326 | G20: 44529 | H20: =+(G20-F20)/90 -> 2.2555556 | I20: En Ejecución | J20: Sin Observaciones | K20: OCCIDENTE | L20: Cuenta de ahorros | M20: 230-85893- 8 | N20: 567 45 | O20: 2910906745 | P20: 180187477 | Q20: 0 | R20: =+(P20+Q20) -> 180187477 | S20: 0 | T20: =(R20/(1+S20))*S20 -> 0 | U20: 0 | V20: 0 | W20: =+V20/(1+$S20)*$S20 -> 0 | X20: =+W20*40% -> 0 | Y20: =+W20*60% -> 0 | Z20: =_xlfn.XLOOKUP(O20,'[4]2DO TRIMESTRE'!$C:$C,'[4]2DO TRIMESTRE'!$I:$I,0,0) -> 0 | AA20: =+Z20/(1+$S20)*$S20 -> 0 | AB20: =+AA20*40% -> 0 | AC20: =+AA20*60% -> 0 | AD20: 0 | AE20: =+AD20/(1+$S20)*$S20 -> 0 | AF20: =+AE20*40% -> 0 | AG20: =+AE20*60% -> 0 | AH20: 0 | AI20: =+AH20/(1+$S20)*$S20 -> 0 | AJ20: =+AI20*40% -> 0 | AK20: =+AI20*60% -> 0 | AL20: 0 | AM20: =W20+AA20+AE20+AI20 -> 0 | AN20: Proyecto sin beneficio institucional estipulado en el presupuesto | AO20: Proyecto sin beneficio institucional estipulado en el presupuesto
A21: 15 | B21: 2021 | C21: COMISIÓN DE REGULACIÓN DE AGUA POTABLE Y SANEAMIENTO BÁSICO - CRA | D21: 97-COMISIÓN DE REGULACIÓN DE AGUA POTABLE Y SANEAMIENTO BÁSICO - CRA | E21: Contrato | F21: 44326 | G21: 44530 | H21: =+(G21-F21)/90 -> 2.2666667 | I21: Cierre Financiero | J21: Sin Observaciones | K21: OCCIDENTE | L21: Cuenta de ahorros | M21: 230-85893- 8 | N21: 567 37 | O21: 2910906737 | P21: =+_xlfn.XLOOKUP(O21,'[3]Benef Primera fecha '!$C:$C,'[3]Benef Primera fecha '!$E:$E,0) -> 50000000 | Q21: 0 | R21: =+(P21+Q21) -> 50000000 | S21: 0.12 | T21: =(R21/(1+S21))*S21 -> 5357142.9 | U21: 50000000 | V21: 0 | W21: =+V21/(1+$S21)*$S21 -> 0 | X21: =+W21*40% -> 0 | Y21: =+W21*60% -> 0 | Z21: =_xlfn.XLOOKUP(O21,'[4]2DO TRIMESTRE'!$C:$C,'[4]2DO TRIMESTRE'!$I:$I,0,0) -> 0 | AA21: =+Z21/(1+$S21)*$S21 -> 0 | AB21: =+AA21*40% -> 0 | AC21: =+AA21*60% -> 0 | AD21: 0 | AE21: =+AD21/(1+$S21)*$S21 -> 0 | AF21: =+AE21*40% -> 0 | AG21: =+AE21*60% -> 0 | AH21: 0 | AI21: =+AH21/(1+$S21)*$S21 -> 0 | AJ21: =+AI21*40% -> 0 | AK21: =+AI21*60% -> 0 | AL21: 5357143 | AM21: =W21+AA21+AE21+AI21 -> 0
A22: 16 | B22: 2021 | C22: MINISTERIO DE DEFENSA NACIONAL INSTITUTO DE CASAS FISCALES DEL EJÉRCITO | D22: 111-MINISTERIO DE DEFENSA NACIONAL INSTITUTO DE CASAS FISCALES DEL EJÉRCITO | E22: Contrato | F22: 44327 | G22: 44510 | H22: =+(G22-F22)/90 -> 2.0333333 | I22: Liquidado | J22: Sin Observaciones | K22: OCCIDENTE | L22: Cuenta de ahorros | M22: 230-85893- 8 | N22: 567 40 | O22: 2910906740 | P22: =+_xlfn.XLOOKUP(O22,'[3]Benef Primera fecha '!$C:$C,'[3]Benef Primera fecha '!$E:$E,0) -> 53704000 | Q22: 0 | R22: =+(P22+Q22) -> 53704000 | S22: 0.12 | T22: 6445000 | U22: 53704000 | V22: 0 | W22: =+V22/(1+$S22)*$S22 -> 0 | X22: =+W22*40% -> 0 | Y22: =+W22*60% -> 0 | Z22: 50638245 | AA22: =+Z22/(1+$S22)*$S22 -> 5425526.2 | AB22: =+AA22*40% -> 2170210.5 | AC22: =+AA22*60% -> 3255315.7 | AD22: 0 | AE22: =+AD22/(1+$S22)*$S22 -> 0 | AF22: =+AE22*40% -> 0 | AG22: =+AE22*60% -> 0 | AH22: 0 | AI22: =+AH22/(1+$S22)*$S22 -> 0 | AJ22: =+AI22*40% -> 0 | AK22: =+AI22*60% -> 0 | AL22: 6445000 | AM22: =W22+AA22+AE22+AI22 -> 5425526.2
A23: 17 | B23: 2021 | C23: UNIVERSIDAD DISTRITAL FRANCISCO JOSÉ DE CALDAS - UD | D23: FAC-ING-8029-UNIVERSIDAD DISTRITAL FRANCISCO JOSÉ DE CALDAS - UD | E23: Curso Propio | F23: 44327 | G23: 44428 | H23: =+(G23-F23)/90 -> 1.1222222 | I23: Liquidado | J23: Sin Observaciones | K23: OCCIDENTE | L23: Cuenta de ahorros | M23: 230-85718-7 | N23: 580 29 | O23: 2910908029 | P23: =+_xlfn.XLOOKUP(O23,'[3]Benef Primera fecha '!$C:$C,'[3]Benef Primera fecha '!$E:$E,0) -> 17160000 | Q23: 0 | R23: =+(P23+Q23) -> 17160000 | S23: 0.12 | T23: =(R23/(1+S23))*S23 -> 1838571.4 | U23: 17160000 | V23: 0 | W23: =+V23/(1+$S23)*$S23 -> 0 | X23: =+W23*40% -> 0 | Y23: =+W23*60% -> 0 | Z23: =_xlfn.XLOOKUP(O23,'[4]2DO TRIMESTRE'!$C:$C,'[4]2DO TRIMESTRE'!$I:$I,0,0) -> 0 | AA23: =+Z23/(1+$S23)*$S23 -> 0 | AB23: =+AA23*40% -> 0 | AC23: =+AA23*60% -> 0 | AD23: 0 | AE23: =+AD23/(1+$S23)*$S23 -> 0 | AF23: =+AE23*40% -> 0 | AG23: =+AE23*60% -> 0 | AH23: 0 | AI23: =+AH23/(1+$S23)*$S23 -> 0 | AJ23: =+AI23*40% -> 0 | AK23: =+AI23*60% -> 0 | AL23: 1838571 | AM23: =W23+AA23+AE23+AI23 -> 0
A24: 18 | B24: 2021 | C24: UNIVERSIDAD DISTRITAL FRANCISCO JOSÉ DE CALDAS - UD | D24: 16161-UNIVERSIDAD DISTRITAL FRANCISCO JOSÉ DE CALDAS - UD | E24: Curso Propio | F24: 44328 | G24: 44695 | H24: =+(G24-F24)/90 -> 4.0777778 | I24: Terminado | J24: Sin Observaciones | K24: OCCIDENTE | L24: Cuenta de ahorros | M24: 230-85718-7 | N24: 580 37 | O24: 2910908037 | P24: 36473350 | Q24: 0 | R24: =+(P24+Q24) -> 36473350 | S24: 0 | T24: =(R24/(1+S24))*S24 -> 0 | U24: 0 | V24: 0 | W24: =+V24/(1+$S24)*$S24 -> 0 | X24: =+W24*40% -> 0 | Y24: =+W24*60% -> 0 | Z24: =_xlfn.XLOOKUP(O24,'[4]2DO TRIMESTRE'!$C:$C,'[4]2DO TRIMESTRE'!$I:$I,0,0) -> 0 | AA24: =+Z24/(1+$S24)*$S24 -> 0 | AB24: =+AA24*40% -> 0 | AC24: =+AA24*60% -> 0 | AD24: 0 | AE24: =+AD24/(1+$S24)*$S24 -> 0 | AF24: =+AE24*40% -> 0 | AG24: =+AE24*60% -> 0 | AH24: 0 | AI24: =+AH24/(1+$S24)*$S24 -> 0 | AJ24: =+AI24*40% -> 0 | AK24: =+AI24*60% -> 0 | AL24: 0 | AM24: =W24+AA24+AE24+AI24 -> 0
A25: 19 | B25: 2021 | C25: INSTITUTO GEOGRAFICO AGUSTIN CODAZZI - IGAC | D25: 24715-INSTITUTO GEOGRAFICO AGUSTIN CODAZZI - IGAC | E25: Contrato | F25: 44329 | G25: 44560 | H25: =+(G25-F25)/90 -> 2.5666667 | I25: Liquidado | J25: Sin Observaciones | K25: OCCIDENTE | L25: Cuenta de ahorros | M25: 230-85893- 8 | N25: 567 39 | O25: 2910906739 | P25: =+_xlfn.XLOOKUP(O25,'[3]Benef Primera fecha '!$C:$C,'[3]Benef Primera fecha '!$E:$E,0) -> 225600000 | Q25: 0 | R25: =+(P25+Q25) -> 225600000 | S25: 0.12 | T25: =(R25/(1+S25))*S25 -> 24171429 | U25: 225600000 | V25: 0 | W25: =+V25/(1+$S25)*$S25 -> 0 | X25: =+W25*40% -> 0 | Y25: =+W25*60% -> 0 | Z25: =_xlfn.XLOOKUP(O25,'[4]2DO TRIMESTRE'!$C:$C,'[4]2DO TRIMESTRE'!$I:$I,0,0) -> 0 | AA25: =+Z25/(1+$S25)*$S25 -> 0 | AB25: =+AA25*40% -> 0 | AC25: =+AA25*60% -> 0 | AD25: 0 | AE25: =+AD25/(1+$S25)*$S25 -> 0 | AF25: =+AE25*40% -> 0 | AG25: =+AE25*60% -> 0 | AH25: 0 | AI25: =+AH25/(1+$S25)*$S25 -> 0 | AJ25: =+AI25*40% -> 0 | AK25: =+AI25*60% -> 0 | AL25: 24171429 | AM25: =W25+AA25+AE25+AI25 -> 0
A26: 20 | B26: 2021 | C26: FIDUPREVISORA S.A. | D26: 80740-023-FIDUPREVISORA S.A. | E26: Contrato | F26: 44330 | G26: 45059 | H26: =+(G26-F26)/90 -> 8.1 | I26: En Ejecución | J26: Sin Observaciones | K26: OCCIDENTE | L26: Cuenta de ahorros | M26: 230-85893- 8 | N26: 567 38 | O26: 2910906738 | P26: 298773815 | Q26: 0 | R26: =+(P26+Q26) -> 298773815 | S26: 0 | T26: =(R26/(1+S26))*S26 -> 0 | U26: 0 | V26: 0 | W26: =+V26/(1+$S26)*$S26 -> 0 | X26: =+W26*40% -> 0 | Y26: =+W26*60% -> 0 | Z26: =_xlfn.XLOOKUP(O26,'[4]2DO TRIMESTRE'!$C:$C,'[4]2DO TRIMESTRE'!$I:$I,0,0) -> 0 | AA26: =+Z26/(1+$S26)*$S26 -> 0 | AB26: =+AA26*40% -> 0 | AC26: =+AA26*60% -> 0 | AD26: 0 | AE26: =+AD26/(1+$S26)*$S26 -> 0 | AF26: =+AE26*40% -> 0 | AG26: =+AE26*60% -> 0 | AH26: 0 | AI26: =+AH26/(1+$S26)*$S26 -> 0 | AJ26: =+AI26*40% -> 0 | AK26: =+AI26*60% -> 0 | AL26: 0 | AM26: =W26+AA26+AE26+AI26 -> 0 | AN26: Proyecto sin beneficio institucional estipulado en el presupuesto | AO26: Proyecto sin beneficio institucional estipulado en el presupuesto
A27: 21 | B27: 2021 | C27: FIDUPREVISORA S.A. | D27: 80740-110-FIDUPREVISORA S.A. | E27: Contrato | F27: 44330 | G27: 44817 | H27: =+(G27-F27)/90 -> 5.4111111 | I27: En Ejecución | J27: Sin Observaciones | K27: OCCIDENTE | L27: Cuenta de ahorros | M27: 230-85893- 8 | N27: 567 41 | O27: 2910906741 | P27: 75266267 | Q27: 0 | R27: =+(P27+Q27) -> 75266267 | S27: 0 | T27: =(R27/(1+S27))*S27 -> 0 | U27: 0 | V27: 0 | W27: =+V27/(1+$S27)*$S27 -> 0 | X27: =+W27*40% -> 0 | Y27: =+W27*60% -> 0 | Z27: =_xlfn.XLOOKUP(O27,'[4]2DO TRIMESTRE'!$C:$C,'[4]2DO TRIMESTRE'!$I:$I,0,0) -> 0 | AA27: =+Z27/(1+$S27)*$S27 -> 0 | AB27: =+AA27*40% -> 0 | AC27: =+AA27*60% -> 0 | AD27: 0 | AE27: =+AD27/(1+$S27)*$S27 -> 0 | AF27: =+AE27*40% -> 0 | AG27: =+AE27*60% -> 0 | AH27: 0 | AI27: =+AH27/(1+$S27)*$S27 -> 0 | AJ27: =+AI27*40% -> 0 | AK27: =+AI27*60% -> 0 | AL27: 0 | AM27: =W27+AA27+AE27+AI27 -> 0 | AN27: Proyecto sin beneficio institucional estipulado en el presupuesto | AO27: Proyecto sin beneficio institucional estipulado en el presupuesto
A28: 22 | B28: 2021 | C28: UNIVERSIDAD DISTRITAL FRANCISCO JOSÉ DE CALDAS - UD | D28: FAC-CIE-8032-UNIVERSIDAD DISTRITAL FRANCISCO JOSÉ DE CALDAS - UD | E28: Curso Propio | F28: 44336 | G28: 44427 | H28: =+(G28-F28)/90 -> 1.0111111 | I28: Liquidado | J28: Sin Observaciones | K28: OCCIDENTE | L28: Cuenta de ahorros | M28: 230-85718-7 | N28: 580 32 | O28: 2910908032 | P28: =+_xlfn.XLOOKUP(O28,'[3]Benef Primera fecha '!$C:$C,'[3]Benef Primera fecha '!$E:$E,0) -> 32706980 | Q28: 0 | R28: =+(P28+Q28) -> 32706980 | S28: 0.12 | T28: 3924832 | U28: 32706980 | V28: 0 | W28: =+V28/(1+$S28)*$S28 -> 0 | X28: =+W28*40% -> 0 | Y28: =+W28*60% -> 0 | Z28: =_xlfn.XLOOKUP(O28,'[4]2DO TRIMESTRE'!$C:$C,'[4]2DO TRIMESTRE'!$I:$I,0,0) -> 0 | AA28: =+Z28/(1+$S28)*$S28 -> 0 | AB28: =+AA28*40% -> 0 | AC28: =+AA28*60% -> 0 | AD28: 0 | AE28: =+AD28/(1+$S28)*$S28 -> 0 | AF28: =+AE28*40% -> 0 | AG28: =+AE28*60% -> 0 | AH28: 0 | AI28: =+AH28/(1+$S28)*$S28 -> 0 | AJ28: =+AI28*40% -> 0 | AK28: =+AI28*60% -> 0 | AL28: 3924832 | AM28: =W28+AA28+AE28+AI28 -> 0
A29: 23 | B29: 2021 | C29: UNIVERSIDAD DE TWENTE | D29: 3-UNIVERSIDAD DE TWENTE | E29: Convenio Interadministrativo | F29: 44351 | G29: 44530 | H29: =+(G29-F29)/90 -> 1.9888889 | I29: En Ejecución | J29: Sin Observaciones | K29: OCCIDENTE | L29: Cuenta de ahorros | M29: 230-85893- 8 | N29: 83 14 | O29: 2453018314 | P29: 24028920 | Q29: 0 | R29: =+(P29+Q29) -> 24028920 | S29: 0 | T29: =(R29/(1+S29))*S29 -> 0 | U29: 0 | V29: 0 | W29: =+V29/(1+$S29)*$S29 -> 0 | X29: =+W29*40% -> 0 | Y29: =+W29*60% -> 0 | Z29: =_xlfn.XLOOKUP(O29,'[4]2DO TRIMESTRE'!$C:$C,'[4]2DO TRIMESTRE'!$I:$I,0,0) -> 0 | AA29: =+Z29/(1+$S29)*$S29 -> 0 | AB29: =+AA29*40% -> 0 | AC29: =+AA29*60% -> 0 | AD29: 0 | AE29: =+AD29/(1+$S29)*$S29 -> 0 | AF29: =+AE29*40% -> 0 | AG29: =+AE29*60% -> 0 | AH29: 0 | AI29: =+AH29/(1+$S29)*$S29 -> 0 | AJ29: =+AI29*40% -> 0 | AK29: =+AI29*60% -> 0 | AL29: 0 | AM29: =W29+AA29+AE29+AI29 -> 0 | AN29: Proyecto sin beneficio institucional estipulado en el presupuesto | AO29: Proyecto sin beneficio institucional estipulado en el presupuesto
A30: 24 | B30: 2021 | C30: GOBERNACIÓN DE LA GUAJIRA | D30: 010-2021-GOBERNACIÓN DE LA GUAJIRA | E30: Contrato | F30: 44351 | G30: 45317 | H30: =+(G30-F30)/90 -> 10.733333 | I30: En Ejecución | J30: Sin Observaciones | K30: OCCIDENTE | L30: Cuenta de ahorros | M30: 230-89464-4 | N30: 567 43 | O30: 2910906743 | P30: =+_xlfn.XLOOKUP(O30,'[3]Benef Primera fecha '!$C:$C,'[3]Benef Primera fecha '!$E:$E,0) -> 577046931 | Q30: 0 | R30: =+(P30+Q30) -> 577046931 | S30: 0.12 | T30: =(R30/(1+S30))*S30 -> 61826457 | U30: 5.2476971e+08 | V30: 0 | W30: =+V30/(1+$S30)*$S30 -> 0 | X30: =+W30*40% -> 0 | Y30: =+W30*60% -> 0 | Z30: =_xlfn.XLOOKUP(O30,'[4]2DO TRIMESTRE'!$C:$C,'[4]2DO TRIMESTRE'!$I:$I,0,0) -> 0 | AA30: =+Z30/(1+$S30)*$S30 -> 0 | AB30: =+AA30*40% -> 0 | AC30: =+AA30*60% -> 0 | AD30: 0 | AE30: =+AD30/(1+$S30)*$S30 -> 0 | AF30: =+AE30*40% -> 0 | AG30: =+AE30*60% -> 0 | AH30: 0 | AI30: =+AH30/(1+$S30)*$S30 -> 0 | AJ30: =+AI30*40% -> 0 | AK30: =+AI30*60% -> 0 | AL30: 5288324 | AM30: =W30+AA30+AE30+AI30 -> 0
A31: 25 | B31: 2021 | C31: REGIÓN ADMINISTRATIVA Y DE PLANEACION ESPECIAL — RAPE | D31: 55-REGIÓN ADMINISTRATIVA Y DE PLANEACION ESPECIAL — RAPE | E31: Convenio Interadministrativo | F31: 44355 | G31: 44561 | H31: =+(G31-F31)/90 -> 2.2888889 | I31: Liquidado | J31: Sin Observaciones | K31: OCCIDENTE | L31: Cuenta de ahorros | M31: 230-89467-7 | N31: 83 13 | O31: 2453018313 | P31: =+_xlfn.XLOOKUP(O31,'[3]Benef Primera fecha '!$C:$C,'[3]Benef Primera fecha '!$E:$E,0) -> 419170248 | Q31: 209552512 | R31: =+(P31+Q31) -> 628722760 | S31: 0.12 | T31: =(R31/(1+S31))*S31 -> 67363153 | U31: 543477013 | V31: 0 | W31: =+V31/(1+$S31)*$S31 -> 0 | X31: =+W31*40% -> 0 | Y31: =+W31*60% -> 0 | Z31: =_xlfn.XLOOKUP(O31,'[4]2DO TRIMESTRE'!$C:$C,'[4]2DO TRIMESTRE'!$I:$I,0,0) -> 0 | AA31: =+Z31/(1+$S31)*$S31 -> 0 | AB31: =+AA31*40% -> 0 | AC31: =+AA31*60% -> 0 | AD31: 0 | AE31: =+AD31/(1+$S31)*$S31 -> 0 | AF31: =+AE31*40% -> 0 | AG31: =+AE31*60% -> 0 | AH31: 0 | AI31: =+AH31/(1+$S31)*$S31 -> 0 | AJ31: =+AI31*40% -> 0 | AK31: =+AI31*60% -> 0 | AL31: 58229680 | AM31: =W31+AA31+AE31+AI31 -> 0
A32: 26 | B32: 2021 | C32: SERVICIO NACIONAL DE APRENDIZAJE - SENA | D32: CO1.PCCNTR.2564825-SERVICIO NACIONAL DE APRENDIZAJE - SENA | E32: Contrato | F32: 44356 | G32: 45464 | H32: =+(G32-F32)/90 -> 12.311111 | I32: En Ejecución | J32: Sin Observaciones | K32: OCCIDENTE | L32: Cuenta Corriente | M32: 230-89517-9 | N32: 567 42 | O32: 2910906742 | P32: =+_xlfn.XLOOKUP(O32,'[3]Benef Primera fecha '!$C:$C,'[3]Benef Primera fecha '!$E:$E,0) -> 7279682085 | Q32: 1980000000 | R32: =+(P32+Q32) -> 9259682085 | S32: 0.12 | T32: =(R32/(1+S32))*S32 -> 9.9210879e+08 | U32: 6813745669 | V32: 0 | W32: =+V32/(1+$S32)*$S32 -> 0 | X32: =+W32*40% -> 0 | Y32: =+W32*60% -> 0 | Z32: =_xlfn.XLOOKUP(O32,'[4]2DO TRIMESTRE'!$C:$C,'[4]2DO TRIMESTRE'!$I:$I,0,0) -> 0 | AA32: =+Z32/(1+$S32)*$S32 -> 0 | AB32: =+AA32*40% -> 0 | AC32: =+AA32*60% -> 0 | AD32: 0 | AE32: =+AD32/(1+$S32)*$S32 -> 0 | AF32: =+AE32*40% -> 0 | AG32: =+AE32*60% -> 0 | AH32: 0 | AI32: =+AH32/(1+$S32)*$S32 -> 0 | AJ32: =+AI32*40% -> 0 | AK32: =+AI32*60% -> 0 | AL32: 7.3004418e+08 | AM32: =W32+AA32+AE32+AI32 -> 0
A33: 27 | B33: 2021 | C33: FIDUPREVISORA S.A. | D33: 80740-194-FIDUPREVISORA S.A. | E33: Contrato | F33: 44362 | G33: 44848 | H33: =+(G33-F33)/90 -> 5.4 | I33: En Ejecución | J33: Sin Observaciones | K33: OCCIDENTE | L33: Cuenta de ahorros | M33: 230-85893- 8 | N33: 567 44 | O33: 2910906744 | P33: 63454623 | Q33: 0 | R33: =+(P33+Q33) -> 63454623 | S33: 0 | T33: =(R33/(1+S33))*S33 -> 0 | U33: 0 | V33: 0 | W33: =+V33/(1+$S33)*$S33 -> 0 | X33: =+W33*40% -> 0 | Y33: =+W33*60% -> 0 | Z33: =_xlfn.XLOOKUP(O33,'[4]2DO TRIMESTRE'!$C:$C,'[4]2DO TRIMESTRE'!$I:$I,0,0) -> 0 | AA33: =+Z33/(1+$S33)*$S33 -> 0 | AB33: =+AA33*40% -> 0 | AC33: =+AA33*60% -> 0 | AD33: 0 | AE33: =+AD33/(1+$S33)*$S33 -> 0 | AF33: =+AE33*40% -> 0 | AG33: =+AE33*60% -> 0 | AH33: 0 | AI33: =+AH33/(1+$S33)*$S33 -> 0 | AJ33: =+AI33*40% -> 0 | AK33: =+AI33*60% -> 0 | AL33: 0 | AM33: =W33+AA33+AE33+AI33 -> 0 | AN33: Proyecto sin beneficio institucional estipulado en el presupuesto | AO33: Proyecto sin beneficio institucional estipulado en el presupuesto
A34: 28 | B34: 2021 | C34: SECRETARÍA DE EDUCACION DEL DISTRITO - SED | D34: 2609142-SECRETARÍA DE EDUCACION DEL DISTRITO - SED | E34: Contrato | F34: 44379 | G34: 44592 | H34: =+(G34-F34)/90 -> 2.3666667 | I34: Liquidado | J34: Sin Observaciones | K34: OCCIDENTE | L34: Cuenta de ahorros | M34: 230-89470-1 | N34: 83 15 | O34: 2453018315 | P34: =+_xlfn.XLOOKUP(O34,'[3]Benef Primera fecha '!$C:$C,'[3]Benef Primera fecha '!$E:$E,0) -> 1518787008 | Q34: 0 | R34: =+(P34+Q34) -> 1518787008 | S34: 0.12 | T34: =(R34/(1+S34))*S34 -> 1.6272718e+08 | U34: 1248942571 | V34: 0 | W34: =+V34/(1+$S34)*$S34 -> 0 | X34: =+W34*40% -> 0 | Y34: =+W34*60% -> 0 | Z34: =_xlfn.XLOOKUP(O34,'[4]2DO TRIMESTRE'!$C:$C,'[4]2DO TRIMESTRE'!$I:$I,0,0) -> 0 | AA34: =+Z34/(1+$S34)*$S34 -> 0 | AB34: =+AA34*40% -> 0 | AC34: =+AA34*60% -> 0 | AD34: 0 | AE34: =+AD34/(1+$S34)*$S34 -> 0 | AF34: =+AE34*40% -> 0 | AG34: =+AE34*60% -> 0 | AH34: 0 | AI34: =+AH34/(1+$S34)*$S34 -> 0 | AJ34: =+AI34*40% -> 0 | AK34: =+AI34*60% -> 0 | AL34: 149761919 | AM34: =W34+AA34+AE34+AI34 -> 0
A35: 29 | B35: 2021 | C35: FDL BOSA | D35: 278-FDL BOSA | E35: Contrato | F35: 44379 | G35: 44537 | H35: =+(G35-F35)/90 -> 1.7555556 | I35: Liquidado | J35: Sin Observaciones | K35: OCCIDENTE | L35: Cuenta de ahorros | M35: 230-85893- 8 | N35: 567 46 | O35: 2910906746 | P35: =+_xlfn.XLOOKUP(O35,'[3]Benef Primera fecha '!$C:$C,'[3]Benef Primera fecha '!$E:$E,0) -> 450000000 | Q35: 0 | R35: =+(P35+Q35) -> 450000000 | S35: 0.12 | T35: =(R35/(1+S35))*S35 -> 48214286 | U35: 450000000 | V35: 0 | W35: =+V35/(1+$S35)*$S35 -> 0 | X35: =+W35*40% -> 0 | Y35: =+W35*60% -> 0 | Z35: =_xlfn.XLOOKUP(O35,'[4]2DO TRIMESTRE'!$C:$C,'[4]2DO TRIMESTRE'!$I:$I,0,0) -> 0 | AA35: =+Z35/(1+$S35)*$S35 -> 0 | AB35: =+AA35*40% -> 0 | AC35: =+AA35*60% -> 0 | AD35: 0 | AE35: =+AD35/(1+$S35)*$S35 -> 0 | AF35: =+AE35*40% -> 0 | AG35: =+AE35*60% -> 0 | AH35: 0 | AI35: =+AH35/(1+$S35)*$S35 -> 0 | AJ35: =+AI35*40% -> 0 | AK35: =+AI35*60% -> 0 | AL35: 48214286 | AM35: =W35+AA35+AE35+AI35 -> 0
A36: 30 | B36: 2021 | C36: UNIDAD ADMINISTRATIVA ESPECIAL DE CATASTRO DISTRITAL - UAECD | D36: 593-2021-UNIDAD ADMINISTRATIVA ESPECIAL DE CATASTRO DISTRITAL - UAECD | E36: Contrato | F36: 44384 | G36: 44794 | H36: =+(G36-F36)/90 -> 4.5555556 | I36: Liquidado | J36: Sin Observaciones | K36: OCCIDENTE | L36: Cuenta de ahorros | M36: 230-85893- 8 | N36: 567 49 | O36: 2910906749 | P36: =+_xlfn.XLOOKUP(O36,'[3]Benef Primera fecha '!$C:$C,'[3]Benef Primera fecha '!$E:$E,0) -> 87371000 | Q36: 43680000 | R36: =+(P36+Q36) -> 131051000 | S36: 0.12 | T36: =(R36/(1+S36))*S36 -> 14041179 | U36: 131051000 | V36: 0 | W36: =+V36/(1+$S36)*$S36 -> 0 | X36: =+W36*40% -> 0 | Y36: =+W36*60% -> 0 | Z36: =_xlfn.XLOOKUP(O36,'[4]2DO TRIMESTRE'!$C:$C,'[4]2DO TRIMESTRE'!$I:$I,0,0) -> 0 | AA36: =+Z36/(1+$S36)*$S36 -> 0 | AB36: =+AA36*40% -> 0 | AC36: =+AA36*60% -> 0 | AD36: 0 | AE36: =+AD36/(1+$S36)*$S36 -> 0 | AF36: =+AE36*40% -> 0 | AG36: =+AE36*60% -> 0 | AH36: 0 | AI36: =+AH36/(1+$S36)*$S36 -> 0 | AJ36: =+AI36*40% -> 0 | AK36: =+AI36*60% -> 0 | AL36: 14041179 | AM36: =W36+AA36+AE36+AI36 -> 0
A37: 31 | B37: 2021 | C37: UNIVERSIDAD DISTRITAL FRANCISCO JOSÉ DE CALDAS - UD | D37: FAC-MED-8040-UNIVERSIDAD DISTRITAL FRANCISCO JOSÉ DE CALDAS - UD | E37: Curso Propio | F37: 44400 | G37: 44522 | H37: =+(G37-F37)/90 -> 1.3555556 | I37: Liquidado | J37: Sin Observaciones | K37: OCCIDENTE | L37: Cuenta de ahorros | M37: 230-85718-7 | N37: 580 40 | O37: 2910908040 | P37: =+_xlfn.XLOOKUP(O37,'[3]Benef Primera fecha '!$C:$C,'[3]Benef Primera fecha '!$E:$E,0) -> 92700000 | Q37: 0 | R37: =+(P37+Q37) -> 92700000 | S37: 0.12 | T37: =(R37/(1+S37))*S37 -> 9932142.9 | U37: 92700000 | V37: 0 | W37: =+V37/(1+$S37)*$S37 -> 0 | X37: =+W37*40% -> 0 | Y37: =+W37*60% -> 0 | Z37: =_xlfn.XLOOKUP(O37,'[4]2DO TRIMESTRE'!$C:$C,'[4]2DO TRIMESTRE'!$I:$I,0,0) -> 0 | AA37: =+Z37/(1+$S37)*$S37 -> 0 | AB37: =+AA37*40% -> 0 | AC37: =+AA37*60% -> 0 | AD37: 0 | AE37: =+AD37/(1+$S37)*$S37 -> 0 | AF37: =+AE37*40% -> 0 | AG37: =+AE37*60% -> 0 | AH37: 0 | AI37: =+AH37/(1+$S37)*$S37 -> 0 | AJ37: =+AI37*40% -> 0 | AK37: =+AI37*60% -> 0 | AL37: 9932143 | AM37: =W37+AA37+AE37+AI37 -> 0
A38: 32 | B38: 2021 | C38: SERVICIO GEOLOGICO COLOMBIANO | D38: 27-SERVICIO GEOLOGICO COLOMBIANO | E38: Contrato | F38: 44403 | G38: 44681 | H38: =+(G38-F38)/90 -> 3.0888889 | I38: Liquidado | J38: Sin Observaciones | K38: OCCIDENTE | L38: Cuenta de ahorros | M38: 230-85893- 8 | N38: 567 52 | O38: 2910906752 | P38: =+_xlfn.XLOOKUP(O38,'[3]Benef Primera fecha '!$C:$C,'[3]Benef Primera fecha '!$E:$E,0) -> 858400000 | Q38: 0 | R38: =+(P38+Q38) -> 858400000 | S38: 0.12 | T38: =(R38/(1+S38))*S38 -> 91971429 | U38: 858400000 | V38: 0 | W38: =+V38/(1+$S38)*$S38 -> 0 | X38: =+W38*40% -> 0 | Y38: =+W38*60% -> 0 | Z38: =_xlfn.XLOOKUP(O38,'[4]2DO TRIMESTRE'!$C:$C,'[4]2DO TRIMESTRE'!$I:$I,0,0) -> 0 | AA38: =+Z38/(1+$S38)*$S38 -> 0 | AB38: =+AA38*40% -> 0 | AC38: =+AA38*60% -> 0 | AD38: 0 | AE38: =+AD38/(1+$S38)*$S38 -> 0 | AF38: =+AE38*40% -> 0 | AG38: =+AE38*60% -> 0 | AH38: 0 | AI38: =+AH38/(1+$S38)*$S38 -> 0 | AJ38: =+AI38*40% -> 0 | AK38: =+AI38*60% -> 0 | AL38: 91971429 | AM38: =W38+AA38+AE38+AI38 -> 0
A39: 33 | B39: 2021 | C39: MASCULTURAL CORPORACION | D39: CPSENELMARCO216921-1-MASCULTURAL CORPORACION | E39: Contrato | F39: 44403 | G39: 44540 | H39: =+(G39-F39)/90 -> 1.5222222 | I39: Cierre Financiero | J39: Sin Observaciones | K39: OCCIDENTE | L39: Cuenta de ahorros | M39: 230-85718-7 | N39: 567 48 | O39: 2910906748 | P39: =+_xlfn.XLOOKUP(O39,'[3]Benef Primera fecha '!$C:$C,'[3]Benef Primera fecha '!$E:$E,0) -> 116000000 | Q39: 0 | R39: =+(P39+Q39) -> 116000000 | S39: 0.12 | T39: =(R39/(1+S39))*S39 -> 12428571 | U39: 115759880 | V39: 0 | W39: =+V39/(1+$S39)*$S39 -> 0 | X39: =+W39*40% -> 0 | Y39: =+W39*60% -> 0 | Z39: =_xlfn.XLOOKUP(O39,'[4]2DO TRIMESTRE'!$C:$C,'[4]2DO TRIMESTRE'!$I:$I,0,0) -> 0 | AA39: =+Z39/(1+$S39)*$S39 -> 0 | AB39: =+AA39*40% -> 0 | AC39: =+AA39*60% -> 0 | AD39: 0 | AE39: =+AD39/(1+$S39)*$S39 -> 0 | AF39: =+AE39*40% -> 0 | AG39: =+AE39*60% -> 0 | AH39: 0 | AI39: =+AH39/(1+$S39)*$S39 -> 0 | AJ39: =+AI39*40% -> 0 | AK39: =+AI39*60% -> 0 | AL39: 12402844 | AM39: =W39+AA39+AE39+AI39 -> 0
A40: 34 | B40: 2021 | C40: CENTRO NACIONAL DE MEMORIA HISTORICA | D40: 419-CENTRO NACIONAL DE MEMORIA HISTORICA | E40: Contrato | F40: 44407 | G40: 44593 | H40: =+(G40-F40)/90 -> 2.0666667 | I40: Liquidado | J40: Sin Observaciones | K40: OCCIDENTE | L40: Cuenta de ahorros | M40: 230-85893- 8 | N40: 567 53 | O40: 2910906753 | P40: =+_xlfn.XLOOKUP(O40,'[3]Benef Primera fecha '!$C:$C,'[3]Benef Primera fecha '!$E:$E,0) -> 737502714 | Q40: 0 | R40: =+(P40+Q40) -> 737502714 | S40: 0.12 | T40: =(R40/(1+S40))*S40 -> 79018148 | U40: 737502714 | V40: 0 | W40: =+V40/(1+$S40)*$S40 -> 0 | X40: =+W40*40% -> 0 | Y40: =+W40*60% -> 0 | Z40: =_xlfn.XLOOKUP(O40,'[4]2DO TRIMESTRE'!$C:$C,'[4]2DO TRIMESTRE'!$I:$I,0,0) -> 0 | AA40: =+Z40/(1+$S40)*$S40 -> 0 | AB40: =+AA40*40% -> 0 | AC40: =+AA40*60% -> 0 | AD40: 0 | AE40: =+AD40/(1+$S40)*$S40 -> 0 | AF40: =+AE40*40% -> 0 | AG40: =+AE40*60% -> 0 | AH40: 0 | AI40: =+AH40/(1+$S40)*$S40 -> 0 | AJ40: =+AI40*40% -> 0 | AK40: =+AI40*60% -> 0 | AL40: 79018148 | AM40: =W40+AA40+AE40+AI40 -> 0
A41: 35 | B41: 2021 | C41: CAJA DE COMPENSACIÓN FAMILIAR - COMPENSAR | D41: 4500184175-CAJA DE COMPENSACIÓN FAMILIAR - COMPENSAR | E41: Contrato | F41: 44420 | G41: 44511 | H41: =+(G41-F41)/90 -> 1.0111111 | I41: Liquidado | J41: Sin Observaciones | K41: OCCIDENTE | L41: Cuenta de ahorros | M41: 230-85893- 8 | N41: 567 51 | O41: 2910906751 | P41: =+_xlfn.XLOOKUP(O41,'[3]Benef Primera fecha '!$C:$C,'[3]Benef Primera fecha '!$E:$E,0) -> 78690000 | Q41: 0 | R41: =+(P41+Q41) -> 78690000 | S41: 0.12 | T41: =(R41/(1+S41))*S41 -> 8431071.4 | U41: 78690000 | V41: 0 | W41: =+V41/(1+$S41)*$S41 -> 0 | X41: =+W41*40% -> 0 | Y41: =+W41*60% -> 0 | Z41: =_xlfn.XLOOKUP(O41,'[4]2DO TRIMESTRE'!$C:$C,'[4]2DO TRIMESTRE'!$I:$I,0,0) -> 0 | AA41: =+Z41/(1+$S41)*$S41 -> 0 | AB41: =+AA41*40% -> 0 | AC41: =+AA41*60% -> 0 | AD41: 0 | AE41: =+AD41/(1+$S41)*$S41 -> 0 | AF41: =+AE41*40% -> 0 | AG41: =+AE41*60% -> 0 | AH41: 0 | AI41: =+AH41/(1+$S41)*$S41 -> 0 | AJ41: =+AI41*40% -> 0 | AK41: =+AI41*60% -> 0 | AL41: 8431071 | AM41: =W41+AA41+AE41+AI41 -> 0
...

Sheet ILUD
E1: FORMATO LIQUIDACIÓN BENEFICIO INSTITUCIONAL | J1: Código: GRF-FR-041
E2: Macroproceso: Gestión de Recursos | J2: Versión: 01
E3: Proceso: Gestión de Recursos Financieros | J3: Fecha de Aprobación: 2025/07/02
A5: BENEFICIO INSTITUCIONAL DEL 01 DE ABRIL AL 30 DE JUNIO DEL 2026 | R5: 1 TRIMESTRE | V5: 2 TRIMESTRE | Z5: 3 TRIMESTRE | AD5: 4 TRIMESTRE
