Workbook
Name IPC: #REF!
Name IPC: #REF!
Name IPC: #REF!
Name IPC: #REF!
Name IPC: #REF!

Sheet EJECUCIÓN
C2: INFORME DE EJECUCIÓN MENSUAL DE GASTOS E INVERSIÓN
C3: UNIVERSIDAD DISTRITAL FRANCISCO JOSÉ DE CALDAS
C4: AGOSTO 2026
F8: =+F13-F9 -> 0 | G8: =+G13-G9 -> 0 | H8: =+H13-H9 -> 0 | I8: =+I13-I9 -> 0 | J8: =+J13-J9 -> 0 | K8: =+K13-K9 -> 0 | L8: =+L13-L9 -> 0 | M8: =+M13-M9 -> 0 | ... O8: =+O13-O9 -> 0
F9: 548567755000 | G9: 14194792521 | H9: 119748855067 | I9: 668316610067 | J9: 37765169384 | K9: 443925954879 | L9: 59277792200 | M9: 411524952140 | N9: 34399054883 | O9: 316933439339
C10: RUBRO PRESUPUESTAL | J10: DISPONIBILIDADES | L10: COMPROMISOS | N10: GIROS | P10: % DE EJECUCIÓN
A11: POSPRE | B11: CÓDIGO SICAPITAL | C11: CÓDIGO | D11: CENTRO DE COSTOS | E11: NOMBRE | F11: PRESUPUESTO INICIAL 2026 RES CSU 024-2025 | G11: MODIFICACIONES | I11: VIGENTE | J11: MES | K11: ACUMULADO | L11: MES | M11: ACUMULADO | N11: MES | O11: ACUMULADO
G12: MES | H12: ACUMULADO
B13: 3 | E13: GASTOS | F13: =+F14+F877 -> 548567755000 | G13: =+G14+G877 -> 14194792521 | H13: =+H14+H877 -> 119748855067 | I13: =+I14+I877 -> 668316610067 | J13: =+J14+J877 -> 37765169384 | K13: =+K14+K877 -> 443925954879 | L13: =+L14+L877 -> 59277792200 | M13: =+M14+M877 -> 411524952140 | ... O13: =+O14+O877 -> 316933439339 | P13: =IFERROR((M13/I13),0) -> 0.61576347
A14: O21 | B14: 3-01 | C14: 2.1 | E14: Funcionamiento | F14: =+F15+F350+F840+F858+F864 -> 505039654000 | G14: =+G15+G350+G840+G858+G864 -> 12533518796 | H14: =+H15+H350+H840+H858+H864 -> 108948092774 | I14: =+I15+I350+I840+I858+I864 -> 613987746774 | J14: =+J15+J350+J840+J858+J864 -> 30729102067 | K14: =+K15+K350+K840+K858+K864 -> 423175367995 | L14: =+L15+L350+L840+L858+L864 -> 55845987005 | M14: =+M15+M350+M840+M858+M864 -> 397629315710 | ... O14: =+O15+O350+O840+O858+O864 -> 308766636586 | P14: =IFERROR((M14/I14),0) -> 0.64761767
A15: O211 | B15: 3-01-001 | C15: 2.1.1 | E15: Gastos de personal | F15: =+F16+F135 -> 339732327000 | G15: =+G16+G135 -> 100199760 | H15: =+H16+H135 -> 9670653489 | I15: =+I16+I135 -> 349402980489 | J15: =+J16+J135 -> 15102353662 | K15: =+K16+K135 -> 236417976510 | L15: =+L16+L135 -> 24845761871 | M15: =+M16+M135 -> 221684160977 | ... O15: =+O16+O135 -> 181789079665 | P15: =IFERROR((M15/I15),0) -> 0.63446557
A16: O21101 | B16: 3-01-001-01 | C16: 2.1.1.01 | E16: Planta de personal permanente | F16: =+F17+F61+F100 -> 253420178000 | G16: =+G17+G61+G100 -> 0 | H16: =+H17+H61+H100 -> -3558522635 | I16: =+I17+I61+I100 -> 249861655365 | J16: =+J17+J61+J100 -> 14056853662 | K16: =+K17+K61+K100 -> 138296753791 | L16: =+L17+L61+L100 -> 14361667706 | M16: =+M17+M61+M100 -> 137856783596 | ... O16: =+O17+O61+O100 -> 132784407292 | P16: =IFERROR((M16/I16),0) -> 0.55173245
A17: O2110101 | B17: 3-01-001-01-01 | C17: 2.1.1.01.01 | E17: Factores constitutivos de salario | F17: =+F18+F56+F52 -> 183865598000 | G17: =+G18+G56+G52 -> 0 | H17: =+H18+H56+H52 -> -1834185350 | I17: =+I18+I56+I52 -> 182031412650 | J17: =+J18+J56+J52 -> 11012166320 | K17: =+K18+K56+K52 -> 96431716152 | L17: =+L18+L56+L52 -> 11108317798 | M17: =+M18+M56+M52 -> 96153501032 | ... O17: =+O18+O56+O52 -> 96102235345 | P17: =IFERROR((M17/I17),0) -> 0.52822477
A18: O2110101001 | C18: 2.1.1.01.01.001 | F18: =+F19+F24+F27+F30+F33+F36+F40+F49 -> 170051047000 | G18: =+G19+G24+G27+G30+G33+G36+G40+G49 -> 0 | H18: =+H19+H24+H27+H30+H33+H36+H40+H49 -> -882993704 | I18: =+I19+I24+I27+I30+I33+I36+I40+I49 -> 169168053296 | J18: =+J19+J24+J27+J30+J33+J36+J40+J49 -> 10928069092 | K18: =+K19+K24+K27+K30+K33+K36+K40+K49 -> 85139230520 | L18: =+L19+L24+L27+L30+L33+L36+L40+L49 -> 11014774851 | M18: =+M19+M24+M27+M30+M33+M36+M40+M49 -> 84913790848 | ... O18: =+O19+O24+O27+O30+O33+O36+O40+O49 -> 84874336780 | P18: =IFERROR((M18/I18),0) -> 0.50194933
A19: O211010100101 | B19: 3-01-001-01-01-11 | C19: 2.1.1.01.01.001.01 | E19: Sueldo básico | F19: =+F20 -> 137847199000 | G19: =+G20 -> 0 | H19: =+H20 -> -882993704 | I19: =+I20 -> 136964205296 | J19: =+J20 -> 9973723386 | K19: =+K20 -> 79163609530 | L19: =+L20 -> 10009017915 | M19: =+M20 -> 79046667804 | ... O19: =+O20 -> 79022119760 | P19: =IFERROR((M19/I19),0) -> 0.57713377
B20: 3-01-001-01-01-11 | C20: 2.1.1.01.01.001.01 | E20: Sueldo Básico | F20: =SUM(F21:F23) -> 137847199000 | G20: =SUM(G21:G23) -> 0 | H20: =SUM(H21:H23) -> -882993704 | I20: =SUM(I21:I23) -> 136964205296 | J20: =SUM(J21:J23) -> 9973723386 | K20: =SUM(K21:K23) -> 79163609530 | L20: =SUM(L21:L23) -> 10009017915 | M20: =SUM(M21:M23) -> 79046667804 | ... O20: =SUM(O21:O23) -> 79022119760 | P20: =IFERROR((M20/I20),0) -> 0.57713377
B21: 3-01-001-01-01-11-0001-00 | C21: 2.1.1.01.01.001.01.1 | D21: A9902 | E21: Sueldo Básico Administrativos | F21: 17229718000 | G21: 0 | H21: 0 | I21: 17229718000 | J21: 1254694045 | K21: 10032071169 | L21: 1260814251 | M21: 9976421376 | N21: 1262337512 | O21: 9970301170 | P21: =IFERROR((M21/I21),0) -> 0.57902407
B22: 3-01-001-01-01-11-0002-00 | C22: 2.1.1.01.01.001.01.2 | D22: A9901 | E22: Sueldo Básico Docentes | F22: 119040611000 | G22: 0 | H22: -882993704 | I22: 118157617296 | J22: 8612498726 | K22: 68133103310 | L22: 8626482424 | M22: 68071811377 | N22: 8626482424 | O22: 68053383539 | P22: =IFERROR((M22/I22),0) -> 0.57611022
B23: 3-01-001-01-01-11-0003-00 | C23: 2.1.1.01.01.001.01.3 | D23: A9903 | E23: Sueldo Trabajadores Oficiales | F23: 1576870000 | G23: 0 | H23: 0 | I23: 1576870000 | J23: 106530615 | K23: 998435051 | L23: 121721240 | M23: 998435051 | N23: 121721240 | O23: 998435051 | P23: =IFERROR((M23/I23),0) -> 0.63317525
A24: O211010100102 | B24: 3-01-001-01-01-12 | C24: 2.1.1.01.01.001.02 | E24: Horas extras, dominicales, festivos y recargos | F24: =+F25 -> 232386000 | G24: =+G25 -> 0 | H24: =+H25 -> 0 | I24: =+I25 -> 232386000 | J24: =+J25 -> 13695907 | K24: =+K25 -> 110111232 | L24: =+L25 -> 13695907 | M24: =+M25 -> 110111232 | ... O24: =+O25 -> 110111232 | P24: =IFERROR((M24/I24),0) -> 0.47382903
A25: O211010100102 | B25: 3-01-001-01-01-12 | C25: 2.1.1.01.01.001.02 | E25: Horas extras, dominicales, festivos y recargos | F25: =+F26 -> 232386000 | G25: =+G26 -> 0 | H25: =+H26 -> 0 | I25: =+I26 -> 232386000 | J25: =+J26 -> 13695907 | K25: =+K26 -> 110111232 | L25: =+L26 -> 13695907 | M25: =+M26 -> 110111232 | ... O25: =+O26 -> 110111232 | P25: =IFERROR((M25/I25),0) -> 0.47382903
B26: 3-01-001-01-01-12-0001-00 | C26: 2.1.1.01.01.001.02.1 | D26: A9902 | E26: Horas Extras, Dominicales, Festivos, Administrativos | F26: 232386000 | G26: 0 | H26: 0 | I26: 232386000 | J26: 13695907 | K26: 110111232 | L26: 13695907 | M26: 110111232 | N26: 13695907 | O26: 110111232 | P26: =IFERROR((M26/I26),0) -> 0.47382903
A27: O211010100103 | B27: 3-01-001-01-01-13 | C27: 2.1.1.01.01.001.03 | E27: Gastos de representación | F27: =+F28 -> 879556000 | G27: =+G28 -> 0 | H27: =+H28 -> 0 | I27: =+I28 -> 879556000 | J27: =+J28 -> 68936516 | K27: =+K28 -> 540508571 | L27: =+L28 -> 68936516 | M27: =+M28 -> 540508571 | ... O27: =+O28 -> 540508571 | P27: =IFERROR((M27/I27),0) -> 0.61452434
A28: O211010100103 | B28: 3-01-001-01-01-13 | C28: 2.1.1.01.01.001.03 | E28: Gastos de representación | F28: =+F29 -> 879556000 | G28: =+G29 -> 0 | H28: =+H29 -> 0 | I28: =+I29 -> 879556000 | J28: =+J29 -> 68936516 | K28: =+K29 -> 540508571 | L28: =+L29 -> 68936516 | M28: =+M29 -> 540508571 | ... O28: =+O29 -> 540508571 | P28: =IFERROR((M28/I28),0) -> 0.61452434
B29: 3-01-001-01-01-13-0001-00 | C29: 2.1.1.01.01.001.03.1 | D29: A9902 | E29: Gastos de Representación Administrativos | F29: 879556000 | G29: 0 | H29: 0 | I29: 879556000 | J29: 68936516 | K29: 540508571 | L29: 68936516 | M29: 540508571 | N29: 68936516 | O29: 540508571 | P29: =IFERROR((M29/I29),0) -> 0.61452434
A30: O211010100104 | B30: 3-01-001-01-01-14 | C30: 2.1.1.01.01.001.04 | E30: Subsidio de alimentación | F30: =+F31 -> 89520000 | G30: =+G31 -> 0 | H30: =+H31 -> 0 | I30: =+I31 -> 89520000 | J30: =+J31 -> 6554973 | K30: =+K31 -> 57670022 | L30: =+L31 -> 6554973 | M30: =+M31 -> 57670022 | ... O30: =+O31 -> 57670022 | P30: =IFERROR((M30/I30),0) -> 0.64421383
A31: O211010100104 | B31: 3-01-001-01-01-14 | C31: 2.1.1.01.01.001.04 | E31: Subsidio de alimentación | F31: =+F32 -> 89520000 | G31: =+G32 -> 0 | H31: =+H32 -> 0 | I31: =+I32 -> 89520000 | J31: =+J32 -> 6554973 | K31: =+K32 -> 57670022 | L31: =+L32 -> 6554973 | M31: =+M32 -> 57670022 | ... O31: =+O32 -> 57670022 | P31: =IFERROR((M31/I31),0) -> 0.64421383
A32: O211010100104 | B32: 3-01-001-01-01-14-0000-00 | C32: 2.1.1.01.01.001.04 | D32: A9903 | E32: Subsidio de alimentación | F32: 89520000 | G32: 0 | H32: 0 | I32: 89520000 | J32: 6554973 | K32: 57670022 | L32: 6554973 | M32: 57670022 | N32: 6554973 | O32: 57670022 | P32: =IFERROR((M32/I32),0) -> 0.64421383
A33: O211010100105 | B33: 3-01-001-01-01-15 | C33: 2.1.1.01.01.001.05 | E33: Auxilio de transporte | F33: =+F34 -> 92533000 | G33: =+G34 -> 0 | H33: =+H34 -> 0 | I33: =+I34 -> 92533000 | J33: =+J34 -> 6050899 | K33: =+K34 -> 53235236 | L33: =+L34 -> 6050899 | M33: =+M34 -> 53235236 | ... O33: =+O34 -> 53235236 | P33: =IFERROR((M33/I33),0) -> 0.57531082
A34: O211010100105 | B34: 3-01-001-01-01-15 | C34: 2.1.1.01.01.001.05 | E34: Auxilio de transporte | F34: =+F35 -> 92533000 | G34: =+G35 -> 0 | H34: =+H35 -> 0 | I34: =+I35 -> 92533000 | J34: =+J35 -> 6050899 | K34: =+K35 -> 53235236 | L34: =+L35 -> 6050899 | M34: =+M35 -> 53235236 | ... O34: =+O35 -> 53235236 | P34: =IFERROR((M34/I34),0) -> 0.57531082
A35: O211010100105 | B35: 3-01-001-01-01-15-0000-00 | C35: 2.1.1.01.01.001.05 | D35: A9903 | E35: Auxilio de transporte | F35: 92533000 | G35: 0 | H35: 0 | I35: 92533000 | J35: 6050899 | K35: 53235236 | L35: 6050899 | M35: 53235236 | N35: 6050899 | O35: 53235236 | P35: =IFERROR((M35/I35),0) -> 0.57531082
A36: O211010100107 | B36: 3-01-001-01-01-17 | C36: 2.1.1.01.01.001.07 | E36: Bonificación por servicios prestados | F36: =+F37 -> 4044818000 | G36: =+G37 -> 0 | H36: =+H37 -> 0 | I36: =+I37 -> 4044818000 | J36: =+J37 -> 521204267 | K36: =+K37 -> 2397348052 | L36: =+L37 -> 523352825 | M36: =+M37 -> 2385667678 | ... O36: =+O37 -> 2383519120 | P36: =IFERROR((M36/I36),0) -> 0.58980841
A37: O211010100107 | B37: 3-01-001-01-01-17 | C37: 2.1.1.01.01.001.07 | E37: Bonificación por servicios prestados | F37: =SUM(F38:F39) -> 4044818000 | G37: =SUM(G38:G39) -> 0 | H37: =SUM(H38:H39) -> 0 | I37: =SUM(I38:I39) -> 4044818000 | J37: =SUM(J38:J39) -> 521204267 | K37: =SUM(K38:K39) -> 2397348052 | L37: =SUM(L38:L39) -> 523352825 | M37: =SUM(M38:M39) -> 2385667678 | ... O37: =SUM(O38:O39) -> 2383519120 | P37: =IFERROR((M37/I37),0) -> 0.58980841
B38: 3-01-001-01-01-17-0001-00 | C38: 2.1.1.01.01.001.07.1 | D38: A9902 | E38: Bonificación por Servicios Prestados Administrativos | F38: 572800000 | G38: 0 | H38: 0 | I38: 572800000 | J38: 13717222 | K38: 367856662 | L38: 15865780 | M38: 361243215 | N38: 15298562 | O38: 359094657 | P38: =IFERROR((M38/I38),0) -> 0.63066204
B39: 3-01-001-01-01-17-0002-00 | C39: 2.1.1.01.01.001.07.2 | D39: A9901 | E39: Bonificación por Servicios Prestados Docentes | F39: 3472018000 | G39: 0 | H39: 0 | I39: 3472018000 | J39: 507487045 | K39: 2029491390 | L39: 507487045 | M39: 2024424463 | N39: 507487045 | O39: 2024424463 | P39: =IFERROR((M39/I39),0) -> 0.58306854
A40: O211010100108 | B40: 3-01-001-01-01-18 | C40: 2.1.1.01.01.001.08 | E40: Prestaciones sociales | F40: =+F41+F45 -> 22992436000 | G40: =+G41+G45 -> 0 | H40: =+H41+H45 -> 0 | I40: =+I41+I45 -> 22992436000 | J40: =+J41+J45 -> 23942177 | K40: =+K41+K45 -> 390355453 | L40: =+L41+L45 -> 73204849 | M40: =+M41+M45 -> 293537881 | ... O40: =+O41+O45 -> 280780415 | P40: =IFERROR((M40/I40),0) -> 0.012766715
A41: O21101010010801 | B41: 3-01-001-01-01-18-0001 | C41: 2.1.1.01.01.001.08.01 | E41: Prima de navidad | F41: =SUM(F42:F44) -> 14300185000 | G41: =SUM(G42:G44) -> 0 | H41: =SUM(H42:H44) -> 0 | I41: =SUM(I42:I44) -> 14300185000 | J41: =SUM(J42:J44) -> 0 | K41: =SUM(K42:K44) -> 119171591 | L41: =SUM(L42:L44) -> 25898987 | M41: =SUM(M42:M44) -> 81636831 | ... O41: =SUM(O42:O44) -> 79143364 | P41: =IFERROR((M41/I41),0) -> 0.0057087954
B42: 3-01-001-01-01-18-0001-01 | C42: 2.1.1.01.01.001.08.01.1 | D42: A9902 | E42: Prima de Navidad Administrativos | F42: 2287604000 | G42: 0 | H42: 0 | I42: 2287604000 | J42: 0 | K42: 10705113 | L42: 889473 | M42: 10705113 | N42: 0 | O42: 9815640 | P42: =IFERROR((M42/I42),0) -> 0.0046796181
B43: 3-01-001-01-01-18-0001-02 | C43: 2.1.1.01.01.001.08.01.2 | D43: A9901 | E43: Prima de Navidad Docentes | F43: 11659997000 | G43: 0 | H43: 0 | I43: 11659997000 | J43: 0 | K43: 99081875 | L43: 15624911 | M43: 61547115 | N43: 15624911 | O43: 59943121 | P43: =IFERROR((M43/I43),0) -> 0.0052784846
B44: 3-01-001-01-01-18-0001-03 | C44: 2.1.1.01.01.001.08.01.3 | D44: A9903 | E44: Prima de Navidad Trabajadores Oficiales | F44: 352584000 | G44: 0 | H44: 0 | I44: 352584000 | J44: 0 | K44: 9384603 | L44: 9384603 | M44: 9384603 | N44: 9384603 | O44: 9384603 | P44: =IFERROR((M44/I44),0) -> 0.026616645
...

Sheet FONDO COMÚN
C2: INFORME DE EJECUCIÓN MENSUAL DE GASTOS E INVERSIÓN- FONDO COMÚN
C3: UNIVERSIDAD DISTRITAL FRANCISCO JOSÉ DE CALDAS
C4: AGOSTO 2026
F8: =+F9-F13 -> 0 | G8: =+G9-G13 -> 0 | H8: =+H9-H13 -> 0 | I8: =+I9-I13 -> 0 | J8: =+J9-J13 -> 0 | K8: =+K9-K13 -> 0 | L8: =+L9-L13 -> 0 | M8: =+M9-M13 -> 0 | ... O8: =+O9-O13 -> 0
F9: 505039654000 | G9: 12533518796 | H9: 108948092774 | I9: 613987746774 | J9: 30729102067 | K9: 423175367995 | L9: 55845987005 | M9: 397629315710 | N9: 33348072457 | O9: 308766636586
C10: RUBRO PRESUPUESTAL | F10: APROPIACION | J10: DISPONIBILIDADES | L10: COMPROMISOS | N10: AUTORIZACION DE GIRO | P10: % DE EJECUCIÓN
A11: POSPRE | B11: CÓDIGO SICAPITAL | C11: CÓDIGO | D11: CENTRO DE COSTOS | E11: NOMBRE | F11: PRESUPUESTO INICIAL 2026 RES CSU 024-2025 | G11: MODIFICACIONES | I11: VIGENTE | J11: MES | K11: ACUMULADO | L11: MES | M11: ACUMULADO | N11: MES | O11: ACUMULADO
G12: MES | H12: ACUMULADO
A13: O21 | B13: 3-01 | C13: 2.1 | E13: Funcionamiento | F13: =+F14+F349+F839+F857+F863 -> 505039654000 | G13: =+G14+G349+G839+G857+G863 -> 12533518796 | H13: =+H14+H349+H839+H857+H863 -> 108948092774 | I13: =+I14+I349+I839+I857+I863 -> 613987746774 | J13: =+J14+J349+J839+J857+J863 -> 30729102067 | K13: =+K14+K349+K839+K857+K863 -> 423175367995 | L13: =+L14+L349+L839+L857+L863 -> 55845987005 | M13: =+M14+M349+M839+M857+M863 -> 397629315710 | ... O13: =+O14+O349+O839+O857+O863 -> 308766636586 | P13: =IFERROR((M13/I13),0) -> 0.64761767
A14: O211 | B14: 3-01-001 | C14: 2.1.1 | E14: Gastos de personal | F14: =+F15+F134 -> 339732327000 | G14: =+G15+G134 -> 100199760 | H14: =+H15+H134 -> 9670653489 | I14: =+I15+I134 -> 349402980489 | J14: =+J15+J134 -> 15102353662 | K14: =+K15+K134 -> 236417976510 | L14: =+L15+L134 -> 24845761871 | M14: =+M15+M134 -> 221684160977 | ... O14: =+O15+O134 -> 181789079665 | P14: 0.23740675
A15: O21101 | B15: 3-01-001-01 | C15: 2.1.1.01 | E15: Planta de personal permanente | F15: =+F16+F60+F99 -> 253420178000 | G15: =+G16+G60+G99 -> 0 | H15: =+H16+H60+H99 -> -3558522635 | I15: =+I16+I60+I99 -> 249861655365 | J15: =+J16+J60+J99 -> 14056853662 | K15: =+K16+K60+K99 -> 138296753791 | L15: =+L16+L60+L99 -> 14361667706 | M15: =+M16+M60+M99 -> 137856783596 | ... O15: =+O16+O60+O99 -> 132784407292 | P15: 0.23740675
A16: O2110101 | B16: 3-01-001-01-01 | C16: 2.1.1.01.01 | E16: Factores constitutivos de salario | F16: =+F17+F51 -> 183865598000 | G16: =+G17+G51 -> 0 | H16: =+H17+H51 -> -1834185350 | I16: =+I17+I51 -> 182031412650 | J16: =+J17+J51 -> 11012166320 | K16: =+K17+K51 -> 96431716152 | L16: =+L17+L51 -> 11108317798 | M16: =+M17+M51 -> 96153501032 | ... O16: =+O17+O51 -> 96102235345 | P16: 0.23740675
A17: O2110101001 | C17: 2.1.1.01.01.001 | E17: Factores salariales comunes | F17: =+F18+F23+F26+F29+F32+F35+F39+F48 -> 170051047000 | G17: =+G18+G23+G26+G29+G32+G35+G39+G48 -> 0 | H17: =+H18+H23+H26+H29+H32+H35+H39+H48 -> -882993704 | I17: =+I18+I23+I26+I29+I32+I35+I39+I48 -> 169168053296 | J17: =+J18+J23+J26+J29+J32+J35+J39+J48 -> 10928069092 | K17: =+K18+K23+K26+K29+K32+K35+K39+K48 -> 85139230520 | L17: =+L18+L23+L26+L29+L32+L35+L39+L48 -> 11014774851 | M17: =+M18+M23+M26+M29+M32+M35+M39+M48 -> 84913790848 | ... O17: =+O18+O23+O26+O29+O32+O35+O39+O48 -> 84874336780 | P17: 0.23740675
A18: O211010100101 | B18: 3-01-001-01-01-11 | C18: 2.1.1.01.01.001.01 | E18: Sueldo básico | F18: =+F19 -> 137847199000 | G18: =+G19 -> 0 | H18: =+H19 -> -882993704 | I18: =+I19 -> 136964205296 | J18: =+J19 -> 9973723386 | K18: =+K19 -> 79163609530 | L18: =+L19 -> 10009017915 | M18: =+M19 -> 79046667804 | ... O18: =+O19 -> 79022119760 | P18: 0.23740675
B19: 3-01-001-01-01-11 | C19: 2.1.1.01.01.001.01 | E19: Sueldo Básico | F19: =SUM(F20:F22) -> 137847199000 | G19: =SUM(G20:G22) -> 0 | H19: =SUM(H20:H22) -> -882993704 | I19: =SUM(I20:I22) -> 136964205296 | J19: =SUM(J20:J22) -> 9973723386 | K19: =SUM(K20:K22) -> 79163609530 | L19: =SUM(L20:L22) -> 10009017915 | M19: =SUM(M20:M22) -> 79046667804 | ... O19: =SUM(O20:O22) -> 79022119760 | P19: 0.23740675
B20: 3-01-001-01-01-11-0001-00 | C20: 2.1.1.01.01.001.01.1 | D20: A9902 | E20: Sueldo Básico Administrativos | F20: 17229718000 | G20: 0 | H20: 0 | I20: 17229718000 | J20: 1254694045 | K20: 10032071169 | L20: 1260814251 | M20: 9976421376 | N20: 1262337512 | O20: 9970301170 | P20: 0.23740675
B21: 3-01-001-01-01-11-0002-00 | C21: 2.1.1.01.01.001.01.2 | D21: A9901 | E21: Sueldo Básico Docentes | F21: 119040611000 | G21: 0 | H21: -882993704 | I21: 118157617296 | J21: 8612498726 | K21: 68133103310 | L21: 8626482424 | M21: 68071811377 | N21: 8626482424 | O21: 68053383539 | P21: 0.23740675
B22: 3-01-001-01-01-11-0003-00 | C22: 2.1.1.01.01.001.01.3 | D22: A9903 | E22: Sueldo Trabajadores Oficiales | F22: 1576870000 | G22: 0 | H22: 0 | I22: 1576870000 | J22: 106530615 | K22: 998435051 | L22: 121721240 | M22: 998435051 | N22: 121721240 | O22: 998435051 | P22: 0.23740675
A23: O211010100102 | B23: 3-01-001-01-01-12 | C23: 2.1.1.01.01.001.02 | E23: Horas extras, dominicales, festivos y recargos | F23: =+F24 -> 232386000 | G23: =+G24 -> 0 | H23: =+H24 -> 0 | I23: =+I24 -> 232386000 | J23: =+J24 -> 13695907 | K23: =+K24 -> 110111232 | L23: =+L24 -> 13695907 | M23: =+M24 -> 110111232 | ... O23: =+O24 -> 110111232 | P23: 0.23740675
A24: O211010100102 | B24: 3-01-001-01-01-12 | C24: 2.1.1.01.01.001.02 | E24: Horas extras, dominicales, festivos y recargos | F24: =+F25 -> 232386000 | G24: =+G25 -> 0 | H24: =+H25 -> 0 | I24: =+I25 -> 232386000 | J24: =+J25 -> 13695907 | K24: =+K25 -> 110111232 | L24: =+L25 -> 13695907 | M24: =+M25 -> 110111232 | ... O24: =+O25 -> 110111232 | P24: 0.23740675
B25: 3-01-001-01-01-12-0001-00 | C25: 2.1.1.01.01.001.02.1 | D25: A9902 | E25: Horas Extras, Dominicales, Festivos, Administrativos | F25: 232386000 | G25: 0 | H25: 0 | I25: 232386000 | J25: 13695907 | K25: 110111232 | L25: 13695907 | M25: 110111232 | N25: 13695907 | O25: 110111232 | P25: 0.23740675
A26: O211010100103 | B26: 3-01-001-01-01-13 | C26: 2.1.1.01.01.001.03 | E26: Gastos de representación | F26: =+F27 -> 879556000 | G26: =+G27 -> 0 | H26: =+H27 -> 0 | I26: =+I27 -> 879556000 | J26: =+J27 -> 68936516 | K26: =+K27 -> 540508571 | L26: =+L27 -> 68936516 | M26: =+M27 -> 540508571 | ... O26: =+O27 -> 540508571 | P26: 0.23740675
A27: O211010100103 | B27: 3-01-001-01-01-13 | C27: 2.1.1.01.01.001.03 | E27: Gastos de representación | F27: =+F28 -> 879556000 | G27: =+G28 -> 0 | H27: =+H28 -> 0 | I27: =+I28 -> 879556000 | J27: =+J28 -> 68936516 | K27: =+K28 -> 540508571 | L27: =+L28 -> 68936516 | M27: =+M28 -> 540508571 | ... O27: =+O28 -> 540508571 | P27: 0.23740675
B28: 3-01-001-01-01-13-0001-00 | C28: 2.1.1.01.01.001.03.1 | D28: A9902 | E28: Gastos de Representación Administrativos | F28: 879556000 | G28: 0 | H28: 0 | I28: 879556000 | J28: 68936516 | K28: 540508571 | L28: 68936516 | M28: 540508571 | N28: 68936516 | O28: 540508571 | P28: 0.23740675
A29: O211010100104 | B29: 3-01-001-01-01-14 | C29: 2.1.1.01.01.001.04 | E29: Subsidio de alimentación | F29: =+F30 -> 89520000 | G29: =+G30 -> 0 | H29: =+H30 -> 0 | I29: =+I30 -> 89520000 | J29: =+J30 -> 6554973 | K29: =+K30 -> 57670022 | L29: =+L30 -> 6554973 | M29: =+M30 -> 57670022 | ... O29: =+O30 -> 57670022 | P29: 0.23740675
A30: O211010100104 | B30: 3-01-001-01-01-14 | C30: 2.1.1.01.01.001.04 | E30: Subsidio de alimentación | F30: =+F31 -> 89520000 | G30: =+G31 -> 0 | H30: =+H31 -> 0 | I30: =+I31 -> 89520000 | J30: =+J31 -> 6554973 | K30: =+K31 -> 57670022 | L30: =+L31 -> 6554973 | M30: =+M31 -> 57670022 | ... O30: =+O31 -> 57670022 | P30: 0.23740675
A31: O211010100104 | B31: 3-01-001-01-01-14-0000-00 | C31: 2.1.1.01.01.001.04 | D31: A9903 | E31: Subsidio de alimentación | F31: 89520000 | G31: 0 | H31: 0 | I31: 89520000 | J31: 6554973 | K31: 57670022 | L31: 6554973 | M31: 57670022 | N31: 6554973 | O31: 57670022 | P31: 0.23740675
A32: O211010100105 | B32: 3-01-001-01-01-15 | C32: 2.1.1.01.01.001.05 | E32: Auxilio de transporte | F32: =+F33 -> 92533000 | G32: =+G33 -> 0 | H32: =+H33 -> 0 | I32: =+I33 -> 92533000 | J32: =+J33 -> 6050899 | K32: =+K33 -> 53235236 | L32: =+L33 -> 6050899 | M32: =+M33 -> 53235236 | ... O32: =+O33 -> 53235236 | P32: 0.23740675
A33: O211010100105 | B33: 3-01-001-01-01-15 | C33: 2.1.1.01.01.001.05 | E33: Auxilio de transporte | F33: =+F34 -> 92533000 | G33: =+G34 -> 0 | H33: =+H34 -> 0 | I33: =+I34 -> 92533000 | J33: =+J34 -> 6050899 | K33: =+K34 -> 53235236 | L33: =+L34 -> 6050899 | M33: =+M34 -> 53235236 | ... O33: =+O34 -> 53235236 | P33: 0.23740675
A34: O211010100105 | B34: 3-01-001-01-01-15-0000-00 | C34: 2.1.1.01.01.001.05 | D34: A9903 | E34: Auxilio de transporte | F34: 92533000 | G34: 0 | H34: 0 | I34: 92533000 | J34: 6050899 | K34: 53235236 | L34: 6050899 | M34: 53235236 | N34: 6050899 | O34: 53235236 | P34: 0.23740675
A35: O211010100107 | B35: 3-01-001-01-01-17 | C35: 2.1.1.01.01.001.07 | E35: Bonificación por servicios prestados | F35: =+F36 -> 4044818000 | G35: =+G36 -> 0 | H35: =+H36 -> 0 | I35: =+I36 -> 4044818000 | J35: =+J36 -> 521204267 | K35: =+K36 -> 2397348052 | L35: =+L36 -> 523352825 | M35: =+M36 -> 2385667678 | ... O35: =+O36 -> 2383519120 | P35: 0.23740675
A36: O211010100107 | B36: 3-01-001-01-01-17 | C36: 2.1.1.01.01.001.07 | E36: Bonificación por servicios prestados | F36: =SUM(F37:F38) -> 4044818000 | G36: =SUM(G37:G38) -> 0 | H36: =SUM(H37:H38) -> 0 | I36: =SUM(I37:I38) -> 4044818000 | J36: =SUM(J37:J38) -> 521204267 | K36: =SUM(K37:K38) -> 2397348052 | L36: =SUM(L37:L38) -> 523352825 | M36: =SUM(M37:M38) -> 2385667678 | ... O36: =SUM(O37:O38) -> 2383519120 | P36: 0.23740675
B37: 3-01-001-01-01-17-0001-00 | C37: 2.1.1.01.01.001.07.1 | D37: A9902 | E37: Bonificación por Servicios Prestados Administrativos | F37: 572800000 | G37: 0 | H37: 0 | I37: 572800000 | J37: 13717222 | K37: 367856662 | L37: 15865780 | M37: 361243215 | N37: 15298562 | O37: 359094657 | P37: 0.23740675
B38: 3-01-001-01-01-17-0002-00 | C38: 2.1.1.01.01.001.07.2 | D38: A9901 | E38: Bonificación por Servicios Prestados Docentes | F38: 3472018000 | G38: 0 | H38: 0 | I38: 3472018000 | J38: 507487045 | K38: 2029491390 | L38: 507487045 | M38: 2024424463 | N38: 507487045 | O38: 2024424463 | P38: 0.23740675
A39: O211010100108 | B39: 3-01-001-01-01-18 | C39: 2.1.1.01.01.001.08 | E39: Prestaciones sociales | F39: =+F40+F44 -> 22992436000 | G39: =+G40+G44 -> 0 | H39: =+H40+H44 -> 0 | I39: =+I40+I44 -> 22992436000 | J39: =+J40+J44 -> 23942177 | K39: =+K40+K44 -> 390355453 | L39: =+L40+L44 -> 73204849 | M39: =+M40+M44 -> 293537881 | ... O39: =+O40+O44 -> 280780415 | P39: 0.23740675
A40: O21101010010801 | B40: 3-01-001-01-01-18-0001 | C40: 2.1.1.01.01.001.08.01 | E40: Prima de navidad | F40: =SUM(F41:F43) -> 14300185000 | G40: =SUM(G41:G43) -> 0 | H40: =SUM(H41:H43) -> 0 | I40: =SUM(I41:I43) -> 14300185000 | J40: =SUM(J41:J43) -> 0 | K40: =SUM(K41:K43) -> 119171591 | L40: =SUM(L41:L43) -> 25898987 | M40: =SUM(M41:M43) -> 81636831 | ... O40: =SUM(O41:O43) -> 79143364 | P40: 0.23740675
B41: 3-01-001-01-01-18-0001-01 | C41: 2.1.1.01.01.001.08.01.1 | D41: A9902 | E41: Prima de Navidad Administrativos | F41: 2287604000 | G41: 0 | H41: 0 | I41: 2287604000 | J41: 0 | K41: 10705113 | L41: 889473 | M41: 10705113 | N41: 0 | O41: 9815640 | P41: 0.23740675
B42: 3-01-001-01-01-18-0001-02 | C42: 2.1.1.01.01.001.08.01.2 | D42: A9901 | E42: Prima de Navidad Docentes | F42: 11659997000 | G42: 0 | H42: 0 | I42: 11659997000 | J42: 0 | K42: 99081875 | L42: 15624911 | M42: 61547115 | N42: 15624911 | O42: 59943121 | P42: 0.23740675
B43: 3-01-001-01-01-18-0001-03 | C43: 2.1.1.01.01.001.08.01.3 | D43: A9903 | E43: Prima de Navidad Trabajadores Oficiales | F43: 352584000 | G43: 0 | H43: 0 | I43: 352584000 | J43: 0 | K43: 9384603 | L43: 9384603 | M43: 9384603 | N43: 9384603 | O43: 9384603 | P43: 0.23740675
A44: O21101010010802 | B44: 3-01-001-01-01-18-0002 | C44: 2.1.1.01.01.001.08.02 | E44: Prima de vacaciones | F44: =SUM(F45:F47) -> 8692251000 | G44: =SUM(G45:G47) -> 0 | H44: =SUM(H45:H47) -> 0 | I44: =SUM(I45:I47) -> 8692251000 | J44: =SUM(J45:J47) -> 23942177 | K44: =SUM(K45:K47) -> 271183862 | L44: =SUM(L45:L47) -> 47305862 | M44: =SUM(M45:M47) -> 211901050 | ... O44: =SUM(O45:O47) -> 201637051 | P44: 0.23740675
...

Sheet FONDO INVERSIONES Y FORT. INST.
C2: INFORME DE EJECUCIÓN MENSUAL DE GASTOS E INVERSIÓN - FONDO DE INVERSIÓN Y FORTALECIMIENTO INSTITUCIONAL
C3: UNIVERSIDAD DISTRITAL FRANCISCO JOSÉ DE CALDAS
C4: AGOSTO 2026
F6: =+F11-F7 -> 0 | G6: =+G11-G7 -> 0 | H6: =+H11-H7 -> 0 | I6: =+I11-I7 -> 0 | J6: =+J11-J7 -> 0 | K6: =+K11-K7 -> 0 | L6: =+L11-L7 -> 0 | M6: =+M11-M7 -> 0 | ... O6: =+O11-O7 -> 0
F7: 43316311000 | G7: 1278780064 | H7: 10418268632 | I7: 53734579632 | J7: 7036067317 | K7: 20746386884 | L7: 3431805195 | M7: 13891436430 | N7: 1050982426 | O7: 8162602753
C8: RUBRO PRESUPUESTAL | F8: PRESUPUESTO INICIAL 2026 RES CSU 024-2025 | G8: APROPIACION | J8: DISPONIBILIDADES | L8: COMPROMISOS | N8: AUTORIZACION DE GIRO | P8: % DE EJECUCIÓN
A9: POSPRE | B9: CÓDIGO SICAPITAL | C9: CÓDIGO | D9: CENTRO DE COSTOS | E9: NOMBRE | G9: MODIFICACIONES | I9: VIGENTE | J9: MES | K9: ACUMULADO | L9: MES | M9: ACUMULADO | N9: MES | O9: ACUMULADO
G10: MES | H10: ACUMULADO
A11: O2301 | B11: 3-03-001 | C11: 2.3.01 | E11: DIRECTA | F11: =F12 -> 43316311000 | G11: =G12 -> 1278780064 | H11: =H12 -> 10418268632 | I11: =I12 -> 53734579632 | J11: =J12 -> 7036067317 | K11: =K12 -> 20746386884 | L11: =L12 -> 3431805195 | M11: =M12 -> 13891436430 | ... O11: =O12 -> 8162602753 | P11: =IFERROR((M11/I11),0) -> 0.2585195
A12: O230117 | B12: 3-03-001-17 | C12: 2.3.01.17 | E12: BOGOTÁ CAMINA SEGURA | F12: =+F13 -> 43316311000 | G12: =+G13 -> 1278780064 | H12: =+H13 -> 10418268632 | I12: =+I13 -> 53734579632 | J12: =+J13 -> 7036067317 | K12: =+K13 -> 20746386884 | L12: =+L13 -> 3431805195 | M12: =+M13 -> 13891436430 | ... O12: =+O13 -> 8162602753 | P12: =IFERROR((M12/I12),0) -> 0.2585195
A13: O23011722 | B13: 3-03-001-17-22 | C13: 2.3.01.17.22 | E13: Objetivo estratégico 03. Bogotá confía en su potencial | F13: =+F14 -> 43316311000 | G13: =+G14 -> 1278780064 | H13: =+H14 -> 10418268632 | I13: =+I14 -> 53734579632 | J13: =+J14 -> 7036067317 | K13: =+K14 -> 20746386884 | L13: =+L14 -> 3431805195 | M13: =+M14 -> 13891436430 | ... O13: =+O14 -> 8162602753 | P13: =IFERROR((M13/I13),0) -> 0.2585195
A14: O2301172202 | B14: 3-03-001-17-22-02-2024 | C14: 2.3.01.17.22.02 | E14: Programa 17. Formación para el trabajo y acceso a oportunidades educativas | F14: =SUM(F15:F23) -> 43316311000 | G14: =SUM(G15:G23) -> 1278780064 | H14: =SUM(H15:H23) -> 10418268632 | I14: =SUM(I15:I23) -> 53734579632 | J14: =SUM(J15:J23) -> 7036067317 | K14: =SUM(K15:K23) -> 20746386884 | L14: =SUM(L15:L23) -> 3431805195 | M14: =SUM(M15:M23) -> 13891436430 | ... O14: =SUM(O15:O23) -> 8162602753 | P14: =IFERROR((M14/I14),0) -> 0.2585195
A15: O230117220220240256 | B15: 3-03-001-17-22-02-2024-0256 | C15: 2.3.01.17.22.02.20240256 | D15: A1205 | E15: Desarrollo y modernización de los procesos relacionados con gestión institucional de la Universidad Distrital Francisco José De Caldas Bogotá D.C. | F15: 0 | G15: 0 | H15: 346985635 | I15: 346985635 | J15: 47909519 | K15: 47909519 | L15: 0 | M15: 47909519 | N15: 0 | O15: 47909519 | P15: =IFERROR((M15/I15),0) -> 0.13807349
A16: O230117220220240257 | B16: 3-03-001-17-22-02-2024-0257 | C16: 2.3.01.17.22.02.20240257 | D16: A1205 | E16: Ampliación y Mejoramiento de la infraestructura física de las Sedes de la Universidad Distrital Francisco José de Caldas. Bogotá D.C | F16: 16072252000 | G16: 0 | H16: 1398412287 | I16: 17470664287 | J16: 307668942 | K16: 868344475 | L16: 103765500 | M16: 448967244 | N16: 403943 | O16: 225632875 | P16: =IFERROR((M16/I16),0) -> 0.02569835
A17: O230117220220240261 | B17: 3-03-001-17-22-02-2024-0261 | C17: 2.3.01.17.22.02.20240261 | D17: A1205 | E17: Fortalecimiento de estrategias para disminuir la tasa de riesgo de deserción, promoción de la permanencia y bienestar de los estudiantes de pregrado de la Universidad Distrital Bogotá D.C | F17: 1762733000 | G17: 0 | H17: 0 | I17: 1762733000 | J17: 325196158 | K17: 1520165290 | L17: 24236588 | M17: 1219205720 | N17: 63524454 | O17: 1125034289 | P17: =IFERROR((M17/I17),0) -> 0.69165649
A18: O230117220220240279 | B18: 3-03-001-17-22-02-2024-0279 | C18: 2.3.01.17.22.02.20240279 | D18: A1205 | E18: Fortalecimiento de las capacidades del sistema de investigaciones frente a los retos de CTEI a nivel regional, nacional e internacional en la UDFJC. Bogotá D.C. | F18: 6466642400 | G18: 0 | H18: 0 | I18: 6466642000 | J18: 1573331127 | K18: 4484328970 | L18: 1206843133 | M18: 4006006034 | N18: 150022643 | O18: 2707469772 | P18: =IFERROR((M18/I18),0) -> 0.61948783
A19: O230117220220240280 | B19: 3-03-001-17-22-02-2024-0280 | C19: 2.3.01.17.22.02.20240280 | D19: A1205 | E19: Incremento del acceso y el impacto socio-cultural de los resultados de conocimientos generados por los doctorados de la Universidad Francisco José De Caldas Bogotá D.C | F19: 2565693000 | G19: 0 | H19: 0 | I19: 2565693000 | J19: 210683056 | K19: 1225247076 | L19: 184248922 | M19: 1123056712 | N19: 62118528 | O19: 937927590 | P19: =IFERROR((M19/I19),0) -> 0.43772061
A20: O230117220220240281 | B20: 3-03-001-17-22-02-2024-0281 | C20: 2.3.01.17.22.02.20240281 | D20: A1205 | E20: Fortalecimiento del uso y apropiación de TIC como soporte de propuestas de formación híbridas, virtuales o con incorporación tecnológica en la UD Bogotá D.C | F20: 574376000 | G20: 0 | H20: 1150011870 | I20: 1724387870 | J20: 867927022 | K20: 1540007292 | L20: 407086764 | M20: 749995422 | N20: 1879217 | O20: 342776937 | P20: =IFERROR((M20/I20),0) -> 0.43493429
A21: O230117220220240282 | B21: 3-03-001-17-22-02-2024-0282 | C21: 2.3.01.17.22.02.20240282 | D21: A1205 | E21: Fortalecimiento de la capacidad para la prestación del servicio en las Unidades Académicas de Laboratorio en la docencia, investigación, extensión y proyección social de la UDFC. Bogotá D.C. | F21: 7937309000 | G21: 0 | H21: 1313535937 | I21: 9250844937 | J21: 1014706255 | K21: 4289585940 | L21: 534141648 | M21: 3263353353 | N21: 646184833 | O21: 866846941 | P21: =IFERROR((M21/I21),0) -> 0.35276273
A22: O230117220220240283 | B22: 3-03-001-17-22-02-2024-0283 | C22: 2.3.01.17.22.02.20240283 | D22: A1205 | E22: Fortalecimiento de los componentes tecnológicos para lograr la Transformación Digital en la institución, especialmente en los procesos respaldados por las áreas de tecnología. Bogotá D.C | F22: 5952979000 | G22: 1278780064 | H22: 6209322903 | I22: 12162301903 | J22: 2698762990 | K22: 5130790211 | L22: 602226492 | M22: 1392934315 | N22: 1413801 | O22: 790707823 | P22: =IFERROR((M22/I22),0) -> 0.11452884
A23: O230117220220240284 | B23: 3-03-001-17-22-02-2024-0284 | C23: 2.3.01.17.22.02.20240284 | D23: A1205 | E23: Fortalecimiento de las líneas de servicios CRAI que conforman el portafolio de servicios y recursos de las bibliotecas y unidades de información de la UDFJC, Bogotá DC | F23: 1984326600 | G23: 0 | H23: 0 | I23: 1984327000 | J23: -10117752 | K23: 1640008111 | L23: 369256148 | M23: 1640008111 | N23: 125435007 | O23: 1118297007 | P23: =IFERROR((M23/I23),0) -> 0.82648077

Sheet FONDO PRÉSTAMOS
C2: INFORME DE EJECUCIÓN MENSUAL DE GASTOS E INVERSIÓN - FONDO DE PRÉSTAMOS
C3: UNIVERSIDAD DISTRITAL FRANCISCO JOSÉ DE CALDAS
C4: AGOSTO 2026
F8: =+F9-F13 -> 0 | G8: =+G9-G13 -> 0 | H8: 0 | I8: =+I9-I13 -> 0 | K8: 0 | L8: 0 | M8: 0 | N8: 0 | O8: 0
F9: 211790000 | G9: 382493661 | I9: 594283661 | K9: 0 | L9: 0 | M9: 0 | N9: 0 | O9: 0
C10: RUBRO PRESUPUESTAL | F10: PRESUPUESTO INICIAL 2026 RES CSU 024-2025 | G10: APROPIACIÓN | J10: DISPONIBILIDADES | L10: COMPROMISOS | N10: AUTORIZACION DE GIRO | P10: % DE EJECUCIÓN
A11: POSPRE | B11: CÓDIGO SICAPITAL | C11: CÓDIGO | D11: CENTRO DE COSTOS | E11: NOMBRE | G11: MODIFICACIONES | I11: VIGENTE | J11: MES | K11: ACUMULADO | L11: MES | M11: ACUMULADO | N11: MES | O11: ACUMULADO
G12: MES | H12: ACUMULADO
A13: O233 | B13: 3-03-003 | C13: 2.3.3 | E13: TRANSFERENCIAS CORRIENTES | F13: =+F14 -> 211790000 | G13: =+G14 -> 382493661 | H13: =+H14 -> 382493661 | I13: =+I14 -> 594283661 | K13: =+K14 -> 0 | L13: =+L14 -> 4200000 | M13: =+M14 -> 0 | N13: =+N14 -> 4200000 | O13: =+O14 -> 0 | P13: =+M13/I13 -> 0
A14: O23305 | B14: 3-03-003-05 | C14: 2.3.3.05 | E14: A ENTIDADES DEL GOBIERNO | F14: =+F15 -> 211790000 | G14: =+G15 -> 382493661 | H14: =+H15 -> 382493661 | I14: =+I15 -> 594283661 | K14: =+K15 -> 0 | L14: =+L15 -> 4200000 | M14: =+M15 -> 0 | N14: =+N15 -> 4200000 | O14: =+O15 -> 0 | P14: =+M14/I14 -> 0
A15: O2330509 | B15: 3-03-003-05-09 | C15: 2.3.3.05.09 | E15: A OTRAS ENTIDADES DEL GOBIERNO GENERAL | F15: =+F16 -> 211790000 | G15: =+G16 -> 382493661 | H15: =+H16 -> 382493661 | I15: =+I16 -> 594283661 | K15: =+K16 -> 0 | L15: =+L16 -> 4200000 | M15: =+M16 -> 0 | N15: =+N16 -> 4200000 | O15: =+O16 -> 0 | P15: =+M15/I15 -> 0
A16: O2330509054 | B16: 3-03-003-05-09-54 | C16: 2.3.3.05.09.054 | E16: A ESTABLECIMIENTOS PUBLICOS Y UNIDADES ADMINISTRATIVAS ESPECIALES | F16: =+F17 -> 211790000 | G16: =+G17 -> 382493661 | H16: =+H17 -> 382493661 | I16: =+I17 -> 594283661 | K16: =+K17 -> 0 | L16: =+L17 -> 4200000 | M16: =+M17 -> 0 | N16: =+N17 -> 4200000 | O16: =+O17 -> 0 | P16: =+M16/I16 -> 0
A17: O233050905422 | B17: 3-03-003-05-09-54-0022 | C17: 2.3.3.05.09.054.22 | E17: OTROS ORGANISMOS | F17: =+F18+F20 -> 211790000 | G17: =+G18+G20 -> 382493661 | H17: =+H18+H20 -> 382493661 | I17: =+I18+I20 -> 594283661 | K17: =+K18+K20 -> 0 | L17: =+L18+L20 -> 4200000 | M17: =+M18+M20 -> 0 | N17: =+N18+N20 -> 4200000 | O17: =+O18+O20 -> 0 | P17: =+M17/I17 -> 0
A18: O23305090542205 | C18: 2.3.3.05.09.054.22.05 | E18: FONDO PRÉSTAMOS A EMPLEADOS (Universidad Distrital) | F18: =+F19 -> 50887000 | G18: =+G19 -> 0 | H18: =+H19 -> 0 | I18: =+I19 -> 50887000 | K18: =+K19 -> 0 | L18: =+L19 -> 4200000 | M18: =+M19 -> 0 | N18: =+N19 -> 4200000 | O18: =+O19 -> 0 | P18: =+M18/I18 -> 0
B19: 3-03-003-05-09-54-0022-01 | C19: 2.3.3.05.09.054.22.05.1 | D19: A1401 | E19: Préstamos Ordinarios Administrativos | F19: 50887000 | G19: 0 | H19: 0 | I19: 50887000 | K19: 0 | L19: 4200000 | M19: 0 | N19: 4200000 | O19: 0 | P19: =+M19/I19 -> 0
A20: O23305090542206 | C20: 2.3.3.05.09.054.22.06 | E20: FONDO DE VIVIENDA (Universidad Distrital) | F20: =+F21 -> 160903000 | G20: =+G21 -> 382493661 | H20: =+H21 -> 382493661 | I20: =+I21 -> 543396661 | K20: =+K21 -> 0 | L20: =+L21 -> 0 | M20: =+M21 -> 0 | N20: =+N21 -> 0 | O20: =+O21 -> 0 | P20: =+M20/I20 -> 0
B21: 3-03-003-05-09-54-0022-02 | C21: 2.3.3.05.09.054.22.06.1 | D21: A1401 | E21: Vivienda Administrativos | F21: 160903000 | G21: 382493661 | H21: 382493661 | I21: 543396661 | K21: 0 | L21: 0 | M21: 0 | N21: 0 | O21: 0 | P21: =+M21/I21 -> 0

Sheet EJECUCIÓN 2026 BOGDATA
A2: INFORME DE EJECUCIÓN MENSUAL DE GASTOS E INVERSIÓN
A3: UNIVERSIDAD DISTRITAL FRANCISCO JOSÉ DE CALDAS
A4: AGOSTO 2026
A6: BOGDATA
C10: =EJECUCIÓN!F13 -> 548567755000 | D10: =EJECUCIÓN!G13 -> 14194792521 | E10: =EJECUCIÓN!H13 -> 119748855067 | F10: =EJECUCIÓN!I13 -> 668316610067 | G10: =EJECUCIÓN!J13 -> 37765169384 | H10: =EJECUCIÓN!K13 -> 443925954879 | I10: =EJECUCIÓN!L13 -> 59277792200 | J10: =EJECUCIÓN!M13 -> 411524952140 | ... L10: =EJECUCIÓN!O13 -> 316933439339
A11: Entidad/Proyecto/ObjetoGasto | B11: NOMBRE | C11: INICIAL | D11: APROPIACION | I11: TOTAL COMPROMISOS | K11: AUTORIZACION DE GIRO | M11: EJECUC. PRESUP. %
D12: MODIFICACIONES | F12: VIGENTE | G12: DISPONIBLE
D13: MES | E13: ACUMULADO | G13: MES | H13: ACUMULADO | I13: MES | J13: ACUMULADO | K13: MES | L13: ACUMULADO
A14: TOTAL | C14: =+C15 -> 548567755000 | D14: =+D15 -> 14194792521 | E14: =+E15 -> 119748855067 | F14: =+F15 -> 668316610067 | G14: =+G15 -> 37765169384 | H14: =+H15 -> 443925954879 | I14: =+I15 -> 59277792200 | J14: =+J15 -> 411524952140 | ... L14: =+L15 -> 316933439339 | M14: =+J14/F14 -> 0.61576347
A15: 0230-01 UNIVERSIDAD DISTRITAL FRANCISCO JOSE DE | C15: =+C16+C133+SUM(C134:C159) -> 548567755000 | D15: =+D16+D133+SUM(D134:D159) -> 14194792521 | E15: =+E16+E133+SUM(E134:E159) -> 119748855067 | F15: =+F16+F133+SUM(F134:F159) -> 668316610067 | G15: =+G16+G133+SUM(G134:G159) -> 37765169384 | H15: =+H16+H133+SUM(H134:H159) -> 443925954879 | I15: =+I16+I133+SUM(I134:I159) -> 59277792200 | J15: =+J16+J133+SUM(J134:J159) -> 411524952140 | ... L15: =+L16+L133+SUM(L134:L159) -> 316933439339 | M15: =+J15/F15 -> 0.61576347
A16: 000000000000000000230 0230 - Programa Funcionamiento - UNIVERSIDAD DISTR | C16: =+SUM(C17:C132) -> 505039654000 | D16: =+SUM(D17:D132) -> 12533518796 | E16: =+SUM(E17:E132) -> 108948092774 | F16: =+SUM(F17:F132) -> 613987746774 | G16: =+SUM(G17:G132) -> 30729102067 | H16: =+SUM(H17:H132) -> 423175367995 | I16: =+SUM(I17:I132) -> 55845987005 | J16: =+SUM(J17:J132) -> 397629315710 | ... L16: =+SUM(L17:L132) -> 308766636586 | M16: =+J16/F16 -> 0.64761767
A17: O211010100101 | B17: Sueldo básico | C17: =EJECUCIÓN!F21+EJECUCIÓN!F22+EJECUCIÓN!F23 -> 137847199000 | D17: =EJECUCIÓN!G21+EJECUCIÓN!G22+EJECUCIÓN!G23 -> 0 | E17: =EJECUCIÓN!H21+EJECUCIÓN!H22+EJECUCIÓN!H23 -> -882993704 | F17: =EJECUCIÓN!I21+EJECUCIÓN!I22+EJECUCIÓN!I23 -> 136964205296 | G17: =EJECUCIÓN!J21+EJECUCIÓN!J22+EJECUCIÓN!J23 -> 9973723386 | H17: =EJECUCIÓN!K21+EJECUCIÓN!K22+EJECUCIÓN!K23 -> 79163609530 | I17: =EJECUCIÓN!L21+EJECUCIÓN!L22+EJECUCIÓN!L23 -> 10009017915 | J17: =EJECUCIÓN!M21+EJECUCIÓN!M22+EJECUCIÓN!M23 -> 79046667804 | ... L17: =EJECUCIÓN!O21+EJECUCIÓN!O22+EJECUCIÓN!O23 -> 79022119760 | M17: =+J17/F17 -> 0.57713377
A18: O211010100102 | B18: Horas extras, dominicales, festivos y recargos | C18: =EJECUCIÓN!F26 -> 232386000 | D18: =EJECUCIÓN!G26 -> 0 | E18: =EJECUCIÓN!H26 -> 0 | F18: =EJECUCIÓN!I26 -> 232386000 | G18: =EJECUCIÓN!J26 -> 13695907 | H18: =EJECUCIÓN!K26 -> 110111232 | I18: =EJECUCIÓN!L26 -> 13695907 | J18: =EJECUCIÓN!M26 -> 110111232 | ... L18: =EJECUCIÓN!O26 -> 110111232 | M18: =+J18/F18 -> 0.47382903
A19: O211010100103 | B19: Gastos de representación | C19: =EJECUCIÓN!F29 -> 879556000 | D19: =EJECUCIÓN!G29 -> 0 | E19: =EJECUCIÓN!H29 -> 0 | F19: =EJECUCIÓN!I29 -> 879556000 | G19: =EJECUCIÓN!J29 -> 68936516 | H19: =EJECUCIÓN!K29 -> 540508571 | I19: =EJECUCIÓN!L29 -> 68936516 | J19: =EJECUCIÓN!M29 -> 540508571 | ... L19: =EJECUCIÓN!O29 -> 540508571 | M19: =+J19/F19 -> 0.61452434
A20: O211010100104 | B20: Subsidio de alimentación | C20: =EJECUCIÓN!F32 -> 89520000 | D20: =EJECUCIÓN!G32 -> 0 | E20: =EJECUCIÓN!H32 -> 0 | F20: =EJECUCIÓN!I32 -> 89520000 | G20: =EJECUCIÓN!J32 -> 6554973 | H20: =EJECUCIÓN!K32 -> 57670022 | I20: =EJECUCIÓN!L32 -> 6554973 | J20: =EJECUCIÓN!M32 -> 57670022 | ... L20: =EJECUCIÓN!O32 -> 57670022 | M20: =+J20/F20 -> 0.64421383
A21: O211010100105 | B21: Auxilio de transporte | C21: =EJECUCIÓN!F35 -> 92533000 | D21: =EJECUCIÓN!G35 -> 0 | E21: =EJECUCIÓN!H35 -> 0 | F21: =EJECUCIÓN!I35 -> 92533000 | G21: =EJECUCIÓN!J35 -> 6050899 | H21: =EJECUCIÓN!K35 -> 53235236 | I21: =EJECUCIÓN!L35 -> 6050899 | J21: =EJECUCIÓN!M35 -> 53235236 | ... L21: =EJECUCIÓN!O35 -> 53235236 | M21: =+J21/F21 -> 0.57531082
A22: O211010100107 | B22: Bonificación por servicios prestados | C22: =EJECUCIÓN!F38+EJECUCIÓN!F39 -> 4044818000 | D22: =EJECUCIÓN!G38+EJECUCIÓN!G39 -> 0 | E22: =EJECUCIÓN!H38+EJECUCIÓN!H39 -> 0 | F22: =EJECUCIÓN!I38+EJECUCIÓN!I39 -> 4044818000 | G22: =EJECUCIÓN!J38+EJECUCIÓN!J39 -> 521204267 | H22: =EJECUCIÓN!K38+EJECUCIÓN!K39 -> 2397348052 | I22: =EJECUCIÓN!L38+EJECUCIÓN!L39 -> 523352825 | J22: =EJECUCIÓN!M38+EJECUCIÓN!M39 -> 2385667678 | ... L22: =EJECUCIÓN!O38+EJECUCIÓN!O39 -> 2383519120 | M22: =+J22/F22 -> 0.58980841
A23: O21101010010801 | B23: Prima de navidad | C23: =EJECUCIÓN!F42+EJECUCIÓN!F43+EJECUCIÓN!F44 -> 14300185000 | D23: =EJECUCIÓN!G42+EJECUCIÓN!G43+EJECUCIÓN!G44 -> 0 | E23: =EJECUCIÓN!H42+EJECUCIÓN!H43+EJECUCIÓN!H44 -> 0 | F23: =EJECUCIÓN!I42+EJECUCIÓN!I43+EJECUCIÓN!I44 -> 14300185000 | G23: =EJECUCIÓN!J42+EJECUCIÓN!J43+EJECUCIÓN!J44 -> 0 | H23: =EJECUCIÓN!K42+EJECUCIÓN!K43+EJECUCIÓN!K44 -> 119171591 | I23: =EJECUCIÓN!L42+EJECUCIÓN!L43+EJECUCIÓN!L44 -> 25898987 | J23: =EJECUCIÓN!M42+EJECUCIÓN!M43+EJECUCIÓN!M44 -> 81636831 | ... L23: =EJECUCIÓN!O42+EJECUCIÓN!O43+EJECUCIÓN!O44 -> 79143364 | M23: =+J23/F23 -> 0.0057087954
A24: O21101010010802 | B24: Prima de vacaciones | C24: =EJECUCIÓN!F46+EJECUCIÓN!F47+EJECUCIÓN!F48 -> 8692251000 | D24: =EJECUCIÓN!G46+EJECUCIÓN!G47+EJECUCIÓN!G48 -> 0 | E24: =EJECUCIÓN!H46+EJECUCIÓN!H47+EJECUCIÓN!H48 -> 0 | F24: =EJECUCIÓN!I46+EJECUCIÓN!I47+EJECUCIÓN!I48 -> 8692251000 | G24: =EJECUCIÓN!J46+EJECUCIÓN!J47+EJECUCIÓN!J48 -> 23942177 | H24: =EJECUCIÓN!K46+EJECUCIÓN!K47+EJECUCIÓN!K48 -> 271183862 | I24: =EJECUCIÓN!L46+EJECUCIÓN!L47+EJECUCIÓN!L48 -> 47305862 | J24: =EJECUCIÓN!M46+EJECUCIÓN!M47+EJECUCIÓN!M48 -> 211901050 | ... L24: =EJECUCIÓN!O46+EJECUCIÓN!O47+EJECUCIÓN!O48 -> 201637051 | M24: =+J24/F24 -> 0.024378156
A25: O211010100109 | B25: Prima técnica salarial | C25: =EJECUCIÓN!F51 -> 3872599000 | D25: =EJECUCIÓN!G51 -> 0 | E25: =EJECUCIÓN!H51 -> 0 | F25: =EJECUCIÓN!I51 -> 3872599000 | G25: =EJECUCIÓN!J51 -> 313960967 | H25: =EJECUCIÓN!K51 -> 2426392424 | I25: =EJECUCIÓN!L51 -> 313960967 | J25: =EJECUCIÓN!M51 -> 2426392424 | ... L25: =EJECUCIÓN!O51 -> 2426392424 | M25: =+J25/F25 -> 0.62655401
A26: O211010100204 | B26: Prima semestral | C26: =EJECUCIÓN!F53+EJECUCIÓN!F54+EJECUCIÓN!F55 -> 12787384000 | D26: =EJECUCIÓN!G53+EJECUCIÓN!G54+EJECUCIÓN!G55 -> 0 | E26: =EJECUCIÓN!H53+EJECUCIÓN!H54+EJECUCIÓN!H55 -> -951191646 | F26: =EJECUCIÓN!I53+EJECUCIÓN!I54+EJECUCIÓN!I55 -> 11836192354 | G26: =EJECUCIÓN!J53+EJECUCIÓN!J54+EJECUCIÓN!J55 -> 13553703 | H26: =EJECUCIÓN!K53+EJECUCIÓN!K54+EJECUCIÓN!K55 -> 10720612031 | I26: =EJECUCIÓN!L53+EJECUCIÓN!L54+EJECUCIÓN!L55 -> 22999422 | J26: =EJECUCIÓN!M53+EJECUCIÓN!M54+EJECUCIÓN!M55 -> 10667836583 | ... L26: =EJECUCIÓN!O53+EJECUCIÓN!O54+EJECUCIÓN!O55 -> 10656024964 | M26: =+J26/F26 -> 0.90128956
A27: O21101010021201 | B27: Beneficios a los empleados a corto plazo | C27: =EJECUCIÓN!F59+EJECUCIÓN!F60 -> 1027167000 | D27: =EJECUCIÓN!G59+EJECUCIÓN!G60 -> 0 | E27: =EJECUCIÓN!H59+EJECUCIÓN!H60 -> 0 | F27: =EJECUCIÓN!I59+EJECUCIÓN!I60 -> 1027167000 | G27: =EJECUCIÓN!J59+EJECUCIÓN!J60 -> 70543525 | H27: =EJECUCIÓN!K59+EJECUCIÓN!K60 -> 571873601 | I27: =EJECUCIÓN!L59+EJECUCIÓN!L60 -> 70543525 | J27: =EJECUCIÓN!M59+EJECUCIÓN!M60 -> 571873601 | ... L27: =EJECUCIÓN!O59+EJECUCIÓN!O60 -> 571873601 | M27: =+J27/F27 -> 0.55674842
A28: O211010200101 | B28: Aportes a la seguridad social en pensiones públicas | C28: =EJECUCIÓN!F64+EJECUCIÓN!F65+EJECUCIÓN!F66 -> 15547240000 | D28: =EJECUCIÓN!G64+EJECUCIÓN!G65+EJECUCIÓN!G66 -> 0 | E28: =EJECUCIÓN!H64+EJECUCIÓN!H65+EJECUCIÓN!H66 -> 0 | F28: =EJECUCIÓN!I64+EJECUCIÓN!I65+EJECUCIÓN!I66 -> 15547240000 | G28: =EJECUCIÓN!J64+EJECUCIÓN!J65+EJECUCIÓN!J66 -> 1145963475 | H28: =EJECUCIÓN!K64+EJECUCIÓN!K65+EJECUCIÓN!K66 -> 7929885000 | I28: =EJECUCIÓN!L64+EJECUCIÓN!L65+EJECUCIÓN!L66 -> 1145963475 | J28: =EJECUCIÓN!M64+EJECUCIÓN!M65+EJECUCIÓN!M66 -> 7929885000 | ... L28: =EJECUCIÓN!O64+EJECUCIÓN!O65+EJECUCIÓN!O66 -> 7929885000 | M28: =+J28/F28 -> 0.51005098
A29: O211010200102 | B29: Aportes a la seguridad social en pensiones privadas | C29: =EJECUCIÓN!F68+EJECUCIÓN!F69+EJECUCIÓN!F70 -> 2312121000 | D29: =EJECUCIÓN!G68+EJECUCIÓN!G69+EJECUCIÓN!G70 -> 0 | E29: =EJECUCIÓN!H68+EJECUCIÓN!H69+EJECUCIÓN!H70 -> 0 | F29: =EJECUCIÓN!I68+EJECUCIÓN!I69+EJECUCIÓN!I70 -> 2312121000 | G29: =EJECUCIÓN!J68+EJECUCIÓN!J69+EJECUCIÓN!J70 -> 125185800 | H29: =EJECUCIÓN!K68+EJECUCIÓN!K69+EJECUCIÓN!K70 -> 847400325 | I29: =EJECUCIÓN!L68+EJECUCIÓN!L69+EJECUCIÓN!L70 -> 125185800 | J29: =EJECUCIÓN!M68+EJECUCIÓN!M69+EJECUCIÓN!M70 -> 847400325 | ... L29: =EJECUCIÓN!O68+EJECUCIÓN!O69+EJECUCIÓN!O70 -> 847400325 | M29: =+J29/F29 -> 0.36650345
A30: O211010200202 | B30: Aportes a la seguridad social en salud privada | C30: =EJECUCIÓN!F73+EJECUCIÓN!F74+EJECUCIÓN!F75 -> 12565168000 | D30: =EJECUCIÓN!G73+EJECUCIÓN!G74+EJECUCIÓN!G75 -> 0 | E30: =EJECUCIÓN!H73+EJECUCIÓN!H74+EJECUCIÓN!H75 -> 0 | F30: =EJECUCIÓN!I73+EJECUCIÓN!I74+EJECUCIÓN!I75 -> 12565168000 | G30: =EJECUCIÓN!J73+EJECUCIÓN!J74+EJECUCIÓN!J75 -> 900141908 | H30: =EJECUCIÓN!K73+EJECUCIÓN!K74+EJECUCIÓN!K75 -> 6215452900 | I30: =EJECUCIÓN!L73+EJECUCIÓN!L74+EJECUCIÓN!L75 -> 900141908 | J30: =EJECUCIÓN!M73+EJECUCIÓN!M74+EJECUCIÓN!M75 -> 6215452900 | ... L30: =EJECUCIÓN!O73+EJECUCIÓN!O74+EJECUCIÓN!O75 -> 6215452900 | M30: =+J30/F30 -> 0.49465737
A31: O211010200301 | B31: Aportes de cesantías a fondos públicos | C31: =EJECUCIÓN!F78+EJECUCIÓN!F79+EJECUCIÓN!F80 -> 8087997000 | D31: =EJECUCIÓN!G78+EJECUCIÓN!G79+EJECUCIÓN!G80 -> 0 | E31: =EJECUCIÓN!H78+EJECUCIÓN!H79+EJECUCIÓN!H80 -> -100000000 | F31: =EJECUCIÓN!I78+EJECUCIÓN!I79+EJECUCIÓN!I80 -> 7987997000 | G31: =EJECUCIÓN!J78+EJECUCIÓN!J79+EJECUCIÓN!J80 -> 0 | H31: =EJECUCIÓN!K78+EJECUCIÓN!K79+EJECUCIÓN!K80 -> 7558379361 | I31: =EJECUCIÓN!L78+EJECUCIÓN!L79+EJECUCIÓN!L80 -> 0 | J31: =EJECUCIÓN!M78+EJECUCIÓN!M79+EJECUCIÓN!M80 -> 7535079637 | ... L31: =EJECUCIÓN!O78+EJECUCIÓN!O79+EJECUCIÓN!O80 -> 7524808784 | M31: =+J31/F31 -> 0.94330026
A32: O211010200302 | B32: Aportes de cesantías a fondos privados | C32: =EJECUCIÓN!F82+EJECUCIÓN!F83+EJECUCIÓN!F84 -> 7185369000 | D32: =EJECUCIÓN!G82+EJECUCIÓN!G83+EJECUCIÓN!G84 -> 0 | E32: =EJECUCIÓN!H82+EJECUCIÓN!H83+EJECUCIÓN!H84 -> -1591811575 | F32: =EJECUCIÓN!I82+EJECUCIÓN!I83+EJECUCIÓN!I84 -> 5593557425 | G32: =EJECUCIÓN!J82+EJECUCIÓN!J83+EJECUCIÓN!J84 -> 0 | H32: =EJECUCIÓN!K82+EJECUCIÓN!K83+EJECUCIÓN!K84 -> 4861270986 | I32: =EJECUCIÓN!L82+EJECUCIÓN!L83+EJECUCIÓN!L84 -> 2876123 | J32: =EJECUCIÓN!M82+EJECUCIÓN!M83+EJECUCIÓN!M84 -> 4833310132 | ... L32: =EJECUCIÓN!O82+EJECUCIÓN!O83+EJECUCIÓN!O84 -> 4833310132 | M32: =+J32/F32 -> 0.86408519
A33: O211010200401 | B33: Compensar | C33: =EJECUCIÓN!F87+EJECUCIÓN!F88+EJECUCIÓN!F89 -> 7329466000 | D33: =EJECUCIÓN!G87+EJECUCIÓN!G88+EJECUCIÓN!G89 -> 0 | E33: =EJECUCIÓN!H87+EJECUCIÓN!H88+EJECUCIÓN!H89 -> 0 | F33: =EJECUCIÓN!I87+EJECUCIÓN!I88+EJECUCIÓN!I89 -> 7329466000 | G33: =EJECUCIÓN!J87+EJECUCIÓN!J88+EJECUCIÓN!J89 -> 429266600 | H33: =EJECUCIÓN!K87+EJECUCIÓN!K88+EJECUCIÓN!K89 -> 3387810800 | I33: =EJECUCIÓN!L87+EJECUCIÓN!L88+EJECUCIÓN!L89 -> 429266600 | J33: =EJECUCIÓN!M87+EJECUCIÓN!M88+EJECUCIÓN!M89 -> 3387810800 | ... L33: =EJECUCIÓN!O87+EJECUCIÓN!O88+EJECUCIÓN!O89 -> 3387810800 | M33: =+J33/F33 -> 0.46221796
A34: O211010200501 | B34: Aportes generales al sistema de riesgos laborales públicos | C34: =EJECUCIÓN!F92+EJECUCIÓN!F93+EJECUCIÓN!F94 -> 957874000 | D34: =EJECUCIÓN!G92+EJECUCIÓN!G93+EJECUCIÓN!G94 -> 0 | E34: =EJECUCIÓN!H92+EJECUCIÓN!H93+EJECUCIÓN!H94 -> 0 | F34: =EJECUCIÓN!I92+EJECUCIÓN!I93+EJECUCIÓN!I94 -> 957874000 | G34: =EJECUCIÓN!J92+EJECUCIÓN!J93+EJECUCIÓN!J94 -> 54716500 | H34: =EJECUCIÓN!K92+EJECUCIÓN!K93+EJECUCIÓN!K94 -> 379133800 | I34: =EJECUCIÓN!L92+EJECUCIÓN!L93+EJECUCIÓN!L94 -> 54716500 | J34: =EJECUCIÓN!M92+EJECUCIÓN!M93+EJECUCIÓN!M94 -> 379133800 | ... L34: =EJECUCIÓN!O92+EJECUCIÓN!O93+EJECUCIÓN!O94 -> 379133800 | M34: =+J34/F34 -> 0.39580759
A35: O2110102006 | B35: Aportes al ICBF | C35: =EJECUCIÓN!F97+EJECUCIÓN!F98+EJECUCIÓN!F99 -> 5432095000 | D35: =EJECUCIÓN!G97+EJECUCIÓN!G98+EJECUCIÓN!G99 -> 0 | E35: =EJECUCIÓN!H97+EJECUCIÓN!H98+EJECUCIÓN!H99 -> 0 | F35: =EJECUCIÓN!I97+EJECUCIÓN!I98+EJECUCIÓN!I99 -> 5432095000 | G35: =EJECUCIÓN!J97+EJECUCIÓN!J98+EJECUCIÓN!J99 -> 321961400 | H35: =EJECUCIÓN!K97+EJECUCIÓN!K98+EJECUCIÓN!K99 -> 2540926400 | I35: =EJECUCIÓN!L97+EJECUCIÓN!L98+EJECUCIÓN!L99 -> 321961400 | J35: =EJECUCIÓN!M97+EJECUCIÓN!M98+EJECUCIÓN!M99 -> 2540926400 | ... L35: =EJECUCIÓN!O97+EJECUCIÓN!O98+EJECUCIÓN!O99 -> 2540926400 | M35: =+J35/F35 -> 0.46776178
A36: O211010300103 | B36: Bonificación especial de recreación | C36: =EJECUCIÓN!F102 -> 96799000 | D36: =EJECUCIÓN!G102 -> 0 | E36: =EJECUCIÓN!H102 -> 0 | F36: =EJECUCIÓN!I102 -> 96799000 | G36: =EJECUCIÓN!J102 -> 1550485 | H36: =EJECUCIÓN!K102 -> 11254644 | I36: =EJECUCIÓN!L102 -> 1968415 | J36: =EJECUCIÓN!M102 -> 9894748 | ... L36: =EJECUCIÓN!O102 -> 9476818 | M36: =+J36/F36 -> 0.10221953
A37: O2110103005 | B37: Reconocimiento por permanencia en el servicio público - Bogotá D.C. | C37: =EJECUCIÓN!F103 -> 382816000 | D37: =EJECUCIÓN!G103 -> 0 | E37: =EJECUCIÓN!H103 -> 0 | F37: =EJECUCIÓN!I103 -> 382816000 | G37: =EJECUCIÓN!J103 -> 0 | H37: =EJECUCIÓN!K103 -> 0 | I37: =EJECUCIÓN!L103 -> 0 | J37: =EJECUCIÓN!M103 -> 0 | ... L37: =EJECUCIÓN!O103 -> 0 | M37: =+J37/F37 -> 0
A38: O2110103068 | B38: Prima secretarial | C38: =EJECUCIÓN!F104 -> 284402000 | D38: =EJECUCIÓN!G104 -> 0 | E38: =EJECUCIÓN!H104 -> 0 | F38: =EJECUCIÓN!I104 -> 284402000 | G38: =EJECUCIÓN!J104 -> 15489585 | H38: =EJECUCIÓN!K104 -> 123290497 | I38: =EJECUCIÓN!L104 -> 15489585 | J38: =EJECUCIÓN!M104 -> 123290497 | ... L38: =EJECUCIÓN!O104 -> 123290497 | M38: =+J38/F38 -> 0.43350784
A39: O2110103121 | B39: Bonificación permanente extralegal | C39: =EJECUCIÓN!F106 -> 9373233000 | D39: =EJECUCIÓN!G106 -> 0 | E39: =EJECUCIÓN!H106 -> -32525710 | F39: =EJECUCIÓN!I106 -> 9340707290 | G39: =EJECUCIÓN!J106 -> 50411589 | H39: =EJECUCIÓN!K106 -> 8010232926 | I39: =EJECUCIÓN!L106 -> 255780102 | J39: =EJECUCIÓN!M106 -> 7901098325 | ... L39: =EJECUCIÓN!O106 -> 2890676491 | M39: =+J39/F39 -> 0.84587795
A40: O211020100101 | B40: Sueldo básico | C40: =EJECUCIÓN!F140+EJECUCIÓN!F141+EJECUCIÓN!F142+EJECUCIÓN!F143+EJECUCIÓN!F144+EJECUCIÓN!F145+EJECUCIÓN!F147+EJECUCIÓN!F146+EJECUCIÓN!F148+EJECUCIÓN!F150+EJECUCIÓN!F151+EJECUCIÓN!F152+EJECUCIÓN!F153+EJECUCIÓN!F154+EJECUCIÓN!F155 -> 55574473000 | D40: =EJECUCIÓN!G140+EJECUCIÓN!G141+EJECUCIÓN!G142+EJECUCIÓN!G143+EJECUCIÓN!G144+EJECUCIÓN!G145+EJECUCIÓN!G147+EJECUCIÓN!G146+EJECUCIÓN!G148+EJECUCIÓN!G150+EJECUCIÓN!G151+EJECUCIÓN!G152+EJECUCIÓN!G153+EJECUCIÓN!G154+EJECUCIÓN!G155 -> 53182890 | E40: =EJECUCIÓN!H140+EJECUCIÓN!H141+EJECUCIÓN!H142+EJECUCIÓN!H143+EJECUCIÓN!H144+EJECUCIÓN!H145+EJECUCIÓN!H147+EJECUCIÓN!H146+EJECUCIÓN!H148+EJECUCIÓN!H150+EJECUCIÓN!H151+EJECUCIÓN!H152+EJECUCIÓN!H153+EJECUCIÓN!H154+EJECUCIÓN!H155 -> 12465978912 | F40: =EJECUCIÓN!I140+EJECUCIÓN!I141+EJECUCIÓN!I142+EJECUCIÓN!I143+EJECUCIÓN!I144+EJECUCIÓN!I145+EJECUCIÓN!I147+EJECUCIÓN!I146+EJECUCIÓN!I148+EJECUCIÓN!I150+EJECUCIÓN!I151+EJECUCIÓN!I152+EJECUCIÓN!I153+EJECUCIÓN!I154+EJECUCIÓN!I155 -> 68040451912 | G40: =EJECUCIÓN!J140+EJECUCIÓN!J141+EJECUCIÓN!J142+EJECUCIÓN!J143+EJECUCIÓN!J144+EJECUCIÓN!J145+EJECUCIÓN!J147+EJECUCIÓN!J146+EJECUCIÓN!J148+EJECUCIÓN!J150+EJECUCIÓN!J151+EJECUCIÓN!J152+EJECUCIÓN!J153+EJECUCIÓN!J154+EJECUCIÓN!J155 -> 0 | H40: =EJECUCIÓN!K140+EJECUCIÓN!K141+EJECUCIÓN!K142+EJECUCIÓN!K143+EJECUCIÓN!K144+EJECUCIÓN!K145+EJECUCIÓN!K147+EJECUCIÓN!K146+EJECUCIÓN!K148+EJECUCIÓN!K150+EJECUCIÓN!K151+EJECUCIÓN!K152+EJECUCIÓN!K153+EJECUCIÓN!K154+EJECUCIÓN!K155 -> 67298701053 | I40: =EJECUCIÓN!L140+EJECUCIÓN!L141+EJECUCIÓN!L142+EJECUCIÓN!L143+EJECUCIÓN!L144+EJECUCIÓN!L145+EJECUCIÓN!L147+EJECUCIÓN!L146+EJECUCIÓN!L148+EJECUCIÓN!L150+EJECUCIÓN!L151+EJECUCIÓN!L152+EJECUCIÓN!L153+EJECUCIÓN!L154+EJECUCIÓN!L155 -> 8496083193 | J40: =EJECUCIÓN!M140+EJECUCIÓN!M141+EJECUCIÓN!M142+EJECUCIÓN!M143+EJECUCIÓN!M144+EJECUCIÓN!M145+EJECUCIÓN!M147+EJECUCIÓN!M146+EJECUCIÓN!M148+EJECUCIÓN!M150+EJECUCIÓN!M151+EJECUCIÓN!M152+EJECUCIÓN!M153+EJECUCIÓN!M154+EJECUCIÓN!M155 -> 62277707832 | ... L40: =EJECUCIÓN!O140+EJECUCIÓN!O141+EJECUCIÓN!O142+EJECUCIÓN!O143+EJECUCIÓN!O144+EJECUCIÓN!O145+EJECUCIÓN!O147+EJECUCIÓN!O146+EJECUCIÓN!O148+EJECUCIÓN!O150+EJECUCIÓN!O151+EJECUCIÓN!O152+EJECUCIÓN!O153+EJECUCIÓN!O154+EJECUCIÓN!O155 -> 37718487754 | M40: =+J40/F40 -> 0.91530415
A41: O211020100106 | B41: Prima de servicio | C41: =EJECUCIÓN!F158+EJECUCIÓN!F159+EJECUCIÓN!F160+EJECUCIÓN!F161+EJECUCIÓN!F162+EJECUCIÓN!F163+EJECUCIÓN!F164+EJECUCIÓN!F165+EJECUCIÓN!F167+EJECUCIÓN!F168+EJECUCIÓN!F169+EJECUCIÓN!F170+EJECUCIÓN!F171+EJECUCIÓN!F172 -> 1504837000 | D41: =EJECUCIÓN!G158+EJECUCIÓN!G159+EJECUCIÓN!G160+EJECUCIÓN!G161+EJECUCIÓN!G162+EJECUCIÓN!G163+EJECUCIÓN!G164+EJECUCIÓN!G165+EJECUCIÓN!G167+EJECUCIÓN!G168+EJECUCIÓN!G169+EJECUCIÓN!G170+EJECUCIÓN!G171+EJECUCIÓN!G172 -> 0 | E41: =EJECUCIÓN!H158+EJECUCIÓN!H159+EJECUCIÓN!H160+EJECUCIÓN!H161+EJECUCIÓN!H162+EJECUCIÓN!H163+EJECUCIÓN!H164+EJECUCIÓN!H165+EJECUCIÓN!H167+EJECUCIÓN!H168+EJECUCIÓN!H169+EJECUCIÓN!H170+EJECUCIÓN!H171+EJECUCIÓN!H172 -> 88649874 | F41: =EJECUCIÓN!I158+EJECUCIÓN!I159+EJECUCIÓN!I160+EJECUCIÓN!I161+EJECUCIÓN!I162+EJECUCIÓN!I163+EJECUCIÓN!I164+EJECUCIÓN!I165+EJECUCIÓN!I167+EJECUCIÓN!I168+EJECUCIÓN!I169+EJECUCIÓN!I170+EJECUCIÓN!I171+EJECUCIÓN!I172 -> 1593486874 | G41: =EJECUCIÓN!J158+EJECUCIÓN!J159+EJECUCIÓN!J160+EJECUCIÓN!J161+EJECUCIÓN!J162+EJECUCIÓN!J163+EJECUCIÓN!J164+EJECUCIÓN!J165+EJECUCIÓN!J167+EJECUCIÓN!J168+EJECUCIÓN!J169+EJECUCIÓN!J170+EJECUCIÓN!J171+EJECUCIÓN!J172 -> 0 | H41: =EJECUCIÓN!K158+EJECUCIÓN!K159+EJECUCIÓN!K160+EJECUCIÓN!K161+EJECUCIÓN!K162+EJECUCIÓN!K163+EJECUCIÓN!K164+EJECUCIÓN!K165+EJECUCIÓN!K167+EJECUCIÓN!K168+EJECUCIÓN!K169+EJECUCIÓN!K170+EJECUCIÓN!K171+EJECUCIÓN!K172 -> 1590462991 | I41: =EJECUCIÓN!L158+EJECUCIÓN!L159+EJECUCIÓN!L160+EJECUCIÓN!L161+EJECUCIÓN!L162+EJECUCIÓN!L163+EJECUCIÓN!L164+EJECUCIÓN!L165+EJECUCIÓN!L167+EJECUCIÓN!L168+EJECUCIÓN!L169+EJECUCIÓN!L170+EJECUCIÓN!L171+EJECUCIÓN!L172 -> 0 | J41: =EJECUCIÓN!M158+EJECUCIÓN!M159+EJECUCIÓN!M160+EJECUCIÓN!M161+EJECUCIÓN!M162+EJECUCIÓN!M163+EJECUCIÓN!M164+EJECUCIÓN!M165+EJECUCIÓN!M167+EJECUCIÓN!M168+EJECUCIÓN!M169+EJECUCIÓN!M170+EJECUCIÓN!M171+EJECUCIÓN!M172 -> 1479580895 | ... L41: =EJECUCIÓN!O158+EJECUCIÓN!O159+EJECUCIÓN!O160+EJECUCIÓN!O161+EJECUCIÓN!O162+EJECUCIÓN!O163+EJECUCIÓN!O164+EJECUCIÓN!O165+EJECUCIÓN!O167+EJECUCIÓN!O168+EJECUCIÓN!O169+EJECUCIÓN!O170+EJECUCIÓN!O171+EJECUCIÓN!O172 -> 9667522 | M41: =+J41/F41 -> 0.92851778
A42: O21102010010801 | B42: Prima de navidad | C42: =EJECUCIÓN!F176+EJECUCIÓN!F177+EJECUCIÓN!F178+EJECUCIÓN!F179+EJECUCIÓN!F180+EJECUCIÓN!F181+EJECUCIÓN!F182+EJECUCIÓN!F183+EJECUCIÓN!F185+EJECUCIÓN!F186+EJECUCIÓN!F187+EJECUCIÓN!F188+EJECUCIÓN!F189+EJECUCIÓN!F190 -> 4778651000 | D42: =EJECUCIÓN!G176+EJECUCIÓN!G177+EJECUCIÓN!G178+EJECUCIÓN!G179+EJECUCIÓN!G180+EJECUCIÓN!G181+EJECUCIÓN!G182+EJECUCIÓN!G183+EJECUCIÓN!G185+EJECUCIÓN!G186+EJECUCIÓN!G187+EJECUCIÓN!G188+EJECUCIÓN!G189+EJECUCIÓN!G190 -> 4318140 | E42: =EJECUCIÓN!H176+EJECUCIÓN!H177+EJECUCIÓN!H178+EJECUCIÓN!H179+EJECUCIÓN!H180+EJECUCIÓN!H181+EJECUCIÓN!H182+EJECUCIÓN!H183+EJECUCIÓN!H185+EJECUCIÓN!H186+EJECUCIÓN!H187+EJECUCIÓN!H188+EJECUCIÓN!H189+EJECUCIÓN!H190 -> 78431792 | F42: =EJECUCIÓN!I176+EJECUCIÓN!I177+EJECUCIÓN!I178+EJECUCIÓN!I179+EJECUCIÓN!I180+EJECUCIÓN!I181+EJECUCIÓN!I182+EJECUCIÓN!I183+EJECUCIÓN!I185+EJECUCIÓN!I186+EJECUCIÓN!I187+EJECUCIÓN!I188+EJECUCIÓN!I189+EJECUCIÓN!I190 -> 4857082792 | G42: =EJECUCIÓN!J176+EJECUCIÓN!J177+EJECUCIÓN!J178+EJECUCIÓN!J179+EJECUCIÓN!J180+EJECUCIÓN!J181+EJECUCIÓN!J182+EJECUCIÓN!J183+EJECUCIÓN!J185+EJECUCIÓN!J186+EJECUCIÓN!J187+EJECUCIÓN!J188+EJECUCIÓN!J189+EJECUCIÓN!J190 -> 0 | H42: =EJECUCIÓN!K176+EJECUCIÓN!K177+EJECUCIÓN!K178+EJECUCIÓN!K179+EJECUCIÓN!K180+EJECUCIÓN!K181+EJECUCIÓN!K182+EJECUCIÓN!K183+EJECUCIÓN!K185+EJECUCIÓN!K186+EJECUCIÓN!K187+EJECUCIÓN!K188+EJECUCIÓN!K189+EJECUCIÓN!K190 -> 4847319269 | I42: =EJECUCIÓN!L176+EJECUCIÓN!L177+EJECUCIÓN!L178+EJECUCIÓN!L179+EJECUCIÓN!L180+EJECUCIÓN!L181+EJECUCIÓN!L182+EJECUCIÓN!L183+EJECUCIÓN!L185+EJECUCIÓN!L186+EJECUCIÓN!L187+EJECUCIÓN!L188+EJECUCIÓN!L189+EJECUCIÓN!L190 -> 520583632 | J42: =EJECUCIÓN!M176+EJECUCIÓN!M177+EJECUCIÓN!M178+EJECUCIÓN!M179+EJECUCIÓN!M180+EJECUCIÓN!M181+EJECUCIÓN!M182+EJECUCIÓN!M183+EJECUCIÓN!M185+EJECUCIÓN!M186+EJECUCIÓN!M187+EJECUCIÓN!M188+EJECUCIÓN!M189+EJECUCIÓN!M190 -> 4468551764 | ... L42: =EJECUCIÓN!O176+EJECUCIÓN!O177+EJECUCIÓN!O178+EJECUCIÓN!O179+EJECUCIÓN!O180+EJECUCIÓN!O181+EJECUCIÓN!O182+EJECUCIÓN!O183+EJECUCIÓN!O185+EJECUCIÓN!O186+EJECUCIÓN!O187+EJECUCIÓN!O188+EJECUCIÓN!O189+EJECUCIÓN!O190 -> 1368204578 | M42: =+J42/F42 -> 0.92000733
A43: O21102010010802 | B43: Prima de vacaciones | C43: =EJECUCIÓN!F193+EJECUCIÓN!F194+EJECUCIÓN!F195+EJECUCIÓN!F196+EJECUCIÓN!F197+EJECUCIÓN!F198+EJECUCIÓN!F199+EJECUCIÓN!F200+EJECUCIÓN!F202+EJECUCIÓN!F203+EJECUCIÓN!F204+EJECUCIÓN!F205+EJECUCIÓN!F206+EJECUCIÓN!F207 -> 3063822000 | D43: =EJECUCIÓN!G193+EJECUCIÓN!G194+EJECUCIÓN!G195+EJECUCIÓN!G196+EJECUCIÓN!G197+EJECUCIÓN!G198+EJECUCIÓN!G199+EJECUCIÓN!G200+EJECUCIÓN!G202+EJECUCIÓN!G203+EJECUCIÓN!G204+EJECUCIÓN!G205+EJECUCIÓN!G206+EJECUCIÓN!G207 -> 2727550 | E43: =EJECUCIÓN!H193+EJECUCIÓN!H194+EJECUCIÓN!H195+EJECUCIÓN!H196+EJECUCIÓN!H197+EJECUCIÓN!H198+EJECUCIÓN!H199+EJECUCIÓN!H200+EJECUCIÓN!H202+EJECUCIÓN!H203+EJECUCIÓN!H204+EJECUCIÓN!H205+EJECUCIÓN!H206+EJECUCIÓN!H207 -> 65413348 | F43: =EJECUCIÓN!I193+EJECUCIÓN!I194+EJECUCIÓN!I195+EJECUCIÓN!I196+EJECUCIÓN!I197+EJECUCIÓN!I198+EJECUCIÓN!I199+EJECUCIÓN!I200+EJECUCIÓN!I202+EJECUCIÓN!I203+EJECUCIÓN!I204+EJECUCIÓN!I205+EJECUCIÓN!I206+EJECUCIÓN!I207 -> 3129235348 | G43: =EJECUCIÓN!J193+EJECUCIÓN!J194+EJECUCIÓN!J195+EJECUCIÓN!J196+EJECUCIÓN!J197+EJECUCIÓN!J198+EJECUCIÓN!J199+EJECUCIÓN!J200+EJECUCIÓN!J202+EJECUCIÓN!J203+EJECUCIÓN!J204+EJECUCIÓN!J205+EJECUCIÓN!J206+EJECUCIÓN!J207 -> 0 | H43: =EJECUCIÓN!K193+EJECUCIÓN!K194+EJECUCIÓN!K195+EJECUCIÓN!K196+EJECUCIÓN!K197+EJECUCIÓN!K198+EJECUCIÓN!K199+EJECUCIÓN!K200+EJECUCIÓN!K202+EJECUCIÓN!K203+EJECUCIÓN!K204+EJECUCIÓN!K205+EJECUCIÓN!K206+EJECUCIÓN!K207 -> 3122428542 | I43: =EJECUCIÓN!L193+EJECUCIÓN!L194+EJECUCIÓN!L195+EJECUCIÓN!L196+EJECUCIÓN!L197+EJECUCIÓN!L198+EJECUCIÓN!L199+EJECUCIÓN!L200+EJECUCIÓN!L202+EJECUCIÓN!L203+EJECUCIÓN!L204+EJECUCIÓN!L205+EJECUCIÓN!L206+EJECUCIÓN!L207 -> 328881254 | J43: =EJECUCIÓN!M193+EJECUCIÓN!M194+EJECUCIÓN!M195+EJECUCIÓN!M196+EJECUCIÓN!M197+EJECUCIÓN!M198+EJECUCIÓN!M199+EJECUCIÓN!M200+EJECUCIÓN!M202+EJECUCIÓN!M203+EJECUCIÓN!M204+EJECUCIÓN!M205+EJECUCIÓN!M206+EJECUCIÓN!M207 -> 2861581773 | ... L43: =EJECUCIÓN!O193+EJECUCIÓN!O194+EJECUCIÓN!O195+EJECUCIÓN!O196+EJECUCIÓN!O197+EJECUCIÓN!O198+EJECUCIÓN!O199+EJECUCIÓN!O200+EJECUCIÓN!O202+EJECUCIÓN!O203+EJECUCIÓN!O204+EJECUCIÓN!O205+EJECUCIÓN!O206+EJECUCIÓN!O207 -> 864213317 | M43: =+J43/F43 -> 0.91446678
