Workbook

Sheet 195
A1: CÓD. ESTUDIANTE | B1: NOMBRE | C1: DOCUMENTO | D1: FECHA GRADO | E1: ACTA | F1: LIBRO | G1: FOLIO | H1: REGISTRO | I1: EMAIL | J1: PROMEDIO | K1: EMPRESA | L1: DIR. EMPRESA
A2: 20152195016 | B2: MU?OZ NU?EZ YENY KATHERINE | C2: 1032432662 | D2: 45107 | E2: 24424 | F2: 24 | G2: 75 | H2: F.I. 26496 | I2: yekamunu@gmail.com | J2: 4.35 | K2: =YEAR(D2) -> 2023 | L2: =COUNTIF(K2:K6,2023) -> 5
A3: 20161195008 | B3: GONZALEZ PRIETO FREDY ALEXANDER | C3: 1049612843 | D3: 45107 | E3: 24422 | F3: 24 | G3: 75 | H3: F.I. 26494 | I3: fredyagonzalez@hotmail.com | J3: 4.64 | K3: =YEAR(D3) -> 2023
A4: 20121195003 | B4: AVILA SANCHEZ JAIME ANTONIO | C4: 7174732 | D4: 45016 | E4: 24226 | F4: 24 | G4: 42 | H4: F.I. 26298 | I4: jaimejaas@gmail.com | J4: 4.3 | K4: =YEAR(D4) -> 2023
A5: 20182195005 | B5: BERMUDEZ BUCURU BRAYAN ANDRES | C5: 1010221959 | D5: 45016 | E5: 24227 | F5: 24 | G5: 42 | H5: F.I. 26299 | I5: babermudezb@udistrital.edu.co | J5: 4.63 | K5: =YEAR(D5) -> 2023
A6: 20191195005 | B6: LOPEZ GARCIA ANDRES CAMILO | C6: 1022395511 | D6: 45016 | E6: 24228 | F6: 24 | G6: 42 | H6: F.I. 26300 | I6: anclopezg@correo.udistrital.edu.co | J6: 4.62 | K6: =YEAR(D6) -> 2023
A7: 20171195006 | B7: ROBAYO MENDEZ GUSTAVO ALEJANDRO | C7: 1026251289 | D7: 44827 | E7: 23780 | F7: 23 | G7: 124 | H7: F.I 25851 | I7: tavoalejo@gmail.com | J7: 4.39 | K7: =YEAR(D7) -> 2022 | L7: =COUNTIF(K7:K15,2022) -> 9
A8: 20181195007 | B8: LUIS ALFREDO NARVAEZ JARAMILLO | C8: 1030597409 | D8: 44827 | E8: 23777 | F8: 23 | G8: 124 | H8: F.I 25848 | I8: lnarvaezj@hotmail.com | J8: 4.42 | K8: =YEAR(D8) -> 2022
A9: 20202195002 | B9: CASTILLO CRUZ JUAN DIEGO | C9: 1101759682 | D9: 44827 | E9: 23774 | F9: 23 | G9: 123 | H9: F.I 25845 | I9: judcastilloc@correo.udistrital.edu.co | J9: 4.59 | K9: =YEAR(D9) -> 2022
A10: 20051195015 | B10: NUVAN HURTADO JAIRO ANTONIO | C10: 9396968 | D10: 44736 | E10: 23460 | F10: 23 | G10: 71 | H10: F.I 25529 | I10: januvan@hotmail.com | J10: 4.13 | K10: =YEAR(D10) -> 2022
A11: 20061195014 | B11: RODRIGUEZ COSSIO HANS | C11: 79999284 | D11: 44736 | E11: 23462 | F11: 23 | G11: 71 | H11: F.I 25531 | I11: hansrodriguez@gmail.com | J11: 4.08 | K11: =YEAR(D11) -> 2022
A12: 20172195007 | B12: DE LEON ARTURO VERBEL | C12: 1143355214 | D12: 44736 | E12: 23465 | F12: 23 | G12: 71 | H12: F.I 25534 | I12: arturo.verbel@gmail.com | J12: 4.48 | K12: =YEAR(D12) -> 2022
A13: 20162195008 | B13: RODRIGUEZ RODRIGUEZ GUSTAVO ALONSO | C13: 79797927 | D13: 44638 | E13: 23269 | F13: 23 | G13: 39 | H13: F.I 25338 | I13: garcaj@hotmail.com | J13: 3.83 | K13: =YEAR(D13) -> 2022
A14: 20172195005 | B14: CASTA?EDA MOSCOSO EDWARD LENIN | C14: 80007028 | D14: 44638 | E14: 23268 | F14: 23 | G14: 39 | H14: F.I 25337 | I14: boogiedca@gmail.com | J14: 3.69 | K14: =YEAR(D14) -> 2022
A15: 20181195002 | B15: ARIAS FORERO JUAN DAVID | C15: 1022374793 | D15: 44638 | E15: 23267 | F15: 23 | G15: 38 | H15: F.I 25336 | I15: jdariasforero2008@gmail.com | J15: 4.66 | K15: =YEAR(D15) -> 2022
A16: 20152195001 | B16: AGUDELO CRISTANCHO NELSON GIOVANNI | C16: 80051486 | D16: 44552 | E16: 23026 | F16: 22 | G16: 145 | H16: F.I 25095 | I16: nelsongiovani@gmail.com | J16: 4.27 | K16: =YEAR(D16) -> 2021 | L16: =COUNTIF(K16:K25,2021) -> 10
A17: 20161195005 | B17: DAVILA ROJAS MIGUEL ANGEL | C17: 1018436623 | D17: 44552 | E17: 23030 | F17: 22 | G17: 145 | H17: F.I 25099 | I17: miadavilar@correo.udistrital.edu.co | J17: 4.4 | K17: =YEAR(D17) -> 2021
A18: 20182195002 | B18: BARRETO SANCHEZ FABIAN DAVID | C18: 1118559031 | D18: 44552 | E18: 23027 | F18: 22 | G18: 145 | H18: F.I 25096 | I18: fabibeto11@hotmail.com | J18: 4.68 | K18: =YEAR(D18) -> 2021
A19: 20142195002 | B19: WILMER ALBERTO FIGUEREDO RODRIGUEZ | C19: 1010175883 | D19: 44484 | E19: 22852 | F19: 22 | G19: 115 | H19: F.I 24919 | I19: wilmerfr@gmail.com | K19: =YEAR(D19) -> 2021
A20: 20161195009 | B20: GOMEZ ACERO JAIRO CESAR | C20: 79049409 | D20: 44357 | E20: 22572 | F20: 22 | G20: 69 | H20: F.I 24639 | I20: jacegom@gmail.com | J20: 4.27 | K20: =YEAR(D20) -> 2021
A21: 20142195001 | B21: JUAN CARLOS DELGADILLO BELTRAN | C21: 79576961 | D21: 44292 | E21: 22421 | F21: 22 | G21: 43 | H21: F.I 24488 | I21: ingjuandel@gmail.com | K21: =YEAR(D21) -> 2021
A22: 20162195004 | B22: CUBILLOS SANCHEZ RAFAEL ORLANDO | C22: 79578336 | D22: 44292 | E22: 22420 | F22: 22 | G22: 43 | H22: F.I 24487 | I22: rafacubillos@gmail.com | J22: 4.35 | K22: =YEAR(D22) -> 2021
A23: 20181195012 | B23: SUAREZ ROLDAN MARCO ALEXANDER | C23: 1110505909 | D23: 44292 | E23: 22423 | F23: 22 | G23: 44 | H23: F.I 24490 | I23: masuarez90@misena.edu.co | J23: 4.32 | K23: =YEAR(D23) -> 2021
A24: 20181195013 | B24: SUAREZ ROLDAN JUAN SEBASTIAN | C24: 1110505907 | D24: 44292 | E24: 22424 | F24: 22 | G24: 44 | H24: F.I 24491 | I24: sebas.suarez.roldan@gmail.com | J24: 4.32 | K24: =YEAR(D24) -> 2021
A25: 20122195005 | B25: REYES BONILLA LUZ YAMILE | C25: 30230686 | D25: 44251 | E25: 22257 | F25: 22 | G25: 16 | H25: F.I 24323 | I25: luzyare@gmail.com | J25: 4.28 | K25: =YEAR(D25) -> 2021
A26: 20152195003 | B26: ALZATE ACU?A GABRIEL ANDRES | C26: 80259743 | D26: 44188 | E26: 22160 | F26: 21 | G26: 144 | H26: F.I 24226 | I26: gabriel.andres.alzate@gmail.com | J26: 4.63 | K26: =YEAR(D26) -> 2020 | L26: =COUNTIF(K26:K32,2020) -> 7
A27: 20162195010 | B27: TORRES CASTILLO CAMILO ANDRES | C27: 1072640773 | D27: 44188 | E27: 22161 | F27: 21 | G27: 144 | H27: F.I 24227 | I27: camito113@gmail.com | J27: 4.64 | K27: =YEAR(D27) -> 2020
A28: 20161195002 | B28: CARRE?O PEREZ JUAN CARLOS | C28: 80215759 | D28: 44063 | E28: 21681 | F28: 21 | G28: 64 | H28: F.I 23747 | I28: juan_carlos_carreno@hotmail.com | J28: 4.67 | K28: =YEAR(D28) -> 2020
A29: 20161195003 | B29: CORREA SANCHEZ LEWYS | C29: 1067906153 | D29: 44046 | E29: 21667 | F29: 21 | G29: 61 | H29: F.I 23733 | I29: lew.correa@gmail.com | J29: 4.51 | K29: =YEAR(D29) -> 2020
A30: 20161195015 | B30: SERRANO MOLINA YOHEL RENE | C30: 14013612 | D30: 44046 | E30: 21671 | F30: 21 | G30: 62 | H30: F.I 23737 | I30: yorry_12@hotmail.com | J30: 4.14 | K30: =YEAR(D30) -> 2020
A31: 20181195009 | B31: RAMIREZ PEREZ NATALIA ANDREA | C31: 1015443760 | D31: 44046 | E31: 21669 | F31: 21 | G31: 62 | H31: F.I 23735 | I31: nata.r_1212@hotmail.com | J31: 4.69 | K31: =YEAR(D31) -> 2020
A32: 20181395003 | B32: DIAZ CARRETERO EDUARDO ALFONSO | C32: 1022386838 | D32: 44046 | E32: 21668 | F32: 21 | G32: 62 | H32: F.I 23734 | I32: eadiaz96@gmail.com | J32: 4.38 | K32: =YEAR(D32) -> 2020
A33: 20142195004 | B33: NESTOR JAVIER RODRIGUEZ GARCIA | C33: 80932160 | D33: 43817 | E33: 21243 | F33: 20 | G33: 178 | H33: F.I 23308 | I33: ing.nestor0818@gmail.com | J33: 4.36 | K33: =YEAR(D33) -> 2019 | L33: =COUNTIF(K33:K39,2019) -> 7
A34: 20152195015 | B34: MORENO MORENO ANDRES JULIAN | C34: 1032431630 | D34: 43817 | E34: 21240 | F34: 20 | G34: 177 | H34: F.I 23305 | I34: andresm2.xy@gmail.com | J34: 4.59 | K34: =YEAR(D34) -> 2019
A35: 20162195006 | B35: OTALORA RIVERO GEOVANNY RENE | C35: 79531717 | D35: 43817 | E35: 21241 | F35: 20 | G35: 178 | H35: F.I 23306 | I35: gotalora68@gmail.com | J35: 4.26 | K35: =YEAR(D35) -> 2019
A36: 20171195004 | B36: PINEDA TORRES DIEGO EDUARDO | C36: 1033712950 | D36: 43817 | E36: 21242 | F36: 20 | G36: 178 | H36: F.I 23307 | I36: deduardopineda@gmail.com | J36: 4.27 | K36: =YEAR(D36) -> 2019
A37: 20142195003 | B37: HECTOR MANUEL HERRERA HERRERA | C37: 1033691855 | D37: 43623 | E37: 20598 | F37: 20 | G37: 70 | H37: F.I. 22661 | I37: hetorherrera@hotmail.com | J37: 4.49 | K37: =YEAR(D37) -> 2019
A38: 20121195014 | B38: SOTO CONDE DIEGO FELIPE | C38: 93453664 | D38: 43546 | E38: 20322 | F38: 20 | G38: 24 | H38: F.I. 22385 | I38: difeso@gmail.com | J38: 4.18 | K38: =YEAR(D38) -> 2019
A39: 20122195003 | B39: GUEVARA RIVEROS ADRIANA YOLANDA | C39: 52147162 | D39: 43546 | E39: 20320 | F39: 20 | G39: 24 | H39: F.I. 22383 | I39: adriveros2006@hotmail.com | J39: 4.31 | K39: =YEAR(D39) -> 2019
A40: 20152195013 | B40: LOPEZ SANCHEZ WILSON RICARDO | C40: 1026268779 | D40: 43357 | E40: 19700 | F40: 19 | G40: 125 | H40: F.I. 21762 | I40: wilrilo@gmail.com | J40: 4.75 | K40: =YEAR(D40) -> 2018 | L40: =COUNTIF(K40:K49,2018) -> 10
...

Sheet 295
A1: CÓD. ESTUDIANTE | B1: NOMBRE | C1: DOCUMENTO | D1: FECHA GRADO | E1: ACTA | F1: LIBRO | G1: FOLIO | H1: REGISTRO | I1: EMAIL | J1: PROMEDIO | K1: EMPRESA | L1: DIR. EMPRESA
A2: 20101295014 | B2: SANCHEZ JOSE ALEJANDRO | C2: 79763774 | D2: 44736 | E2: 23463 | F2: 23 | G2: 71 | H2: F.I 25532 | I2: ijasanchez@gmail.com | J2: 4.4 | K2: =YEAR(D2) -> 2022 | L2: =COUNTIF(K2:K11,2022) -> 1
A3: 20111295007 | B3: RAMIREZ AREVALO HELIO HENRY | C3: 80238298 | D3: 44174 | E3: 22135 | F3: 21 | G3: 139 | H3: F.I 24201 | I3: helio.ramirez@gmail.com | J3: 4.25 | K3: =YEAR(D3) -> 2020 | L3: =COUNTIF(K3:K12,2020) -> 3
A4: 20062295048 | B4: RODRIGUEZ MORENO JOSE JULIAN | C4: 79925864 | D4: 44046 | E4: 21670 | F4: 21 | G4: 62 | H4: F.I 23736 | I4: julian.rodriguez.moreno@gmail.com | J4: 4.4 | K4: =YEAR(D4) -> 2020
A5: 20151295007 | B5: PINZON ORTIZ JESUS EMILSEN | C5: 17311419 | D5: 43994 | E5: 21533 | F5: 21 | G5: 39 | H5: F.I 23599 | I5: jesus.pinzon@hotmail.com | J5: 4.29 | K5: =YEAR(D5) -> 2020
A6: 20131295002 | B6: CASTELLANOS ROJAS MARTHA CARMENZA | C6: 51839772 | D6: 43546 | E6: 20319 | F6: 20 | G6: 24 | H6: F.I. 22382 | I6: martha.castellanos@gmail.com | J6: 4.41 | K6: =YEAR(D6) -> 2019 | L6: =COUNTIF(K6:K15,2019) -> 2
A7: 20131295006 | B7: PINILLA AVILA EDWIN GUSTAVO | C7: 80746790 | D7: 43546 | E7: 20321 | F7: 20 | G7: 24 | H7: F.I. 22384 | I7: egpinilla@gmail.com | J7: 4.27 | K7: =YEAR(D7) -> 2019
A8: 20141295002 | B8: BECERRA GONZALEZ LAURA CRISTINA | C8: 63560187 | D8: 43441 | E8: 20091 | G8: 190 | H8: F.I. 22153 | I8: lauracriss@misena.edu.co | J8: 4.28 | K8: =YEAR(D8) -> 2018 | L8: =COUNTIF(K8:K17,2018) -> 6
A9: 20111295006 | B9: PUENTES PUENTES OSCAR JAVIER | C9: 80074145 | D9: 43182 | E9: 19172 | F9: 19 | G9: 37 | H9: F.I. 21234 | I9: oskarj84@gmail.com | J9: 4.33 | K9: =YEAR(D9) -> 2018
A10: 20112295009 | B10: MENDEZ MATAMOROS JORGE HERNANDO | C10: 80037717 | D10: 43182 | E10: 19166 | F10: 19 | G10: 36 | H10: F.I. 21228 | I10: is.jorge@gmail.com | J10: 3.89 | K10: =YEAR(D10) -> 2018
A11: 20122295003 | B11: DIAZ HERNANDEZ MARIA FERNANDA | C11: 51661990 | D11: 43182 | E11: 19164 | F11: 19 | G11: 36 | H11: F.I. 21226 | I11: mafediazh77@gmail.com | J11: 4.27 | K11: =YEAR(D11) -> 2018
A12: 20141295005 | B12: MOYA JUTINICO CARLOS JULIO | C12: 80881311 | D12: 43182 | E12: 19168 | F12: 19 | G12: 36 | H12: F.I. 21230 | I12: ingcarlosmoya@hotmail.com | J12: 4.33 | K12: =YEAR(D12) -> 2018
A13: 20141295007 | B13: VARGAS BARRIOS PEDRO JULIO | C13: 80192128 | D13: 43182 | E13: 19175 | F13: 19 | G13: 37 | H13: F.I. 21237 | I13: pedrojvar@gmail.com | J13: 4.23 | K13: =YEAR(D13) -> 2018

Sheet 395
A1: CÓD. ESTUDIANTE | B1: NOMBRE | C1: DOCUMENTO | D1: FECHA GRADO | E1: ACTA | F1: LIBRO | G1: FOLIO | H1: REGISTRO | I1: EMAIL | J1: PROMEDIO | K1: EMPRESA | L1: DIR. EMPRESA
A2: 20161395011 | B2: SANDOVAL LAGOS JONATHAN SAID | C2: 1030576910 | D2: 45107 | E2: 24427 | F2: 24 | G2: 75 | H2: F.I. 26499 | I2: jssandovall@udistrital.edu.co | J2: 4.18 | K2: =YEAR(D2) -> 2023 | L2: =COUNTIF(K2:K11,2023) -> 6
A3: 20081295008 | B3: MEJIA ROCHA MARINO | C3: 79788977 | D3: 45016 | E3: 24225 | F3: 24 | G3: 42 | H3: F.I. 26297 | I3: marino.mejia@gmail.com | J3: 4.77 | K3: =YEAR(D3) -> 2023
A4: 20161395002 | B4: CABIATIVA SANCHEZ OSCAR ABRAHAM | C4: 1019040864 | D4: 45016 | E4: 24219 | F4: 24 | G4: 41 | H4: F.I. 26291 | I4: cabiato90@gmail.com | J4: 4.1 | K4: =YEAR(D4) -> 2023
A5: 20171395002 | B5: CABALLERO MODERA NICOLS ERNESTO | C5: 1026285580 | D5: 45016 | E5: 24218 | F5: 24 | G5: 41 | H5: F.I. 26290 | I5: necaballerom@gmail.com | J5: 4.4 | K5: =YEAR(D5) -> 2023
A6: 20172395002 | B6: BECERRA GARCIA LAURA JUANITA | C6: 1024554082 | D6: 45016 | E6: 24217 | F6: 24 | G6: 40 | H6: F.I. 26289 | I6: ljbecerrag@gmail.com | J6: 4.49 | K6: =YEAR(D6) -> 2023
A7: 20192395010 | B7: ZARAZA AGUILERA MAYCOL ALEJANDRO | C7: 1013667943 | D7: 45016 | E7: 24220 | F7: 24 | G7: 41 | H7: F.I. 26292 | I7: maikolzaraza07@gmail.com | J7: 4.71 | K7: =YEAR(D7) -> 2023
A8: 20161395008 | B8: MARTINEZ AGUIRRE NELSON DAVID | C8: 1019008786 | D8: 44911 | E8: 23948 | F8: 23 | G8: 152 | H8: F.I. 26020 | I8: davidmartinezaguirre@hotmail.com | J8: 4.43 | K8: =YEAR(D8) -> 2022 | L8: =COUNTIF(K8:K22,2022) -> 15
A9: 20201395003 | B9: MONTES LOPEZ DIEGO FERNANDO | C9: 80779247 | D9: 44911 | E9: 23949 | F9: 23 | G9: 153 | H9: F.I. 26021 | I9: adiegomontes@gmail.com | J9: 4.38 | K9: =YEAR(D9) -> 2022
A10: 20142395005 | B10: JESSICA ANDREA ZAPATA GRAJALES | C10: 1026269883 | D10: 44827 | E10: 23783 | F10: 23 | G10: 125 | H10: F.I 25854 | I10: jessiandre71@gmail.com | J10: 4.32 | K10: =YEAR(D10) -> 2022
A11: 20181395006 | B11: ROBLES MONDRAGON DUVAN ALEXANDER | C11: 1010191260 | D11: 44827 | E11: 23781 | F11: 23 | G11: 124 | H11: F.I 25852 | I11: dalexrobles@gmail.com | J11: 4.58 | K11: =YEAR(D11) -> 2022
A12: 20182395009 | B12: MANRIQUE CHACON LAURA MELISSA | C12: 1031159767 | D12: 44827 | E12: 23775 | F12: 23 | G12: 123 | H12: F.I 25846 | I12: manriquelaura31@gmail.com | J12: 4.8 | K12: =YEAR(D12) -> 2022
A13: 20191395006 | B13: MONTOYA QUINTERO GERMAN DAVID | C13: 1069304778 | D13: 44827 | E13: 23776 | F13: 23 | G13: 124 | H13: F.I 25847 | I13: gdmontoyaq@gmail.com | J13: 4.44 | K13: =YEAR(D13) -> 2022
A14: 20191395010 | B14: RAYO BERMUDEZ KAREN YULIETH | C14: 1023009167 | D14: 44827 | E14: 23778 | F14: 23 | G14: 124 | H14: F.I 25849 | I14: kyrayob@correo.udistrital.edu.co | J14: 4.51 | K14: =YEAR(D14) -> 2022
A15: 20192395012 | B15: SUAREZ RODRIGUEZ JUAN MANUEL | C15: 1013600362 | D15: 44827 | E15: 23782 | F15: 23 | G15: 125 | H15: F.I 25853 | I15: ingjuanmasuarez@gmail.com | J15: 4.66 | K15: =YEAR(D15) -> 2022
A16: 20152395001 | B16: ALVARADO VARGAS DIANA CAROLINA | C16: 1014196634 | D16: 44736 | E16: 23453 | F16: 23 | G16: 69 | H16: F.I 25522 | I16: diana.caro5212@gmail.com | J16: 4.26 | K16: =YEAR(D16) -> 2022
A17: 20162395007 | B17: LUNA AREVALO FABIO NICOLAS | C17: 1026258763 | D17: 44736 | E17: 23459 | F17: 23 | G17: 70 | H17: F.I 25528 | I17: nicolaslunageo2@gmail.com | J17: 4.36 | K17: =YEAR(D17) -> 2022
A18: 20181395004 | B18: GUERRERO BUELVAS LUIS MANUEL | C18: 1018454765 | D18: 44736 | E18: 23456 | F18: 23 | G18: 70 | H18: F.I 25525 | I18: lmguerrerob@correo.udistrital.edu.co | J18: 4.53 | K18: =YEAR(D18) -> 2022
A19: 20182395006 | B19: GONZALEZ BUITRAGO GABRIEL HERNAN | C19: 1016083013 | D19: 44736 | E19: 23455 | F19: 23 | G19: 70 | H19: F.I 25524 | I19: ghgonzalezb@correo.udistrital.edu.co | J19: 4.72 | K19: =YEAR(D19) -> 2022
A20: 20182395012 | B20: PARRA GARZON JUAN CARLOS | C20: 79499302 | D20: 44736 | E20: 23461 | F20: 23 | G20: 71 | H20: F.I 25530 | I20: Jcparrag2000@gmail.com | J20: 4.53 | K20: =YEAR(D20) -> 2022
... A22: 20162395012 | B22: ZARATE AREVALO HERNAN DARIO | C22: 79992153 | D22: 44638 | E22: 23271 | F22: 23 | G22: 39 | H22: F.I 25340 | I22: hzaratepot2013@gmail.com | J22: 4.09 | K22: =YEAR(D22) -> 2022
A23: 20131395007 | B23: LOPEZ LOPEZ JHON FREDY | C23: 1023863636 | D23: 44552 | E23: 23032 | F23: 22 | G23: 146 | H23: F.I 25101 | I23: jfredyl@gmail.com | J23: 4.17 | K23: =YEAR(D23) -> 2021 | L23: =COUNTIF(K22:K39,2021) -> 17
A24: 20131395009 | B24: RAMIREZ NAVARRO SERGIO ALEXANDER | C24: 1026258258 | D24: 44552 | E24: 23033 | F24: 22 | G24: 146 | H24: F.I 25102 | I24: sergio.ramirez@incige.com | J24: 4.3 | K24: =YEAR(D24) -> 2021
A25: 20171395011 | B25: RODRIGUEZ LAMUS DIEGO FERNANDO | C25: 1018469957 | D25: 44552 | E25: 23034 | F25: 22 | G25: 146 | H25: F.I 25103 | I25: dfrodriguezl94@gmail.com | J25: 4.6 | K25: =YEAR(D25) -> 2021
A26: 20191395003 | B26: GONZALEZ HERRE?O DAVID EDUARDO | C26: 1032469491 | D26: 44552 | E26: 23031 | F26: 22 | G26: 145 | H26: F.I 25100 | I26: davide_245@hotmail.com | J26: 4.33 | K26: =YEAR(D26) -> 2021
A27: 20171395004 | B27: CARDONA PIEDRAHITA LEONARDO ALEXANDER | C27: 1032433743 | D27: 44524 | E27: 22953 | F27: 22 | G27: 132 | H27: F.I 25020 | I27: leocardonapiedrahita@gmail.com | J27: 4.62 | K27: =YEAR(D27) -> 2021
A28: 20171395007 | B28: CORTES BUITRAGO OMAR | C28: 19486872 | D28: 44524 | E28: 22954 | F28: 22 | G28: 132 | H28: F.I 25021 | I28: omar.cortes@wgsltda.com.co | J28: 4.41 | K28: =YEAR(D28) -> 2021
A29: 20171395010 | B29: NU?EZ EGUIS EMILY DAYANA | C29: 1026267632 | D29: 44524 | E29: 22955 | F29: 22 | G29: 132 | H29: F.I 25022 | I29: emilyda9@gmail.com | J29: 4.06 | K29: =YEAR(D29) -> 2021
A30: 20162395006 | B30: GUTIERREZ GUERRERO HELBER LEONARDO | C30: 1121838201 | D30: 44484 | E30: 22853 | F30: 22 | G30: 115 | H30: F.I 24920 | I30: leonardoh12@gmail.com | J30: 4.19 | K30: =YEAR(D30) -> 2021
A31: 20192395001 | B31: MORALES ESCOBAR ANA ALEXANDRA | C31: 52897032 | D31: 44484 | E31: 22854 | F31: 22 | G31: 116 | H31: F.I 24921 | I31: analexandra.morales@gmail.com | J31: 4.46 | K31: =YEAR(D31) -> 2021
A32: 20152395002 | B32: BENAVIDES GODOY JEISSON ENRIQUE | C32: 1016034010 | D32: 44428 | E32: 22695 | F32: 22 | G32: 89 | H32: F.I 24762 | I32: jeissonbenavides@hotmail.com | J32: 4.31 | K32: =YEAR(D32) -> 2021
A33: 20161395004 | B33: CORTES BUITRAGO WALTER ANDRES | C33: 1032408256 | D33: 44428 | E33: 22696 | F33: 22 | G33: 89 | H33: F.I 24763 | I33: wacortes88@gmail.com | J33: 4.25 | K33: =YEAR(D33) -> 2021
A34: 20161395005 | B34: CUELLAR GUTIERREZ JULIO ARMANDO | C34: 1032423220 | D34: 44428 | E34: 22697 | F34: 22 | G34: 89 | H34: F.I 24764 | I34: ingjuliocuellar@gmail.com | J34: 4.35 | K34: =YEAR(D34) -> 2021
A35: 20162395009 | B35: OCHOA TORRES SINDY NATALI | C35: 1010191974 | D35: 44428 | E35: 22699 | F35: 22 | G35: 90 | H35: F.I 24766 | I35: nathaliochoa@gmail.com | J35: 4.24 | K35: =YEAR(D35) -> 2021
... A39: 20172395019 | B39: TORO GARAY GISELLE HELENA | C39: 1030586151 | D39: 44251 | E39: 22258 | F39: 22 | G39: 16 | H39: F.I 24324 | I39: gisetoga@live.com | J39: 4.44 | K39: =YEAR(D39) -> 2021
A40: 20161395006 | B40: FLOREZ GARCIA ANDRES CAMILO | C40: 1018454644 | D40: 44174 | E40: 22134 | F40: 21 | G40: 139 | H40: F.I 24200 | I40: andrescfg@gmail.com | J40: 4.25 | K40: =YEAR(D40) -> 2020 | L40: =COUNTIF(K39:K56,2020) -> 4
A41: 20172395006 | B41: LEON CAROLINA GIRON | C41: 53014101 | D41: 44161 | E41: 22081 | F41: 21 | G41: 130 | H41: F.I 24147 | I41: cleongiron@gmail.com | J41: 4.22 | K41: =YEAR(D41) -> 2020
A42: 20171395005 | B42: CARRILLO DURAN IVAN DARIO | C42: 1002021534 | D42: 44118 | E42: 21971 | F42: 21 | G42: 112 | H42: F.I 24037 | I42: Ivancho4321@hotmail.com | J42: 4.68 | K42: =YEAR(D42) -> 2020
A43: 20172395020 | B43: VALLEJO AREVALO WILMER HARVEY | C43: 1018442787 | D43: 43994 | E43: 21534 | F43: 21 | G43: 39 | H43: F.I 23600 | I43: whvallejoa@gmail.com | J43: 4.49 | K43: =YEAR(D43) -> 2020
A44: 20121395004 | B44: FIGUEROA CEFERINO DIANA CAROLINA | C44: 52884117 | D44: 43728 | E44: 20877 | F44: 20 | G44: 117 | H44: F.I. 22941 | I44: carofc@gmail.com | J44: 4.17 | K44: =YEAR(D44) -> 2019 | L44: =COUNTIF(K43:K60,2019) -> 3
...

Sheet 495
A1: CÓD. ESTUDIANTE | B1: NOMBRE | C1: DOCUMENTO | D1: FECHA GRADO | E1: ACTA | F1: LIBRO | G1: FOLIO | H1: REGISTRO | I1: EMAIL | J1: PROMEDIO | K1: EMPRESA | L1: DIR. EMPRESA
A2: 20151295006 | B2: PINZON CASAS CHRISTIAN JESUS | C2: 1018449456 | D2: 45107 | E2: 24425 | F2: 24 | G2: 75 | H2: F.I. 26497 | I2: christian.pinzon92@gmail.com | J2: 4.2 | K2: =YEAR(D2) -> 2023 | L2: =COUNTIF(K2:K14,2023) -> 13
A3: 20161495001 | B3: ARCOS MU?OZ NOE | C3: 80747472 | D3: 45107 | E3: 24420 | F3: 24 | G3: 74 | H3: F.I. 26492 | I3: narcosm@udistrital.edu.co | J3: 4.33 | K3: =YEAR(D3) -> 2023
A4: 20161495023 | B4: WISK CEBALLOS SEBASTIAN | C4: 1032373444 | D4: 45107 | E4: 24429 | F4: 24 | G4: 76 | H4: F.I. 26501 | I4: sebastianwc@hotmail.com | J4: 4.51 | K4: =YEAR(D4) -> 2023
A5: 20162495019 | B5: VARGAS CARRILLO LUZ ANGELA | C5: 53047662 | D5: 45107 | E5: 24428 | F5: 24 | G5: 76 | H5: F.I. 26500 | I5: lavargasc@udistrital.edu.co | J5: 4.48 | K5: =YEAR(D5) -> 2023
A6: 20182495005 | B6: CA?ON CLAVIJO RUBEN ENRIQUE | C6: 81754742 | D6: 45107 | E6: 24421 | F6: 24 | G6: 74 | H6: F.I. 26493 | I6: rubendreamteam@hotmail.com | J6: 4.42 | K6: =YEAR(D6) -> 2023
A7: 20211495004 | B7: MILLAN GOMEZ JORGE ARMANDO | C7: 1030649042 | D7: 45107 | E7: 24423 | F7: 24 | G7: 75 | H7: F.I. 26495 | I7: jamillan94@gmail.com | J7: 4.74 | K7: =YEAR(D7) -> 2023
A8: 20211495010 | B8: ROCHA CALDERON CAMILO ENRIQUE | C8: 1022435418 | D8: 45107 | E8: 24426 | F8: 24 | G8: 75 | H8: F.I. 26498 | I8: cerochac@udistrital.edu.co | J8: 4.85 | K8: =YEAR(D8) -> 2023
A9: 20161495016 | B9: PUPIALES AREVALO ANDRES | C9: 1018413339 | D9: 45016 | E9: 24222 | F9: 24 | G9: 41 | H9: F.I. 26294 | I9: apupiales@gmail.com | J9: 4.52 | K9: =YEAR(D9) -> 2023
A10: 20171495015 | B10: PE?A MENESES JOSE DANIEL | C10: 80111613 | D10: 45016 | E10: 24221 | F10: 24 | G10: 41 | H10: F.I. 26293 | I10: temp2010@msn.com | J10: 4.24 | K10: =YEAR(D10) -> 2023
A11: 20171495022 | B11: VACA VILLAMIL TANIA ALEXANDRA | C11: 1032390922 | D11: 45016 | E11: 24224 | F11: 24 | G11: 42 | H11: F.I. 26296 | I11: alexandra0512sys@gmail.com | J11: 4.21 | K11: =YEAR(D11) -> 2023
A12: 20191495023 | B12: SAENZ BUSTOS DAISY JOHANNA | C12: 1015999367 | D12: 45016 | E12: 24223 | F12: 24 | G12: 41 | H12: F.I. 26295 | I12: daisysaenz1223@gmail.com | J12: 4.36 | K12: =YEAR(D12) -> 2023
A13: 20211495013 | B13: SANCHEZ MANCILLA JUAN SEBASTIAN | C13: 1016098293 | D13: 44973 | E13: 23962 | F13: 24 | G13: 1 | H13: F.I. 26034 | I13: juansanchez011@gmail.com | J13: 4.58 | K13: =YEAR(D13) -> 2023
A14: 20212395003 | B14: GONZALEZ PARDO SONIA LUZ | C14: 1035420008 | D14: 44973 | E14: 23963 | F14: 24 | G14: 1 | H14: F.I. 26035 | I14: sonigonzalezpardo@gmail.com | J14: 4.71 | K14: =YEAR(D14) -> 2023
A15: 20152495001 | B15: BERMUDEZ AMAYA MAURICIO ORLANDO | C15: 79498689 | D15: 44911 | E15: 23950 | F15: 23 | G15: 153 | H15: F.I. 26022 | I15: mobermudeza@udistrital.edu.co | J15: 4.36 | K15: =YEAR(D15) -> 2022 | L15: =COUNTIF(K15:K27,2022) -> 10
A16: 20162495017 | B16: SANCHEZ RODRIGUEZ DANIEL ESTEBAN | C16: 1032417886 | D16: 44911 | E16: 23952 | F16: 23 | G16: 153 | H16: F.I. 26024 | I16: danielssj88@gmail.com | J16: 4.45 | K16: =YEAR(D16) -> 2022
A17: 20192495007 | B17: HERNANDEZ RODRIGUEZ JORGE EDUARDO | C17: 1013673538 | D17: 44911 | E17: 23951 | F17: 23 | G17: 153 | H17: F.I. 26023 | I17: jehernandezrodriguez@gmail.com | J17: 4.66 | K17: =YEAR(D17) -> 2022
A18: 20192495006 | B18: RESTREPO RODRIGUEZ ANDRES OVIDIO | C18: 1032479265 | D18: 44827 | E18: 23779 | F18: 23 | G18: 124 | H18: F.I 25850 | I18: aorestrepor@correo.udistrital.edu.co | J18: 4.84 | K18: =YEAR(D18) -> 2022
A19: 20192495014 | B19: ARIZA RIA?O MADDYZETH | C19: 1023948001 | D19: 44827 | E19: 23773 | F19: 23 | G19: 123 | H19: F.I 25844 | I19: maddyz182@gmail.com | J19: 4.82 | K19: =YEAR(D19) -> 2022
A20: 20162495008 | B20: GUZMAN CASTILLO NANCI MILENA | C20: 52859033 | D20: 44736 | E20: 23457 | F20: 23 | G20: 70 | H20: F.I 25526 | I20: Guzmanmiller02@gmail.com | J20: 3.83 | K20: =YEAR(D20) -> 2022
A21: 20191495029 | B21: VARGAS ANZOLA MANUEL ANTONIO | C21: 79810570 | D21: 44736 | E21: 23464 | F21: 23 | G21: 71 | H21: F.I 25533 | I21: wanuel@gmail.com | J21: 4.46 | K21: =YEAR(D21) -> 2022
A22: 20202495012 | B22: LEAL LARA DANIEL DAVID | C22: 1016103685 | D22: 44736 | E22: 23458 | F22: 23 | G22: 70 | H22: F.I 25527 | I22: ddleall@correo.udistrital.edu.co | J22: 4.91 | K22: =YEAR(D22) -> 2022
A23: 20171495001 | B23: AMEZQUITA TOVAR JUAN CARLOS | C23: 80124664 | D23: 44638 | E23: 23266 | F23: 23 | G23: 38 | H23: F.I 25335 | I23: t.amezquita.juancarlos@gmail.com | J23: 4.63 | K23: =YEAR(D23) -> 2022
A24: 20202495019 | B24: VANEGAS AYALA SEBASTIAN CAMILO | C24: 1026591661 | D24: 44638 | E24: 23270 | F24: 23 | G24: 39 | H24: F.I 25339 | I24: scvanegasa@correo.udistrital.edu.co | J24: 4.93 | K24: =YEAR(D24) -> 2022
A25: 20152495003 | B25: BUITRAGO CASTELLANOS RAUL ALEJANDRO | C25: 1018441667 | D25: 44552 | E25: 23028 | F25: 22 | G25: 145 | H25: F.I 25097 | I25: Raulhabits@gmail.com | J25: 4.33 | K25: =YEAR(D25) -> 2021 | L25: =COUNTIF(K25:K37,2021) -> 10
A26: 20161495003 | B26: CALDERON COY MILTON VICENTE | C26: 80730767 | D26: 44552 | E26: 23029 | F26: 22 | G26: 145 | H26: F.I 25098 | I26: miltonv.calderonc@gmail.com | J26: 4.58 | K26: =YEAR(D26) -> 2021
A27: 20171495018 | B27: RUEDA BASTO JOSE FERNANDO | C27: 11233164 | D27: 44524 | E27: 22956 | F27: 22 | G27: 133 | H27: F.I 25023 | I27: jfrueda@opentic.co | J27: 4.05 | K27: =YEAR(D27) -> 2021
A28: 20181495005 | B28: CIFUENTES SANCHEZ JOSE WILLIAM | C28: 80813753 | D28: 44484 | E28: 22851 | F28: 22 | G28: 115 | H28: F.I 24918 | I28: jwcifuentes@gmail.com | J28: 4.35 | K28: =YEAR(D28) -> 2021
A29: 20192495002 | B29: CARDENAS LANCHEROS ESTEBAN ALEJANDRO | C29: 1013610921 | D29: 44484 | E29: 22850 | F29: 22 | G29: 115 | H29: F.I 24917 | I29: esteban.cardenas.lancheros@gmail.com | J29: 4.71 | K29: =YEAR(D29) -> 2021
A30: 20161495011 | B30: KATZ DELGADO JUAN ESTEBAN | C30: 1018442453 | D30: 44428 | E30: 22698 | F30: 22 | G30: 90 | H30: F.I 24765 | I30: jesteban.katz@gmail.com | J30: 4.39 | K30: =YEAR(D30) -> 2021
A31: 20171495011 | B31: GOMEZ RODRIGUEZ JOSE IGNACIO | C31: 79221631 | D31: 44321 | E31: 22509 | F31: 22 | G31: 58 | H31: F.I 24576 | I31: jignaciogomezr@gmail.com | J31: 4.49 | K31: =YEAR(D31) -> 2021
A32: 20191495016 | B32: MARTINEZ CERVERA DANIEL ESTEBAN | C32: 1019112987 | D32: 44321 | E32: 22510 | F32: 22 | G32: 58 | H32: F.I 24577 | I32: demartinezc@correo.udistrital.edu.co | J32: 4.51 | K32: =YEAR(D32) -> 2021
A33: 20152495008 | B33: RAMIREZ OCHOA JHON JAIME | C33: 1032437478 | D33: 44292 | E33: 22422 | F33: 22 | G33: 44 | H33: F.I 24489 | I33: jjramIrezochoa@gmail.com | J33: 4.45 | K33: =YEAR(D33) -> 2021
A34: 20181495003 | B34: CARDONA TABORDA CARLOS HERNAN | C34: 1018462268 | D34: 44292 | E34: 22419 | F34: 22 | G34: 43 | H34: F.I 24486 | I34: chcardonat@gmail.com | J34: 4.46 | K34: =YEAR(D34) -> 2021
A35: 20162495004 | B35: CASTRO MUNAR VERONICA | C35: 1012352548 | D35: 44174 | E35: 22133 | F35: 21 | G35: 139 | H35: F.I 24199 | I35: vkasmunar@gmail.com | J35: 4.05 | K35: =YEAR(D35) -> 2020 | L35: =COUNTIF(K35:K47,2020) -> 7
A36: 20171495021 | B36: SOLER LOPEZ JORGE FERNANDO | C36: 74085494 | D36: 44174 | E36: 22136 | F36: 21 | G36: 140 | H36: F.I 24202 | I36: jorgesoler1@gmail.com | J36: 4.38 | K36: =YEAR(D36) -> 2020
A37: 20152495002 | B37: BUITRAGO ALVARADO ELISEO FERNANDO | C37: 79703994 | D37: 44161 | E37: 22080 | F37: 21 | G37: 130 | H37: F.I 24146 | I37: ebuitrago@kpmg.com | J37: 4.31 | K37: =YEAR(D37) -> 2020
A38: 20162495016 | B38: ROMERO MORENO FREDY YARNEY | C38: 7170018 | D38: 44118 | E38: 112 | F38: 21 | G38: 112 | H38: F.I 24038 | I38: fredyromero1975@gmail.com | J38: 4.55 | K38: =YEAR(D38) -> 2020
A39: 20162495015 | B39: ROJAS MORENO JUAN FERNANDO | C39: 1014193564 | D39: 43966 | E39: 21451 | F39: 21 | G39: 25 | H39: F.I 23517 | I39: egeda9@gmail.com | J39: 4.74 | K39: =YEAR(D39) -> 2020
A40: 20172495010 | B40: MORENO MARIN JOHN EDISON | C40: 1031124274 | D40: 43966 | E40: 21450 | F40: 21 | G40: 25 | H40: F.I 23516 | I40: johnmoreno333@gmail.com | J40: 4.35 | K40: =YEAR(D40) -> 2020
...

Sheet Hoja5
A1: TOTALIDAD
A2: 2023 | B2: =SUM('195'!L2+'395'!L2+'495'!L2) -> 24
A3: 2022 | B3: =SUM('195'!L7+'295'!L2+'395'!L8+'495'!L15) -> 35
A4: 2021 | B4: =SUM('195'!L16+'395'!L23+'495'!L25) -> 37
A5: 2020 | B5: =SUM('195'!L26+'295'!L3+'395'!L40+'495'!L35) -> 21
A6: 2019 | B6: =SUM('195'!L33+'295'!L6+'395'!L44+'495'!L42) -> 13
