Workbook
Name _Hlk137488061: Ponderacion!$A$1
Name _Toc474160443: anterior!$A$15
Name _Toc474160444: anterior!$A$20
Name _Toc9345829: anterior!$A$16
Name _Toc9345832: anterior!$A$21
Name _Toc9345835: anterior!$A$26
Name _Toc9345838: anterior!$B$31
Name _Toc9345841: anterior!$H$11
Name _Toc9345844: anterior!$H$16
Name _Toc9345847: anterior!$H$21
Name _Toc9345850: anterior!$H$26
Name _Toc9345853: anterior!$H$31
Name _Toc9345856: anterior!$B$38
Name _Toc9348702: anterior!$A$10
Name _Toc9348705: anterior!$A$25
Name _Toc9348706: anterior!$A$30
Name _Toc9348707: anterior!$H$10
Name _Toc9348708: anterior!$H$15
Name _Toc9348709: anterior!$H$20
Name _Toc9348710: anterior!$H$25
Name _Toc9348711: anterior!$H$30
Name _Toc9348712: anterior!$B$36

Sheet FACTORES
A1: Haga clic para escribir el texto de la pregunta | B1: Valor del factor | C1: Recuento | E1: Puntuación | G1: Prueba puntuación | H1: =SUM(C2:C13) -> 0 | I1: =SUM(I2:I145) -> 1482
A2: PROYECTO EDUCATIVO DEL PROGRAMA E IDENTIDAD INSTITUCIONAL. | B2: 1 | C2: 5 | D2: 5 | E2: 12 | G2: =IF(C2>=1,E2,0) -> 12 | H2: =G2*C2 -> 60 | I2: =SUM(H2:H13) -> 179 | J2: =I2/$I$1 -> 0.12078273
A3: PROYECTO EDUCATIVO DEL PROGRAMA E IDENTIDAD INSTITUCIONAL. | B3: 2 | C3: 4 | D3: 4 | E3: 11 | G3: =IF(C3>=1,E3,0) -> 11 | H3: =G3*C3 -> 44
A4: PROYECTO EDUCATIVO DEL PROGRAMA E IDENTIDAD INSTITUCIONAL. | B4: 3 | C4: 1 | D4: 1 | E4: 10 | G4: =IF(C4>=1,E4,0) -> 10 | H4: =G4*C4 -> 10
A5: PROYECTO EDUCATIVO DEL PROGRAMA E IDENTIDAD INSTITUCIONAL. | B5: 4 | C5: 3 | D5: 3 | E5: 9 | G5: =IF(C5>=1,E5,0) -> 9 | H5: =G5*C5 -> 27
A6: PROYECTO EDUCATIVO DEL PROGRAMA E IDENTIDAD INSTITUCIONAL. | B6: 5 | C6: 2 | D6: 2 | E6: 8 | G6: =IF(C6>=1,E6,0) -> 8 | H6: =G6*C6 -> 16
A7: PROYECTO EDUCATIVO DEL PROGRAMA E IDENTIDAD INSTITUCIONAL. | B7: 6 | C7: 2 | D7: 2 | E7: 7 | G7: =IF(C7>=1,E7,0) -> 7 | H7: =G7*C7 -> 14
A8: PROYECTO EDUCATIVO DEL PROGRAMA E IDENTIDAD INSTITUCIONAL. | B8: 7 | C8: 0 | D8: 0 | E8: 6 | G8: =IF(C8>=1,E8,0) -> 6 | H8: =G8*C8 -> 0
A9: PROYECTO EDUCATIVO DEL PROGRAMA E IDENTIDAD INSTITUCIONAL. | B9: 8 | C9: 1 | D9: 1 | E9: 5 | G9: =IF(C9>=1,E9,0) -> 5 | H9: =G9*C9 -> 5
A10: PROYECTO EDUCATIVO DEL PROGRAMA E IDENTIDAD INSTITUCIONAL. | B10: 9 | C10: 0 | D10: 0 | E10: 4 | G10: =IF(C10>=1,E10,0) -> 4 | H10: =G10*C10 -> 0
A11: PROYECTO EDUCATIVO DEL PROGRAMA E IDENTIDAD INSTITUCIONAL. | B11: 10 | C11: 1 | D11: 1 | E11: 3 | G11: =IF(C11>=1,E11,0) -> 3 | H11: =G11*C11 -> 3
A12: PROYECTO EDUCATIVO DEL PROGRAMA E IDENTIDAD INSTITUCIONAL. | B12: 11 | C12: 0 | D12: 0 | E12: 2 | G12: =IF(C12>=1,E12,0) -> 2 | H12: =G12*C12 -> 0
A13: PROYECTO EDUCATIVO DEL PROGRAMA E IDENTIDAD INSTITUCIONAL. | B13: 12 | C13: 0 | D13: 0 | E13: 1 | G13: =IF(C13>=1,E13,0) -> 1 | H13: =G13*C13 -> 0
A14: ESTUDIANTES | B14: 1 | C14: 8 | D14: 8 | E14: 12 | G14: =IF(C14>=1,E14,0) -> 12 | H14: =G14*C14 -> 96 | I14: =SUM(H14:H25) -> 184 | J14: =I14/$I$1 -> 0.12415655
A15: ESTUDIANTES | B15: 2 | C15: 1 | D15: 1 | E15: 11 | G15: =IF(C15>=1,E15,0) -> 11 | H15: =G15*C15 -> 11
A16: ESTUDIANTES | B16: 3 | C16: 4 | D16: 4 | E16: 10 | G16: =IF(C16>=1,E16,0) -> 10 | H16: =G16*C16 -> 40
A17: ESTUDIANTES | B17: 4 | C17: 0 | D17: 0 | E17: 9 | G17: =IF(C17>=1,E17,0) -> 9 | H17: =G17*C17 -> 0
A18: ESTUDIANTES | B18: 5 | C18: 2 | D18: 2 | E18: 8 | G18: =IF(C18>=1,E18,0) -> 8 | H18: =G18*C18 -> 16
A19: ESTUDIANTES | B19: 6 | C19: 1 | D19: 1 | E19: 7 | G19: =IF(C19>=1,E19,0) -> 7 | H19: =G19*C19 -> 7
A20: ESTUDIANTES | B20: 7 | C20: 1 | D20: 1 | E20: 6 | G20: =IF(C20>=1,E20,0) -> 6 | H20: =G20*C20 -> 6
A21: ESTUDIANTES | B21: 8 | C21: 1 | D21: 1 | E21: 5 | G21: =IF(C21>=1,E21,0) -> 5 | H21: =G21*C21 -> 5
A22: ESTUDIANTES | B22: 9 | C22: 0 | D22: 0 | E22: 4 | G22: =IF(C22>=1,E22,0) -> 4 | H22: =G22*C22 -> 0
A23: ESTUDIANTES | B23: 10 | C23: 1 | D23: 1 | E23: 3 | G23: =IF(C23>=1,E23,0) -> 3 | H23: =G23*C23 -> 3
A24: ESTUDIANTES | B24: 11 | C24: 0 | D24: 0 | E24: 2 | G24: =IF(C24>=1,E24,0) -> 2 | H24: =G24*C24 -> 0
A25: ESTUDIANTES | B25: 12 | C25: 0 | D25: 0 | E25: 1 | G25: =IF(C25>=1,E25,0) -> 1 | H25: =G25*C25 -> 0
A26: PROFESORES | B26: 1 | C26: 1 | D26: 1 | E26: 12 | G26: =IF(C26>=1,E26,0) -> 12 | H26: =G26*C26 -> 12 | I26: =SUM(H26:H37) -> 173 | J26: =I26/$I$1 -> 0.11673414
A27: PROFESORES | B27: 2 | C27: 7 | D27: 7 | E27: 11 | G27: =IF(C27>=1,E27,0) -> 11 | H27: =G27*C27 -> 77
A28: PROFESORES | B28: 3 | C28: 4 | D28: 4 | E28: 10 | G28: =IF(C28>=1,E28,0) -> 10 | H28: =G28*C28 -> 40
A29: PROFESORES | B29: 4 | C29: 2 | D29: 2 | E29: 9 | G29: =IF(C29>=1,E29,0) -> 9 | H29: =G29*C29 -> 18
A30: PROFESORES | B30: 5 | C30: 0 | D30: 0 | E30: 8 | G30: =IF(C30>=1,E30,0) -> 8 | H30: =G30*C30 -> 0
A31: PROFESORES | B31: 6 | C31: 1 | D31: 1 | E31: 7 | G31: =IF(C31>=1,E31,0) -> 7 | H31: =G31*C31 -> 7
A32: PROFESORES | B32: 7 | C32: 1 | D32: 1 | E32: 6 | G32: =IF(C32>=1,E32,0) -> 6 | H32: =G32*C32 -> 6
A33: PROFESORES | B33: 8 | C33: 1 | D33: 1 | E33: 5 | G33: =IF(C33>=1,E33,0) -> 5 | H33: =G33*C33 -> 5
A34: PROFESORES | B34: 9 | C34: 2 | D34: 2 | E34: 4 | G34: =IF(C34>=1,E34,0) -> 4 | H34: =G34*C34 -> 8
A35: PROFESORES | B35: 10 | C35: 0 | D35: 0 | E35: 3 | G35: =IF(C35>=1,E35,0) -> 3 | H35: =G35*C35 -> 0
A36: PROFESORES | B36: 11 | C36: 0 | D36: 0 | E36: 2 | G36: =IF(C36>=1,E36,0) -> 2 | H36: =G36*C36 -> 0
A37: PROFESORES | B37: 12 | C37: 0 | D37: 0 | E37: 1 | G37: =IF(C37>=1,E37,0) -> 1 | H37: =G37*C37 -> 0
A38: ASPECTOS ACADÉMICOS Y RESULTADOS DE APRENDIZAJE | B38: 1 | C38: 2 | D38: 2 | E38: 12 | G38: =IF(C38>=1,E38,0) -> 12 | H38: =G38*C38 -> 24 | I38: =SUM(H38:H49) -> 160 | J38: =I38/$I$1 -> 0.10796221
A39: ASPECTOS ACADÉMICOS Y RESULTADOS DE APRENDIZAJE | B39: 2 | C39: 3 | D39: 3 | E39: 11 | G39: =IF(C39>=1,E39,0) -> 11 | H39: =G39*C39 -> 33
A40: ASPECTOS ACADÉMICOS Y RESULTADOS DE APRENDIZAJE | B40: 3 | C40: 3 | D40: 3 | E40: 10 | G40: =IF(C40>=1,E40,0) -> 10 | H40: =G40*C40 -> 30
...

Sheet PEP
A1: Haga clic para escribir el texto de la pregunta | B1: Valor del factor | C1: Recuento | E1: Puntuación | G1: Prueba puntuación | H1: =SUM(C2:C5) -> 0 | I1: =SUM(I2:I5) -> 39
A2: Proyecto educativo del Programa. | B2: 1 | C2: 8 | E2: 2 | G2: =IF(C2>=1,E2,0) -> 2 | H2: =G2*C2 -> 16 | I2: =SUM(H2:H3) -> 21 | J2: =I2/$I$1 -> 0.53846154
A3: Proyecto educativo del Programa. | B3: 2 | C3: 5 | E3: 1 | G3: =IF(C3>=1,E3,0) -> 1 | H3: =G3*C3 -> 5
A4: Relevancia académica y pertinencia social del programa académico | B4: 1 | C4: 5 | E4: 2 | G4: =IF(C4>=1,E4,0) -> 2 | H4: =G4*C4 -> 10 | I4: =SUM(H4:H5) -> 18 | J4: =I4/$I$1 -> 0.46153846
A5: Relevancia académica y pertinencia social del programa académico | B5: 2 | C5: 8 | E5: 1 | G5: =IF(C5>=1,E5,0) -> 1 | H5: =G5*C5 -> 8

Sheet EST
A1: Haga clic para escribir el texto de la pregunta | B1: Valor del factor | C1: Recuento | E1: Puntuación | G1: Prueba puntuación | H1: =SUM(C2:C6) -> 0 | I1: =SUM(I2:I26) -> 172
A2: Participación en actividades de formación integral | B2: 1 | C2: 5 | E2: 5 | G2: =IF(C2>=1,E2,0) -> 5 | H2: =G2*C2 -> 25 | I2: =SUM(H2:H6) -> 57 | J2: =I2/$I$1 -> 0.33139535
A3: Participación en actividades de formación integral | B3: 2 | C3: 4 | E3: 4 | G3: =IF(C3>=1,E3,0) -> 4 | H3: =G3*C3 -> 16
A4: Participación en actividades de formación integral | B4: 3 | C4: 3 | E4: 3 | G4: =IF(C4>=1,E4,0) -> 3 | H4: =G4*C4 -> 9
A5: Participación en actividades de formación integral | B5: 4 | C5: 2 | E5: 2 | G5: =IF(C5>=1,E5,0) -> 2 | H5: =G5*C5 -> 4
A6: Participación en actividades de formación integral | B6: 5 | C6: 3 | E6: 1 | G6: =IF(C6>=1,E6,0) -> 1 | H6: =G6*C6 -> 3
A7: Orientación y seguimiento a estudiantes | B7: 1 | C7: 3 | E7: 3 | G7: =IF(C7>=1,E7,0) -> 3 | H7: =G7*C7 -> 9 | I7: =SUM(H7:H10) -> 31 | J7: =I7/$I$1 -> 0.18023256
A8: Orientación y seguimiento a estudiantes | B8: 2 | C8: 3 | E8: 2 | G8: =IF(C8>=1,E8,0) -> 2 | H8: =G8*C8 -> 6
A9: Orientación y seguimiento a estudiantes | B9: 3 | C9: 8 | E9: 1 | G9: =IF(C9>=1,E9,0) -> 1 | H9: =G9*C9 -> 8
A10: Orientación y seguimiento a estudiantes | B10: 4 | C10: 2 | E10: 4 | G10: =IF(C10>=1,E10,0) -> 4 | H10: =G10*C10 -> 8
A11: Orientación y seguimiento a estudiantes | B11: 5 | C11: 1 | E11: 3 | G11: =IF(C11>=1,E11,0) -> 3 | H11: =G11*C11 -> 3
A12: Capacidad de trabajo autónomo | B12: 1 | C12: 0 | E12: 2 | G12: =IF(C12>=1,E12,0) -> 2 | H12: =G12*C12 -> 0 | I12: =SUM(H12:H15) -> 33 | J12: =I12/$I$1 -> 0.19186047
A13: Capacidad de trabajo autónomo | B13: 2 | C13: 4 | E13: 1 | G13: =IF(C13>=1,E13,0) -> 1 | H13: =G13*C13 -> 4
A14: Capacidad de trabajo autónomo | B14: 3 | C14: 5 | E14: 4 | G14: =IF(C14>=1,E14,0) -> 4 | H14: =G14*C14 -> 20
A15: Capacidad de trabajo autónomo | B15: 4 | C15: 3 | E15: 3 | G15: =IF(C15>=1,E15,0) -> 3 | H15: =G15*C15 -> 9
A16: Capacidad de trabajo autónomo | B16: 5 | C16: 5 | E16: 2 | G16: =IF(C16>=1,E16,0) -> 2 | H16: =G16*C16 -> 10
A17: Reglamento estudiantil y política académica | B17: 1 | C17: 7 | E17: 1 | G17: =IF(C17>=1,E17,0) -> 1 | H17: =G17*C17 -> 7 | I17: =SUM(H17:H20) -> 23 | J17: =I17/$I$1 -> 0.13372093
A18: Reglamento estudiantil y política académica | B18: 2 | C18: 2 | E18: 4 | G18: =IF(C18>=1,E18,0) -> 4 | H18: =G18*C18 -> 8
A19: Reglamento estudiantil y política académica | B19: 3 | C19: 0 | E19: 3 | G19: =IF(C19>=1,E19,0) -> 3 | H19: =G19*C19 -> 0
A20: Reglamento estudiantil y política académica | B20: 4 | C20: 4 | E20: 2 | G20: =IF(C20>=1,E20,0) -> 2 | H20: =G20*C20 -> 8
A21: Reglamento estudiantil y política académica | B21: 5 | C21: 4 | E21: 1 | G21: =IF(C21>=1,E21,0) -> 1 | H21: =G21*C21 -> 4
A22: Estímulos y apoyos para estudiantes | B22: 1 | C22: 2 | E22: 4 | G22: =IF(C22>=1,E22,0) -> 4 | H22: =G22*C22 -> 8 | I22: =SUM(H22:H25) -> 28 | J22: =I22/$I$1 -> 0.1627907
A23: Estímulos y apoyos para estudiantes | B23: 2 | C23: 4 | E23: 3 | G23: =IF(C23>=1,E23,0) -> 3 | H23: =G23*C23 -> 12
A24: Estímulos y apoyos para estudiantes | B24: 3 | C24: 1 | E24: 2 | G24: =IF(C24>=1,E24,0) -> 2 | H24: =G24*C24 -> 2
A25: Estímulos y apoyos para estudiantes | B25: 4 | C25: 6 | E25: 1 | G25: =IF(C25>=1,E25,0) -> 1 | H25: =G25*C25 -> 6
A26: Estímulos y apoyos para estudiantes | B26: 5 | C26: 4 | E26: 4 | G26: =IF(C26>=1,E26,0) -> 4 | H26: =G26*C26 -> 16

Sheet DOC
A1: Haga clic para escribir el texto de la pregunta | B1: Valor del factor | C1: Recuento | E1: Puntuación | G1: Prueba puntuación | H1: =SUM(C2:C9) -> 0 | I1: =SUM(I2:I65) -> 648
A2: Selección, vinculación y permanencia | B2: 1 | C2: 6 | E2: 8 | G2: =IF(C2>=1,E2,0) -> 8 | H2: =G2*C2 -> 48 | I2: =SUM(H2:H9) -> 111 | J2: =I2/$I$1 -> 0.1712963
A3: Selección, vinculación y permanencia | B3: 2 | C3: 4 | E3: 7 | G3: =IF(C3>=1,E3,0) -> 7 | H3: =G3*C3 -> 28
A4: Selección, vinculación y permanencia | B4: 3 | C4: 1 | E4: 6 | G4: =IF(C4>=1,E4,0) -> 6 | H4: =G4*C4 -> 6
A5: Selección, vinculación y permanencia | B5: 4 | C5: 3 | E5: 5 | G5: =IF(C5>=1,E5,0) -> 5 | H5: =G5*C5 -> 15
A6: Selección, vinculación y permanencia | B6: 5 | C6: 3 | E6: 4 | G6: =IF(C6>=1,E6,0) -> 4 | H6: =G6*C6 -> 12
A7: Selección, vinculación y permanencia | B7: 6 | C7: 0 | E7: 3 | G7: =IF(C7>=1,E7,0) -> 3 | H7: =G7*C7 -> 0
A8: Selección, vinculación y permanencia | B8: 7 | C8: 1 | E8: 2 | G8: =IF(C8>=1,E8,0) -> 2 | H8: =G8*C8 -> 2
A9: Selección, vinculación y permanencia | B9: 8 | C9: 0 | E9: 1 | G9: =IF(C9>=1,E9,0) -> 1 | H9: =G9*C9 -> 0
A10: Estatuto profesoral | B10: 1 | C10: 4 | E10: 8 | G10: =IF(C10>=1,E10,0) -> 8 | H10: =G10*C10 -> 32 | I10: =SUM(H10:H17) -> 89 | J10: =I10/$I$1 -> 0.13734568
A11: Estatuto profesoral | B11: 2 | C11: 3 | E11: 7 | G11: =IF(C11>=1,E11,0) -> 7 | H11: =G11*C11 -> 21
A12: Estatuto profesoral | B12: 3 | C12: 3 | E12: 6 | G12: =IF(C12>=1,E12,0) -> 6 | H12: =G12*C12 -> 18
A13: Estatuto profesoral | B13: 4 | C13: 0 | E13: 5 | G13: =IF(C13>=1,E13,0) -> 5 | H13: =G13*C13 -> 0
A14: Estatuto profesoral | B14: 5 | C14: 2 | E14: 4 | G14: =IF(C14>=1,E14,0) -> 4 | H14: =G14*C14 -> 8
A15: Estatuto profesoral | B15: 6 | C15: 2 | E15: 3 | G15: =IF(C15>=1,E15,0) -> 3 | H15: =G15*C15 -> 6
A16: Estatuto profesoral | B16: 7 | C16: 0 | E16: 2 | G16: =IF(C16>=1,E16,0) -> 2 | H16: =G16*C16 -> 0
A17: Estatuto profesoral | B17: 8 | C17: 4 | E17: 1 | G17: =IF(C17>=1,E17,0) -> 1 | H17: =G17*C17 -> 4
A18: Número, dedicación, nivel de formación y experiencia | B18: 1 | C18: 3 | E18: 8 | G18: =IF(C18>=1,E18,0) -> 8 | H18: =G18*C18 -> 24 | I18: =SUM(H18:H25) -> 102 | J18: =I18/$I$1 -> 0.15740741
A19: Número, dedicación, nivel de formación y experiencia | B19: 2 | C19: 5 | E19: 7 | G19: =IF(C19>=1,E19,0) -> 7 | H19: =G19*C19 -> 35
A20: Número, dedicación, nivel de formación y experiencia | B20: 3 | C20: 1 | E20: 6 | G20: =IF(C20>=1,E20,0) -> 6 | H20: =G20*C20 -> 6
A21: Número, dedicación, nivel de formación y experiencia | B21: 4 | C21: 5 | E21: 5 | G21: =IF(C21>=1,E21,0) -> 5 | H21: =G21*C21 -> 25
A22: Número, dedicación, nivel de formación y experiencia | B22: 5 | C22: 2 | E22: 4 | G22: =IF(C22>=1,E22,0) -> 4 | H22: =G22*C22 -> 8
A23: Número, dedicación, nivel de formación y experiencia | B23: 6 | C23: 1 | E23: 3 | G23: =IF(C23>=1,E23,0) -> 3 | H23: =G23*C23 -> 3
A24: Número, dedicación, nivel de formación y experiencia | B24: 7 | C24: 0 | E24: 2 | G24: =IF(C24>=1,E24,0) -> 2 | H24: =G24*C24 -> 0
A25: Número, dedicación, nivel de formación y experiencia | B25: 8 | C25: 1 | E25: 1 | G25: =IF(C25>=1,E25,0) -> 1 | H25: =G25*C25 -> 1
A26: Desarrollo profesoral | B26: 1 | C26: 3 | E26: 8 | G26: =IF(C26>=1,E26,0) -> 8 | H26: =G26*C26 -> 24 | I26: =SUM(H26:H33) -> 99 | J26: =I26/$I$1 -> 0.15277778
A27: Desarrollo profesoral | B27: 2 | C27: 2 | E27: 7 | G27: =IF(C27>=1,E27,0) -> 7 | H27: =G27*C27 -> 14
A28: Desarrollo profesoral | B28: 3 | C28: 6 | E28: 6 | G28: =IF(C28>=1,E28,0) -> 6 | H28: =G28*C28 -> 36
A29: Desarrollo profesoral | B29: 4 | C29: 2 | E29: 5 | G29: =IF(C29>=1,E29,0) -> 5 | H29: =G29*C29 -> 10
A30: Desarrollo profesoral | B30: 5 | C30: 1 | E30: 4 | G30: =IF(C30>=1,E30,0) -> 4 | H30: =G30*C30 -> 4
A31: Desarrollo profesoral | B31: 6 | C31: 3 | E31: 3 | G31: =IF(C31>=1,E31,0) -> 3 | H31: =G31*C31 -> 9
A32: Desarrollo profesoral | B32: 7 | C32: 1 | E32: 2 | G32: =IF(C32>=1,E32,0) -> 2 | H32: =G32*C32 -> 2
A33: Desarrollo profesoral | B33: 8 | C33: 0 | E33: 1 | G33: =IF(C33>=1,E33,0) -> 1 | H33: =G33*C33 -> 0
A34: Estímulos a la trayectoria profesoral | B34: 1 | C34: 0 | E34: 8 | G34: =IF(C34>=1,E34,0) -> 8 | H34: =G34*C34 -> 0 | I34: =SUM(H34:H41) -> 67 | J34: =I34/$I$1 -> 0.10339506
A35: Estímulos a la trayectoria profesoral | B35: 2 | C35: 1 | E35: 7 | G35: =IF(C35>=1,E35,0) -> 7 | H35: =G35*C35 -> 7
A36: Estímulos a la trayectoria profesoral | B36: 3 | C36: 1 | E36: 6 | G36: =IF(C36>=1,E36,0) -> 6 | H36: =G36*C36 -> 6
A37: Estímulos a la trayectoria profesoral | B37: 4 | C37: 4 | E37: 5 | G37: =IF(C37>=1,E37,0) -> 5 | H37: =G37*C37 -> 20
A38: Estímulos a la trayectoria profesoral | B38: 5 | C38: 3 | E38: 4 | G38: =IF(C38>=1,E38,0) -> 4 | H38: =G38*C38 -> 12
A39: Estímulos a la trayectoria profesoral | B39: 6 | C39: 4 | E39: 3 | G39: =IF(C39>=1,E39,0) -> 3 | H39: =G39*C39 -> 12
A40: Estímulos a la trayectoria profesoral | B40: 7 | C40: 5 | E40: 2 | G40: =IF(C40>=1,E40,0) -> 2 | H40: =G40*C40 -> 10
...

Sheet FAC 5
A1: Haga clic para escribir el texto de la pregunta | B1: Valor del factor | C1: Recuento | E1: Puntuación | G1: Prueba puntuación | H1: =SUM(C2:C10) -> 0 | I1: =SUM(I2:I82) -> 810
A2: Integralidad de los aspectos curriculares | B2: 1 | C2: 9 | E2: 9 | G2: 9 | H2: =G2*C2 -> 81 | I2: =SUM(H2:H10) -> 139 | J2: =I2/$I$1 -> 0.17160494
A3: Integralidad de los aspectos curriculares | B3: 2 | C3: 2 | E3: 8 | G3: 8 | H3: =G3*C3 -> 16
A4: Integralidad de los aspectos curriculares | B4: 3 | C4: 4 | E4: 7 | G4: 7 | H4: =G4*C4 -> 28
A5: Integralidad de los aspectos curriculares | B5: 4 | C5: 2 | E5: 6 | G5: 6 | H5: =G5*C5 -> 12
A6: Integralidad de los aspectos curriculares | B6: 5 | C6: 0 | E6: 5 | G6: 5 | H6: =G6*C6 -> 0
A7: Integralidad de los aspectos curriculares | B7: 6 | C7: 0 | E7: 4 | G7: 4 | H7: =G7*C7 -> 0
A8: Integralidad de los aspectos curriculares | B8: 7 | C8: 0 | E8: 3 | G8: 3 | H8: =G8*C8 -> 0
A9: Integralidad de los aspectos curriculares | B9: 8 | C9: 1 | E9: 2 | G9: 2 | H9: =G9*C9 -> 2
A10: Integralidad de los aspectos curriculares | B10: 9 | C10: 0 | E10: 1 | G10: 1 | H10: =G10*C10 -> 0
A11: Flexibilidad de los aspectos curriculares | B11: 1 | C11: 2 | E11: 9 | G11: 9 | H11: =G11*C11 -> 18 | I11: =SUM(H11:H19) -> 119 | J11: =I11/$I$1 -> 0.14691358
A12: Flexibilidad de los aspectos curriculares | B12: 2 | C12: 5 | E12: 8 | G12: 8 | H12: =G12*C12 -> 40
A13: Flexibilidad de los aspectos curriculares | B13: 3 | C13: 1 | E13: 7 | G13: 7 | H13: =G13*C13 -> 7
A14: Flexibilidad de los aspectos curriculares | B14: 4 | C14: 6 | E14: 6 | G14: 6 | H14: =G14*C14 -> 36
A15: Flexibilidad de los aspectos curriculares | B15: 5 | C15: 2 | E15: 5 | G15: 5 | H15: =G15*C15 -> 10
A16: Flexibilidad de los aspectos curriculares | B16: 6 | C16: 2 | E16: 4 | G16: 4 | H16: =G16*C16 -> 8
A17: Flexibilidad de los aspectos curriculares | B17: 7 | C17: 0 | E17: 3 | G17: 3 | H17: =G17*C17 -> 0
A18: Flexibilidad de los aspectos curriculares | B18: 8 | C18: 0 | E18: 2 | G18: 2 | H18: =G18*C18 -> 0
A19: Flexibilidad de los aspectos curriculares | B19: 9 | C19: 0 | E19: 1 | G19: 1 | H19: =G19*C19 -> 0
A20: Interdisciplinariedad | B20: 1 | C20: 1 | E20: 9 | G20: 9 | H20: =G20*C20 -> 9 | I20: =SUM(H20:H28) -> 104 | J20: =I20/$I$1 -> 0.12839506
A21: Interdisciplinariedad | B21: 2 | C21: 3 | E21: 8 | G21: 8 | H21: =G21*C21 -> 24
A22: Interdisciplinariedad | B22: 3 | C22: 3 | E22: 7 | G22: 7 | H22: =G22*C22 -> 21
A23: Interdisciplinariedad | B23: 4 | C23: 3 | E23: 6 | G23: 6 | H23: =G23*C23 -> 18
A24: Interdisciplinariedad | B24: 5 | C24: 4 | E24: 5 | G24: 5 | H24: =G24*C24 -> 20
A25: Interdisciplinariedad | B25: 6 | C25: 1 | E25: 4 | G25: 4 | H25: =G25*C25 -> 4
A26: Interdisciplinariedad | B26: 7 | C26: 2 | E26: 3 | G26: 3 | H26: =G26*C26 -> 6
A27: Interdisciplinariedad | B27: 8 | C27: 1 | E27: 2 | G27: 2 | H27: =G27*C27 -> 2
A28: Interdisciplinariedad | B28: 9 | C28: 0 | E28: 1 | G28: 1 | H28: =G28*C28 -> 0
A29: Estrategias pedagógicas | B29: 1 | C29: 0 | E29: 9 | G29: 9 | H29: =G29*C29 -> 0 | I29: =SUM(H29:H37) -> 92 | J29: =I29/$I$1 -> 0.11358025
A30: Estrategias pedagógicas | B30: 2 | C30: 2 | E30: 8 | G30: 8 | H30: =G30*C30 -> 16
A31: Estrategias pedagógicas | B31: 3 | C31: 1 | E31: 7 | G31: 7 | H31: =G31*C31 -> 7
A32: Estrategias pedagógicas | B32: 4 | C32: 3 | E32: 6 | G32: 6 | H32: =G32*C32 -> 18
A33: Estrategias pedagógicas | B33: 5 | C33: 5 | E33: 5 | G33: 5 | H33: =G33*C33 -> 25
A34: Estrategias pedagógicas | B34: 6 | C34: 5 | E34: 4 | G34: 4 | H34: =G34*C34 -> 20
A35: Estrategias pedagógicas | B35: 7 | C35: 2 | E35: 3 | G35: 3 | H35: =G35*C35 -> 6
A36: Estrategias pedagógicas | B36: 8 | C36: 0 | E36: 2 | G36: 2 | H36: =G36*C36 -> 0
A37: Estrategias pedagógicas | B37: 9 | C37: 0 | E37: 1 | G37: 1 | H37: =G37*C37 -> 0
A38: Sistema de evaluación de estudiantes | B38: 1 | C38: 0 | E38: 9 | G38: 9 | H38: =G38*C38 -> 0 | I38: =SUM(H38:H46) -> 61 | J38: =I38/$I$1 -> 0.075308642
A39: Sistema de evaluación de estudiantes | B39: 2 | C39: 0 | E39: 8 | G39: 8 | H39: =G39*C39 -> 0
A40: Sistema de evaluación de estudiantes | B40: 3 | C40: 0 | E40: 7 | G40: 7 | H40: =G40*C40 -> 0
...

Sheet FAC 6
A1: Haga clic para escribir el texto de la pregunta | B1: Valor del factor | C1: Recuento | E1: Puntuación | G1: Prueba puntuación | H1: =SUM(C2:C5) -> 0 | I1: =SUM(I2:I26) -> 180
A2: Políticas, estrategias y estructura para la permanencia y la graduación | B2: 1 | C2: 5 | E2: 4 | G2: 4 | H2: =G2*C2 -> 20 | I2: =SUM(H2:H5) -> 47 | J2: =I2/$I$1 -> 0.26111111
A3: Políticas, estrategias y estructura para la permanencia y la graduación | B3: 2 | C3: 6 | E3: 3 | G3: 3 | H3: =G3*C3 -> 18
A4: Políticas, estrategias y estructura para la permanencia y la graduación | B4: 3 | C4: 2 | E4: 2 | G4: 2 | H4: =G4*C4 -> 4
A5: Políticas, estrategias y estructura para la permanencia y la graduación | B5: 4 | C5: 5 | E5: 1 | G5: 1 | H5: =G5*C5 -> 5
A6: Caracterización de estudiantes y sistema de alertas tempranas | B6: 1 | C6: 6 | E6: 4 | G6: 4 | H6: =G6*C6 -> 24 | I6: =SUM(H6:H9) -> 50 | J6: =I6/$I$1 -> 0.27777778
A7: Caracterización de estudiantes y sistema de alertas tempranas | B7: 2 | C7: 2 | E7: 3 | G7: 3 | H7: =G7*C7 -> 6
A8: Caracterización de estudiantes y sistema de alertas tempranas | B8: 3 | C8: 10 | E8: 2 | G8: 2 | H8: =G8*C8 -> 20
A9: Caracterización de estudiantes y sistema de alertas tempranas | B9: 4 | C9: 0 | E9: 1 | G9: 1 | H9: =G9*C9 -> 0
A10: Ajustes a los aspectos curriculares | B10: 1 | C10: 2 | E10: 4 | G10: 4 | H10: =G10*C10 -> 8 | I10: =SUM(H10:H13) -> 38 | J10: =I10/$I$1 -> 0.21111111
A11: Ajustes a los aspectos curriculares | B11: 2 | C11: 6 | E11: 3 | G11: 3 | H11: =G11*C11 -> 18
A12: Ajustes a los aspectos curriculares | B12: 3 | C12: 2 | E12: 2 | G12: 2 | H12: =G12*C12 -> 4
A13: Ajustes a los aspectos curriculares | B13: 4 | C13: 8 | E13: 1 | G13: 1 | H13: =G13*C13 -> 8
A14: Mecanismos de selección | B14: 1 | C14: 5 | E14: 4 | G14: 4 | H14: =G14*C14 -> 20 | I14: =SUM(H14:H17) -> 45 | J14: =I14/$I$1 -> 0.25
A15: Mecanismos de selección | B15: 2 | C15: 4 | E15: 3 | G15: 3 | H15: =G15*C15 -> 12
A16: Mecanismos de selección | B16: 3 | C16: 4 | E16: 2 | G16: 2 | H16: =G16*C16 -> 8
A17: Mecanismos de selección | B17: 4 | C17: 5 | E17: 1 | G17: 1 | H17: =G17*C17 -> 5

Sheet FAC 7
A1: Haga clic para escribir el texto de la pregunta | B1: Valor del factor | C1: Recuento | E1: Puntuación | G1: Prueba puntuación | H1: =SUM(C2:C4) -> 0 | I1: =SUM(I2:I26) -> 138
A2: Inserción del programa en contextos académicos nacionales e internacionales | B2: 1 | C2: 5 | E2: 3 | G2: 3 | H2: =G2*C2 -> 15 | I2: =SUM(H2:H5) -> 48 | J2: =I2/$I$1 -> 0.34782609
A3: Inserción del programa en contextos académicos nacionales e internacionales | B3: 2 | C3: 6 | E3: 2 | G3: 2 | H3: =G3*C3 -> 12
A4: Inserción del programa en contextos académicos nacionales e internacionales | B4: 3 | C4: 6 | E4: 1 | G4: 1 | H4: =G4*C4 -> 6
A5: Relaciones externas de profesores y estudiantes | B5: 1 | C5: 5 | E5: 3 | G5: 3 | H5: =G5*C5 -> 15 | I5: =SUM(H5:H8) -> 56 | J5: =I5/$I$1 -> 0.4057971
A6: Relaciones externas de profesores y estudiantes | B6: 2 | C6: 8 | E6: 2 | G6: 2 | H6: =G6*C6 -> 16
A7: Relaciones externas de profesores y estudiantes | B7: 3 | C7: 4 | E7: 1 | G7: 1 | H7: =G7*C7 -> 4
A8: Habilidades comunicativas en una segunda lengua | B8: 1 | C8: 7 | E8: 3 | G8: 3 | H8: =G8*C8 -> 21 | I8: =SUM(H8:H11) -> 34 | J8: =I8/$I$1 -> 0.24637681
A9: Habilidades comunicativas en una segunda lengua | B9: 2 | C9: 3 | E9: 2 | G9: 2 | H9: =G9*C9 -> 6
A10: Habilidades comunicativas en una segunda lengua | B10: 3 | C10: 7 | E10: 1 | G10: 1 | H10: =G10*C10 -> 7

Sheet FAC 8
A1: Haga clic para escribir el texto de la pregunta | B1: Valor del factor | C1: Recuento | E1: Puntuación | G1: Prueba puntuación | H1: =SUM(C2:C3) -> 0 | I1: =SUM(I2:I5) -> 45
A2: Formación para la investigación, desarrollo tecnológico, la innovación y la creación | B2: 1 | C2: 9 | E2: 2 | G2: =IF(C2>=1,E2,0) -> 2 | H2: =G2*C2 -> 18 | I2: =SUM(H2:H3) -> 24 | J2: =I2/$I$1 -> 0.53333333
A3: Formación para la investigación, desarrollo tecnológico, la innovación y la creación | B3: 2 | C3: 6 | E3: 1 | G3: =IF(C3>=1,E3,0) -> 1 | H3: =G3*C3 -> 6
A4: Compromiso con la investigación, desarrollo tecnológico, la innovación y la creación | B4: 1 | C4: 6 | E4: 2 | G4: =IF(C4>=1,E4,0) -> 2 | H4: =G4*C4 -> 12 | I4: =SUM(H4:H5) -> 21 | J4: =I4/$I$1 -> 0.46666667
A5: Compromiso con la investigación, desarrollo tecnológico, la innovación y la creación | B5: 2 | C5: 9 | E5: 1 | G5: =IF(C5>=1,E5,0) -> 1 | H5: =G5*C5 -> 9

Sheet FAC 9
A1: Haga clic para escribir el texto de la pregunta | B1: Valor del factor | C1: Recuento | E1: Puntuación | G1: Prueba puntuación | H1: =SUM(C2:C3) -> 0 | I1: =SUM(I2:I5) -> 42
A2: Programas y servicios | B2: 1 | C2: 9 | E2: 2 | G2: =IF(C2>=1,E2,0) -> 2 | H2: =G2*C2 -> 18 | I2: =SUM(H2:H3) -> 23 | J2: =I2/$I$1 -> 0.54761905
A3: Programas y servicios | B3: 2 | C3: 5 | E3: 1 | G3: =IF(C3>=1,E3,0) -> 1 | H3: =G3*C3 -> 5
A4: Participación y seguimiento | B4: 1 | C4: 5 | E4: 2 | G4: =IF(C4>=1,E4,0) -> 2 | H4: =G4*C4 -> 10 | I4: =SUM(H4:H5) -> 19 | J4: =I4/$I$1 -> 0.45238095
A5: Participación y seguimiento | B5: 2 | C5: 9 | E5: 1 | G5: =IF(C5>=1,E5,0) -> 1 | H5: =G5*C5 -> 9

Sheet FAC 10
A1: Haga clic para escribir el texto de la pregunta | B1: Valor del factor | C1: Recuento | E1: Puntuación | G1: Prueba puntuación | H1: =SUM(C2:C4) -> 0 | I1: =SUM(I2:I26) -> 138
A2: Estrategias y recursos de apoyo a profesores | B2: 1 | C2: 8 | E2: 3 | G2: 3 | H2: =G2*C2 -> 24 | I2: =SUM(H2:H5) -> 55 | J2: =I2/$I$1 -> 0.39855072
A3: Estrategias y recursos de apoyo a profesores | B3: 2 | C3: 6 | E3: 2 | G3: 2 | H3: =G3*C3 -> 12
A4: Estrategias y recursos de apoyo a profesores | B4: 3 | C4: 4 | E4: 1 | G4: 1 | H4: =G4*C4 -> 4
A5: Estrategias y recursos de apoyo a estudiantes | B5: 1 | C5: 5 | E5: 3 | G5: 3 | H5: =G5*C5 -> 15 | I5: =SUM(H5:H8) -> 49 | J5: =I5/$I$1 -> 0.35507246
A6: Estrategias y recursos de apoyo a estudiantes | B6: 2 | C6: 6 | E6: 2 | G6: 2 | H6: =G6*C6 -> 12
A7: Estrategias y recursos de apoyo a estudiantes | B7: 3 | C7: 7 | E7: 1 | G7: 1 | H7: =G7*C7 -> 7
A8: Recursos bibliográficos y de información | B8: 1 | C8: 5 | E8: 3 | G8: 3 | H8: =G8*C8 -> 15 | I8: =SUM(H8:H11) -> 34 | J8: =I8/$I$1 -> 0.24637681
A9: Recursos bibliográficos y de información | B9: 2 | C9: 6 | E9: 2 | G9: 2 | H9: =G9*C9 -> 12
A10: Recursos bibliográficos y de información | B10: 3 | C10: 7 | E10: 1 | G10: 1 | H10: =G10*C10 -> 7

Sheet FAC 11
A1: Haga clic para escribir el texto de la pregunta | B1: Valor del factor | C1: Recuento | E1: Puntuación | G1: Prueba puntuación | H1: =SUM(C2:C7) -> 0 | I1: =SUM(I2:I79) -> 378
A2: Organización y administración | B2: 1 | C2: 6 | E2: 6 | G2: 6 | H2: =G2*C2 -> 36 | I2: =SUM(H2:H7) -> 87 | J2: =I2/$I$1 -> 0.23015873
A3: Organización y administración | B3: 2 | C3: 6 | E3: 5 | G3: 5 | H3: =G3*C3 -> 30
A4: Organización y administración | B4: 3 | C4: 4 | E4: 4 | G4: 4 | H4: =G4*C4 -> 16
A5: Organización y administración | B5: 4 | C5: 1 | E5: 3 | G5: 3 | H5: =G5*C5 -> 3
A6: Organización y administración | B6: 5 | C6: 1 | E6: 2 | G6: 2 | H6: =G6*C6 -> 2
A7: Organización y administración | B7: 6 | C7: 0 | E7: 1 | G7: 1 | H7: =G7*C7 -> 0
A8: Dirección y gestión | B8: 1 | C8: 3 | E8: 6 | G8: 6 | H8: =G8*C8 -> 18 | I8: =SUM(H8:H13) -> 80 | J8: =I8/$I$1 -> 0.21164021
A9: Dirección y gestión | B9: 2 | C9: 6 | E9: 5 | G9: 5 | H9: =G9*C9 -> 30
A10: Dirección y gestión | B10: 3 | C10: 5 | E10: 4 | G10: 4 | H10: =G10*C10 -> 20
A11: Dirección y gestión | B11: 4 | C11: 4 | E11: 3 | G11: 3 | H11: =G11*C11 -> 12
A12: Dirección y gestión | B12: 5 | C12: 0 | E12: 2 | G12: 2 | H12: =G12*C12 -> 0
A13: Dirección y gestión | B13: 6 | C13: 0 | E13: 1 | G13: 1 | H13: =G13*C13 -> 0
A14: Sistemas de comunicación e información | B14: 1 | C14: 0 | E14: 6 | G14: 6 | H14: =G14*C14 -> 0 | I14: =SUM(H14:H19) -> 50 | J14: =I14/$I$1 -> 0.13227513
A15: Sistemas de comunicación e información | B15: 2 | C15: 0 | E15: 5 | G15: 5 | H15: =G15*C15 -> 0
A16: Sistemas de comunicación e información | B16: 3 | C16: 4 | E16: 4 | G16: 4 | H16: =G16*C16 -> 16
A17: Sistemas de comunicación e información | B17: 4 | C17: 6 | E17: 3 | G17: 3 | H17: =G17*C17 -> 18
A18: Sistemas de comunicación e información | B18: 5 | C18: 8 | E18: 2 | G18: 2 | H18: =G18*C18 -> 16
A19: Sistemas de comunicación e información | B19: 6 | C19: 0 | E19: 1 | G19: 1 | H19: =G19*C19 -> 0
A20: Estudiantes y capacidad institucional | B20: 1 | C20: 1 | E20: 6 | G20: 6 | H20: =G20*C20 -> 6 | I20: =SUM(H20:H25) -> 45 | J20: =I20/$I$1 -> 0.11904762
A21: Estudiantes y capacidad institucional | B21: 2 | C21: 0 | E21: 5 | G21: 5 | H21: =G21*C21 -> 0
A22: Estudiantes y capacidad institucional | B22: 3 | C22: 3 | E22: 4 | G22: 4 | H22: =G22*C22 -> 12
A23: Estudiantes y capacidad institucional | B23: 4 | C23: 4 | E23: 3 | G23: 3 | H23: =G23*C23 -> 12
A24: Estudiantes y capacidad institucional | B24: 5 | C24: 5 | E24: 2 | G24: 2 | H24: =G24*C24 -> 10
A25: Estudiantes y capacidad institucional | B25: 6 | C25: 5 | E25: 1 | G25: 1 | H25: =G25*C25 -> 5
A26: Financiación del programa académico | B26: 1 | C26: 3 | E26: 6 | G26: 6 | H26: =G26*C26 -> 18 | I26: =SUM(H26:H31) -> 49 | J26: =I26/$I$1 -> 0.12962963
A27: Financiación del programa académico | B27: 2 | C27: 3 | E27: 5 | G27: 5 | H27: =G27*C27 -> 15
A28: Financiación del programa académico | B28: 3 | C28: 0 | E28: 4 | G28: 4 | H28: =G28*C28 -> 0
A29: Financiación del programa académico | B29: 4 | C29: 1 | E29: 3 | G29: 3 | H29: =G29*C29 -> 3
A30: Financiación del programa académico | B30: 5 | C30: 2 | E30: 2 | G30: 2 | H30: =G30*C30 -> 4
A31: Financiación del programa académico | B31: 6 | C31: 9 | E31: 1 | G31: 1 | H31: =G31*C31 -> 9
A32: Aseguramiento de la alta calidad y mejora continua | B32: 1 | C32: 5 | E32: 6 | G32: 6 | H32: =G32*C32 -> 30 | I32: =SUM(H32:H37) -> 67 | J32: =I32/$I$1 -> 0.17724868
A33: Aseguramiento de la alta calidad y mejora continua | B33: 2 | C33: 3 | E33: 5 | G33: 5 | H33: =G33*C33 -> 15
A34: Aseguramiento de la alta calidad y mejora continua | B34: 3 | C34: 2 | E34: 4 | G34: 4 | H34: =G34*C34 -> 8
A35: Aseguramiento de la alta calidad y mejora continua | B35: 4 | C35: 2 | E35: 3 | G35: 3 | H35: =G35*C35 -> 6
A36: Aseguramiento de la alta calidad y mejora continua | B36: 5 | C36: 2 | E36: 2 | G36: 2 | H36: =G36*C36 -> 4
A37: Aseguramiento de la alta calidad y mejora continua | B37: 6 | C37: 4 | E37: 1 | G37: 1 | H37: =G37*C37 -> 4

Sheet FAC 12
A1: Haga clic para escribir el texto de la pregunta | B1: Valor del factor | C1: Recuento | E1: Puntuación | G1: Prueba puntuación | H1: =SUM(C2:C3) -> 0 | I1: =SUM(I2:I5) -> 42
A2: Recursos de infraestructura física y tecnológica | B2: 1 | C2: 8 | E2: 2 | G2: =IF(C2>=1,E2,0) -> 2 | H2: =G2*C2 -> 16 | I2: =SUM(H2:H3) -> 22 | J2: =I2/$I$1 -> 0.52380952
A3: Recursos de infraestructura física y tecnológica | B3: 2 | C3: 6 | E3: 1 | G3: =IF(C3>=1,E3,0) -> 1 | H3: =G3*C3 -> 6
A4: Recursos informáticos y de comunicación | B4: 1 | C4: 6 | E4: 2 | G4: =IF(C4>=1,E4,0) -> 2 | H4: =G4*C4 -> 12 | I4: =SUM(H4:H5) -> 20 | J4: =I4/$I$1 -> 0.47619048
A5: Recursos informáticos y de comunicación | B5: 2 | C5: 8 | E5: 1 | G5: =IF(C5>=1,E5,0) -> 1 | H5: =G5*C5 -> 8

Sheet Graficos
B2: FACTOR | C2: PONDERACIÓN
B3: PROYECTO EDUCATIVO DEL PROGRAMA E IDENTIDAD INSTITUCIONAL. | C3: =FACTORES!J2 -> 0.12078273
B4: ESTUDIANTES | C4: =FACTORES!J14 -> 0.12415655
B5: PROFESORES | C5: =FACTORES!J26 -> 0.11673414
B6: EGRESADOS | C6: =FACTORES!J38 -> 0.10796221
B7: ASPECTOS ACADÉMICOS Y RESULTADOS DE APRENDIZAJE | C7: =FACTORES!J50 -> 0.067476383
B8: PERMANENCIA Y GRADUACIÓN | C8: =FACTORES!J62 -> 0.072874494
B9: INTERACCIÓN CON EL ENTORNO NACIONAL E INTERNACIONAL | C9: =FACTORES!J74 -> 0.10593792
B10: APORTES DE LA INVESTIGACIÓN, LA INNOVACIÓN, EL DESARROLLO TECNOLÓGICO Y LA CREACIÓN, ASOCIADOS AL PROGRAMA ACADÉMICO | C10: =FACTORES!J86 -> 0.047908232
B11: BIENESTAR DE LA COMUNIDAD ACADÉMICA DEL PROGRAMA | C11: =FACTORES!J98 -> 0.064102564
B12: MEDIOS EDUCATIVOS Y AMBIENTES DE APRENDIZAJE | C12: =FACTORES!J110 -> 0.068825911
B13: ORGANIZACIÓN, ADMINISTRACIÓN Y FINANCIACIÓN DEL PROGRAMA ACADÉMICO | C13: =FACTORES!J122 -> 0.066801619
B14: RECURSOS FÍSICOS Y TECNOLÓGICOS | C14: =FACTORES!J134 -> 0.036437247
B17: FACTOR 1 | C17: PONDERACIÓN
A18: 1 | B18: Proyecto educativo del Programa. | C18: =PEP!J2 -> 0.53846154
A19: 2 | B19: Relevancia académica y pertinencia social del programa académico | C19: =PEP!J4 -> 0.46153846
B22: FACTOR 2 | C22: PONDERACIÓN
A23: 3 | B23: Participación en actividades de formación integral | C23: =EST!J2 -> 0.33139535
A24: 4 | B24: Orientación y seguimiento a estudiantes | C24: =EST!J7 -> 0.18023256
A25: 5 | B25: Capacidad de trabajo autónomo | C25: =EST!J12 -> 0.19186047
A26: 6 | B26: Reglamento estudiantil y política académica | C26: =EST!J17 -> 0.13372093
A27: 7 | B27: Estímulos y apoyos para estudiantes | C27: =EST!J22 -> 0.1627907
B30: FACTOR 3 | C30: PONDERACIÓN
A31: 8 | B31: Selección, vinculación y permanencia | C31: =DOC!J2 -> 0.1712963
A32: 9 | B32: Estatuto profesoral | C32: =DOC!J10 -> 0.13734568
A33: 10 | B33: Número, dedicación, nivel de formación y experiencia | C33: =DOC!J18 -> 0.15740741
A34: 11 | B34: Desarrollo profesoral | C34: =DOC!J26 -> 0.15277778
A35: 12 | B35: Estímulos a la trayectoria profesoral | C35: =DOC!J34 -> 0.10339506
A36: 13 | B36: Producción, pertinencia, utilización e impacto del material docente | C36: =DOC!J42 -> 0.11728395
A37: 14 | B37: Remuneración por méritos | C37: =DOC!J50 -> 0.094135802
A38: 15 | B38: Evaluación de profesores | C38: =DOC!J58 -> 0.066358025
B41: FACTOR 5 | C41: PONDERACIÓN
A42: 16 | B42: Integralidad de los aspectos curriculares | C42: ='FAC 5'!J2 -> 0.17160494
A43: 17 | B43: Flexibilidad de los aspectos curriculares | C43: ='FAC 5'!J11 -> 0.14691358
A44: 18 | B44: Interdisciplinariedad | C44: ='FAC 5'!J20 -> 0.12839506
A45: 19 | B45: Estrategias pedagógicas | C45: ='FAC 5'!J29 -> 0.11358025
A46: 20 | B46: Sistema de evaluación de estudiantes | C46: ='FAC 5'!J38 -> 0.075308642
A47: 21 | B47: Resultados de aprendizaje | C47: ='FAC 5'!J47 -> 0.12839506
A48: 22 | B48: Competencias | C48: ='FAC 5'!J56 -> 0.10987654
A49: 23 | B49: Evaluación y autorregulación del programa académico | C49: ='FAC 5'!J65 -> 0.067901235
...

Sheet Ponderacion
A1: # Factor | B1: Factor | C1: Ponderación | D1: Características | E1: Ponderación
A2: 1 | B2: PROYECTO EDUCATIVO DEL PROGRAMA E IDENTIDAD INSTITUCIONAL. | C2: =Graficos!C3 -> 0.12078273 | D2: Proyecto educativo del Programa. | E2: =Graficos!C18 -> 0.53846154
D3: Relevancia académica y pertinencia social del programa académico | E3: =Graficos!C19 -> 0.46153846
A4: 2 | B4: ESTUDIANTES | C4: =Graficos!C4 -> 0.12415655 | D4: Participación en actividades de formación integral | E4: =Graficos!C23 -> 0.33139535
D5: Orientación y seguimiento a estudiantes | E5: =Graficos!C24 -> 0.18023256
D6: Capacidad de trabajo autónomo | E6: =Graficos!C25 -> 0.19186047
D7: Reglamento estudiantil y política académica | E7: =Graficos!C26 -> 0.13372093
D8: Estímulos y apoyos para estudiantes | E8: =Graficos!C27 -> 0.1627907
A9: 3 | B9: PROFESORES | C9: =Graficos!C5 -> 0.11673414 | D9: Selección, vinculación y permanencia | E9: =Graficos!C31 -> 0.1712963
D10: Estatuto profesoral | E10: =Graficos!C32 -> 0.13734568
D11: Número, dedicación, nivel de formación y experiencia | E11: =Graficos!C33 -> 0.15740741
D12: Desarrollo profesoral | E12: =Graficos!C34 -> 0.15277778
D13: Estímulos a la trayectoria profesoral | E13: =Graficos!C35 -> 0.10339506
D14: Producción, pertinencia, utilización e impacto del material docente | E14: =Graficos!C36 -> 0.11728395
D15: Remuneración por méritos | E15: =Graficos!C37 -> 0.094135802
D16: Evaluación de profesores | E16: =Graficos!C38 -> 0.066358025
A17: 4 | B17: EGRESADOS | C17: =Graficos!C6 -> 0.10796221 | D17: Seguimiento a los egresados | E17: 0.54761905
D18: Impacto de los egresados en el medio social y académico | E18: 0.45238095
A19: 5 | B19: ASPECTOS ACADÉMICOS Y RESULTADOS DE APRENDIZAJE | C19: =Graficos!C7 -> 0.067476383 | D19: Integralidad de los aspectos curriculares | E19: =Graficos!C42 -> 0.17160494
D20: Flexibilidad de los aspectos curriculares | E20: =Graficos!C43 -> 0.14691358
D21: Interdisciplinariedad | E21: =Graficos!C44 -> 0.12839506
D22: Estrategias pedagógicas | E22: =Graficos!C45 -> 0.11358025
D23: Sistema de evaluación de estudiantes | E23: =Graficos!C46 -> 0.075308642
D24: Resultados de aprendizaje | E24: =Graficos!C47 -> 0.12839506
D25: Competencias | E25: =Graficos!C48 -> 0.10987654
D26: Evaluación y autorregulación del programa académico | E26: =Graficos!C49 -> 0.067901235
D27: Vinculación e interacción social | E27: =Graficos!C50 -> 0.058024691
A28: 6 | B28: PERMANENCIA Y GRADUACIÓN | C28: =Graficos!C8 -> 0.072874494 | D28: Políticas, estrategias y estructura para la permanencia y la graduación | E28: =Graficos!C54 -> 0.26111111
D29: Caracterización de estudiantes y sistema de alertas tempranas | E29: =Graficos!C55 -> 0.27777778
D30: Ajustes a los aspectos curriculares | E30: =Graficos!C56 -> 0.21111111
D31: Mecanismos de selección | E31: =Graficos!C57 -> 0.25
A32: 7 | B32: INTERACCIÓN CON EL ENTORNO NACIONAL E INTERNACIONAL | C32: =Graficos!C9 -> 0.10593792 | D32: Inserción del programa en contextos académicos nacionales e internacionales | E32: =Graficos!C61 -> 0.34782609
D33: Relaciones externas de profesores y estudiantes | E33: =Graficos!C62 -> 0.4057971
D34: Habilidades comunicativas en una segunda lengua | E34: =Graficos!C63 -> 0.24637681
A35: 8 | B35: APORTES DE LA INVESTIGACIÓN, LA INNOVACIÓN, EL DESARROLLO TECNOLÓGICO Y LA CREACIÓN, ASOCIADOS AL PROGRAMA ACADÉMICO | C35: =Graficos!C10 -> 0.047908232 | D35: Formación para la investigación, desarrollo tecnológico, la innovación y la creación | E35: =Graficos!C66 -> 0.53333333
D37: Compromiso con la investigación, desarrollo tecnológico, la innovación y la creación | E37: =Graficos!C67 -> 0.46666667
A38: 9 | B38: BIENESTAR DE LA COMUNIDAD ACADÉMICA DEL PROGRAMA | C38: =Graficos!C11 -> 0.064102564 | D38: Programas y servicios | E38: =Graficos!C71 -> 0.54761905
D39: Participación y seguimiento | E39: =Graficos!C72 -> 0.45238095
A40: 10 | B40: MEDIOS EDUCATIVOS Y AMBIENTES DE APRENDIZAJE | C40: =Graficos!C12 -> 0.068825911 | D40: Estrategias y recursos de apoyo a profesores | E40: =Graficos!C76 -> 0.39855072
A41: 10 | D41: Estrategias y recursos de apoyo a estudiantes | E41: =Graficos!C77 -> 0.35507246
...

Sheet Hoja2
A1: FACTOR | B1: Valoración interpretativa | C1: NOTA | D1: PONDERACIÓN | G1: # Factor | H1: Factor | I1: Ponderación | J1: Valoración interpretativa | K1: NOTA | M1: PROYECTO EDUCATIVO DEL PROGRAMA E IDENTIDAD INSTITUCIONAL.
A2: Factor 1. Misión y visión de la Universidad. | B2: Se cumple en alto grado | C2: 4.4 | D2: 0.147 | E2: 0.7 | G2: 1 | H2: PROYECTO EDUCATIVO DEL PROGRAMA E IDENTIDAD INSTITUCIONAL. | I2: 0.12078273 | M2: Grado de cumplimiento | O2: Calificación numérica | Q2: Ponderación del factor
M4: Anterior 2020 | N4: Actual 2025 | O4: Anterior 2020 | P4: Actual 2025
M5: Se cumple en alto grado | N5: Se cumple en alto grado | O5: 4.4 | P5: 4 | Q5: 0.12078273
M6: Fortalezas | O6: Oportunidades de mejora
A9: Factor 2. Estudiantes. | B9: Se cumple en alto grado | C9: 4 | D9: 0.137 | E9: 0.5 | G9: 2 | H9: ESTUDIANTES | I9: 0.12415655 | M9: ESTUDIANTES
M10: Grado de cumplimiento | O10: Calificación numérica | Q10: Ponderación del factor
M12: Anterior 2020 | N12: Actual 2025 | O12: Anterior 2020 | P12: Actual 2025
M13: Se cumple en alto grado | N13: Se cumple en alto grado | O13: 4 | P13: 4.6 | Q13: 0.12415655
M14: Fortalezas | O14: Oportunidades de mejora
A17: Factor 3. Profesores. | B17: Se cumple en alto grado | C17: 4.2 | D17: 0.126 | E17: 0.5 | G17: 3 | H17: PROFESORES | I17: 0.11673414 | M17: PROFESORES
M18: Grado de cumplimiento | O18: Calificación numérica | Q18: Ponderación del factor
M20: Anterior 2020 | N20: Actual 2025 | O20: Anterior 2020 | P20: Actual 2025
M21: Se cumple en alto grado | N21: Se cumple en alto grado | O21: 4.2 | P21: 4.7 | Q21: 0.11673414
M22: Fortalezas | O22: Oportunidades de mejora
A25: Factor 9. Graduados y Análisis de Impacto del Programa. | B25: Se cumple en alto grado | C25: 4.1 | D25: 0.067 | E25: 0.3 | G25: 4 | H25: EGRESADOS | I25: 0.10796221 | M25: EGRESADOS
M26: Grado de cumplimiento | O26: Calificación numérica | Q26: Ponderación del factor
M28: Anterior 2020 | N28: Actual 2025 | O28: Anterior 2020 | P28: Actual 2025
M29: Se cumple en alto grado | N29: Se cumple en alto grado | O29: 4 | P29: 4.8 | Q29: 0.10796221
M30: Fortalezas | O30: Oportunidades de mejora
A33: Factor 4. Procesos Académicos y Lineamientos Curriculares. | B33: Se cumple en alto grado | C33: 4 | D33: 0.11 | E33: 0.4 | G33: 5 | H33: ASPECTOS ACADÉMICOS Y RESULTADOS DE APRENDIZAJE | I33: 0.067476383 | M33: ASPECTOS ACADÉMICOS Y RESULTADOS DE APRENDIZAJE
M34: Grado de cumplimiento | O34: Calificación numérica | Q34: Ponderación del factor
M36: Anterior 2020 | N36: Actual 2025 | O36: Anterior 2020 | P36: Actual 2025
M37: Se cumple en alto grado | N37: Se cumple en alto grado | O37: 4.2 | P37: 4.3 | Q37: 0.067476383
M38: Fortalezas | O38: Oportunidades de mejora
A41: Factor 5. Investigación, generación de conocimiento y producción artística. | B41: Se cumple en alto grado | C41: 4.2 | D41: 0.114 | E41: 0.5 | G41: 6 | H41: PERMANENCIA Y GRADUACIÓN | I41: 0.072874494 | M41: PERMANENCIA Y GRADUACIÓN
M42: Grado de cumplimiento | O42: Calificación numérica | Q42: Ponderación del factor
M44: Anterior 2020 | N44: Actual 2025 | O44: Anterior 2020 | P44: Actual 2025
M45: Se cumple en alto grado | N45: Se cumple en alto grado | O45: 4 | P45: 5 | Q45: 0.072874494
M46: Fortalezas | O46: Oportunidades de mejora
A49: Factor 6. Articulación con el entorno y capacidad para generar procesos de innovación. | B49: Se cumple en alto grado | C49: 4 | D49: 0.093 | E49: 0.4 | G49: 7 | H49: INTERACCIÓN CON EL ENTORNO NACIONAL E INTERNACIONAL | I49: 0.10593792 | M49: INTERACCIÓN CON EL ENTORNO NACIONAL E INTERNACIONAL
M50: Grado de cumplimiento | O50: Calificación numérica | Q50: Ponderación del factor
M52: Anterior 2020 | N52: Actual 2025 | O52: Anterior 2020 | P52: Actual 2025
M53: Se cumple en alto grado | N53: Se cumple en alto grado | O53: 4 | P53: 4.5 | Q53: 0.10593792
M54: Fortalezas | O54: Oportunidades de mejora
A57: Factor 7. Internacionalización, Alianzas Estratégicas e Inserción en Redes Científicas Globales. | B57: Se cumple aceptablemente | C57: 3.4 | D57: 0.085 | E57: 0.3 | G57: 8 | H57: APORTES DE LA INVESTIGACIÓN, LA INNOVACIÓN, EL DESARROLLO TECNOLÓGICO Y LA CREACIÓN, ASOCIADOS AL PROGRAMA ACADÉMICO | I57: 0.047908232 | M57: APORTES DE LA INVESTIGACIÓN, LA INNOVACIÓN, EL DESARROLLO TECNOLÓGICO Y LA CREACIÓN, ASOCIADOS AL PROGRAMA ACADÉMICO
M58: Grado de cumplimiento | O58: Calificación numérica | Q58: Ponderación del factor
M60: Anterior 2020 | N60: Actual 2025 | O60: Anterior 2020 | P60: Actual 2025
M61: Se cumple aceptablemente | N61: Se cumple en alto grado | O61: 3.4 | P61: 4.5 | Q61: 0.047908232
M62: Fortalezas | O62: Oportunidades de mejora
...

Sheet anterior
C3: Grado de cumplimiento | E3: Valoración Cualitativa | G3: Cuantitativa
C4: Se cumple plenamente | D4: 45 - 50 | E4: Existen y tienen coherencia total con los indicadores | F4: Se cumple plenamente | G4: 5
C5: Se cumple en alto grado | D5: 38 – 44 | E5: Existen y tienen coherencia parcial con los indicadores | F5: Se cumple en alto grado | G5: 4
C6: Se cumple aceptablemente | D6: 30- 37 | E6: Existen y no tienen coherencia con los indicadores | F6: Se cumple aceptablemente | G6: 3
C7: Es insuficiente | D7: 20 - 29 | E7: Está en elaboración - Dependiendo el estado | F7: Se cumple insatisfactoriamente | G7: 2
C8: Es deficiente | D8: 0 - 19 | E8: No existe | F8: No se cumple | G8: 1
A10: FACTOR 1. MISIÓN Y VISIÓN DE LA UNIVERSIDAD | H10: FACTOR 6. ARTICULACIÓN CON EL ENTORNO Y CAPACIDAD PARA GENERAR PROCESOS DE INNOVACIÓN.
A12: Ponderación | B12: Grado de cumplimiento (1-5) | C12: Evaluación -ponderación | D12: Logro Ideal | E12: Relación con el logro ideal | F12: Valoración interpretativa | H12: Ponderación | I12: Grado de cumplimiento (1-5) | J12: Evaluación -ponderación | K12: Logro Ideal | L12: Relación con el logro ideal | M12: Valoración interpretativa
A13: 0.147 | B13: 4.4 | C13: 0.7 | D13: 0.8 | E13: 0.9 | F13: Se cumple en alto grado | H13: 0.09 | I13: 4 | J13: 0.4 | K13: 0.5 | L13: 0.8 | M13: Se cumple en alto grado
A15: FACTOR 2. ESTUDIANTES | H15: FACTOR 7. INTERNACIONALIZACIÓN, ALIANZAS ESTRATÉGICAS E INSERCIÓN EN REDES CIENTÍFICAS GLOBALES
A17: Ponderación | B17: Grado de cumplimiento (1-5) | C17: Evaluación -ponderación | D17: Logro Ideal | E17: Relación con el logro ideal | F17: Valoración interpretativa | H17: Ponderación | I17: Grado de cumplimiento (1-5) | J17: Evaluación -ponderación | K17: Logro Ideal | L17: Relación con el logro ideal | M17: Valoración interpretativa
A18: 0.14 | B18: 4 | C18: 0.5 | D18: 0.7 | E18: 0.8 | F18: Se cumple en alto grado | H18: 0.09 | I18: 3.4 | J18: 0.3 | K18: 0.5 | L18: 0.6 | M18: Cumple Aceptablemente
A20: FACTOR 3. PROFESORES | H20: FACTOR 8. BIENESTAR Y AMBIENTE INSTITUCIONAL
A22: Ponderación | B22: Grado de cumplimiento (1-5) | C22: Evaluación -ponderación | D22: Logro Ideal | E22: Relación con el logro ideal | F22: Valoración interpretativa | H22: Ponderación | I22: Grado de cumplimiento (1-5) | J22: Evaluación -ponderación | K22: Logro Ideal | L22: Relación con el logro ideal | M22: Valoración interpretativa
A23: 0.13 | B23: 4.2 | C23: 0.6 | D23: 0.7 | E23: 0.9 | F23: Se cumple en alto grado | H23: 0.05 | I23: 4 | J23: 0.2 | K23: 0.3 | L23: 0.8 | M23: Se cumple en alto grado
A25: FACTOR 4. PROCESOS ACADÉMICOS Y LINEAMIENTOS CURRICULARES. | H25: FACTOR 9. GRADUADOS Y ANÁLISIS DE IMPACTO
A27: Ponderación | B27: Grado de cumplimiento (1-5) | C27: Evaluación -ponderación | D27: Logro Ideal | E27: Relación con el logro ideal | F27: Valoración interpretativa | H27: Ponderación | I27: Grado de cumplimiento (1-5) | J27: Evaluación -ponderación | K27: Logro Ideal | L27: Relación con el logro ideal | M27: Valoración interpretativa
A28: 0.11 | B28: 4 | C28: 0.4 | D28: 0.6 | E28: 0.8 | F28: Se cumple en alto grado | H28: 0.07 | I28: 4.1 | J28: 0.3 | K28: 0.35 | L28: 0.8 | M28: Se cumple en alto grado
A30: FACTOR 5. INVESTIGACIÓN, GENERACIÓN DE CONOCIMIENTO Y PRODUCCIÓN ARTÍSTICA | H30: FACTOR 10. RECURSOS FÍSICOS Y GESTIÓN ADMINISTRATIVA Y FINANCIERA
A32: Ponderación | B32: Grado de cumplimiento (1-5) | C32: Evaluación -ponderación | D32: Logro Ideal | E32: Relación con el logro ideal | F32: Valoración interpretativa | H32: Ponderación | I32: Grado de cumplimiento (1-5) | J32: Evaluación -ponderación | K32: Logro Ideal | L32: Relación con el logro ideal | M32: Valoración interpretativa
A33: 0.11 | B33: 4.2 | C33: 0.5 | D33: 0.6 | E33: 0.8 | F33: Se cumple en alto grado | H33: 0.07 | I33: 3.9 | J33: 0.3 | K33: 0.4 | L33: 0.8 | M33: Se cumple en alto grado
B36: RESULTADOS FINALES DE AUTOEVALUACIÓN
B39: FACTOR | C39: Valoración interpretativa | D39: NOTA | E39: PONDERACIÓN
B40: Factor 1. Misión y visión de la Universidad. | C40: Se cumple en alto grado | D40: 4.4 | E40: 0.147 | F40: 0.7
B41: Factor 2. Estudiantes. | C41: Se cumple en alto grado | D41: 4 | E41: 0.137 | F41: 0.5
B42: Factor 3. Profesores. | C42: Se cumple en alto grado | D42: 4.2 | E42: 0.126 | F42: 0.5
B43: Factor 4. Procesos Académicos y Lineamientos Curriculares. | C43: Se cumple en alto grado | D43: 4 | E43: 0.11 | F43: 0.4
B44: Factor 5. Investigación, generación de conocimiento y producción artística. | C44: Se cumple en alto grado | D44: 4.2 | E44: 0.114 | F44: 0.5
B45: Factor 6. Articulación con el entorno y capacidad para generar procesos de innovación. | C45: Se cumple en alto grado | D45: 4 | E45: 0.093 | F45: 0.4
B46: Factor 7. Internacionalización, Alianzas Estratégicas e Inserción en Redes Científicas Globales. | C46: Se cumple aceptablemente | D46: 3.4 | E46: 0.085 | F46: 0.3
B47: Factor 8. Bienestar y Ambiente Institucional. | C47: Se cumple en alto grado | D47: 4 | E47: 0.05 | F47: 0.2
B48: Factor 9. Graduados y Análisis de Impacto del Programa. | C48: Se cumple en alto grado | D48: 4.1 | E48: 0.067 | F48: 0.3
B49: Factor 10. Recursos Físicos y Gestión Administrativa y Financiera. | C49: Se cumple en alto grado | D49: 3.9 | E49: 0.071 | F49: 0.3
B50: TOTAL | C50: Se cumple en alto grado | D50: 1 | F50: 4.1

Sheet Hoja5
A2: ° | B2: FACTOR | C2: POONDERACIÓN | D2: CARCATERISTICA | E2: POONDERACIÓN | F2: ASPECTO | G2: Grado de cumplimiento (1-5) | H2: POONDERACIÓN | I2: PROMEDIO CALIFICACIÓN | J2: PROMEDIO CALIFICACIÓN
A3: 1 | B3: FACTOR 1. PROYECTO EDUCATIVO DEL PROGRAMA E IDENTIDAD INSTITUCIONAL | C3: 0.12078273 | D3: Proyecto educativo del programa | E3: 0.53846154 | F3: Demostrar coherencia del Proyecto Educativo del Programa (PEP) o el que haga sus veces, con los lineamientos y políticas institucionales, así como en la definición de objetivos de formación y resultados de aprendizaje y la manera cómo el PEP ha ido mejorando, como resultado de los procesos de aseguramiento de la calidad, la consolidación de la identidad institucional y la relación que mantiene con la comunidad y sus grupos de interés. | G3: 4 | H3: =+AVERAGE(G3) -> 4 | I3: =AVERAGE(G3:G6) -> 4 | J3: =IF(I3>=4.5,"Se cumple plenamente",IF(I3>=4,"Se cumple en alto grado",IF(I3>=3.5,"Se cumple aceptablemente",IF(I3>=2.5,"Se cumple insatisfactoriamente",IF(I3>=1,"No se cumple",""))))) -> Se cumple en alto grado | K3: Falta aprobación para socializar | T3: Gradación no numérica | U3: Gradación numérica | V3: Grado de cumplimiento
D4: Relevancia académica y pertinencia social del programa académico. | E4: 0.46153846 | F4: Análisis sobre las tendencias, necesidades y líneas de desarrollo de la disciplina o profesión, en el contexto regional, nacional e internacional. | G4: 4 | H4: =AVERAGE(G4:G6) -> 4 | K4: PEP
F5: Estudio de la pertinencia social del programa desde la perspectiva de la comunidad académica y de sus grupos de interés con el fin de identificar necesidades y requerimientos del entorno local, regional o nacional en términos productivos y de competitividad, tecnológicos, culturales, científicos y de talento humano. | G5: 5 | K5: PEP | T5: 1 | U5: 1 | V5: No se cumple
F6: Evidencia de las transformaciones sociales pertinentes para el contexto y el territorio en el que se ofrece el programa académico, y del entorno tanto nacional como internacional. | G6: 3 | K6: PEP/convenio doble titulación | T6: 2.5 | U6: 2 | V6: Se cumple insatisfactoriamente
A7: 2 | B7: FACTOR 2. ESTUDIANTES | C7: 0.12415655 | D7: Participación en actividades de formación integral | E7: 0.33139535 | F7: Apreciación de los estudiantes en relación con su participación en las actividades de investigación, desarrollo tecnológico, creación artística, culturales, deportivas y de extensión, que contribuyen a su formación integral, junto con las acciones emprendidas como resultado de dichas apreciaciones. | G7: 4 | H7: =AVERAGE(G7:G10) -> 4 | I7: =+AVERAGE(G7:G16) -> 4.6 | J7: =IF(I3>=4.5,"Se cumple plenamente",IF(I3>=4,"Se cumple en alto grado",IF(I3>=3.5,"Se cumple aceptablemente",IF(I3>=2.5,"Se cumple insatisfactoriamente",IF(I3>=1,"No se cumple",""))))) -> Se cumple en alto grado | K7: Encuesta | L7: Docentes 12 | M7: Egresados 1 | N7: Egresados 2 | O7: Estudiantes 3 | P7: Estudiantes 8 | Q7: Estudiantes 9 | T7: 3.5 | U7: 3 | V7: Se cumple aceptablemente
F8: Resultados del análisis de la participación y principales logros de los estudiantes en actividades de investigación, desarrollo tecnológico, innovación, creación artística, culturales y deportivas. | G8: 4 | K8: Encuesta | L8: Estudiantes 9 | T8: 4 | U8: 4 | V8: Se cumple en alto grado
F9: Resultados del análisis de la participación y principales logros de los estudiantes en proyectos de desarrollo empresarial, relacionamiento nacional e internacional. | G9: 4 | K9: Encuesta | L9: Estudiantes 9 | T9: 4.5 | U9: 5 | V9: Se cumple plenamente
F10: Resultados del análisis de la participación y principales logros de los estudiantes en otras acciones de formación complementaria, que promuevan la comprensión de la realidad social, la empatía, la ética, habilidades blandas, así como el relacionamiento con otras culturas y lenguas, de acuerdo con el nivel de formación y la modalidad del programa. | G10: 4 | K10: Encuesta | L10: Estudiantes 9
D11: Orientación y seguimiento a estudiantes | E11: 0.18023256 | F11: Evidencia de los efectos en la formación de los estudiantes, a partir de los procesos de orientación y seguimiento de los estudiantes, teniendo como referencia sus características de ingreso. | G11: 5 | H11: =+AVERAGE(G3) -> 4 | K11: Listas se asistencia a reuniones e inducciones, investigación
D12: Capacidad de trabajo autónomo | E12: 0.19186047 | F12: Evidencia de los resultados de las estrategias de seguimiento y evaluación de los resultados de aprendizaje en el desarrollo de capacidades para el del trabajo autónomo del estudiante. | G12: 5 | H12: =+AVERAGE(G3) -> 4 | K12: Listas se asistencia a reuniones e inducciones, investigación | L12: Egresados 2 | M12: Estudiantes 3
D13: Reglamento estudiantil y política académica | E13: 0.13372093 | F13: Apreciación de estudiantes y profesores del programa sobre la pertinencia, vigencia y aplicación del reglamento estudiantil y las políticas académicas y, sobre las estrategias de divulgación de dicha reglamentación, junto con las acciones emprendidas como resultado de dichas apreciaciones. | G13: 5 | H13: =+AVERAGE(G13:G14) -> 5 | L13: Docentes 1 | M13: Docentes 9 | N13: Egresados 2 | O13: Estudiantes 4
F14: Evidencia de los mecanismos para la aplicación, actualización y divulgación del reglamento estudiantil. | G14: 5 | L14: Docentes 1 | M14: Estudiantes 4
D15: Estímulos y apoyos para estudiantes | E15: 0.1627907 | F15: Evidencia de los beneficios generados por el otorgamiento de estímulos académicos y apoyos socioeconómicos a los estudiantes. | G15: 5 | H15: =+AVERAGE(G15:G16) -> 5 | L15: Docentes 2 | M15: Estudiantes 3
F16: Apreciación de los estudiantes del programa frente a la aplicación de los estímulos académicos y apoyos socioeconómicos, y el cumplimiento institucional de estas medidas, junto con las acciones emprendidas como resultado de dichas apreciaciones. | G16: 5 | L16: Estudiantes 3 | M16: Estudiantes 5
A17: 3 | B17: FACTOR 3. PROFESORES | C17: 0.11673414 | D17: Selección, vinculación y permanencia | E17: 0.1712963 | F17: Evidencia de la aplicación de los procesos de selección, vinculación y permanencia de los profesores, en coherencia con el nivel de formación, modalidad del programa académico y lugar de desarrollo. | G17: 5 | H17: =+AVERAGE(G17:G18) -> 5 | I17: =+AVERAGE(G17:G34) -> 4.6666667 | J17: =IF(I3>=4.5,"Se cumple plenamente",IF(I3>=4,"Se cumple en alto grado",IF(I3>=3.5,"Se cumple aceptablemente",IF(I3>=2.5,"Se cumple insatisfactoriamente",IF(I3>=1,"No se cumple",""))))) -> Se cumple en alto grado
F18: Apreciación de los profesores sobre la aplicación, pertinencia y vigencia de las políticas, normas y criterios académicos establecidos por la institución para su selección, vinculación y permanencia, junto con las acciones emprendidas como resultado de dichas apreciaciones. | G18: 5
D19: Estatuto profesoral | E19: 0.13734568 | F19: Evidencia que demuestren los resultados de la aplicación del estatuto profesoral, o el que haga sus veces, sobre la trayectoria profesoral, la inclusión, el reconocimiento de méritos y el ascenso en el escalafón, de acuerdo con el nivel de formación y la modalidad del programa. | G19: 5 | H19: =+AVERAGE(G19:G21) -> 5 | L19: Docentes 4 | M19: Docentes 5
F20: Resultados en el mejoramiento de la calidad del programa, a partir de la aplicación de un estatuto que promueve la trayectoria profesoral, la inclusión, el reconocimiento de los méritos y el ascenso en el escalafón. | G20: 5 | L20: Docentes 3 | M20: Docentes 4
F21: Apreciación de los profesores sobre la aplicación y pertinencia del estatuto profesoral y de las políticas que establecen distinciones, estímulos que promueven la trayectoria profesoral, junto con las acciones emprendidas como resultado de dichas apreciaciones. | G21: 5 | L21: Docentes 3 | M21: Docentes 5 | N21: Docentes 6
D22: Número, dedicación, nivel de formación y experiencia | E22: 0.15740741 | F22: Evidencia de la coherencia entre el número, dedicación, nivel de formación y experiencia de los profesores de tiempo completo, con el número de estudiantes, nivel de formación y modalidad del programa académico. | G22: 5 | H22: =+AVERAGE(G22:G24) -> 5
F23: Evidencia de la existencia de un núcleo básico de profesores de tiempo completo, preferiblemente con contratación a término indefinido, y su relación con la formación de la comunidad académica del programa y el cumplimiento con alta calidad de las funciones esenciales del programa. | G23: 5
F24: Evidencia de la vinculación de una planta profesoral pertinente con el área disciplinar del programa con título de maestría y/o doctorado con experiencia o formación pedagógica, investigativa y profesional certificada y experiencia en investigación, que garantice el logro de los resultados de aprendizaje de los estudiantes y el cumplimiento de las funciones asignadas en condiciones de calidad, atendiendo a estándares internacionales, en coherencia con el nivel de formación y modalidad del programa. | G24: 5
D25: Desarrollo profesoral | E25: 0.15277778 | F25: Análisis de los resultados de la aplicación de políticas y estrategias institucionales en materia de desarrollo integral del profesorado, que incluya la capacitación y la actualización en los aspectos académicos, profesionales y pedagógicos relacionados con la naturaleza, nivel de formación y modalidad del programa. | G25: 5 | H25: =+AVERAGE(G25:G27) -> 4.3333333 | L25: Docentes 4 | M25: Docentes 5
F26: Evidencia de cómo el desarrollo profesoral atiende a la diversidad de los estudiantes, a las modalidades de la docencia y a los requerimientos de internacionalización y de inter y multiculturalidad de profesores y estudiantes. | G26: 4 | K26: Movilidad docente entrante y de estudiantes | L26: Docentes 4
F27: Apreciación de directivos y profesores del programa sobre los resultados que han tenido las acciones orientadas al desarrollo integral de los profesores, en el mejoramiento de las competencias pedagógicas, científicas y sociales para el sostenimiento de las funciones misionales, junto con las acciones emprendidas como resultado de dichas apreciaciones. | G27: 4 | L27: Docentes 3 | M27: Docentes 5
D28: Estímulos a la trayectoria profesoral | E28: 0.10339506 | F28: Evidencia de los efectos generados en el desempeño de las labores de docencia, investigación y extensión con el otorgamiento de estímulos a los profesores. | G28: 5 | H28: =+AVERAGE(G28:G29) -> 5 | K28: Reglamento, excelencia académica | L28: Docentes 4 | M28: Docentes 5
F29: Apreciación de directivos y profesores del programa, sobre el efecto que ha tenido el régimen de estímulos al profesorado en el ejercicio cualificado de la docencia, la investigación, la innovación, la creación artística y cultural, la extensión o proyección social, en los aportes al desarrollo técnico y tecnológico y la cooperación internacional, junto con las acciones emprendidas como resultado de dichas apreciaciones. | G29: 5 | K29: CvLac | L29: Docentes 3 | M29: Docentes 5 | N29: Docentes 6 | O29: Docentes 10
D30: Producción, pertinencia, utilización e impacto de material docente | E30: 0.11728395 | F30: Evidencia de la efectividad de los criterios de evaluación del material producido por los profesores en la calidad de los aprendizajes de los estudiantes, de acuerdo con el nivel de formación y modalidad del programa académico. | G30: 3 | H30: =+AVERAGE(G30:G31) -> 3 | K30: Hay material, pero no evaluacion del material | L30: Docentes 4 | M30: Docentes 5
F31: Presentación de los resultados de evaluación de los materiales académicos producidos por los profesores para el desarrollo de las diversas actividades académicas, que soportan los ambientes de aprendizaje, de acuerdo con el nivel de formación y modalidad. | G31: 3 | K31: Hay material, pero no evaluacion del material | L31: Docentes 4
D32: Remuneración por méritos | E32: 0.094135802 | F32: La remuneración que reciben los profesores está de acuerdo con sus méritos académicos y profesionales, el aporte en el desarrollo de los componentes formativos, pedagógicos y de evaluación, la interacción y relevancia social, el nivel de formación y la modalidad del programa académico. | G32: 5 | H32: =+AVERAGE(G32) -> 5 | L32: Docentes 3 | M32: Docentes 5
