Workbook

Sheet DIRECTIVOS
A1: NOMBRE | B1: CORREO DIRECTIVO | C1: CORREO INSTITUCIONAL JEFE AREA | D1: CARGO
A2: GIOVANNY MAURICIO TARAZONA | B2: rectoria@udistrital.edu.co | C2: gtarazona@udistrital.edu.co | D2: RECTOR
A3: LUZ ESPERANZA BOHORQUEZ | B3: vicerrecacad@udistrital.edu.co | C3: lebohorqueza@udistrital.edu.co | D3: VICERECTORA ACADEMICA
A4: JOSE IGNACIO RODRIGUEZ MOLANO | B4: decano_ing@udistrital.edu.co | C4: jirodriguezm@udistrital.edu.co | D4: DECANO
A5: NELSON ENRIQUE VERA P | B5: direccion-cidc@udistrital.edu.co | C5: neverap@udistrital.edu.co | D5: VICERECTOR INVESTIGACIONES
A6: CESAR ANDREY PERDOMO CH. | C6: cperdomo@udistrital.edu.co | D6: DIRECTOR IDEXUD
A7: LEONARDO EMIRO CONTRERAS | B7: unidad-extension-ing@udistrital.edu.co | C7: lecontrerasb@udistrital.edu.co | D7: COORDINADOR UNIDAD DE EXTENSION
A8: BEITMANT CARDENAS QUINTERO | B8: unidad-extension-ing@udistrital.edu.co | C8: bgcardenasq@udistrital.edu.co | D8: COORDINADOR UEFI
A9: Ivette Catalina Martínez Martínez | B9: planeac@udistrital.edu.co | C9: icmartinezm@udistrital.edu.co | D9: JEFE PLANEACIÓN
A10: Lisseth Paola Salazar Narvaez | B10: sgral@udistrital.edu.co | C10: lpsalazarn@udistrital.edu.co | D10: SECRETARIA GENERAL
A11: ROBERTO PAVA | B11: curriculoposing@udistrital.edu.co | C11: rapavad@udistrital.edu.co | D11: COORDINADOR DE CURRICULO Y CALIDAD FACULTAD
A12: ALVARO ENRIQUE ORTIZ D | D12: COORDINADOR MCIC

Sheet DOCENTES
A1: DOCENTE | B1: CORREO | C1: TIPO | D1: OK
A2: JOSE ANTONIO VALERO MEDINA | B2: jvalero@udistrital.edu.co | C2: PLANTA | D2: OK
A3: MARCO AURELIO ALZATE MONROY | B3: malzate@udistrital.edu.co | C3: PLANTA | D3: OK
A4: OCTAVIO JOSE SALCEDO PARRA | B4: osalcedo@udistrital.edu.co | C4: PLANTA | E4: INTERN
A5: ALVARO ESPINEL ORTEGA | B5: aespinel@udistrital.edu.co | C5: PLANTA | D5: OK | E5: GESETIC
A6: ALVARO ENRIQUE ORTIZ DAVILA | B6: aeortizd@udistrital.edu.co | C6: PLANTA | D6: OK | E6: NIDE
A7: LEONARDO PLAZAS NOSSA | B7: lplazasn@udistrital.edu.co | C7: PLANTA | D7: OK | E7: GITEM++
A8: HENRY ALBERTO DIOSA | B8: hdiosa@udistrital.edu.co | C8: FACULTAD | D8: OK | E8: ARQUISOF
A9: JOSE ROBERTO CARDENAS CASTIBLANCO | B9: rcardenas@udistrital.edu.co | C9: PLANTA | D9: OK
A10: ALEJANDRO PAOLO DAZA CORREDOR | B10: apdazac@udistrital.edu.co | C10: FACULTAD
A11: CESAR ANDREY PERDOMO CHARRY | B11: cperdomo@udistrital.edu.co | C11: FACULTAD | E11: LASER
A12: ERNESTO GOMEZ VARGAS | B12: egomez@udistrital.edu.co | C12: FACULTAD | D12: OK
A13: ELVIS EDUARDO GAONA GARCIA | B13: egaona@udistrital.edu.co | C13: FACULTAD | E13: MULTI /
A14: HANS IGOR LOPEZ CHAVEZ | B14: hilopezc@udistrital.edu.co | C14: FACULTAD | D14: OK
A15: LUIS EDUARDO CASTILLO MENDEZ | B15: lecastillom@udistrital.edu.co | C15: FACULTAD | D15: OK | E15: GEFEM
A16: NELSON ENRIQUE VERA PARRA | B16: neverap@udistrital.edu.co | C16: FACULTAD
A17: LUZ ANGELA ROCHA SALAMANCA | B17: lrocha@udistrital.edu.co | C17: FACULTAD | D17: OK
A18: RUBEN JAVIER MEDINA DAZA | B18: rmedina@udistrital.edu.co | C18: FACULTAD | D18: OK
A19: JORGE ENRIQUE RODRIGUEZ RODRIGUEZ | B19: jerodriguezr@udistrital.edu.co | C19: FACULTAD | D19: OK | E19: IAFT
A20: MU?OZ QUI?ONES GERARDO ALCIDES | B20: gmunoz@udistrital.edu.co | C20: FACULTAD
A21: ROJAS GALEANO SERGIO ANDRES | B21: srojas@udistrital.edu.co | C21: FACULTAD | E21: LAMIC
A22: FIGUEROA GARCIA JUAN CARLOS | B22: jcfigueroag@udistrital.edu.co | C22: FACULTAD
A23: GAONA BARRERA ANDRES EDUARDO | B23: aegaonab@udistrital.edu.co | C23: FACULTAD | D23: ok
A24: CARDENAS CONTRERAS ANDRES | B24: acardenas@udistrital.edu.co | C24: FACULTAD | D24: OK
A25: Edilberto Suarez Torres | B25: esuarez@udistrital.edu.co | C25: FACULTAD
A26: Julio Baron Velandia | B26: jbaron@udistrital.edu.co | C26: FACULTAD
A27: NANCY YANETH GELVEZ | B27: nygelvezg@udistrital.edu.co | C27: FACULTAD
A28: Paulo Alonso Gaona Garcia | B28: pagaonag@udistrital.edu.co | C28: FACULTAD | D28: OK
A29: ANDRES LEONARDO JUTINICO | B29: aljutinicoa@udistrital.edu.co | C29: FACULTAD
A30: Carlos Enrique Montenegro Marin | B30: cemontenegrom@udistrital.edu.co | C30: FACULTAD | E30: MULTI
A31: Mariam Rivas | B31: mrivasd@udistrital.edu.co | C31: FACULTAD | D31: OK
A32: VICTOR HUGO MEDINA GARCIA | B32: vmedina@udistrital.edu.co | C32: FACULTAD | E32: GICOGE
A33: HECTOR JAVIER FUENTES | B33: hjfuentesl@udistrital.edu.co | C33: FACULTAD

Sheet ESTUDIANTES
A1: CODIGO | B1: NOMBRE ESTUDIANTE | C1: ESTADO | D1: ESTADOS | E1: ESTRATO | F1: CORREO INSTITUCIONAL | G1: CORREO PERSONAL | H1: ID | I1: DOCUMENTO | J1: CELULAR
K2: OK YA
A3: 20181495002 | B3: CALLE TORRES JULIAN DAVID | C3: A | D3: ACTIVO | E3: 3 | F3: jdcallet@udistrital.edu.co | G3: jdcallet@unal.edu.co | H3: CC | I3: 1014238861 | J3: 3194345874 | K3: =VLOOKUP(I3,'Estudiantes ya'!L:M,1,0) -> #N/A
A4: 20181495018 | B4: SALAMANCA VASQUEZ ESTEBAN | C4: A | D4: ACTIVO | E4: 3 | F4: esalamancav@udistrital.edu.co | G4: esalamancav@gmail.com | H4: CC | I4: 80211143 | J4: 3014939976 | K4: =VLOOKUP(I4,'Estudiantes ya'!L:M,1,0) -> #N/A
A5: 20182395007 | B5: HURTADO VASQUEZ CRISTIAN CAMILO | C5: A | D5: ACTIVO | E5: 2 | F5: cchurtadov@udistrital.edu.co | G5: cchurtadov@udistrital.edu.co | H5: CC | I5: 1026269815 | J5: 3118341177 | K5: =VLOOKUP(I5,'Estudiantes ya'!L:M,1,0) -> #N/A
A6: 20182495004 | B6: BARRAGAN SARMIENTO ANDRES MAURICIO | C6: A | D6: ACTIVO | E6: 2 | F6: ambarragans@udistrital.edu.co | G6: barragan_amb@hotmail.com | H6: CC | I6: 1110537094 | J6: 3138730050 | K6: =VLOOKUP(I6,'Estudiantes ya'!L:M,1,0) -> #N/A
A7: 20182495006 | B7: ERIRA TRUJILLO WILLIAM ALBERTO | C7: A | D7: ACTIVO | E7: 3 | F7: waerirat@udistrital.edu.co | G7: werira@hotmail.com | H7: CC | I7: 79595381 | J7: 3002064489 | K7: =VLOOKUP(I7,'Estudiantes ya'!L:M,1,0) -> #N/A
A8: 20182495011 | B8: PI?EROS RAMIREZ JEISSON RODRIGO | C8: A | D8: ACTIVO | E8: 2 | F8: jrpinerosr@udistrital.edu.co | G8: jeisson005@hotmail.com | H8: CC | I8: 1030678110 | J8: 3115339687 | K8: =VLOOKUP(I8,'Estudiantes ya'!L:M,1,0) -> #N/A
A9: 20182495014 | B9: ROMERO PINTO JAWY ANDRES | C9: A | D9: ACTIVO | E9: 3 | F9: jawaromerop@udistrital.edu.co | G9: jawy.romero@gmail.com | H9: CC | I9: 1022955756 | J9: 3208536808 | K9: =VLOOKUP(I9,'Estudiantes ya'!L:M,1,0) -> #N/A
A10: 20191195007 | B10: RENGIFO GUIZA WILMAR NEISER | C10: A | D10: ACTIVO | E10: 2 | F10: wnrengifog@udistrital.edu.co | G10: wilrengui@gmail.com | H10: CC | I10: 80248462 | J10: 3187906508 | K10: =VLOOKUP(I10,'Estudiantes ya'!L:M,1,0) -> #N/A
A11: 20191395005 | B11: LOPEZ CALLE MARIA ISABEL | C11: A | D11: ACTIVO | E11: 4 | F11: milopezc@udistrital.edu.co | G11: isalopez0216@gmail.com | H11: CC | I11: 1018483105 | J11: 3204006059 | K11: =VLOOKUP(I11,'Estudiantes ya'!L:M,1,0) -> #N/A
A12: 20191395011 | B12: SUAREZ JAIMES PAOLA ANDREA | C12: A | D12: ACTIVO | E12: 4 | F12: pasuarezj@udistrital.edu.co | G12: ingpaolasuarez@gmail.com | H12: CC | I12: 1014267962 | J12: 3157533711 | K12: =VLOOKUP(I12,'Estudiantes ya'!L:M,1,0) -> #N/A
A13: 20191495003 | B13: CARVAJAL TORRES JOSE AUGUSTO | C13: A | D13: ACTIVO | E13: 4 | F13: jacarvajalt@udistrital.edu.co | G13: jacarvajalt@correo.udistrital.edu.co | H13: CC | I13: 1026295788 | J13: 3134606915 | K13: =VLOOKUP(I13,'Estudiantes ya'!L:M,1,0) -> #N/A
A14: 20191495006 | B14: COTTA GARCIA JUAN GUILLERMO | C14: A | D14: ACTIVO | E14: 1 | F14: jgcottag@udistrital.edu.co | G14: jgcotta@hotmail.com | H14: CC | I14: 1032470566 | J14: 3057117319 | K14: =VLOOKUP(I14,'Estudiantes ya'!L:M,1,0) -> #N/A
... A20: 20191495030 | B20: QUIROGA RUIZ JAVIER ALBERTO | C20: A | D20: ACTIVO | E20: 4 | F20: jaaquirogar@udistrital.edu.co | G20: ja_quiroga@hotmail.com | H20: CC | I20: 79410997 | J20: 3208575262 | K20: =VLOOKUP(I20,'Estudiantes ya'!L:M,1,0) -> #N/A
A21: 20191495031 | B21: ESPITIA PARDO DANIEL ENRIQUE | C21: A | D21: ACTIVO | E21: NO REGISTRA | F21: deespitiap@udistrital.edu.co | G21: danielespitia63@gmail.com | H21: CC | I21: 1024478452 | J21: 3164979161 | K21: =VLOOKUP(I21,'Estudiantes ya'!L:M,1,0) -> #N/A
A22: 20192195003 | B22: ESPINEL GOMEZ DIEGO FERNANDO | C22: A | D22: ACTIVO | E22: 2 | F22: dfespinelg@udistrital.edu.co | G22: espineldago@gmail.com | H22: CC | I22: 1018470424 | J22: 3144929188 | K22: =VLOOKUP(I22,'Estudiantes ya'!L:M,1,0) -> #N/A
A23: 20192195004 | B23: PEREZ CRISTANCHO JERSON FERNANDO | C23: A | D23: ACTIVO | E23: 3 | F23: jfperezc@udistrital.edu.co | G23: injerson@gmail.com | H23: CC | I23: 74327152 | J23: 3204754652 | K23: =VLOOKUP(I23,'Estudiantes ya'!L:M,1,0) -> #N/A
A24: 20192395002 | B24: GARCIA GUZMAN PEDRO PABLO | C24: A | D24: ACTIVO | E24: 4 | F24: ggpedrop@udistrital.edu.co | G24: pedropgarciag@gmail.com | H24: CC | I24: 79365082 | J24: 3134556444 | K24: =VLOOKUP(I24,'Estudiantes ya'!L:M,1,0) -> #N/A
A25: 20192395005 | B25: CAITA SOTAQUIRA NATALIA | C25: A | D25: ACTIVO | E25: 3 | F25: ncaitas@udistrital.edu.co | G25: nati.caita@gmail.com | H25: CC | I25: 1026273952 | J25: 3192310138 | K25: =VLOOKUP(I25,'Estudiantes ya'!L:M,1,0) -> #N/A
A26: 20192395007 | B26: MALAGON MARQUEZ DIEGO ALEJANDRO | C26: A | D26: ACTIVO | E26: 3 | F26: mmdiegoa@udistrital.edu.co | G26: dalejomalagon@gmail.com | H26: CC | I26: 1022395401 | J26: 3133376495 | K26: =VLOOKUP(I26,'Estudiantes ya'!L:M,1,0) -> #N/A
A27: 20192395008 | B27: HUERTAS VARGAS KAREN ANDREA | C27: A | D27: ACTIVO | E27: 3 | F27: hvkarena@udistrital.edu.co | G27: karenahva@gmail.com | H27: CC | I27: 1023923782 | J27: 3204431938 | K27: =VLOOKUP(I27,'Estudiantes ya'!L:M,1,0) -> #N/A
A28: 20192395011 | B28: RUIZ MORALES TANIA LORENA | C28: A | D28: ACTIVO | E28: 2 | F28: tlruizm@udistrital.edu.co | G28: tlorena.icg@gmail.com | H28: CC | I28: 1018480123 | J28: 3015938056 | K28: =VLOOKUP(I28,'Estudiantes ya'!L:M,1,0) -> #N/A
A29: 20192495001 | B29: MU?OZ PENAGOS NATHALIA CATALINA | C29: A | D29: ACTIVO | E29: 4 | F29: mpnathaliac@udistrital.edu.co | G29: nathmunoz19@gmail.com | H29: CC | I29: 1032449961 | J29: 3185215312 | K29: =VLOOKUP(I29,'Estudiantes ya'!L:M,1,0) -> #N/A
A30: 20192495003 | B30: MONTENEGRO ALVARADO ANDRES DAVID | C30: A | D30: ACTIVO | E30: 2 | F30: admontenegroa@udistrital.edu.co | G30: admontenegroa@gmail.com | H30: CC | I30: 1023924156 | J30: 3505212562 | K30: =VLOOKUP(I30,'Estudiantes ya'!L:M,1,0) -> #N/A
A31: 20192495004 | B31: CASTRO CASTRO OMAR JOSE | C31: A | D31: ACTIVO | E31: 3 | F31: ccomarj@udistrital.edu.co | G31: kstroomar@yahoo.es | H31: CC | I31: 1010204406 | J31: 3008818918 | K31: =VLOOKUP(I31,'Estudiantes ya'!L:M,1,0) -> #N/A
A32: 20192495005 | B32: DAZA NARVAEZ ERIKA JUNNIETH | C32: A | D32: ACTIVO | E32: 3 | F32: dnerikaj@udistrital.edu.co | G32: ekdaza1709@gmail.com | H32: CC | I32: 1018460864 | J32: 3207553745 | K32: =VLOOKUP(I32,'Estudiantes ya'!L:M,1,0) -> #N/A
A33: 20192495013 | B33: IDROBO LOPEZ OSCAR JAVIER | C33: A | D33: ACTIVO | E33: 3 | F33: ojidrobol@udistrital.edu.co | G33: oscaridrobolopez@hotmail.com | H33: CC | I33: 1022386417 | J33: 3118649680 | K33: =VLOOKUP(I33,'Estudiantes ya'!L:M,1,0) -> #N/A
... A77: 20221395001 | B77: ANGEL VILLAREAL SERGIO LEONARDO | C77: A | D77: ACTIVO | E77: 3 | F77: slangelv@udistrital.edu.co | G77: angelvsergio@gmail.com | H77: CC | I77: 1030631243 | J77: 3204542891 | K77: =VLOOKUP(I77,'Estudiantes ya'!L:M,1,0) -> 1030631243
A78: 20221395002 | B78: CABEZAS MARTIN GONZALO | C78: A | D78: ACTIVO | E78: NO REGISTRA | F78: gcabezasm@udistrital.edu.co | G78: gonzalocabezas06@gmail.com | H78: CC | I78: 1018477001 | J78: 3219534044 | K78: =VLOOKUP(I78,'Estudiantes ya'!L:M,1,0) -> #N/A
A79: 20221395003 | B79: CUMBE LOAIZA LAURA CAMILA | C79: A | D79: ACTIVO | E79: 2 | F79: lccumbel@udistrital.edu.co | G79: cumbelc@gmail.com | H79: CC | I79: 1012391241 | J79: 3162523202 | K79: =VLOOKUP(I79,'Estudiantes ya'!L:M,1,0) -> #N/A
A80: 20221395004 | B80: GUERRERO VARONA LUIS MIGUEL | C80: A | D80: ACTIVO | E80: 3 | F80: lmguerrerov@udistrital.edu.co | G80: lmguerrerov@udistrital.edu.co | H80: CC | I80: 1030534583 | J80: 3246804677 | K80: =VLOOKUP(I80,'Estudiantes ya'!L:M,1,0) -> #N/A
A81: 20221395009 | B81: JASON MAURICIO ROMERO RIOS | C81: A | D81: ACTIVO | E81: 2 | F81: jamromeror@udistrital.edu.co | G81: jamromeror@udistrital.edu.co | H81: CC | I81: 1032501251 | J81: 3203122493 | K81: =VLOOKUP(I81,'Estudiantes ya'!L:M,1,0) -> #N/A
A82: 20221395010 | B82: ROJAS NARANJO JORGE ELIECER | C82: A | D82: ACTIVO | E82: 3 | F82: jorerojasn@udistrital.edu.co | G82: jerojasn@gmail.com | H82: CC | I82: 80903757 | J82: 3006399338 | K82: =VLOOKUP(I82,'Estudiantes ya'!L:M,1,0) -> #N/A
A83: 20221495002 | B83: BEJARANO MEDELLIN SEBASTIAN LEONARDO | C83: A | D83: ACTIVO | E83: 3 | F83: slbejaranom@udistrital.edu.co | G83: slbejaranom@gmail.com | H83: CC | I83: 1030671497 | J83: 3224093121 | K83: =VLOOKUP(I83,'Estudiantes ya'!L:M,1,0) -> #N/A
A84: 20221495005 | B84: FORERO CASTRO DIEGO DANIEL | C84: A | D84: ACTIVO | E84: 2 | F84: ddforeroc@udistrital.edu.co | G84: ddforeroc@gmail.com | H84: CC | I84: 1010219920 | J84: 3124029463 | K84: =VLOOKUP(I84,'Estudiantes ya'!L:M,1,0) -> #N/A
A85: 20221495008 | B85: PERDOMO ORJUELA LUIS EDUARDO | C85: A | D85: ACTIVO | E85: 3 | F85: leperdomoo@udistrital.edu.co | G85: luis1988perdomo@gmail.com | H85: CC | I85: 1020734582 | K85: =VLOOKUP(I85,'Estudiantes ya'!L:M,1,0) -> #N/A
A86: 20221495010 | B86: RODRIGUEZ DAZA NICOLAS | C86: A | D86: ACTIVO | E86: 3 | F86: nrodriguezd@udistrital.edu.co | G86: nicolasrd1808@gmail.com | H86: CC | I86: 1032492665 | J86: 3004183473 | K86: =VLOOKUP(I86,'Estudiantes ya'!L:M,1,0) -> #N/A
A87: 20221495012 | B87: SALAZAR ORTIZ JAIVER ESTIVEN | C87: A | D87: ACTIVO | E87: 1 | F87: jesalazaro@udistrital.edu.co | G87: jesalazaro@correo.udistrital.edu.co | H87: CC | I87: 1010226431 | J87: 3124029089 | K87: =VLOOKUP(I87,'Estudiantes ya'!L:M,1,0) -> #N/A
A88: 20221495013 | B88: SANCHEZ BOLA?OS CRISTIAN DAVID | C88: A | D88: ACTIVO | E88: 3 | F88: cdsanchezbo@udistrital.edu.co | G88: crdsanchezb@correo.udistrital.edu.co | H88: CC | I88: 1013677336 | J88: 3102196856 | K88: =VLOOKUP(I88,'Estudiantes ya'!L:M,1,0) -> #N/A
...

Sheet Estudiantes ya
A1: Id | B1: Hora de inicio | C1: Hora de finalización | D1: Correo electrónico | E1: Nombre | F1: Total de puntos | G1: Comentarios del cuestionario | H1: Hora de publicación de la calificación | I1: ¿Cuales es su nombre? | J1: Puntos: ¿Cuales es su nombre? | K1: Comentarios: ¿Cuales es su nombre? | L1: Digite su número de cedula | M1: Puntos: Digite su número de cedula | N1: Comentarios: Digite su número de cedula | O1: ¿En que rango de edad se encuentra? | P1: Puntos: ¿En que rango de edad se encuentra? | Q1: Comentarios: ¿En que rango de edad se encuentra? | R1: Por favor actualice su número de contacto telefónico | S1: Puntos: Por favor actualice su número de contacto telefónico | T1: Comentarios: Por favor actualice su número de contacto telefónico | U1: ¿En qué año ingreso a la Maestría en Ciencias de la Información y las Comunicaciones? | V1: Puntos: ¿En qué año ingreso a la Maestría en Ciencias de la Información y las Comunicaciones? | W1: Comentarios: ¿En qué año ingreso a la Maestría en Ciencias de la Información y las Comunicaciones? | X1: ¿En qué énfasis se encuentra inscrito? | Y1: Puntos: ¿En qué énfasis se encuentra inscrito? | Z1: Comentarios: ¿En qué énfasis se encuentra inscrito? | AA1: ¿En qué Modalidad o Metodología se encuentra inscrito? | AB1: Puntos: ¿En qué Modalidad o Metodología se encuentra inscrito? | AC1: Comentarios: ¿En qué Modalidad o Metodología se encuentra inscrito? | AD1: ¿Cuáles son sus áreas de investigación? | AE1: Puntos: ¿Cuáles son sus áreas de investigación? | AF1: Comentarios: ¿Cuáles son sus áreas de investigación? | AG1: Si se ofreciera una asignatura impartida en un 50% en inglés el próximo semestre, ¿se inscribiría? | AH1: Puntos: Si se ofreciera una asignatura impartida en un 50% en inglés el próximo semestre, ¿se inscribiría? | AI1: Comentarios: Si se ofreciera una asignatura impartida en un 50% en inglés el próximo semestre, ¿se inscribiría? | AJ1: ¿Cómo cree que una asignatura en inglés podría mejorar sus oportunidades futuras? | AK1: Puntos: ¿Cómo cree que una asignatura en inglés podría mejorar sus oportunidades futuras? | AL1: Comentarios: ¿Cómo cree que una asignatura en inglés podría mejorar sus oportunidades futuras? | AM1: Considero que mi participación en actividades de investigación, desarrollo tecnológico, creación artística, culturales, deportivas y de extensión ha contribuido a mi desarrollo integral como persona, | AN1: Puntos: Considero que mi participación en actividades de investigación, desarrollo tecnológico, creación artística, culturales, deportivas y de extensión ha contribuido a mi desarrollo integral como persona, | AO1: Comentarios: Considero que mi participación en actividades de investigación, desarrollo tecnológico, creación artística, culturales, deportivas y de extensión ha contribuido a mi desarrollo integral como persona, | AP1: Por favor, proporciona ejemplos específicos de actividades de investigación en las que has participado y cómo han impactado en tu formación integral: | AQ1: Puntos: Por favor, proporciona ejemplos específicos de actividades de investigación en las que has participado y cómo han impactado en tu formación integral: | AR1: Comentarios: Por favor, proporciona ejemplos específicos de actividades de investigación en las que has participado y cómo han impactado en tu formación integral: | AS1: Considero que el reglamento estudiantil y las políticas académicas del programa son pertinentes y están actualizadas. | AT1: Puntos: Considero que el reglamento estudiantil y las políticas académicas del programa son pertinentes y están actualizadas. | AU1: Comentarios: Considero que el reglamento estudiantil y las políticas académicas del programa son pertinentes y están actualizadas. | AV1: ¿Tienes sugerencias para mejorar la divulgación y comprensión del reglamento estudiantil y las políticas académicas? | AW1: Puntos: ¿Tienes sugerencias para mejorar la divulgación y comprensión del reglamento estudiantil y las políticas académicas? | AX1: Comentarios: ¿Tienes sugerencias para mejorar la divulgación y comprensión del reglamento estudiantil y las políticas académicas? | AY1: Considero que los criterios para la concesión de estímulos académicos y apoyos socioeconómicos, son claros y justos. | AZ1: Puntos: Considero que los criterios para la concesión de estímulos académicos y apoyos socioeconómicos, son claros y justos. | BA1: Comentarios: Considero que los criterios para la concesión de estímulos académicos y apoyos socioeconómicos, son claros y justos. | BB1: ¿Qué acciones crees que la institución debería emprender para mejorar la aplicación de los estímulos académicos y apoyos socioeconómicos? | BC1: Puntos: ¿Qué acciones crees que la institución debería emprender para mejorar la aplicación de los estímulos académicos y apoyos socioeconómicos? | BD1: Comentarios: ¿Qué acciones crees que la institución debería emprender para mejorar la aplicación de los estímulos académicos y apoyos socioeconómicos? | BE1: Considero que el material académico producido por los docentes es pertinente y adecuado con las necesidades y objetivos de la Maestría en Ciencias de la Información y las Comunicaciones. | BF1: Puntos: Considero que el material académico producido por los docentes es pertinente y adecuado con las necesidades y objetivos de la Maestría en Ciencias de la Información y las Comunicaciones. | BG1: Comentarios: Considero que el material académico producido por los docentes es pertinente y adecuado con las necesidades y objetivos de la Maestría en Ciencias de la Información y las Comunicaciones. | BH1: Considero que los criterios y mecanismos utilizados para la evaluación de los profesores son transparentes, accesibles y eficaces | BI1: Puntos: Considero que los criterios y mecanismos utilizados para la evaluación de los profesores son transparentes, accesibles y eficaces | BJ1: Comentarios: Considero que los criterios y mecanismos utilizados para la evaluación de los profesores son transparentes, accesibles y eficaces | BK1: Considero que las estrategias de flexibilidad curricular me han permitido personalizar mi formación de acuerdo con mis objetivos profesionales y académicos. | BL1: Puntos: Considero que las estrategias de flexibilidad curricular me han permitido personalizar mi formación de acuerdo con mis objetivos profesionales y académicos. | BM1: Comentarios: Considero que las estrategias de flexibilidad curricular me han permitido personalizar mi formación de acuerdo con mis objetivos profesionales y académicos. | BN1: ¿Podrías proporcionar ejemplos específicos de cómo las rutas de formación alternativas te han beneficiado para tu desarrollo académico y profesional? | BO1: Puntos: ¿Podrías proporcionar ejemplos específicos de cómo las rutas de formación alternativas te han beneficiado para tu desarrollo académico y profesional? | BP1: Comentarios: ¿Podrías proporcionar ejemplos específicos de cómo las rutas de formación alternativas te han beneficiado para tu desarrollo académico y profesional? | BQ1: ¿Cómo valorarías la efectividad de los énfasis en "Teleinformática" “Ingeniería de Software”, “Geomática” y "Inteligencia Artificial" en la formación integral de los estudiantes? | BR1: Puntos: ¿Cómo valorarías la efectividad de los énfasis en "Teleinformática" “Ingeniería de Software”, “Geomática” y "Inteligencia Artificial" en la formación integral de los estudiantes? | BS1: Comentarios: ¿Cómo valorarías la efectividad de los énfasis en "Teleinformática" “Ingeniería de Software”, “Geomática” y "Inteligencia Artificial" en la formación integral de los estudiantes? | BT1: Considero que las estrategias pedagógicas y escenarios de práctica utilizadas en la Maestría en Ciencias de la Información y las Comunicaciones son coherentes y efectivas para facilitar los resultados | BU1: Puntos: Considero que las estrategias pedagógicas y escenarios de práctica utilizadas en la Maestría en Ciencias de la Información y las Comunicaciones son coherentes y efectivas para facilitar los resultados | BV1: Comentarios: Considero que las estrategias pedagógicas y escenarios de práctica utilizadas en la Maestría en Ciencias de la Información y las Comunicaciones son coherentes y efectivas para facilitar los resultados | BW1: Considero que los sistemas de evaluación de los resultados de aprendizaje permiten una realimentación efectiva que contribuye a la mejora continua de la formación en los estudiantes. | BX1: Puntos: Considero que los sistemas de evaluación de los resultados de aprendizaje permiten una realimentación efectiva que contribuye a la mejora continua de la formación en los estudiantes. | BY1: Comentarios: Considero que los sistemas de evaluación de los resultados de aprendizaje permiten una realimentación efectiva que contribuye a la mejora continua de la formación en los estudiantes. | BZ1: Considero que el proceso de evaluación y autorregulación de la Maestría en Ciencias de la Información y las Comunicaciones tiene en cuenta de manera efectiva las necesidades y expectativas de los estu | CA1: Puntos: Considero que el proceso de evaluación y autorregulación de la Maestría en Ciencias de la Información y las Comunicaciones tiene en cuenta de manera efectiva las necesidades y expectativas de los estu | CB1: Comentarios: Considero que el proceso de evaluación y autorregulación de la Maestría en Ciencias de la Información y las Comunicaciones tiene en cuenta de manera efectiva las necesidades y expectativas de los estu | CC1: Considero que las intervenciones y el apoyo proporcionados para alertarme de forma temprana, han sido útiles para mejorar mi rendimiento académico y facilitar mi progreso hacia la graduación. | CD1: Puntos: Considero que las intervenciones y el apoyo proporcionados para alertarme de forma temprana, han sido útiles para mejorar mi rendimiento académico y facilitar mi progreso hacia la graduación. | CE1: Comentarios: Considero que las intervenciones y el apoyo proporcionados para alertarme de forma temprana, han sido útiles para mejorar mi rendimiento académico y facilitar mi progreso hacia la graduación. | CF1: Considero que la interacción con homólogos nacionales e internacionales ha mejorado mis competencias académicas y científicas, así como las oportunidades de desarrollo profesional. | CG1: Puntos: Considero que la interacción con homólogos nacionales e internacionales ha mejorado mis competencias académicas y científicas, así como las oportunidades de desarrollo profesional. | CH1: Comentarios: Considero que la interacción con homólogos nacionales e internacionales ha mejorado mis competencias académicas y científicas, así como las oportunidades de desarrollo profesional. | CI1: ¿Podrías proporcionar ejemplos específicos de proyectos, investigaciones o colaboraciones exitosas que hayan resultado de la cooperación académica y científica promovida por la Maestría en Ciencias de | CJ1: Puntos: ¿Podrías proporcionar ejemplos específicos de proyectos, investigaciones o colaboraciones exitosas que hayan resultado de la cooperación académica y científica promovida por la Maestría en Ciencias de | CK1: Comentarios: ¿Podrías proporcionar ejemplos específicos de proyectos, investigaciones o colaboraciones exitosas que hayan resultado de la cooperación académica y científica promovida por la Maestría en Ciencias de | CL1: Considero que la Maestría en Ciencias de la Información y las Comunicaciones me proporciona una formación adecuada para la investigación, fomentando el desarrollo de un pensamiento crítico, creativo e | CM1: Puntos: Considero que la Maestría en Ciencias de la Información y las Comunicaciones me proporciona una formación adecuada para la investigación, fomentando el desarrollo de un pensamiento crítico, creativo e | CN1: Comentarios: Considero que la Maestría en Ciencias de la Información y las Comunicaciones me proporciona una formación adecuada para la investigación, fomentando el desarrollo de un pensamiento crítico, creativo e | CO1: ¿Podrías proporcionar ejemplos específicos de proyectos o experiencias en los que hayas participado y que hayan contribuido significativamente a tu formación en investigación y desarrollo tecnológico, | CP1: Puntos: ¿Podrías proporcionar ejemplos específicos de proyectos o experiencias en los que hayas participado y que hayan contribuido significativamente a tu formación en investigación y desarrollo tecnológico, | CQ1: Comentarios: ¿Podrías proporcionar ejemplos específicos de proyectos o experiencias en los que hayas participado y que hayan contribuido significativamente a tu formación en investigación y desarrollo tecnológico, | CR1: Considero que las políticas, programas y servicios de bienestar implementados en Maestría en Ciencias de la Información y las Comunicaciones son coherentes con las condiciones y necesidades específica | CS1: Puntos: Considero que las políticas, programas y servicios de bienestar implementados en Maestría en Ciencias de la Información y las Comunicaciones son coherentes con las condiciones y necesidades específica | CT1: Comentarios: Considero que las políticas, programas y servicios de bienestar implementados en Maestría en Ciencias de la Información y las Comunicaciones son coherentes con las condiciones y necesidades específica | CU1: Considero que el acompañamiento proporcionado en la Maestría en Ciencias de la Información y las Comunicaciones facilita una comunicación efectiva y una interacción constructiva entre profesores y est | CV1: Puntos: Considero que el acompañamiento proporcionado en la Maestría en Ciencias de la Información y las Comunicaciones facilita una comunicación efectiva y una interacción constructiva entre profesores y est | CW1: Comentarios: Considero que el acompañamiento proporcionado en la Maestría en Ciencias de la Información y las Comunicaciones facilita una comunicación efectiva y una interacción constructiva entre profesores y est | CX1: Considero que los espacios, recurso, herramientas y equipos de apoyo ofrecidos son pertinentes y se ajustan adecuadamente a mis necesidades formativas en los diferentes contextos que requiero. | CY1: Puntos: Considero que los espacios, recurso, herramientas y equipos de apoyo ofrecidos son pertinentes y se ajustan adecuadamente a mis necesidades formativas en los diferentes contextos que requiero. | CZ1: Comentarios: Considero que los espacios, recurso, herramientas y equipos de apoyo ofrecidos son pertinentes y se ajustan adecuadamente a mis necesidades formativas en los diferentes contextos que requiero. | DA1: ¿Has notado alguna mejora en las estrategias y recursos de apoyo como resultado de retroalimentaciones previas? | DB1: Puntos: ¿Has notado alguna mejora en las estrategias y recursos de apoyo como resultado de retroalimentaciones previas? | DC1: Comentarios: ¿Has notado alguna mejora en las estrategias y recursos de apoyo como resultado de retroalimentaciones previas? | DD1: Considero que el material bibliográfico y de información disponible en la Maestría en Ciencias de la Información y las Comunicaciones es pertinente y adecuado para apoyar el desarrollo de las distinta | DE1: Puntos: Considero que el material bibliográfico y de información disponible en la Maestría en Ciencias de la Información y las Comunicaciones es pertinente y adecuado para apoyar el desarrollo de las distinta | DF1: Comentarios: Considero que el material bibliográfico y de información disponible en la Maestría en Ciencias de la Información y las Comunicaciones es pertinente y adecuado para apoyar el desarrollo de las distinta | DG1: Considero que el representante estudiantil en los diferentes escenarios institucionales ha sido valorada y ha influido en las decisiones orientadas al mejoramiento de la Maestría en Ciencias de la Inf | DH1: Puntos: Considero que el representante estudiantil en los diferentes escenarios institucionales ha sido valorada y ha influido en las decisiones orientadas al mejoramiento de la Maestría en Ciencias de la Inf | DI1: Comentarios: Considero que el representante estudiantil en los diferentes escenarios institucionales ha sido valorada y ha influido en las decisiones orientadas al mejoramiento de la Maestría en Ciencias de la Inf | DJ1: Creo que los procesos administrativos están orientados adecuadamente y son eficaces para apoyar el desarrollo integral de las labores formativas, académicas, docentes, científicas, culturales y de ext | DK1: Puntos: Creo que los procesos administrativos están orientados adecuadamente y son eficaces para apoyar el desarrollo integral de las labores formativas, académicas, docentes, científicas, culturales y de ext | DL1: Comentarios: Creo que los procesos administrativos están orientados adecuadamente y son eficaces para apoyar el desarrollo integral de las labores formativas, académicas, docentes, científicas, culturales y de ext | DM1: Considero que los recursos humanos (profesores, personal administrativo, etc.) disponibles en la Maestría en Ciencias de la Información y las Comunicaciones son suficientes y adecuados para atender el | DN1: Puntos: Considero que los recursos humanos (profesores, personal administrativo, etc.) disponibles en la Maestría en Ciencias de la Información y las Comunicaciones son suficientes y adecuados para atender el | DO1: Comentarios: Considero que los recursos humanos (profesores, personal administrativo, etc.) disponibles en la Maestría en Ciencias de la Información y las Comunicaciones son suficientes y adecuados para atender el | DP1: Considero que los recursos informáticos disponibles, corresponden adecuadamente con las | DQ1: Puntos: Considero que los recursos informáticos disponibles, corresponden adecuadamente con las | DR1: Comentarios: Considero que los recursos informáticos disponibles, corresponden adecuadamente con las | DS1: ¿En qué sector se desempeña su trabajo actual? | DT1: Puntos: ¿En qué sector se desempeña su trabajo actual? | DU1: Comentarios: ¿En qué sector se desempeña su trabajo actual? | DV1: ¿El trabajo que realiza actualmente se relaciona directamente con los conocimientos adquiridos en la maestría? | DW1: Puntos: ¿El trabajo que realiza actualmente se relaciona directamente con los conocimientos adquiridos en la maestría? | DX1: Comentarios: ¿El trabajo que realiza actualmente se relaciona directamente con los conocimientos adquiridos en la maestría? | DY1: ¿Siente que la maestría te ha abierto nuevas oportunidades laborales? | DZ1: Puntos: ¿Siente que la maestría te ha abierto nuevas oportunidades laborales? | EA1: Comentarios: ¿Siente que la maestría te ha abierto nuevas oportunidades laborales? | EB1: ¿Podría indicar el nombre de la empresa/compañía con la que labora actualmente? | EC1: Puntos: ¿Podría indicar el nombre de la empresa/compañía con la que labora actualmente? | ED1: Comentarios: ¿Podría indicar el nombre de la empresa/compañía con la que labora actualmente? | EE1: Como parte del proceso de autoevaluación y Acreditación de Alta Calidad, la Universidad requiere contactar a los empleadores de nuestros estudiantes. | EF1: Puntos: Como parte del proceso de autoevaluación y Acreditación de Alta Calidad, la Universidad requiere contactar a los empleadores de nuestros estudiantes. | EG1: Comentarios: Como parte del proceso de autoevaluación y Acreditación de Alta Calidad, la Universidad requiere contactar a los empleadores de nuestros estudiantes.
DP2: necesidades tecnológicas de la Maestría en Ciencias de la Información y las Comunicaciones y de sus miembros (pr | DQ2: necesidades tecnológicas de la Maestría en Ciencias de la Información y las Comunicaciones y de sus miembros (pr | DR2: necesidades tecnológicas de la Maestría en Ciencias de la Información y las Comunicaciones y de sus miembros (pr | EE2: Por lo tanto, le solicitamos de ser posible, prop | EF2: Por lo tanto, le solicitamos de ser posible, prop | EG2: Por lo tanto, le solicitamos de ser posible, prop
A3: 1 | B3: 45719.546 | C3: 45719.549 | D3: anfpulidoc@udistrital.edu.co | E3: ANDRES FELIPE PULIDO CASTRO | I3: Andrés\ Felipe\ Pulido\ Castro | J3: 0 | L3: 1010001829 | M3: 0 | O3: 25 a 30 | P3: 0 | R3: 3118210139 | S3: 0 | U3: 2024 | V3: 0 | X3: Geomtatica | Y3: 0 | AA3: Profundización | AB3: 0 | AD3: Catastro | AE3: 0 | AG3: Si | AH3: 0 | AJ3: es\ funcional | AK3: 0 | AM3: Totalmente de acuerdo. | AN3: 0 | AP3: . | AQ3: 0 | AS3: Totalmente de acuerdo. | AT3: 0 | AV3: No | AW3: 0 | AY3: Totalmente de acuerdo. | AZ3: 0 | BB3: Ninguna | BC3: 0 | BE3: Totalmente de acuerdo. | BF3: 0 | BH3: Totalmente de acuerdo. | BI3: 0 | BK3: Totalmente de acuerdo. | BL3: 0 | BN3: . | BO3: 0 | BQ3: Muy eficiente | BR3: 0 | BT3: Totalmente de acuerdo. | BU3: 0 | BW3: Totalmente de acuerdo. | BX3: 0 | BZ3: Totalmente de acuerdo. | CA3: 0 | CC3: Totalmente de acuerdo. | CD3: 0 | CF3: Totalmente de acuerdo. | CG3: 0 | CI3: No | CJ3: 0 | CL3: Totalmente de acuerdo. | CM3: 0 | CO3: No | CP3: 0 | CR3: Totalmente de acuerdo. | CS3: 0 | CU3: Totalmente de acuerdo. | CV3: 0 | CX3: Totalmente de acuerdo. | CY3: 0 | DA3: Sí. | DB3: 0 | DD3: Totalmente de acuerdo. | DE3: 0 | DG3: Totalmente de acuerdo. | DH3: 0 | DJ3: Totalmente de acuerdo. | DK3: 0 | DM3: Totalmente de acuerdo. | DN3: 0 | DP3: Totalmente de acuerdo. | DQ3: 0 | DS3: Tecnología (desarrollo de software, IA, ciberseguridad, telecomunicaciones) | DT3: 0 | DV3: Totalmente de acuerdo. | DW3: 0 | DY3: Totalmente de acuerdo. | DZ3: 0 | EB3: IGAC | EC3: 0 | EE3: . | EF3: 0
A4: 2 | B4: 45719.569 | C4: 45719.588 | D4: clalapea@udistrital.edu.co | E4: CRISTIAN LEONARDO ALAPE AVILA ALAPE AVILA | I4: Cristian\ Leonardo\ Alape\ Avila | J4: 0 | L4: 1016060113 | M4: 0 | O4: 31 a 40 | P4: 0 | R4: 3194284737 | S4: 0 | U4: 2025 | V4: 0 | X4: Ingeniería de Software | Y4: 0 | AA4: Investigación | AB4: 0 | AD4: Inteligencia artificial, ingeniería de software | AE4: 0 | AG4: No | AH4: 0 | AJ4: Es\ cierto\ que\ la\ mayoria\ de\ referentes\ del\ estado\ del\ arte\ de\ la\ tesis\ es\tan\ en\ ingles,\ pero\ esto\ no\ es\ \inf luyente\ en\ el\ ejercicio\ academico\ de\ impartir\ una\ clase\ | AK4: 0 | AM4: Totalmente de acuerdo. | AN4: 0 | AP4: Seminarios, asistencia a ponencias y congresos en computación como por ejemplo CICOM | AQ4: 0 | AS4: Ni en acuerdo, ni en desacuerdo. | AT4: 0 | AV4: Tener públicos los criterios y resultados de de admisión | AW4: 0 | AY4: De acuerdo. | AZ4: 0 | BB4: Reducir la burocracia en estos tramites. | BC4: 0 | BE4: De acuerdo. | BF4: 0 | BH4: De acuerdo. | BI4: 0 | BK4: De acuerdo. | BL4: 0 | BN4: No conozco rutas de formación alternativas | BO4: 0 | BQ4: Claramente ofrecen la capacidad de especializarse en áreas de conocimiento profundas por medio de las asignaturas y el área de conocimiento a fin en la tesis | BR4: 0 | BT4: De acuerdo. | BU4: 0 | BW4: De acuerdo. | BX4: 0 | BZ4: Ni en acuerdo, ni en desacuerdo. | CA4: 0 | CC4: Ni en acuerdo, ni en desacuerdo. | CD4: 0 | CF4: Totalmente de acuerdo. | CG4: 0 | CI4: unos docentes de planta recientemente contratados en la planta de la ud, hicieron su tesis doctoral en continuación de su tesis de maestría y de la misma forma esta ultima en continuación de su proyecto de grado en pregrado | CJ4: 0 | CL4: Totalmente de acuerdo. | CM4: 0 | CO4: Escribir y publicar artículos con rigor investigativo en bases de datos académicas | CP4: 0 | CR4: Ni en acuerdo, ni en desacuerdo. | CS4: 0 | CU4: De acuerdo. | CV4: 0 | CX4: Totalmente de acuerdo. | CY4: 0 | DA4: Sí. | DB4: 0 | DD4: Ni en acuerdo, ni en desacuerdo. | DE4: 0 | DG4: Ni en acuerdo, ni en desacuerdo. | DH4: 0 | DJ4: Ni en acuerdo, ni en desacuerdo. | DK4: 0 | DM4: De acuerdo. | DN4: 0 | DP4: Totalmente de acuerdo. | DQ4: 0 | DS4: Tecnología (desarrollo de software, IA, ciberseguridad, telecomunicaciones) | DT4: 0 | DV4: Totalmente de acuerdo. | DW4: 0 | DY4: Totalmente de acuerdo. | DZ4: 0 | EB4: Universidad Distrital Francisco Jose de Caldas | EC4: 0 | EE4: Alejandro Daza | EF4: 0
A5: 3 | B5: 45719.713 | C5: 45719.713 | D5: wfpinedar@udistrital.edu.co | E5: WILMAR FERNANDO PINEDA ROJAS | I5: Wilmar\ Fernando\ Pineda\ Rojas | J5: 0 | L5: 1015416478 | M5: 0 | O5: 31 a 40 | P5: 0 | R5: 3017852790 | S5: 0 | U5: 2024 | V5: 0 | X5: Ingeniería de Software | Y5: 0 | AA5: Profundización | AB5: 0 | AD5: Redes complejas y sistemas de radar | AE5: 0 | AG5: Si | AH5: 0 | AJ5: Si. | AK5: 0 | AM5: Totalmente de acuerdo. | AN5: 0 | AP5: escritura de articulos, esto contribuye a extender el entendimiento de la ciencia en las areas del conocimiento en la cual me desempeño laboralmente. | AQ5: 0 | AS5: De acuerdo. | AT5: 0 | AV5: de momento no. | AW5: 0 | AY5: Ni en acuerdo, ni en desacuerdo. | AZ5: 0 | BB5: Una estrategia clara acerca de los mismos, que evite el proceso infructuoso y desgastante de los procesos para acceder a dichos estimulos que no estan debidamente reglamentados. | BC5: 0 | BE5: De acuerdo. | BF5: 0 | BH5: De acuerdo. | BI5: 0 | BK5: De acuerdo. | BL5: 0 | BN5: Por que me permiten acceder a la formación enfocada en mis objetivos. | BO5: 0 | BQ5: Estos abarcan grandes areas del conocimiento aplicable en le quehacer profesional. | BR5: 0 | BT5: De acuerdo. | BU5: 0 | BW5: De acuerdo. | BX5: 0 | BZ5: De acuerdo. | CA5: 0 | CC5: De acuerdo. | CD5: 0 | CF5: De acuerdo. | CG5: 0 | CI5: De momento no tengo ninguno en la mente. | CJ5: 0 | CL5: De acuerdo. | CM5: 0 | CO5: La lectura y desarrollo de multiples articuos y proyectos enfocados en areas del conocimiento que son diversas me ha contribuido a mejorar mi forma de investigación. | CP5: 0 | CR5: Ni en acuerdo, ni en desacuerdo. | CS5: 0 | CU5: De acuerdo. | CV5: 0 | CX5: De acuerdo. | CY5: 0 | DA5: No sabe/ No responde. | DB5: 0 | DD5: De acuerdo. | DE5: 0 | DG5: Ni en acuerdo, ni en desacuerdo. | DH5: 0 | DJ5: De acuerdo. | DK5: 0 | DM5: Ni en acuerdo, ni en desacuerdo. | DN5: 0 | DP5: Ni en acuerdo, ni en desacuerdo. | DQ5: 0 | DS5: Tecnología (desarrollo de software, IA, ciberseguridad, telecomunicaciones) | DT5: 0 | DV5: Totalmente de acuerdo. | DW5: 0 | DY5: Ni en acuerdo, ni en desacuerdo. | DZ5: 0 | EB5: Imagemaker | EC5: 0 | EE5: Actualmente no tengo jefe directo. | EF5: 0
A6: 4 | B6: 45719.912 | C6: 45719.912 | D6: lpgarciam@udistrital.edu.co | E6: LINA PAOLA GARCIA MALAGON | I6: Lina\ Paola\ García\ Malagón | J6: 0 | L6: 1075687506 | M6: 0 | O6: 25 a 30 | P6: 0 | R6: 3008450551 | S6: 0 | U6: 2024 | V6: 0 | X6: Geomtatica | Y6: 0 | AA6: Profundización | AB6: 0 | AD6: Análisis espacial - Geomática - Gestión del Riesgo | AE6: 0 | AG6: Si | AH6: 0 | AJ6: La\ incorporación\ de\ este\ idioma\ en\ una\ asignatura\ sería\ impor\tan te\ porque\ promoveria\ la\ práctica\ de\ este\ idioma\ que\ aportaría\ a\ que\ en\ la\ vida\ academica\ y\ profesional\ se\ tenga\ mejor\ manejo\ de\ este\ como\ segundo\ idioma | AK6: 0 | AM6: De acuerdo. | AN6: 0 | AP6: Participe en el Seminario en IA y Machine Learning - Posgrado Fac. Ingeniería U. Distrital y aporto bastante a mi curso de big data y al entendimiento de la inteligencia artificial y su importancia, también participe en el reto de desarrolladores el cual tuvo un nivel alto y se pudieron aplicar diversos conocimientos obtenidos a lo largo de la Maestría para brindar una solución. | AQ6: 0 | AS6: Totalmente de acuerdo. | AT6: 0 | AV6: Tal vez enviarlos por medio como el Grupo de Whatsapp en formatos como infografías | AW6: 0 | AY6: Totalmente de acuerdo. | AZ6: 0 | BB6: Me parece que la aplicación de estímulos y apoyos socioeconómicos que maneja son adecuados y de conocimiento para todo aquel que quiera optar por realizar la MCIC | BC6: 0 | BE6: Totalmente de acuerdo. | BF6: 0 | BH6: Totalmente de acuerdo. | BI6: 0 | BK6: De acuerdo. | BL6: 0 | BN6: Opte por elegir como electiva Big data en donde vimos temas de inteligencia artifical que actualmente es un tema de ínteres en el mundo al igual que en la vida profesional esta asignatura me permitió entender de una mejor manera los conceptos que muchas veces son aplicado en mi trabajo. | BO6: 0 | BQ6: Adecuada y pertinente | BR6: 0 | BT6: Totalmente de acuerdo. | BU6: 0 | BW6: Totalmente de acuerdo. | BX6: 0 | BZ6: De acuerdo. | CA6: 0 | CC6: De acuerdo. | CD6: 0 | CF6: Ni en acuerdo, ni en desacuerdo. | CG6: 0 | CI6: Tengo conocimiento que actualmente se esta manejando algunos proyectos con el IGAC, para una colaboración interinstitucional. | CJ6: 0 | CL6: De acuerdo. | CM6: 0 | CO6: El reto de desarrolladores de Esri. | CP6: 0 | CR6: De acuerdo. | CS6: 0 | CU6: De acuerdo. | CV6: 0 | CX6: Totalmente de acuerdo. | CY6: 0 | DA6: Sí. | DB6: 0 | DD6: Totalmente de acuerdo. | DE6: 0 | DG6: Totalmente en desacuerdo. | DH6: 0 | DJ6: De acuerdo. | DK6: 0 | DM6: Totalmente de acuerdo. | DN6: 0 | DP6: Totalmente de acuerdo. | DQ6: 0 | DS6: Sector público (administración pública, gobierno) | DT6: 0 | DV6: Totalmente de acuerdo. | DW6: 0 | DY6: Totalmente de acuerdo. | DZ6: 0 | EB6: Instituto Geográfico Agustín Codazzi | EC6: 0 | EE6: Johan Andres Avendaño Arias - johan.avendano@igac.gov.co | EF6: 0
A7: 5 | B7: 45720.287 | C7: 45720.299 | D7: jgonzalezs@udistrital.edu.co | E7: JHONATAN GONZALEZ SALGUERO | I7: JHONATAN\ GONZALEZ\ SALGUERO | J7: 0 | L7: 1024486322 | M7: 0 | O7: 31 a 40 | P7: 0 | R7: 3153934467 | S7: 0 | U7: 2024 | V7: 0 | X7: Geomtatica | Y7: 0 | AA7: Profundización | AB7: 0 | AD7: Machine learning | AE7: 0 | AG7: Si | AH7: 0 | AJ7: Al\ ser\ una\ materia\ impratida\ en\ inglés,\ se\ podría\ aprender\ mucho\ vocabulario\ técnico\ acorde\ a\ la\ carrea,\ a\lg o\ que\ no\ se\ ve\ en\ cursos\ normales\ de\ inglés | AK7: 0 | AM7: Ni en acuerdo, ni en desacuerdo. | AN7: 0 | AP7: Ninguna | AQ7: 0 | AS7: De acuerdo. | AT7: 0 | AV7: Podría ser en la materia de seminario de investigación dedicarle una clase inicial a reforzar esto | AW7: 0 | AY7: Ni en acuerdo, ni en desacuerdo. | AZ7: 0 | BB7: Una mayor divulgación de los mismos de manera frecuente | BC7: 0 | BE7: De acuerdo. | BF7: 0 | BH7: De acuerdo. | BI7: 0 | BK7: Ni en acuerdo, ni en desacuerdo. | BL7: 0 | BN7: Ninguna | BO7: 0 | BQ7: Muy buena | BR7: 0 | BT7: De acuerdo. | BU7: 0 | BW7: De acuerdo. | BX7: 0 | BZ7: De acuerdo. | CA7: 0 | CC7: De acuerdo. | CD7: 0 | CF7: Ni en acuerdo, ni en desacuerdo. | CG7: 0 | CI7: No tengo ningún ejemplo | CJ7: 0 | CL7: De acuerdo. | CM7: 0 | CO7: Conferencias sobre inteligencia artificial hechas en la universidad | CP7: 0 | CR7: De acuerdo. | CS7: 0 | CU7: De acuerdo. | CV7: 0 | CX7: Ni en acuerdo, ni en desacuerdo. | CY7: 0 | DA7: No. | DB7: 0 | DD7: Ni en acuerdo, ni en desacuerdo. | DE7: 0 | DG7: En desacuerdo. | DH7: 0 | DJ7: Ni en acuerdo, ni en desacuerdo. | DK7: 0 | DM7: De acuerdo. | DN7: 0 | DP7: Ni en acuerdo, ni en desacuerdo. | DQ7: 0 | DS7: Sector público (administración pública, gobierno) | DT7: 0 | DV7: Ni en acuerdo, ni en desacuerdo. | DW7: 0 | DY7: En desacuerdo. | DZ7: 0 | EB7: UT CATASTRO MULTIPROPOSITO | EC7: 0 | EE7: CARLOS ARTURO CASTELLANOS CASTILLO - 3002324325 | EF7: 0
A8: 6 | B8: 45720.497 | C8: 45720.549 | D8: fzubietac@udistrital.edu.co | E8: FERNANDO ZUBIETA CORTES | I8: Fernando Zubieta | J8: 0 | L8: 1033798653 | M8: 0 | O8: 25 a 30 | P8: 0 | R8: 3194467960 | S8: 0 | U8: 2024 | V8: 0 | X8: Geomtatica | Y8: 0 | AA8: Profundización | AB8: 0 | AD8: Geomática, Economía, SIG | AE8: 0 | AG8: Si | AH8: 0 | AJ8: Ayuda a mejorar la práctica y la dialéctica del idioma | AK8: 0 | AM8: Ni en acuerdo, ni en desacuerdo. | AN8: 0 | AP8: No he participado en el momento | AQ8: 0 | AS8: Ni en acuerdo, ni en desacuerdo. | AT8: 0 | AV8: Mejorar los canales de comunicación del programa | AW8: 0 | AY8: De acuerdo. | AZ8: 0 | BB8: Analizar los datos sociodemográficos de los aspirantes para generar matrículas más justas y acordes con la realidad económica de la población, ésto aumentaría el nivel de cobertura en posgrado | BC8: 0 | BE8: Totalmente de acuerdo. | BF8: 0 | BH8: Totalmente de acuerdo. | BI8: 0 | BK8: Ni en acuerdo, ni en desacuerdo. | BL8: 0 | BN8: No conozco rutas de formación alternativas del programa | BO8: 0 | BQ8: Acorde con la estructura tecnológica del mercado laboral | BR8: 0 | BT8: De acuerdo. | BU8: 0 | BW8: Ni en acuerdo, ni en desacuerdo. | BX8: 0 | BZ8: Ni en acuerdo, ni en desacuerdo. | CA8: 0 | CC8: De acuerdo. | CD8: 0 | CF8: Ni en acuerdo, ni en desacuerdo. | CG8: 0 | CI8: No conozco éste tipo de cooperaciones | CJ8: 0 | CL8: Totalmente de acuerdo. | CM8: 0 | CO8: Innovación del conocimiento | CP8: 0 | CR8: Ni en acuerdo, ni en desacuerdo. | CS8: 0 | CU8: En desacuerdo. | CV8: 0 | CX8: De acuerdo. | CY8: 0 | DA8: No sabe/ No responde. | DB8: 0 | DD8: Totalmente de acuerdo. | DE8: 0 | DG8: Ni en acuerdo, ni en desacuerdo. | DH8: 0 | DJ8: En desacuerdo. | DK8: 0 | DM8: De acuerdo. | DN8: 0 | DP8: Ni en acuerdo, ni en desacuerdo. | DQ8: 0 | DS8: Tecnología (desarrollo de software, IA, ciberseguridad, telecomunicaciones) | DT8: 0 | DV8: De acuerdo. | DW8: 0 | DY8: Ni en acuerdo, ni en desacuerdo. | DZ8: 0 | EB8: Simón Movilidad | EC8: 0 | EE8: No puedo dar esa información | EF8: 0
A9: 7 | B9: 45720.572 | C9: 45720.583 | D9: jecaicedon@udistrital.edu.co | E9: EDUARDO NAVARRO JOAQUIN | I9: Joaquin\ Eduardo\ Caicedo\ Navarro | J9: 0 | L9: 1024481940 | M9: 0 | O9: 31 a 40 | P9: 0 | R9: 3232898653 | S9: 0 | U9: 2020 | V9: 0 | X9: Ingeniería de Software | Y9: 0 | AA9: Investigación | AB9: 0 | AD9: Calidad de potencia, Inteligencia Artificial | AE9: 0 | AG9: Si | AH9: 0 | AJ9: Mejor\ prepararacion\ para\ trabajar\ en\ empresas\ extranjeras | AK9: 0 | AM9: Totalmente de acuerdo. | AN9: 0 | AP9: Preparación y publicación de artículos científicos. Me ha formado como investigador | AQ9: 0 | AS9: Ni en acuerdo, ni en desacuerdo. | AT9: 0 | AV9: No | AW9: 0 | AY9: Totalmente de acuerdo. | AZ9: 0 | BB9: Mayor divulgación de los posibles beneficios | BC9: 0 | BE9: De acuerdo. | BF9: 0 | BH9: De acuerdo. | BI9: 0 | BK9: Totalmente de acuerdo. | BL9: 0 | BN9: He podido participar en materias diversas, como por ejemplo, en diferentes áreas de inteligencia artificial | BO9: 0 | BQ9: Los énfasis son efectivos | BR9: 0 | BT9: De acuerdo. | BU9: 0 | BW9: De acuerdo. | BX9: 0 | BZ9: De acuerdo. | CA9: 0 | CC9: De acuerdo. | CD9: 0 | CF9: Totalmente de acuerdo. | CG9: 0 | CI9: Convocatorias de la ODI para llevar a cabo participación en conferencias académicas | CJ9: 0 | CL9: Totalmente de acuerdo. | CM9: 0 | CO9: Desarrollo de artículos de investigación como parte de la evaluación en materias como Bases de Datos, Inteligencia Computacional, Minería de datos, etc. Proyectos integradores como en las materias Tendencias en ingeniería de software y Computación en la nube | CP9: 0 | CR9: De acuerdo. | CS9: 0 | CU9: De acuerdo. | CV9: 0 | CX9: Totalmente de acuerdo. | CY9: 0 | DA9: No sabe/ No responde. | DB9: 0 | DD9: Totalmente de acuerdo. | DE9: 0 | DG9: Ni en acuerdo, ni en desacuerdo. | DH9: 0 | DJ9: De acuerdo. | DK9: 0 | DM9: Totalmente de acuerdo. | DN9: 0 | DP9: De acuerdo. | DQ9: 0 | DS9: Sector secundario (industria manufacturera, construcción, energía) | DT9: 0 | DV9: Totalmente de acuerdo. | DW9: 0 | DY9: Totalmente de acuerdo. | DZ9: 0 | EB9: Empresa de Energía de San Andrés | EC9: 0 | EE9: Wilmar Moreno (Supervisor de contrato). Email: consultenergy2021@gmail.com | EF9: 0
A10: 8 | B10: 45721.448 | C10: 45721.462 | D10: juamgarzong@udistrital.edu.co | E10: JUAN MANUEL GARZON GIL | I10: Juan\ Manuel\ Garzón\ Gil | J10: 0 | L10: 1014263322 | M10: 0 | O10: 25 a 30 | P10: 0 | R10: 3138717415 | S10: 0 | U10: 2025 | V10: 0 | X10: Geomtatica | Y10: 0 | AA10: Profundización | AB10: 0 | AD10: Calidad del aire, imágenes satelitales, vegetación urbana, ordenamiento territorial | AE10: 0 | AG10: No | AH10: 0 | AJ10: Abre\ as\ purts\ a\ un\ comercio\ internacional,\ también\ mejora\ el\ acceso\ a\ ayor\ \inf ormación\ ya\ que\ la\ comundad\ y\ los\ recursos\ es\tan\ en\ ese\ idioma | AK10: 0 | AM10: De acuerdo. | AN10: 0 | AP10: Trabaje en mi proyecto de grado en la modalidad de investigación e innovación, esta fue patrocinada por minciencias, me ayudo en procesos de redacción, manejo de datos, sustentación de hallazgos, adquisición de conocimiento en un área especifica. | AQ10: 0 | AS10: De acuerdo. | AT10: 0 | AV10: No | AW10: 0 | AY10: Ni en acuerdo, ni en desacuerdo. | AZ10: 0 | BB10: Mejorar la divulgación y que los tiempos para aplicar sean coherentes con dicha divulgación | BC10: 0 | BE10: De acuerdo. | BF10: 0 | BH10: De acuerdo. | BI10: 0 | BK10: Ni en acuerdo, ni en desacuerdo. | BL10: 0 | BN10: No tengo mayor conocimiento sobre este tema | BO10: 0 | BQ10: Considero que son adecuados. | BR10: 0 | BT10: De acuerdo. | BU10: 0 | BW10: Totalmente de acuerdo. | BX10: 0 | BZ10: De acuerdo. | CA10: 0 | CC10: De acuerdo. | CD10: 0 | CF10: Ni en acuerdo, ni en desacuerdo. | CG10: 0 | CI10: Al momento no | CJ10: 0 | CL10: Totalmente de acuerdo. | CM10: 0 | CO10: Hasta el momento solo en clases, donde la forma de exponer los temas e interactuar con los estudiantes, fomenta un pensamiento diferente sobre los temas que se ven y permiten el pensar variables para los métodos expuestos | CP10: 0 | CR10: Ni en acuerdo, ni en desacuerdo. | CS10: 0 | CU10: De acuerdo. | CV10: 0 | CX10: En desacuerdo. | CY10: 0 | DA10: No sabe/ No responde. | DB10: 0 | DD10: De acuerdo. | DE10: 0 | DG10: Ni en acuerdo, ni en desacuerdo. | DH10: 0 | DJ10: De acuerdo. | DK10: 0 | DM10: De acuerdo. | DN10: 0 | DP10: De acuerdo. | DQ10: 0 | DS10: Tecnología (desarrollo de software, IA, ciberseguridad, telecomunicaciones) | DT10: 0 | DV10: De acuerdo. | DW10: 0 | DY10: Ni en acuerdo, ni en desacuerdo. | DZ10: 0 | EB10: ETB | EC10: 0 | EE10: No me es posible | EF10: 0
A11: 9 | B11: 45721.765 | C11: 45721.771 | D11: sforeroz@udistrital.edu.co | E11: SEBASTIAN FORERO ZAPATA | I11: SEBASTIAN FORERO ZAPATA | J11: 0 | L11: 1000514921 | M11: 0 | O11: 25 a 30 | P11: 0 | R11: 3194970523 | S11: 0 | U11: 2024 | V11: 0 | X11: Geomtatica | Y11: 0 | AA11: Investigación | AB11: 0 | AD11: INTELIGENCIA ARTIFICIAL | AE11: 0 | AG11: Si | AH11: 0 | AJ11: MEJORAR IDIOMA Y ACCEDER A MEJORES OPORTUNIDADES | AK11: 0 | AM11: De acuerdo. | AN11: 0 | AP11: CHARLAS, HACKATONES, WEBINAR. AYUDAN A MEJORAR HABILIDADES TEORICAS Y TECNICAS | AQ11: 0 | AS11: De acuerdo. | AT11: 0 | AV11: NO | AW11: 0 | AY11: De acuerdo. | AZ11: 0 | BB11: INCENTIVO PERMANENCIA O APOYO | BC11: 0 | BE11: De acuerdo. | BF11: 0 | BH11: De acuerdo. | BI11: 0 | BK11: De acuerdo. | BL11: 0 | BN11: DANDO MAS OPCIONES DE MEJORA ACADEMICA | BO11: 0 | BQ11: DE ACUERDO CON LAS NECESIDADES DEL MERCADO ACTUALMENTE | BR11: 0 | BT11: De acuerdo. | BU11: 0 | BW11: De acuerdo. | BX11: 0 | BZ11: De acuerdo. | CA11: 0 | CC11: De acuerdo. | CD11: 0 | CF11: De acuerdo. | CG11: 0 | CI11: NINGUNA | CJ11: 0 | CL11: De acuerdo. | CM11: 0 | CO11: PARTICIPACION EN TALLERES CHARLAS | CP11: 0 | CR11: De acuerdo. | CS11: 0 | CU11: De acuerdo. | CV11: 0 | CX11: De acuerdo. | CY11: 0 | DA11: Sí. | DB11: 0 | DD11: De acuerdo. | DE11: 0 | DG11: De acuerdo. | DH11: 0 | DJ11: De acuerdo. | DK11: 0 | DM11: De acuerdo. | DN11: 0 | DP11: De acuerdo. | DQ11: 0 | DS11: Tecnología (desarrollo de software, IA, ciberseguridad, telecomunicaciones) | DT11: 0 | DV11: De acuerdo. | DW11: 0 | DY11: Ni en acuerdo, ni en desacuerdo. | DZ11: 0 | EB11: ESRI COLOMBIA | EC11: 0 | EE11: DEIRO GONZALEZ | EF11: 0
A12: 10 | B12: 45721.765 | C12: 45721.776 | D12: jeahernandezn@udistrital.edu.co | E12: ANDRES NAVARRETE JEISSON | I12: JEISSON\ ANDRES\ HERNANDEZ\ NAVARRETE | J12: 0 | L12: 1014298952 | M12: 0 | O12: 25 a 30 | P12: 0 | R12: 3209190949 | S12: 0 | U12: 2024 | V12: 0 | X12: Geomtatica | Y12: 0 | AA12: Investigación | AB12: 0 | AD12: Procesamiento digital de imágenes, análisis espacial, series de tiempo | AE12: 0 | AG12: Si | AH12: 0 | AJ12: Una\ asignatura\ en\ inglés\ puede\ ayudar\ a\ reforzar\ la\ comprensión\ y\ producción\ de\ conocimiento\ científico\ y\ preparar\ para\ posibles\ estudios\ posteriores. | AK12: 0 | AM12: Totalmente de acuerdo. | AN12: 0 | AP12: El desarrollo del proyecto de grado como actividad transversal al desarrollo de la maestría permite tomar los temas impartidos en las asignaturas desde un punto de vista mas crítico y enriquecedor por el lado de la investigación propia | AQ12: 0 | AS12: Totalmente de acuerdo. | AT12: 0 | AV12: No | AW12: 0 | AY12: Totalmente de acuerdo. | AZ12: 0 | BB12: NA | BC12: 0 | BE12: Totalmente de acuerdo. | BF12: 0 | BH12: Totalmente de acuerdo. | BI12: 0 | BK12: Totalmente de acuerdo. | BL12: 0 | BN12: La posibilidad de tomar asignaturas electivas de otro énfasis permite ampliar el horizonte de conocimientos e intentar aplicar metodologías diferentes para el análisis de información laboral y académica | BO12: 0 | BQ12: Desde el énfasis de geomática se obtienen conocimientos que aplican para el desarrollo de proyectos por fuera del contexto académico | BR12: 0 | BT12: De acuerdo. | BU12: 0 | BW12: De acuerdo. | BX12: 0 | BZ12: Ni en acuerdo, ni en desacuerdo. | CA12: 0 | CC12: Totalmente de acuerdo. | CD12: 0 | CF12: De acuerdo. | CG12: 0 | CI12: La participación en el reto de desarrolladores de ESRI | CJ12: 0 | CL12: De acuerdo. | CM12: 0 | CO12: El desarrollo del proyecto de grado de la maestría | CP12: 0 | CR12: Ni en acuerdo, ni en desacuerdo. | CS12: 0 | CU12: De acuerdo. | CV12: 0 | CX12: Ni en acuerdo, ni en desacuerdo. | CY12: 0 | DA12: Sí. | DB12: 0 | DD12: De acuerdo. | DE12: 0 | DG12: En desacuerdo. | DH12: 0 | DJ12: Totalmente de acuerdo. | DK12: 0 | DM12: Totalmente de acuerdo. | DN12: 0 | DP12: De acuerdo. | DQ12: 0 | DS12: Sector terciario (comercio, servicios: educación, salud, finanzas, etc.) | DT12: 0 | DV12: De acuerdo. | DW12: 0 | DY12: Ni en acuerdo, ni en desacuerdo. | DZ12: 0 | EB12: GEOS SAS | EC12: 0 | EE12: NA | EF12: 0
A13: 11 | B13: 45721.767 | C13: 45721.776 | D13: cisancheza@udistrital.edu.co | E13: CARLOS IVAN SANCHEZ ARIZA | I13: Carlos Ivan Sanchez Ariza | J13: 0 | L13: 1022377565 | M13: 0 | O13: 31 a 40 | P13: 0 | R13: 3013997773 | S13: 0 | U13: 2024 | V13: 0 | X13: Geomtatica | Y13: 0 | AA13: Profundización | AB13: 0 | AD13: Geomatica | AE13: 0 | AG13: No | AH13: 0 | AJ13: Familiarizacion con el idioma | AK13: 0 | AM13: Ni en acuerdo, ni en desacuerdo. | AN13: 0 | AP13: En impacto ambiental | AQ13: 0 | AS13: Ni en acuerdo, ni en desacuerdo. | AT13: 0 | AV13: Ninguna | AW13: 0 | AY13: De acuerdo. | AZ13: 0 | BB13: Ninguna | BC13: 0 | BE13: Ni en acuerdo, ni en desacuerdo. | BF13: 0 | BH13: Ni en acuerdo, ni en desacuerdo. | BI13: 0 | BK13: Ni en acuerdo, ni en desacuerdo. | BL13: 0 | BN13: No se entiende la pregunta | BO13: 0 | BQ13: Acertada | BR13: 0 | BT13: En desacuerdo. | BU13: 0 | BW13: Ni en acuerdo, ni en desacuerdo. | BX13: 0 | BZ13: En desacuerdo. | CA13: 0 | CC13: De acuerdo. | CD13: 0 | CF13: Ni en acuerdo, ni en desacuerdo. | CG13: 0 | CI13: modelo dinámico para analizar los factores ambientales y antropogenicos en el páramo de chingaza | CJ13: 0 | CL13: De acuerdo. | CM13: 0 | CO13: En mi proyecto de grado: modelo dinámico para analizar los factores ambientales y antropogenicos en el páramo de chingaza | CP13: 0 | CR13: En desacuerdo. | CS13: 0 | CU13: Ni en acuerdo, ni en desacuerdo. | CV13: 0 | CX13: En desacuerdo. | CY13: 0 | DA13: No sabe/ No responde. | DB13: 0 | DD13: De acuerdo. | DE13: 0 | DG13: Ni en acuerdo, ni en desacuerdo. | DH13: 0 | DJ13: De acuerdo. | DK13: 0 | DM13: Ni en acuerdo, ni en desacuerdo. | DN13: 0 | DP13: Ni en acuerdo, ni en desacuerdo. | DQ13: 0 | DS13: Otro | DT13: 0 | DV13: Ni en acuerdo, ni en desacuerdo. | DW13: 0 | DY13: Ni en acuerdo, ni en desacuerdo. | DZ13: 0 | EB13: IGAC | EC13: 0 | EE13: Recién entré entonces no tengo contacto con la persona encargada | EF13: 0
A14: 12 | B14: 45721.766 | C14: 45721.778 | D14: rvcastroa@udistrital.edu.co | E14: RUSBY VANESSA CASTRO ALFEREZ | I14: Rusby\ Vanessa\ Castro\ Alferez | J14: 0 | L14: 1030683963 | M14: 0 | O14: 25 a 30 | P14: 0 | R14: 3196297112 | S14: 0 | U14: 2024 | V14: 0 | X14: Geomtatica | Y14: 0 | AA14: Profundización | AB14: 0 | AD14: estadística, econometría | AE14: 0 | AG14: Si | AH14: 0 | AJ14: podria\ afianzar\ mis\ conocimientos\ en\ el\ idioma | AK14: 0 | AM14: Totalmente de acuerdo. | AN14: 0 | AP14: La realización de artículos de investigación en cada una de las asignaturas de la maestría con el fin de reforzar y crear conocimientos en el estudiante. | AQ14: 0 | AS14: De acuerdo. | AT14: 0 | AV14: teniendo un canal de difusión actualizado | AW14: 0 | AY14: En desacuerdo. | AZ14: 0 | BB14: No poner un limite en las notas de los estudiantes ya que muchos no cuentan con los recursos y tienen que desertar la carrera por ello | BC14: 0 | BE14: De acuerdo. | BF14: 0 | BH14: De acuerdo. | BI14: 0 | BK14: Totalmente en desacuerdo. | BL14: 0 | BN14: Quizás faltan oferta de espacios académicos de acuerdo a los énfasis de cada estudiante. | BO14: 0 | BQ14: Ayuda a enfocar al estudiante en un área de interés, sin embargo es bueno que se oferten mas electivas de acuerdo al énfasis escogido | BR14: 0 | BT14: Ni en acuerdo, ni en desacuerdo. | BU14: 0 | BW14: De acuerdo. | BX14: 0 | BZ14: De acuerdo. | CA14: 0 | CC14: De acuerdo. | CD14: 0 | CF14: Ni en acuerdo, ni en desacuerdo. | CG14: 0 | CI14: No he evidenciado estos ejemplos | CJ14: 0 | CL14: De acuerdo. | CM14: 0 | CO14: La realización de papers y artículos científicos en cada una de las asignaturas | CP14: 0 | CR14: De acuerdo. | CS14: 0 | CU14: De acuerdo. | CV14: 0 | CX14: Ni en acuerdo, ni en desacuerdo. | CY14: 0 | DA14: Sí. | DB14: 0 | DD14: Totalmente de acuerdo. | DE14: 0 | DG14: Ni en acuerdo, ni en desacuerdo. | DH14: 0 | DJ14: De acuerdo. | DK14: 0 | DM14: En desacuerdo. | DN14: 0 | DP14: De acuerdo. | DQ14: 0 | DS14: Otro | DT14: 0 | DV14: De acuerdo. | DW14: 0 | DY14: En desacuerdo. | DZ14: 0 | EB14: No cuento con empleo actualmente | EC14: 0 | EE14: No cuento con empleo actualmente | EF14: 0
